{
  "resolution": 29,
  "gridSize": {
    "x": 28,
    "y": 16,
    "z": 29
  },
  "voxelCount": 4097,
  "voxels": [
    {
      "x": 3,
      "y": 9,
      "z": 22,
      "r": 5,
      "g": 134,
      "b": 5
    },
    {
      "x": 4,
      "y": 9,
      "z": 22,
      "r": 134,
      "g": 110,
      "b": 8
    },
    {
      "x": 12,
      "y": 9,
      "z": 22,
      "r": 143,
      "g": 223,
      "b": 87
    },
    {
      "x": 15,
      "y": 9,
      "z": 19,
      "r": 176,
      "g": 27,
      "b": 148
    },
    {
      "x": 15,
      "y": 9,
      "z": 15,
      "r": 27,
      "g": 88,
      "b": 176
    },
    {
      "x": 17,
      "y": 9,
      "z": 14,
      "r": 176,
      "g": 27,
      "b": 148
    },
    {
      "x": 19,
      "y": 2,
      "z": 24,
      "r": 228,
      "g": 166,
      "b": 214
    },
    {
      "x": 13,
      "y": 2,
      "z": 14,
      "r": 228,
      "g": 166,
      "b": 214
    },
    {
      "x": 12,
      "y": 2,
      "z": 14,
      "r": 223,
      "g": 198,
      "b": 87
    },
    {
      "x": 6,
      "y": 2,
      "z": 19,
      "r": 5,
      "g": 134,
      "b": 5
    },
    {
      "x": 13,
      "y": 2,
      "z": 20,
      "r": 228,
      "g": 166,
      "b": 214
    },
    {
      "x": 15,
      "y": 2,
      "z": 21,
      "r": 134,
      "g": 110,
      "b": 8
    },
    {
      "x": 18,
      "y": 2,
      "z": 15,
      "r": 5,
      "g": 134,
      "b": 5
    },
    {
      "x": 15,
      "y": 2,
      "z": 15,
      "r": 143,
      "g": 223,
      "b": 87
    },
    {
      "x": 15,
      "y": 2,
      "z": 14,
      "r": 143,
      "g": 223,
      "b": 87
    },
    {
      "x": 17,
      "y": 2,
      "z": 17,
      "r": 176,
      "g": 27,
      "b": 148
    },
    {
      "x": 0,
      "y": 0,
      "z": 27,
      "r": 143,
      "g": 223,
      "b": 87
    },
    {
      "x": 0,
      "y": 1,
      "z": 27,
      "r": 143,
      "g": 223,
      "b": 87
    },
    {
      "x": 0,
      "y": 2,
      "z": 27,
      "r": 143,
      "g": 223,
      "b": 87
    },
    {
      "x": 0,
      "y": 3,
      "z": 27,
      "r": 143,
      "g": 223,
      "b": 87
    },
    {
      "x": 1,
      "y": 0,
      "z": 27,
      "r": 143,
      "g": 223,
      "b": 87
    },
    {
      "x": 1,
      "y": 1,
      "z": 27,
      "r": 143,
      "g": 223,
      "b": 87
    },
    {
      "x": 1,
      "y": 2,
      "z": 27,
      "r": 143,
      "g": 223,
      "b": 87
    },
    {
      "x": 1,
      "y": 3,
      "z": 27,
      "r": 143,
      "g": 223,
      "b": 87
    },
    {
      "x": 1,
      "y": 4,
      "z": 27,
      "r": 143,
      "g": 223,
      "b": 87
    },
    {
      "x": 1,
      "y": 5,
      "z": 27,
      "r": 143,
      "g": 223,
      "b": 87
    },
    {
      "x": 1,
      "y": 6,
      "z": 27,
      "r": 143,
      "g": 223,
      "b": 87
    },
    {
      "x": 0,
      "y": 4,
      "z": 27,
      "r": 143,
      "g": 223,
      "b": 87
    },
    {
      "x": 0,
      "y": 5,
      "z": 27,
      "r": 143,
      "g": 223,
      "b": 87
    },
    {
      "x": 0,
      "y": 6,
      "z": 27,
      "r": 143,
      "g": 223,
      "b": 87
    },
    {
      "x": 0,
      "y": 0,
      "z": 26,
      "r": 143,
      "g": 223,
      "b": 87
    },
    {
      "x": 0,
      "y": 1,
      "z": 26,
      "r": 143,
      "g": 223,
      "b": 87
    },
    {
      "x": 0,
      "y": 2,
      "z": 26,
      "r": 143,
      "g": 223,
      "b": 87
    },
    {
      "x": 0,
      "y": 3,
      "z": 26,
      "r": 143,
      "g": 223,
      "b": 87
    },
    {
      "x": 0,
      "y": 4,
      "z": 26,
      "r": 143,
      "g": 223,
      "b": 87
    },
    {
      "x": 0,
      "y": 5,
      "z": 26,
      "r": 143,
      "g": 223,
      "b": 87
    },
    {
      "x": 0,
      "y": 6,
      "z": 26,
      "r": 143,
      "g": 223,
      "b": 87
    },
    {
      "x": 21,
      "y": 0,
      "z": 26,
      "r": 143,
      "g": 223,
      "b": 87
    },
    {
      "x": 21,
      "y": 1,
      "z": 26,
      "r": 143,
      "g": 223,
      "b": 87
    },
    {
      "x": 21,
      "y": 2,
      "z": 26,
      "r": 143,
      "g": 223,
      "b": 87
    },
    {
      "x": 21,
      "y": 3,
      "z": 26,
      "r": 143,
      "g": 223,
      "b": 87
    },
    {
      "x": 21,
      "y": 4,
      "z": 26,
      "r": 143,
      "g": 223,
      "b": 87
    },
    {
      "x": 21,
      "y": 5,
      "z": 26,
      "r": 143,
      "g": 223,
      "b": 87
    },
    {
      "x": 21,
      "y": 6,
      "z": 26,
      "r": 143,
      "g": 223,
      "b": 87
    },
    {
      "x": 24,
      "y": 0,
      "z": 18,
      "r": 143,
      "g": 223,
      "b": 87
    },
    {
      "x": 25,
      "y": 0,
      "z": 18,
      "r": 143,
      "g": 223,
      "b": 87
    },
    {
      "x": 25,
      "y": 1,
      "z": 18,
      "r": 143,
      "g": 223,
      "b": 87
    },
    {
      "x": 25,
      "y": 2,
      "z": 18,
      "r": 143,
      "g": 223,
      "b": 87
    },
    {
      "x": 25,
      "y": 3,
      "z": 18,
      "r": 143,
      "g": 223,
      "b": 87
    },
    {
      "x": 25,
      "y": 4,
      "z": 18,
      "r": 143,
      "g": 223,
      "b": 87
    },
    {
      "x": 25,
      "y": 5,
      "z": 18,
      "r": 143,
      "g": 223,
      "b": 87
    },
    {
      "x": 25,
      "y": 6,
      "z": 18,
      "r": 143,
      "g": 223,
      "b": 87
    },
    {
      "x": 24,
      "y": 1,
      "z": 18,
      "r": 143,
      "g": 223,
      "b": 87
    },
    {
      "x": 24,
      "y": 2,
      "z": 18,
      "r": 143,
      "g": 223,
      "b": 87
    },
    {
      "x": 24,
      "y": 3,
      "z": 18,
      "r": 143,
      "g": 223,
      "b": 87
    },
    {
      "x": 24,
      "y": 4,
      "z": 18,
      "r": 143,
      "g": 223,
      "b": 87
    },
    {
      "x": 24,
      "y": 5,
      "z": 18,
      "r": 143,
      "g": 223,
      "b": 87
    },
    {
      "x": 24,
      "y": 6,
      "z": 18,
      "r": 143,
      "g": 223,
      "b": 87
    },
    {
      "x": 25,
      "y": 0,
      "z": 17,
      "r": 143,
      "g": 223,
      "b": 87
    },
    {
      "x": 25,
      "y": 1,
      "z": 17,
      "r": 143,
      "g": 223,
      "b": 87
    },
    {
      "x": 25,
      "y": 2,
      "z": 17,
      "r": 143,
      "g": 223,
      "b": 87
    },
    {
      "x": 25,
      "y": 3,
      "z": 17,
      "r": 143,
      "g": 223,
      "b": 87
    },
    {
      "x": 25,
      "y": 4,
      "z": 17,
      "r": 143,
      "g": 223,
      "b": 87
    },
    {
      "x": 25,
      "y": 5,
      "z": 17,
      "r": 143,
      "g": 223,
      "b": 87
    },
    {
      "x": 25,
      "y": 6,
      "z": 17,
      "r": 143,
      "g": 223,
      "b": 87
    },
    {
      "x": 0,
      "y": 0,
      "z": 0,
      "r": 143,
      "g": 223,
      "b": 87
    },
    {
      "x": 0,
      "y": 1,
      "z": 0,
      "r": 143,
      "g": 223,
      "b": 87
    },
    {
      "x": 0,
      "y": 2,
      "z": 0,
      "r": 143,
      "g": 223,
      "b": 87
    },
    {
      "x": 0,
      "y": 3,
      "z": 0,
      "r": 143,
      "g": 223,
      "b": 87
    },
    {
      "x": 0,
      "y": 4,
      "z": 0,
      "r": 143,
      "g": 223,
      "b": 87
    },
    {
      "x": 0,
      "y": 5,
      "z": 0,
      "r": 143,
      "g": 223,
      "b": 87
    },
    {
      "x": 1,
      "y": 0,
      "z": 0,
      "r": 143,
      "g": 223,
      "b": 87
    },
    {
      "x": 1,
      "y": 1,
      "z": 0,
      "r": 143,
      "g": 223,
      "b": 87
    },
    {
      "x": 1,
      "y": 2,
      "z": 0,
      "r": 143,
      "g": 223,
      "b": 87
    },
    {
      "x": 1,
      "y": 3,
      "z": 0,
      "r": 143,
      "g": 223,
      "b": 87
    },
    {
      "x": 1,
      "y": 4,
      "z": 0,
      "r": 143,
      "g": 223,
      "b": 87
    },
    {
      "x": 1,
      "y": 5,
      "z": 0,
      "r": 143,
      "g": 223,
      "b": 87
    },
    {
      "x": 0,
      "y": 0,
      "z": 1,
      "r": 143,
      "g": 223,
      "b": 87
    },
    {
      "x": 0,
      "y": 1,
      "z": 1,
      "r": 143,
      "g": 223,
      "b": 87
    },
    {
      "x": 0,
      "y": 2,
      "z": 1,
      "r": 143,
      "g": 223,
      "b": 87
    },
    {
      "x": 0,
      "y": 3,
      "z": 1,
      "r": 143,
      "g": 223,
      "b": 87
    },
    {
      "x": 0,
      "y": 4,
      "z": 1,
      "r": 143,
      "g": 223,
      "b": 87
    },
    {
      "x": 0,
      "y": 5,
      "z": 1,
      "r": 143,
      "g": 223,
      "b": 87
    },
    {
      "x": 0,
      "y": 6,
      "z": 1,
      "r": 143,
      "g": 223,
      "b": 87
    },
    {
      "x": 0,
      "y": 0,
      "z": 18,
      "r": 143,
      "g": 223,
      "b": 87
    },
    {
      "x": 0,
      "y": 1,
      "z": 17,
      "r": 143,
      "g": 223,
      "b": 87
    },
    {
      "x": 0,
      "y": 1,
      "z": 18,
      "r": 143,
      "g": 223,
      "b": 87
    },
    {
      "x": 0,
      "y": 2,
      "z": 17,
      "r": 143,
      "g": 223,
      "b": 87
    },
    {
      "x": 0,
      "y": 2,
      "z": 18,
      "r": 143,
      "g": 223,
      "b": 87
    },
    {
      "x": 0,
      "y": 3,
      "z": 17,
      "r": 143,
      "g": 223,
      "b": 87
    },
    {
      "x": 0,
      "y": 3,
      "z": 18,
      "r": 143,
      "g": 223,
      "b": 87
    },
    {
      "x": 0,
      "y": 4,
      "z": 17,
      "r": 143,
      "g": 223,
      "b": 87
    },
    {
      "x": 0,
      "y": 4,
      "z": 18,
      "r": 143,
      "g": 223,
      "b": 87
    },
    {
      "x": 0,
      "y": 5,
      "z": 17,
      "r": 143,
      "g": 223,
      "b": 87
    },
    {
      "x": 0,
      "y": 5,
      "z": 18,
      "r": 143,
      "g": 223,
      "b": 87
    },
    {
      "x": 0,
      "y": 6,
      "z": 17,
      "r": 143,
      "g": 223,
      "b": 87
    },
    {
      "x": 0,
      "y": 6,
      "z": 18,
      "r": 143,
      "g": 223,
      "b": 87
    },
    {
      "x": 0,
      "y": 0,
      "z": 17,
      "r": 143,
      "g": 223,
      "b": 87
    },
    {
      "x": 9,
      "y": 0,
      "z": 27,
      "r": 143,
      "g": 223,
      "b": 87
    },
    {
      "x": 9,
      "y": 1,
      "z": 27,
      "r": 143,
      "g": 223,
      "b": 87
    },
    {
      "x": 9,
      "y": 2,
      "z": 27,
      "r": 143,
      "g": 223,
      "b": 87
    },
    {
      "x": 9,
      "y": 3,
      "z": 27,
      "r": 143,
      "g": 223,
      "b": 87
    },
    {
      "x": 9,
      "y": 4,
      "z": 27,
      "r": 143,
      "g": 223,
      "b": 87
    },
    {
      "x": 9,
      "y": 5,
      "z": 27,
      "r": 143,
      "g": 223,
      "b": 87
    },
    {
      "x": 9,
      "y": 6,
      "z": 27,
      "r": 143,
      "g": 223,
      "b": 87
    },
    {
      "x": 15,
      "y": 0,
      "z": 27,
      "r": 143,
      "g": 223,
      "b": 87
    },
    {
      "x": 15,
      "y": 1,
      "z": 27,
      "r": 143,
      "g": 223,
      "b": 87
    },
    {
      "x": 15,
      "y": 2,
      "z": 27,
      "r": 143,
      "g": 223,
      "b": 87
    },
    {
      "x": 15,
      "y": 3,
      "z": 27,
      "r": 143,
      "g": 223,
      "b": 87
    },
    {
      "x": 15,
      "y": 4,
      "z": 27,
      "r": 143,
      "g": 223,
      "b": 87
    },
    {
      "x": 15,
      "y": 5,
      "z": 27,
      "r": 143,
      "g": 223,
      "b": 87
    },
    {
      "x": 15,
      "y": 6,
      "z": 27,
      "r": 143,
      "g": 223,
      "b": 87
    },
    {
      "x": 20,
      "y": 0,
      "z": 27,
      "r": 143,
      "g": 223,
      "b": 87
    },
    {
      "x": 20,
      "y": 1,
      "z": 27,
      "r": 143,
      "g": 223,
      "b": 87
    },
    {
      "x": 20,
      "y": 2,
      "z": 27,
      "r": 143,
      "g": 223,
      "b": 87
    },
    {
      "x": 20,
      "y": 3,
      "z": 27,
      "r": 143,
      "g": 223,
      "b": 87
    },
    {
      "x": 20,
      "y": 4,
      "z": 27,
      "r": 143,
      "g": 223,
      "b": 87
    },
    {
      "x": 20,
      "y": 5,
      "z": 27,
      "r": 143,
      "g": 223,
      "b": 87
    },
    {
      "x": 21,
      "y": 0,
      "z": 27,
      "r": 143,
      "g": 223,
      "b": 87
    },
    {
      "x": 21,
      "y": 1,
      "z": 27,
      "r": 143,
      "g": 223,
      "b": 87
    },
    {
      "x": 21,
      "y": 2,
      "z": 27,
      "r": 143,
      "g": 223,
      "b": 87
    },
    {
      "x": 21,
      "y": 3,
      "z": 27,
      "r": 143,
      "g": 223,
      "b": 87
    },
    {
      "x": 21,
      "y": 4,
      "z": 27,
      "r": 143,
      "g": 223,
      "b": 87
    },
    {
      "x": 21,
      "y": 5,
      "z": 27,
      "r": 143,
      "g": 223,
      "b": 87
    },
    {
      "x": 21,
      "y": 6,
      "z": 27,
      "r": 143,
      "g": 223,
      "b": 87
    },
    {
      "x": 20,
      "y": 6,
      "z": 27,
      "r": 143,
      "g": 223,
      "b": 87
    },
    {
      "x": 25,
      "y": 0,
      "z": 3,
      "r": 143,
      "g": 223,
      "b": 87
    },
    {
      "x": 25,
      "y": 0,
      "z": 4,
      "r": 143,
      "g": 223,
      "b": 87
    },
    {
      "x": 25,
      "y": 1,
      "z": 3,
      "r": 143,
      "g": 223,
      "b": 87
    },
    {
      "x": 25,
      "y": 1,
      "z": 4,
      "r": 143,
      "g": 223,
      "b": 87
    },
    {
      "x": 25,
      "y": 2,
      "z": 3,
      "r": 143,
      "g": 223,
      "b": 87
    },
    {
      "x": 25,
      "y": 2,
      "z": 4,
      "r": 143,
      "g": 223,
      "b": 87
    },
    {
      "x": 25,
      "y": 3,
      "z": 3,
      "r": 143,
      "g": 223,
      "b": 87
    },
    {
      "x": 25,
      "y": 3,
      "z": 4,
      "r": 143,
      "g": 223,
      "b": 87
    },
    {
      "x": 25,
      "y": 4,
      "z": 3,
      "r": 143,
      "g": 223,
      "b": 87
    },
    {
      "x": 25,
      "y": 4,
      "z": 4,
      "r": 143,
      "g": 223,
      "b": 87
    },
    {
      "x": 25,
      "y": 5,
      "z": 3,
      "r": 143,
      "g": 223,
      "b": 87
    },
    {
      "x": 25,
      "y": 5,
      "z": 4,
      "r": 143,
      "g": 223,
      "b": 87
    },
    {
      "x": 25,
      "y": 6,
      "z": 4,
      "r": 143,
      "g": 223,
      "b": 87
    },
    {
      "x": 24,
      "y": 0,
      "z": 3,
      "r": 143,
      "g": 223,
      "b": 87
    },
    {
      "x": 24,
      "y": 1,
      "z": 3,
      "r": 143,
      "g": 223,
      "b": 87
    },
    {
      "x": 24,
      "y": 2,
      "z": 3,
      "r": 143,
      "g": 223,
      "b": 87
    },
    {
      "x": 24,
      "y": 3,
      "z": 3,
      "r": 143,
      "g": 223,
      "b": 87
    },
    {
      "x": 24,
      "y": 4,
      "z": 3,
      "r": 143,
      "g": 223,
      "b": 87
    },
    {
      "x": 24,
      "y": 5,
      "z": 3,
      "r": 143,
      "g": 223,
      "b": 87
    },
    {
      "x": 10,
      "y": 2,
      "z": 10,
      "r": 143,
      "g": 223,
      "b": 87
    },
    {
      "x": 10,
      "y": 2,
      "z": 11,
      "r": 143,
      "g": 223,
      "b": 87
    },
    {
      "x": 10,
      "y": 2,
      "z": 7,
      "r": 143,
      "g": 223,
      "b": 87
    },
    {
      "x": 10,
      "y": 2,
      "z": 8,
      "r": 143,
      "g": 223,
      "b": 87
    },
    {
      "x": 1,
      "y": 0,
      "z": 26,
      "r": 143,
      "g": 223,
      "b": 87
    },
    {
      "x": 1,
      "y": 1,
      "z": 26,
      "r": 143,
      "g": 223,
      "b": 87
    },
    {
      "x": 9,
      "y": 0,
      "z": 26,
      "r": 143,
      "g": 223,
      "b": 87
    },
    {
      "x": 15,
      "y": 0,
      "z": 26,
      "r": 143,
      "g": 223,
      "b": 87
    },
    {
      "x": 16,
      "y": 0,
      "z": 26,
      "r": 143,
      "g": 223,
      "b": 87
    },
    {
      "x": 16,
      "y": 1,
      "z": 26,
      "r": 143,
      "g": 223,
      "b": 87
    },
    {
      "x": 17,
      "y": 0,
      "z": 26,
      "r": 143,
      "g": 223,
      "b": 87
    },
    {
      "x": 17,
      "y": 1,
      "z": 26,
      "r": 143,
      "g": 223,
      "b": 87
    },
    {
      "x": 17,
      "y": 2,
      "z": 26,
      "r": 143,
      "g": 223,
      "b": 87
    },
    {
      "x": 18,
      "y": 0,
      "z": 26,
      "r": 143,
      "g": 223,
      "b": 87
    },
    {
      "x": 18,
      "y": 1,
      "z": 26,
      "r": 143,
      "g": 223,
      "b": 87
    },
    {
      "x": 18,
      "y": 2,
      "z": 26,
      "r": 143,
      "g": 223,
      "b": 87
    },
    {
      "x": 18,
      "y": 3,
      "z": 26,
      "r": 143,
      "g": 223,
      "b": 87
    },
    {
      "x": 19,
      "y": 0,
      "z": 26,
      "r": 143,
      "g": 223,
      "b": 87
    },
    {
      "x": 19,
      "y": 1,
      "z": 26,
      "r": 143,
      "g": 223,
      "b": 87
    },
    {
      "x": 19,
      "y": 2,
      "z": 26,
      "r": 143,
      "g": 223,
      "b": 87
    },
    {
      "x": 19,
      "y": 3,
      "z": 26,
      "r": 143,
      "g": 223,
      "b": 87
    },
    {
      "x": 20,
      "y": 0,
      "z": 26,
      "r": 143,
      "g": 223,
      "b": 87
    },
    {
      "x": 19,
      "y": 4,
      "z": 26,
      "r": 143,
      "g": 223,
      "b": 87
    },
    {
      "x": 19,
      "y": 5,
      "z": 26,
      "r": 143,
      "g": 223,
      "b": 87
    },
    {
      "x": 16,
      "y": 5,
      "z": 26,
      "r": 143,
      "g": 223,
      "b": 87
    },
    {
      "x": 17,
      "y": 5,
      "z": 26,
      "r": 143,
      "g": 223,
      "b": 87
    },
    {
      "x": 18,
      "y": 5,
      "z": 26,
      "r": 143,
      "g": 223,
      "b": 87
    },
    {
      "x": 16,
      "y": 3,
      "z": 26,
      "r": 143,
      "g": 223,
      "b": 87
    },
    {
      "x": 16,
      "y": 4,
      "z": 26,
      "r": 143,
      "g": 223,
      "b": 87
    },
    {
      "x": 16,
      "y": 2,
      "z": 26,
      "r": 143,
      "g": 223,
      "b": 87
    },
    {
      "x": 17,
      "y": 3,
      "z": 26,
      "r": 143,
      "g": 223,
      "b": 87
    },
    {
      "x": 2,
      "y": 0,
      "z": 0,
      "r": 143,
      "g": 223,
      "b": 87
    },
    {
      "x": 2,
      "y": 1,
      "z": 0,
      "r": 143,
      "g": 223,
      "b": 87
    },
    {
      "x": 2,
      "y": 2,
      "z": 0,
      "r": 143,
      "g": 223,
      "b": 87
    },
    {
      "x": 3,
      "y": 0,
      "z": 0,
      "r": 143,
      "g": 223,
      "b": 87
    },
    {
      "x": 3,
      "y": 1,
      "z": 0,
      "r": 143,
      "g": 223,
      "b": 87
    },
    {
      "x": 3,
      "y": 2,
      "z": 0,
      "r": 143,
      "g": 223,
      "b": 87
    },
    {
      "x": 3,
      "y": 3,
      "z": 0,
      "r": 143,
      "g": 223,
      "b": 87
    },
    {
      "x": 4,
      "y": 0,
      "z": 0,
      "r": 143,
      "g": 223,
      "b": 87
    },
    {
      "x": 4,
      "y": 1,
      "z": 0,
      "r": 143,
      "g": 223,
      "b": 87
    },
    {
      "x": 4,
      "y": 2,
      "z": 0,
      "r": 143,
      "g": 223,
      "b": 87
    },
    {
      "x": 5,
      "y": 0,
      "z": 0,
      "r": 143,
      "g": 223,
      "b": 87
    },
    {
      "x": 5,
      "y": 1,
      "z": 0,
      "r": 143,
      "g": 223,
      "b": 87
    },
    {
      "x": 5,
      "y": 2,
      "z": 0,
      "r": 143,
      "g": 223,
      "b": 87
    },
    {
      "x": 6,
      "y": 0,
      "z": 0,
      "r": 143,
      "g": 223,
      "b": 87
    },
    {
      "x": 6,
      "y": 1,
      "z": 0,
      "r": 143,
      "g": 223,
      "b": 87
    },
    {
      "x": 6,
      "y": 2,
      "z": 0,
      "r": 143,
      "g": 223,
      "b": 87
    },
    {
      "x": 7,
      "y": 0,
      "z": 0,
      "r": 143,
      "g": 223,
      "b": 87
    },
    {
      "x": 7,
      "y": 1,
      "z": 0,
      "r": 143,
      "g": 223,
      "b": 87
    },
    {
      "x": 8,
      "y": 0,
      "z": 0,
      "r": 143,
      "g": 223,
      "b": 87
    },
    {
      "x": 8,
      "y": 1,
      "z": 0,
      "r": 143,
      "g": 223,
      "b": 87
    },
    {
      "x": 9,
      "y": 0,
      "z": 0,
      "r": 143,
      "g": 223,
      "b": 87
    },
    {
      "x": 9,
      "y": 1,
      "z": 0,
      "r": 143,
      "g": 223,
      "b": 87
    },
    {
      "x": 10,
      "y": 0,
      "z": 0,
      "r": 143,
      "g": 223,
      "b": 87
    },
    {
      "x": 10,
      "y": 1,
      "z": 0,
      "r": 143,
      "g": 223,
      "b": 87
    },
    {
      "x": 2,
      "y": 3,
      "z": 0,
      "r": 143,
      "g": 223,
      "b": 87
    },
    {
      "x": 2,
      "y": 4,
      "z": 0,
      "r": 143,
      "g": 223,
      "b": 87
    },
    {
      "x": 2,
      "y": 5,
      "z": 0,
      "r": 143,
      "g": 223,
      "b": 87
    },
    {
      "x": 3,
      "y": 4,
      "z": 0,
      "r": 143,
      "g": 223,
      "b": 87
    },
    {
      "x": 3,
      "y": 5,
      "z": 0,
      "r": 143,
      "g": 223,
      "b": 87
    },
    {
      "x": 4,
      "y": 5,
      "z": 0,
      "r": 143,
      "g": 223,
      "b": 87
    },
    {
      "x": 5,
      "y": 5,
      "z": 0,
      "r": 143,
      "g": 223,
      "b": 87
    },
    {
      "x": 6,
      "y": 5,
      "z": 0,
      "r": 143,
      "g": 223,
      "b": 87
    },
    {
      "x": 7,
      "y": 5,
      "z": 0,
      "r": 143,
      "g": 223,
      "b": 87
    },
    {
      "x": 8,
      "y": 5,
      "z": 0,
      "r": 143,
      "g": 223,
      "b": 87
    },
    {
      "x": 9,
      "y": 5,
      "z": 0,
      "r": 143,
      "g": 223,
      "b": 87
    },
    {
      "x": 10,
      "y": 5,
      "z": 0,
      "r": 143,
      "g": 223,
      "b": 87
    },
    {
      "x": 4,
      "y": 3,
      "z": 0,
      "r": 143,
      "g": 223,
      "b": 87
    },
    {
      "x": 5,
      "y": 3,
      "z": 0,
      "r": 143,
      "g": 223,
      "b": 87
    },
    {
      "x": 6,
      "y": 3,
      "z": 0,
      "r": 143,
      "g": 223,
      "b": 87
    },
    {
      "x": 7,
      "y": 2,
      "z": 0,
      "r": 143,
      "g": 223,
      "b": 87
    },
    {
      "x": 7,
      "y": 3,
      "z": 0,
      "r": 143,
      "g": 223,
      "b": 87
    },
    {
      "x": 8,
      "y": 2,
      "z": 0,
      "r": 143,
      "g": 223,
      "b": 87
    },
    {
      "x": 8,
      "y": 3,
      "z": 0,
      "r": 143,
      "g": 223,
      "b": 87
    },
    {
      "x": 9,
      "y": 2,
      "z": 0,
      "r": 143,
      "g": 223,
      "b": 87
    },
    {
      "x": 9,
      "y": 3,
      "z": 0,
      "r": 143,
      "g": 223,
      "b": 87
    },
    {
      "x": 10,
      "y": 2,
      "z": 0,
      "r": 143,
      "g": 223,
      "b": 87
    },
    {
      "x": 10,
      "y": 3,
      "z": 0,
      "r": 143,
      "g": 223,
      "b": 87
    },
    {
      "x": 5,
      "y": 4,
      "z": 0,
      "r": 143,
      "g": 223,
      "b": 87
    },
    {
      "x": 6,
      "y": 4,
      "z": 0,
      "r": 143,
      "g": 223,
      "b": 87
    },
    {
      "x": 7,
      "y": 4,
      "z": 0,
      "r": 143,
      "g": 223,
      "b": 87
    },
    {
      "x": 8,
      "y": 4,
      "z": 0,
      "r": 143,
      "g": 223,
      "b": 87
    },
    {
      "x": 9,
      "y": 4,
      "z": 0,
      "r": 143,
      "g": 223,
      "b": 87
    },
    {
      "x": 13,
      "y": 0,
      "z": 26,
      "r": 143,
      "g": 223,
      "b": 87
    },
    {
      "x": 13,
      "y": 1,
      "z": 26,
      "r": 143,
      "g": 223,
      "b": 87
    },
    {
      "x": 14,
      "y": 0,
      "z": 26,
      "r": 143,
      "g": 223,
      "b": 87
    },
    {
      "x": 14,
      "y": 1,
      "z": 26,
      "r": 143,
      "g": 223,
      "b": 87
    },
    {
      "x": 14,
      "y": 2,
      "z": 26,
      "r": 143,
      "g": 223,
      "b": 87
    },
    {
      "x": 14,
      "y": 3,
      "z": 26,
      "r": 143,
      "g": 223,
      "b": 87
    },
    {
      "x": 14,
      "y": 4,
      "z": 26,
      "r": 143,
      "g": 223,
      "b": 87
    },
    {
      "x": 14,
      "y": 5,
      "z": 26,
      "r": 143,
      "g": 223,
      "b": 87
    },
    {
      "x": 13,
      "y": 2,
      "z": 26,
      "r": 143,
      "g": 223,
      "b": 87
    },
    {
      "x": 13,
      "y": 3,
      "z": 26,
      "r": 143,
      "g": 223,
      "b": 87
    },
    {
      "x": 13,
      "y": 4,
      "z": 26,
      "r": 143,
      "g": 223,
      "b": 87
    },
    {
      "x": 13,
      "y": 5,
      "z": 26,
      "r": 143,
      "g": 223,
      "b": 87
    },
    {
      "x": 11,
      "y": 5,
      "z": 26,
      "r": 143,
      "g": 223,
      "b": 87
    },
    {
      "x": 12,
      "y": 5,
      "z": 26,
      "r": 143,
      "g": 223,
      "b": 87
    },
    {
      "x": 10,
      "y": 0,
      "z": 26,
      "r": 143,
      "g": 223,
      "b": 87
    },
    {
      "x": 10,
      "y": 1,
      "z": 26,
      "r": 143,
      "g": 223,
      "b": 87
    },
    {
      "x": 10,
      "y": 2,
      "z": 26,
      "r": 143,
      "g": 223,
      "b": 87
    },
    {
      "x": 10,
      "y": 3,
      "z": 26,
      "r": 143,
      "g": 223,
      "b": 87
    },
    {
      "x": 10,
      "y": 4,
      "z": 26,
      "r": 143,
      "g": 223,
      "b": 87
    },
    {
      "x": 10,
      "y": 5,
      "z": 26,
      "r": 143,
      "g": 223,
      "b": 87
    },
    {
      "x": 11,
      "y": 0,
      "z": 26,
      "r": 143,
      "g": 223,
      "b": 87
    },
    {
      "x": 11,
      "y": 1,
      "z": 26,
      "r": 143,
      "g": 223,
      "b": 87
    },
    {
      "x": 11,
      "y": 2,
      "z": 26,
      "r": 143,
      "g": 223,
      "b": 87
    },
    {
      "x": 11,
      "y": 3,
      "z": 26,
      "r": 143,
      "g": 223,
      "b": 87
    },
    {
      "x": 11,
      "y": 4,
      "z": 26,
      "r": 143,
      "g": 223,
      "b": 87
    },
    {
      "x": 12,
      "y": 0,
      "z": 26,
      "r": 143,
      "g": 223,
      "b": 87
    },
    {
      "x": 0,
      "y": 0,
      "z": 25,
      "r": 143,
      "g": 223,
      "b": 87
    },
    {
      "x": 0,
      "y": 1,
      "z": 25,
      "r": 143,
      "g": 223,
      "b": 87
    },
    {
      "x": 0,
      "y": 2,
      "z": 24,
      "r": 143,
      "g": 223,
      "b": 87
    },
    {
      "x": 0,
      "y": 2,
      "z": 25,
      "r": 143,
      "g": 223,
      "b": 87
    },
    {
      "x": 0,
      "y": 3,
      "z": 24,
      "r": 143,
      "g": 223,
      "b": 87
    },
    {
      "x": 0,
      "y": 3,
      "z": 25,
      "r": 143,
      "g": 223,
      "b": 87
    },
    {
      "x": 0,
      "y": 4,
      "z": 23,
      "r": 143,
      "g": 223,
      "b": 87
    },
    {
      "x": 0,
      "y": 4,
      "z": 24,
      "r": 143,
      "g": 223,
      "b": 87
    },
    {
      "x": 0,
      "y": 4,
      "z": 25,
      "r": 143,
      "g": 223,
      "b": 87
    },
    {
      "x": 0,
      "y": 5,
      "z": 23,
      "r": 143,
      "g": 223,
      "b": 87
    },
    {
      "x": 0,
      "y": 5,
      "z": 24,
      "r": 143,
      "g": 223,
      "b": 87
    },
    {
      "x": 0,
      "y": 5,
      "z": 25,
      "r": 143,
      "g": 223,
      "b": 87
    },
    {
      "x": 0,
      "y": 6,
      "z": 23,
      "r": 143,
      "g": 223,
      "b": 87
    },
    {
      "x": 0,
      "y": 6,
      "z": 24,
      "r": 143,
      "g": 223,
      "b": 87
    },
    {
      "x": 0,
      "y": 6,
      "z": 25,
      "r": 143,
      "g": 223,
      "b": 87
    },
    {
      "x": 0,
      "y": 6,
      "z": 19,
      "r": 143,
      "g": 223,
      "b": 87
    },
    {
      "x": 0,
      "y": 4,
      "z": 19,
      "r": 143,
      "g": 223,
      "b": 87
    },
    {
      "x": 0,
      "y": 5,
      "z": 19,
      "r": 143,
      "g": 223,
      "b": 87
    },
    {
      "x": 0,
      "y": 1,
      "z": 19,
      "r": 143,
      "g": 223,
      "b": 87
    },
    {
      "x": 0,
      "y": 2,
      "z": 19,
      "r": 143,
      "g": 223,
      "b": 87
    },
    {
      "x": 0,
      "y": 3,
      "z": 19,
      "r": 143,
      "g": 223,
      "b": 87
    },
    {
      "x": 0,
      "y": 0,
      "z": 19,
      "r": 143,
      "g": 223,
      "b": 87
    },
    {
      "x": 0,
      "y": 1,
      "z": 20,
      "r": 143,
      "g": 223,
      "b": 87
    },
    {
      "x": 0,
      "y": 1,
      "z": 21,
      "r": 143,
      "g": 223,
      "b": 87
    },
    {
      "x": 0,
      "y": 3,
      "z": 23,
      "r": 143,
      "g": 223,
      "b": 87
    },
    {
      "x": 0,
      "y": 0,
      "z": 20,
      "r": 143,
      "g": 223,
      "b": 87
    },
    {
      "x": 0,
      "y": 0,
      "z": 21,
      "r": 143,
      "g": 223,
      "b": 87
    },
    {
      "x": 0,
      "y": 0,
      "z": 22,
      "r": 143,
      "g": 223,
      "b": 87
    },
    {
      "x": 0,
      "y": 0,
      "z": 23,
      "r": 143,
      "g": 223,
      "b": 87
    },
    {
      "x": 0,
      "y": 0,
      "z": 24,
      "r": 143,
      "g": 223,
      "b": 87
    },
    {
      "x": 0,
      "y": 1,
      "z": 22,
      "r": 143,
      "g": 223,
      "b": 87
    },
    {
      "x": 0,
      "y": 1,
      "z": 23,
      "r": 143,
      "g": 223,
      "b": 87
    },
    {
      "x": 0,
      "y": 1,
      "z": 24,
      "r": 143,
      "g": 223,
      "b": 87
    },
    {
      "x": 0,
      "y": 2,
      "z": 23,
      "r": 143,
      "g": 223,
      "b": 87
    },
    {
      "x": 0,
      "y": 0,
      "z": 16,
      "r": 143,
      "g": 223,
      "b": 87
    },
    {
      "x": 0,
      "y": 1,
      "z": 16,
      "r": 143,
      "g": 223,
      "b": 87
    },
    {
      "x": 0,
      "y": 2,
      "z": 16,
      "r": 143,
      "g": 223,
      "b": 87
    },
    {
      "x": 0,
      "y": 3,
      "z": 16,
      "r": 143,
      "g": 223,
      "b": 87
    },
    {
      "x": 0,
      "y": 4,
      "z": 16,
      "r": 143,
      "g": 223,
      "b": 87
    },
    {
      "x": 0,
      "y": 5,
      "z": 16,
      "r": 143,
      "g": 223,
      "b": 87
    },
    {
      "x": 0,
      "y": 6,
      "z": 16,
      "r": 143,
      "g": 223,
      "b": 87
    },
    {
      "x": 0,
      "y": 5,
      "z": 12,
      "r": 143,
      "g": 223,
      "b": 87
    },
    {
      "x": 0,
      "y": 6,
      "z": 2,
      "r": 143,
      "g": 223,
      "b": 87
    },
    {
      "x": 0,
      "y": 6,
      "z": 3,
      "r": 143,
      "g": 223,
      "b": 87
    },
    {
      "x": 0,
      "y": 6,
      "z": 4,
      "r": 143,
      "g": 223,
      "b": 87
    },
    {
      "x": 0,
      "y": 6,
      "z": 5,
      "r": 143,
      "g": 223,
      "b": 87
    },
    {
      "x": 0,
      "y": 6,
      "z": 9,
      "r": 143,
      "g": 223,
      "b": 87
    },
    {
      "x": 0,
      "y": 6,
      "z": 10,
      "r": 143,
      "g": 223,
      "b": 87
    },
    {
      "x": 0,
      "y": 6,
      "z": 11,
      "r": 143,
      "g": 223,
      "b": 87
    },
    {
      "x": 0,
      "y": 6,
      "z": 12,
      "r": 143,
      "g": 223,
      "b": 87
    },
    {
      "x": 0,
      "y": 5,
      "z": 10,
      "r": 143,
      "g": 223,
      "b": 87
    },
    {
      "x": 0,
      "y": 5,
      "z": 11,
      "r": 143,
      "g": 223,
      "b": 87
    },
    {
      "x": 0,
      "y": 5,
      "z": 9,
      "r": 143,
      "g": 223,
      "b": 87
    },
    {
      "x": 0,
      "y": 4,
      "z": 5,
      "r": 143,
      "g": 223,
      "b": 87
    },
    {
      "x": 0,
      "y": 5,
      "z": 3,
      "r": 143,
      "g": 223,
      "b": 87
    },
    {
      "x": 0,
      "y": 5,
      "z": 4,
      "r": 143,
      "g": 223,
      "b": 87
    },
    {
      "x": 0,
      "y": 5,
      "z": 5,
      "r": 143,
      "g": 223,
      "b": 87
    },
    {
      "x": 0,
      "y": 0,
      "z": 2,
      "r": 143,
      "g": 223,
      "b": 87
    },
    {
      "x": 0,
      "y": 0,
      "z": 3,
      "r": 143,
      "g": 223,
      "b": 87
    },
    {
      "x": 0,
      "y": 1,
      "z": 2,
      "r": 143,
      "g": 223,
      "b": 87
    },
    {
      "x": 0,
      "y": 1,
      "z": 3,
      "r": 143,
      "g": 223,
      "b": 87
    },
    {
      "x": 0,
      "y": 1,
      "z": 4,
      "r": 143,
      "g": 223,
      "b": 87
    },
    {
      "x": 0,
      "y": 1,
      "z": 5,
      "r": 143,
      "g": 223,
      "b": 87
    },
    {
      "x": 0,
      "y": 2,
      "z": 2,
      "r": 143,
      "g": 223,
      "b": 87
    },
    {
      "x": 0,
      "y": 2,
      "z": 3,
      "r": 143,
      "g": 223,
      "b": 87
    },
    {
      "x": 0,
      "y": 2,
      "z": 4,
      "r": 143,
      "g": 223,
      "b": 87
    },
    {
      "x": 0,
      "y": 2,
      "z": 5,
      "r": 143,
      "g": 223,
      "b": 87
    },
    {
      "x": 0,
      "y": 3,
      "z": 2,
      "r": 143,
      "g": 223,
      "b": 87
    },
    {
      "x": 0,
      "y": 3,
      "z": 3,
      "r": 143,
      "g": 223,
      "b": 87
    },
    {
      "x": 0,
      "y": 3,
      "z": 4,
      "r": 143,
      "g": 223,
      "b": 87
    },
    {
      "x": 0,
      "y": 3,
      "z": 5,
      "r": 143,
      "g": 223,
      "b": 87
    },
    {
      "x": 0,
      "y": 4,
      "z": 2,
      "r": 143,
      "g": 223,
      "b": 87
    },
    {
      "x": 0,
      "y": 4,
      "z": 3,
      "r": 143,
      "g": 223,
      "b": 87
    },
    {
      "x": 0,
      "y": 4,
      "z": 4,
      "r": 143,
      "g": 223,
      "b": 87
    },
    {
      "x": 0,
      "y": 5,
      "z": 2,
      "r": 143,
      "g": 223,
      "b": 87
    },
    {
      "x": 0,
      "y": 1,
      "z": 6,
      "r": 143,
      "g": 223,
      "b": 87
    },
    {
      "x": 0,
      "y": 2,
      "z": 9,
      "r": 143,
      "g": 223,
      "b": 87
    },
    {
      "x": 0,
      "y": 3,
      "z": 9,
      "r": 143,
      "g": 223,
      "b": 87
    },
    {
      "x": 0,
      "y": 3,
      "z": 10,
      "r": 143,
      "g": 223,
      "b": 87
    },
    {
      "x": 0,
      "y": 0,
      "z": 4,
      "r": 143,
      "g": 223,
      "b": 87
    },
    {
      "x": 0,
      "y": 1,
      "z": 7,
      "r": 143,
      "g": 223,
      "b": 87
    },
    {
      "x": 0,
      "y": 1,
      "z": 8,
      "r": 143,
      "g": 223,
      "b": 87
    },
    {
      "x": 0,
      "y": 2,
      "z": 10,
      "r": 143,
      "g": 223,
      "b": 87
    },
    {
      "x": 0,
      "y": 2,
      "z": 11,
      "r": 143,
      "g": 223,
      "b": 87
    },
    {
      "x": 0,
      "y": 3,
      "z": 11,
      "r": 143,
      "g": 223,
      "b": 87
    },
    {
      "x": 0,
      "y": 3,
      "z": 12,
      "r": 143,
      "g": 223,
      "b": 87
    },
    {
      "x": 0,
      "y": 0,
      "z": 5,
      "r": 143,
      "g": 223,
      "b": 87
    },
    {
      "x": 0,
      "y": 0,
      "z": 6,
      "r": 143,
      "g": 223,
      "b": 87
    },
    {
      "x": 0,
      "y": 0,
      "z": 7,
      "r": 143,
      "g": 223,
      "b": 87
    },
    {
      "x": 0,
      "y": 0,
      "z": 8,
      "r": 143,
      "g": 223,
      "b": 87
    },
    {
      "x": 0,
      "y": 0,
      "z": 9,
      "r": 143,
      "g": 223,
      "b": 87
    },
    {
      "x": 0,
      "y": 0,
      "z": 10,
      "r": 143,
      "g": 223,
      "b": 87
    },
    {
      "x": 0,
      "y": 0,
      "z": 11,
      "r": 143,
      "g": 223,
      "b": 87
    },
    {
      "x": 0,
      "y": 0,
      "z": 12,
      "r": 143,
      "g": 223,
      "b": 87
    },
    {
      "x": 0,
      "y": 0,
      "z": 13,
      "r": 143,
      "g": 223,
      "b": 87
    },
    {
      "x": 0,
      "y": 0,
      "z": 14,
      "r": 143,
      "g": 223,
      "b": 87
    },
    {
      "x": 0,
      "y": 0,
      "z": 15,
      "r": 143,
      "g": 223,
      "b": 87
    },
    {
      "x": 0,
      "y": 1,
      "z": 9,
      "r": 143,
      "g": 223,
      "b": 87
    },
    {
      "x": 0,
      "y": 1,
      "z": 10,
      "r": 143,
      "g": 223,
      "b": 87
    },
    {
      "x": 0,
      "y": 1,
      "z": 11,
      "r": 143,
      "g": 223,
      "b": 87
    },
    {
      "x": 0,
      "y": 1,
      "z": 12,
      "r": 143,
      "g": 223,
      "b": 87
    },
    {
      "x": 0,
      "y": 1,
      "z": 13,
      "r": 143,
      "g": 223,
      "b": 87
    },
    {
      "x": 0,
      "y": 1,
      "z": 14,
      "r": 143,
      "g": 223,
      "b": 87
    },
    {
      "x": 0,
      "y": 1,
      "z": 15,
      "r": 143,
      "g": 223,
      "b": 87
    },
    {
      "x": 0,
      "y": 2,
      "z": 12,
      "r": 143,
      "g": 223,
      "b": 87
    },
    {
      "x": 2,
      "y": 0,
      "z": 26,
      "r": 143,
      "g": 223,
      "b": 87
    },
    {
      "x": 3,
      "y": 0,
      "z": 26,
      "r": 143,
      "g": 223,
      "b": 87
    },
    {
      "x": 3,
      "y": 1,
      "z": 26,
      "r": 143,
      "g": 223,
      "b": 87
    },
    {
      "x": 4,
      "y": 0,
      "z": 26,
      "r": 143,
      "g": 223,
      "b": 87
    },
    {
      "x": 4,
      "y": 1,
      "z": 26,
      "r": 143,
      "g": 223,
      "b": 87
    },
    {
      "x": 4,
      "y": 2,
      "z": 26,
      "r": 143,
      "g": 223,
      "b": 87
    },
    {
      "x": 5,
      "y": 0,
      "z": 26,
      "r": 143,
      "g": 223,
      "b": 87
    },
    {
      "x": 5,
      "y": 1,
      "z": 26,
      "r": 143,
      "g": 223,
      "b": 87
    },
    {
      "x": 5,
      "y": 2,
      "z": 26,
      "r": 143,
      "g": 223,
      "b": 87
    },
    {
      "x": 6,
      "y": 0,
      "z": 26,
      "r": 143,
      "g": 223,
      "b": 87
    },
    {
      "x": 6,
      "y": 1,
      "z": 26,
      "r": 143,
      "g": 223,
      "b": 87
    },
    {
      "x": 6,
      "y": 2,
      "z": 26,
      "r": 143,
      "g": 223,
      "b": 87
    },
    {
      "x": 6,
      "y": 3,
      "z": 26,
      "r": 143,
      "g": 223,
      "b": 87
    },
    {
      "x": 7,
      "y": 0,
      "z": 26,
      "r": 143,
      "g": 223,
      "b": 87
    },
    {
      "x": 7,
      "y": 1,
      "z": 26,
      "r": 143,
      "g": 223,
      "b": 87
    },
    {
      "x": 7,
      "y": 2,
      "z": 26,
      "r": 143,
      "g": 223,
      "b": 87
    },
    {
      "x": 7,
      "y": 3,
      "z": 26,
      "r": 143,
      "g": 223,
      "b": 87
    },
    {
      "x": 8,
      "y": 0,
      "z": 26,
      "r": 143,
      "g": 223,
      "b": 87
    },
    {
      "x": 8,
      "y": 1,
      "z": 26,
      "r": 143,
      "g": 223,
      "b": 87
    },
    {
      "x": 8,
      "y": 2,
      "z": 26,
      "r": 143,
      "g": 223,
      "b": 87
    },
    {
      "x": 7,
      "y": 4,
      "z": 26,
      "r": 143,
      "g": 223,
      "b": 87
    },
    {
      "x": 8,
      "y": 3,
      "z": 26,
      "r": 143,
      "g": 223,
      "b": 87
    },
    {
      "x": 8,
      "y": 4,
      "z": 26,
      "r": 143,
      "g": 223,
      "b": 87
    },
    {
      "x": 8,
      "y": 5,
      "z": 26,
      "r": 143,
      "g": 223,
      "b": 87
    },
    {
      "x": 7,
      "y": 5,
      "z": 26,
      "r": 143,
      "g": 223,
      "b": 87
    },
    {
      "x": 5,
      "y": 5,
      "z": 26,
      "r": 143,
      "g": 223,
      "b": 87
    },
    {
      "x": 6,
      "y": 5,
      "z": 26,
      "r": 143,
      "g": 223,
      "b": 87
    },
    {
      "x": 3,
      "y": 5,
      "z": 26,
      "r": 143,
      "g": 223,
      "b": 87
    },
    {
      "x": 4,
      "y": 5,
      "z": 26,
      "r": 143,
      "g": 223,
      "b": 87
    },
    {
      "x": 2,
      "y": 3,
      "z": 26,
      "r": 143,
      "g": 223,
      "b": 87
    },
    {
      "x": 2,
      "y": 4,
      "z": 26,
      "r": 143,
      "g": 223,
      "b": 87
    },
    {
      "x": 2,
      "y": 5,
      "z": 26,
      "r": 143,
      "g": 223,
      "b": 87
    },
    {
      "x": 3,
      "y": 3,
      "z": 26,
      "r": 143,
      "g": 223,
      "b": 87
    },
    {
      "x": 3,
      "y": 4,
      "z": 26,
      "r": 143,
      "g": 223,
      "b": 87
    },
    {
      "x": 2,
      "y": 1,
      "z": 26,
      "r": 143,
      "g": 223,
      "b": 87
    },
    {
      "x": 2,
      "y": 2,
      "z": 26,
      "r": 143,
      "g": 223,
      "b": 87
    },
    {
      "x": 3,
      "y": 2,
      "z": 26,
      "r": 143,
      "g": 223,
      "b": 87
    },
    {
      "x": 4,
      "y": 3,
      "z": 26,
      "r": 143,
      "g": 223,
      "b": 87
    },
    {
      "x": 5,
      "y": 3,
      "z": 26,
      "r": 143,
      "g": 223,
      "b": 87
    },
    {
      "x": 21,
      "y": 0,
      "z": 25,
      "r": 143,
      "g": 223,
      "b": 87
    },
    {
      "x": 21,
      "y": 1,
      "z": 24,
      "r": 143,
      "g": 223,
      "b": 87
    },
    {
      "x": 21,
      "y": 1,
      "z": 25,
      "r": 143,
      "g": 223,
      "b": 87
    },
    {
      "x": 21,
      "y": 2,
      "z": 23,
      "r": 143,
      "g": 223,
      "b": 87
    },
    {
      "x": 21,
      "y": 2,
      "z": 24,
      "r": 143,
      "g": 223,
      "b": 87
    },
    {
      "x": 21,
      "y": 2,
      "z": 25,
      "r": 143,
      "g": 223,
      "b": 87
    },
    {
      "x": 21,
      "y": 3,
      "z": 23,
      "r": 143,
      "g": 223,
      "b": 87
    },
    {
      "x": 21,
      "y": 3,
      "z": 24,
      "r": 143,
      "g": 223,
      "b": 87
    },
    {
      "x": 21,
      "y": 3,
      "z": 25,
      "r": 143,
      "g": 223,
      "b": 87
    },
    {
      "x": 21,
      "y": 4,
      "z": 23,
      "r": 143,
      "g": 223,
      "b": 87
    },
    {
      "x": 21,
      "y": 4,
      "z": 24,
      "r": 143,
      "g": 223,
      "b": 87
    },
    {
      "x": 21,
      "y": 4,
      "z": 25,
      "r": 143,
      "g": 223,
      "b": 87
    },
    {
      "x": 21,
      "y": 5,
      "z": 24,
      "r": 143,
      "g": 223,
      "b": 87
    },
    {
      "x": 21,
      "y": 5,
      "z": 25,
      "r": 143,
      "g": 223,
      "b": 87
    },
    {
      "x": 21,
      "y": 6,
      "z": 25,
      "r": 143,
      "g": 223,
      "b": 87
    },
    {
      "x": 21,
      "y": 0,
      "z": 18,
      "r": 143,
      "g": 223,
      "b": 87
    },
    {
      "x": 21,
      "y": 0,
      "z": 19,
      "r": 143,
      "g": 223,
      "b": 87
    },
    {
      "x": 21,
      "y": 0,
      "z": 20,
      "r": 143,
      "g": 223,
      "b": 87
    },
    {
      "x": 21,
      "y": 0,
      "z": 21,
      "r": 143,
      "g": 223,
      "b": 87
    },
    {
      "x": 21,
      "y": 0,
      "z": 22,
      "r": 143,
      "g": 223,
      "b": 87
    },
    {
      "x": 21,
      "y": 0,
      "z": 23,
      "r": 143,
      "g": 223,
      "b": 87
    },
    {
      "x": 21,
      "y": 0,
      "z": 24,
      "r": 143,
      "g": 223,
      "b": 87
    },
    {
      "x": 21,
      "y": 1,
      "z": 19,
      "r": 143,
      "g": 223,
      "b": 87
    },
    {
      "x": 21,
      "y": 1,
      "z": 20,
      "r": 143,
      "g": 223,
      "b": 87
    },
    {
      "x": 21,
      "y": 1,
      "z": 21,
      "r": 143,
      "g": 223,
      "b": 87
    },
    {
      "x": 21,
      "y": 1,
      "z": 22,
      "r": 143,
      "g": 223,
      "b": 87
    },
    {
      "x": 21,
      "y": 1,
      "z": 23,
      "r": 143,
      "g": 223,
      "b": 87
    },
    {
      "x": 21,
      "y": 2,
      "z": 20,
      "r": 143,
      "g": 223,
      "b": 87
    },
    {
      "x": 21,
      "y": 2,
      "z": 21,
      "r": 143,
      "g": 223,
      "b": 87
    },
    {
      "x": 21,
      "y": 2,
      "z": 22,
      "r": 143,
      "g": 223,
      "b": 87
    },
    {
      "x": 21,
      "y": 3,
      "z": 22,
      "r": 143,
      "g": 223,
      "b": 87
    },
    {
      "x": 21,
      "y": 2,
      "z": 19,
      "r": 143,
      "g": 223,
      "b": 87
    },
    {
      "x": 21,
      "y": 3,
      "z": 20,
      "r": 143,
      "g": 223,
      "b": 87
    },
    {
      "x": 21,
      "y": 3,
      "z": 21,
      "r": 143,
      "g": 223,
      "b": 87
    },
    {
      "x": 21,
      "y": 3,
      "z": 19,
      "r": 143,
      "g": 223,
      "b": 87
    },
    {
      "x": 21,
      "y": 4,
      "z": 20,
      "r": 143,
      "g": 223,
      "b": 87
    },
    {
      "x": 21,
      "y": 4,
      "z": 21,
      "r": 143,
      "g": 223,
      "b": 87
    },
    {
      "x": 21,
      "y": 5,
      "z": 20,
      "r": 143,
      "g": 223,
      "b": 87
    },
    {
      "x": 21,
      "y": 5,
      "z": 21,
      "r": 143,
      "g": 223,
      "b": 87
    },
    {
      "x": 21,
      "y": 4,
      "z": 19,
      "r": 143,
      "g": 223,
      "b": 87
    },
    {
      "x": 21,
      "y": 5,
      "z": 19,
      "r": 143,
      "g": 223,
      "b": 87
    },
    {
      "x": 21,
      "y": 6,
      "z": 19,
      "r": 143,
      "g": 223,
      "b": 87
    },
    {
      "x": 21,
      "y": 6,
      "z": 20,
      "r": 143,
      "g": 223,
      "b": 87
    },
    {
      "x": 21,
      "y": 5,
      "z": 22,
      "r": 143,
      "g": 223,
      "b": 87
    },
    {
      "x": 21,
      "y": 5,
      "z": 23,
      "r": 143,
      "g": 223,
      "b": 87
    },
    {
      "x": 21,
      "y": 6,
      "z": 21,
      "r": 143,
      "g": 223,
      "b": 87
    },
    {
      "x": 21,
      "y": 6,
      "z": 22,
      "r": 143,
      "g": 223,
      "b": 87
    },
    {
      "x": 21,
      "y": 6,
      "z": 23,
      "r": 143,
      "g": 223,
      "b": 87
    },
    {
      "x": 21,
      "y": 6,
      "z": 24,
      "r": 143,
      "g": 223,
      "b": 87
    },
    {
      "x": 22,
      "y": 0,
      "z": 18,
      "r": 143,
      "g": 223,
      "b": 87
    },
    {
      "x": 22,
      "y": 1,
      "z": 18,
      "r": 143,
      "g": 223,
      "b": 87
    },
    {
      "x": 22,
      "y": 2,
      "z": 18,
      "r": 143,
      "g": 223,
      "b": 87
    },
    {
      "x": 22,
      "y": 3,
      "z": 18,
      "r": 143,
      "g": 223,
      "b": 87
    },
    {
      "x": 23,
      "y": 0,
      "z": 18,
      "r": 143,
      "g": 223,
      "b": 87
    },
    {
      "x": 23,
      "y": 1,
      "z": 18,
      "r": 143,
      "g": 223,
      "b": 87
    },
    {
      "x": 23,
      "y": 2,
      "z": 18,
      "r": 143,
      "g": 223,
      "b": 87
    },
    {
      "x": 23,
      "y": 3,
      "z": 18,
      "r": 143,
      "g": 223,
      "b": 87
    },
    {
      "x": 23,
      "y": 4,
      "z": 18,
      "r": 143,
      "g": 223,
      "b": 87
    },
    {
      "x": 22,
      "y": 4,
      "z": 18,
      "r": 143,
      "g": 223,
      "b": 87
    },
    {
      "x": 22,
      "y": 5,
      "z": 18,
      "r": 143,
      "g": 223,
      "b": 87
    },
    {
      "x": 22,
      "y": 6,
      "z": 18,
      "r": 143,
      "g": 223,
      "b": 87
    },
    {
      "x": 23,
      "y": 5,
      "z": 18,
      "r": 143,
      "g": 223,
      "b": 87
    },
    {
      "x": 23,
      "y": 6,
      "z": 18,
      "r": 143,
      "g": 223,
      "b": 87
    },
    {
      "x": 25,
      "y": 0,
      "z": 9,
      "r": 143,
      "g": 223,
      "b": 87
    },
    {
      "x": 25,
      "y": 0,
      "z": 10,
      "r": 143,
      "g": 223,
      "b": 87
    },
    {
      "x": 25,
      "y": 0,
      "z": 11,
      "r": 143,
      "g": 223,
      "b": 87
    },
    {
      "x": 25,
      "y": 0,
      "z": 12,
      "r": 143,
      "g": 223,
      "b": 87
    },
    {
      "x": 25,
      "y": 1,
      "z": 9,
      "r": 143,
      "g": 223,
      "b": 87
    },
    {
      "x": 25,
      "y": 2,
      "z": 9,
      "r": 143,
      "g": 223,
      "b": 87
    },
    {
      "x": 25,
      "y": 3,
      "z": 9,
      "r": 143,
      "g": 223,
      "b": 87
    },
    {
      "x": 25,
      "y": 4,
      "z": 9,
      "r": 143,
      "g": 223,
      "b": 87
    },
    {
      "x": 25,
      "y": 5,
      "z": 9,
      "r": 143,
      "g": 223,
      "b": 87
    },
    {
      "x": 25,
      "y": 0,
      "z": 8,
      "r": 143,
      "g": 223,
      "b": 87
    },
    {
      "x": 25,
      "y": 1,
      "z": 7,
      "r": 143,
      "g": 223,
      "b": 87
    },
    {
      "x": 25,
      "y": 1,
      "z": 8,
      "r": 143,
      "g": 223,
      "b": 87
    },
    {
      "x": 25,
      "y": 2,
      "z": 7,
      "r": 143,
      "g": 223,
      "b": 87
    },
    {
      "x": 25,
      "y": 2,
      "z": 8,
      "r": 143,
      "g": 223,
      "b": 87
    },
    {
      "x": 25,
      "y": 3,
      "z": 6,
      "r": 143,
      "g": 223,
      "b": 87
    },
    {
      "x": 25,
      "y": 3,
      "z": 7,
      "r": 143,
      "g": 223,
      "b": 87
    },
    {
      "x": 25,
      "y": 3,
      "z": 8,
      "r": 143,
      "g": 223,
      "b": 87
    },
    {
      "x": 25,
      "y": 4,
      "z": 5,
      "r": 143,
      "g": 223,
      "b": 87
    },
    {
      "x": 25,
      "y": 4,
      "z": 6,
      "r": 143,
      "g": 223,
      "b": 87
    },
    {
      "x": 25,
      "y": 4,
      "z": 7,
      "r": 143,
      "g": 223,
      "b": 87
    },
    {
      "x": 25,
      "y": 4,
      "z": 8,
      "r": 143,
      "g": 223,
      "b": 87
    },
    {
      "x": 25,
      "y": 5,
      "z": 5,
      "r": 143,
      "g": 223,
      "b": 87
    },
    {
      "x": 25,
      "y": 5,
      "z": 6,
      "r": 143,
      "g": 223,
      "b": 87
    },
    {
      "x": 25,
      "y": 5,
      "z": 7,
      "r": 143,
      "g": 223,
      "b": 87
    },
    {
      "x": 25,
      "y": 5,
      "z": 8,
      "r": 143,
      "g": 223,
      "b": 87
    },
    {
      "x": 25,
      "y": 6,
      "z": 5,
      "r": 143,
      "g": 223,
      "b": 87
    },
    {
      "x": 25,
      "y": 6,
      "z": 6,
      "r": 143,
      "g": 223,
      "b": 87
    },
    {
      "x": 25,
      "y": 6,
      "z": 7,
      "r": 143,
      "g": 223,
      "b": 87
    },
    {
      "x": 25,
      "y": 6,
      "z": 8,
      "r": 143,
      "g": 223,
      "b": 87
    },
    {
      "x": 25,
      "y": 6,
      "z": 9,
      "r": 143,
      "g": 223,
      "b": 87
    },
    {
      "x": 25,
      "y": 5,
      "z": 10,
      "r": 143,
      "g": 223,
      "b": 87
    },
    {
      "x": 25,
      "y": 5,
      "z": 11,
      "r": 143,
      "g": 223,
      "b": 87
    },
    {
      "x": 25,
      "y": 5,
      "z": 12,
      "r": 143,
      "g": 223,
      "b": 87
    },
    {
      "x": 25,
      "y": 6,
      "z": 10,
      "r": 143,
      "g": 223,
      "b": 87
    },
    {
      "x": 25,
      "y": 6,
      "z": 11,
      "r": 143,
      "g": 223,
      "b": 87
    },
    {
      "x": 25,
      "y": 6,
      "z": 12,
      "r": 143,
      "g": 223,
      "b": 87
    },
    {
      "x": 25,
      "y": 6,
      "z": 13,
      "r": 143,
      "g": 223,
      "b": 87
    },
    {
      "x": 25,
      "y": 6,
      "z": 14,
      "r": 143,
      "g": 223,
      "b": 87
    },
    {
      "x": 25,
      "y": 6,
      "z": 15,
      "r": 143,
      "g": 223,
      "b": 87
    },
    {
      "x": 25,
      "y": 6,
      "z": 16,
      "r": 143,
      "g": 223,
      "b": 87
    },
    {
      "x": 25,
      "y": 1,
      "z": 12,
      "r": 143,
      "g": 223,
      "b": 87
    },
    {
      "x": 25,
      "y": 1,
      "z": 13,
      "r": 143,
      "g": 223,
      "b": 87
    },
    {
      "x": 25,
      "y": 2,
      "z": 12,
      "r": 143,
      "g": 223,
      "b": 87
    },
    {
      "x": 25,
      "y": 2,
      "z": 13,
      "r": 143,
      "g": 223,
      "b": 87
    },
    {
      "x": 25,
      "y": 2,
      "z": 14,
      "r": 143,
      "g": 223,
      "b": 87
    },
    {
      "x": 25,
      "y": 3,
      "z": 12,
      "r": 143,
      "g": 223,
      "b": 87
    },
    {
      "x": 25,
      "y": 3,
      "z": 13,
      "r": 143,
      "g": 223,
      "b": 87
    },
    {
      "x": 25,
      "y": 3,
      "z": 14,
      "r": 143,
      "g": 223,
      "b": 87
    },
    {
      "x": 25,
      "y": 3,
      "z": 15,
      "r": 143,
      "g": 223,
      "b": 87
    },
    {
      "x": 25,
      "y": 4,
      "z": 12,
      "r": 143,
      "g": 223,
      "b": 87
    },
    {
      "x": 25,
      "y": 4,
      "z": 13,
      "r": 143,
      "g": 223,
      "b": 87
    },
    {
      "x": 25,
      "y": 4,
      "z": 14,
      "r": 143,
      "g": 223,
      "b": 87
    },
    {
      "x": 25,
      "y": 4,
      "z": 15,
      "r": 143,
      "g": 223,
      "b": 87
    },
    {
      "x": 25,
      "y": 4,
      "z": 16,
      "r": 143,
      "g": 223,
      "b": 87
    },
    {
      "x": 25,
      "y": 5,
      "z": 13,
      "r": 143,
      "g": 223,
      "b": 87
    },
    {
      "x": 25,
      "y": 5,
      "z": 14,
      "r": 143,
      "g": 223,
      "b": 87
    },
    {
      "x": 25,
      "y": 5,
      "z": 15,
      "r": 143,
      "g": 223,
      "b": 87
    },
    {
      "x": 25,
      "y": 5,
      "z": 16,
      "r": 143,
      "g": 223,
      "b": 87
    },
    {
      "x": 25,
      "y": 0,
      "z": 13,
      "r": 143,
      "g": 223,
      "b": 87
    },
    {
      "x": 25,
      "y": 0,
      "z": 14,
      "r": 143,
      "g": 223,
      "b": 87
    },
    {
      "x": 25,
      "y": 0,
      "z": 15,
      "r": 143,
      "g": 223,
      "b": 87
    },
    {
      "x": 25,
      "y": 0,
      "z": 16,
      "r": 143,
      "g": 223,
      "b": 87
    },
    {
      "x": 25,
      "y": 1,
      "z": 14,
      "r": 143,
      "g": 223,
      "b": 87
    },
    {
      "x": 25,
      "y": 1,
      "z": 15,
      "r": 143,
      "g": 223,
      "b": 87
    },
    {
      "x": 25,
      "y": 1,
      "z": 16,
      "r": 143,
      "g": 223,
      "b": 87
    },
    {
      "x": 25,
      "y": 2,
      "z": 15,
      "r": 143,
      "g": 223,
      "b": 87
    },
    {
      "x": 25,
      "y": 2,
      "z": 16,
      "r": 143,
      "g": 223,
      "b": 87
    },
    {
      "x": 25,
      "y": 3,
      "z": 16,
      "r": 143,
      "g": 223,
      "b": 87
    },
    {
      "x": 25,
      "y": 0,
      "z": 5,
      "r": 143,
      "g": 223,
      "b": 87
    },
    {
      "x": 25,
      "y": 0,
      "z": 6,
      "r": 143,
      "g": 223,
      "b": 87
    },
    {
      "x": 25,
      "y": 0,
      "z": 7,
      "r": 143,
      "g": 223,
      "b": 87
    },
    {
      "x": 25,
      "y": 1,
      "z": 5,
      "r": 143,
      "g": 223,
      "b": 87
    },
    {
      "x": 25,
      "y": 1,
      "z": 6,
      "r": 143,
      "g": 223,
      "b": 87
    },
    {
      "x": 25,
      "y": 2,
      "z": 5,
      "r": 143,
      "g": 223,
      "b": 87
    },
    {
      "x": 25,
      "y": 2,
      "z": 6,
      "r": 143,
      "g": 223,
      "b": 87
    },
    {
      "x": 25,
      "y": 3,
      "z": 5,
      "r": 143,
      "g": 223,
      "b": 87
    },
    {
      "x": 16,
      "y": 0,
      "z": 3,
      "r": 143,
      "g": 223,
      "b": 87
    },
    {
      "x": 16,
      "y": 1,
      "z": 3,
      "r": 143,
      "g": 223,
      "b": 87
    },
    {
      "x": 16,
      "y": 2,
      "z": 3,
      "r": 143,
      "g": 223,
      "b": 87
    },
    {
      "x": 16,
      "y": 3,
      "z": 3,
      "r": 143,
      "g": 223,
      "b": 87
    },
    {
      "x": 16,
      "y": 4,
      "z": 3,
      "r": 143,
      "g": 223,
      "b": 87
    },
    {
      "x": 16,
      "y": 5,
      "z": 3,
      "r": 143,
      "g": 223,
      "b": 87
    },
    {
      "x": 17,
      "y": 0,
      "z": 3,
      "r": 143,
      "g": 223,
      "b": 87
    },
    {
      "x": 17,
      "y": 1,
      "z": 3,
      "r": 143,
      "g": 223,
      "b": 87
    },
    {
      "x": 17,
      "y": 2,
      "z": 3,
      "r": 143,
      "g": 223,
      "b": 87
    },
    {
      "x": 17,
      "y": 3,
      "z": 3,
      "r": 143,
      "g": 223,
      "b": 87
    },
    {
      "x": 17,
      "y": 4,
      "z": 3,
      "r": 143,
      "g": 223,
      "b": 87
    },
    {
      "x": 18,
      "y": 0,
      "z": 3,
      "r": 143,
      "g": 223,
      "b": 87
    },
    {
      "x": 18,
      "y": 1,
      "z": 3,
      "r": 143,
      "g": 223,
      "b": 87
    },
    {
      "x": 18,
      "y": 2,
      "z": 3,
      "r": 143,
      "g": 223,
      "b": 87
    },
    {
      "x": 18,
      "y": 3,
      "z": 3,
      "r": 143,
      "g": 223,
      "b": 87
    },
    {
      "x": 18,
      "y": 4,
      "z": 3,
      "r": 143,
      "g": 223,
      "b": 87
    },
    {
      "x": 19,
      "y": 0,
      "z": 3,
      "r": 143,
      "g": 223,
      "b": 87
    },
    {
      "x": 19,
      "y": 1,
      "z": 3,
      "r": 143,
      "g": 223,
      "b": 87
    },
    {
      "x": 19,
      "y": 2,
      "z": 3,
      "r": 143,
      "g": 223,
      "b": 87
    },
    {
      "x": 19,
      "y": 3,
      "z": 3,
      "r": 143,
      "g": 223,
      "b": 87
    },
    {
      "x": 20,
      "y": 0,
      "z": 3,
      "r": 143,
      "g": 223,
      "b": 87
    },
    {
      "x": 20,
      "y": 1,
      "z": 3,
      "r": 143,
      "g": 223,
      "b": 87
    },
    {
      "x": 20,
      "y": 2,
      "z": 3,
      "r": 143,
      "g": 223,
      "b": 87
    },
    {
      "x": 21,
      "y": 0,
      "z": 3,
      "r": 143,
      "g": 223,
      "b": 87
    },
    {
      "x": 21,
      "y": 1,
      "z": 3,
      "r": 143,
      "g": 223,
      "b": 87
    },
    {
      "x": 21,
      "y": 2,
      "z": 3,
      "r": 143,
      "g": 223,
      "b": 87
    },
    {
      "x": 22,
      "y": 0,
      "z": 3,
      "r": 143,
      "g": 223,
      "b": 87
    },
    {
      "x": 22,
      "y": 1,
      "z": 3,
      "r": 143,
      "g": 223,
      "b": 87
    },
    {
      "x": 23,
      "y": 0,
      "z": 3,
      "r": 143,
      "g": 223,
      "b": 87
    },
    {
      "x": 23,
      "y": 1,
      "z": 3,
      "r": 143,
      "g": 223,
      "b": 87
    },
    {
      "x": 17,
      "y": 5,
      "z": 3,
      "r": 143,
      "g": 223,
      "b": 87
    },
    {
      "x": 18,
      "y": 5,
      "z": 3,
      "r": 143,
      "g": 223,
      "b": 87
    },
    {
      "x": 19,
      "y": 5,
      "z": 3,
      "r": 143,
      "g": 223,
      "b": 87
    },
    {
      "x": 20,
      "y": 5,
      "z": 3,
      "r": 143,
      "g": 223,
      "b": 87
    },
    {
      "x": 20,
      "y": 3,
      "z": 3,
      "r": 143,
      "g": 223,
      "b": 87
    },
    {
      "x": 20,
      "y": 4,
      "z": 3,
      "r": 143,
      "g": 223,
      "b": 87
    },
    {
      "x": 21,
      "y": 4,
      "z": 3,
      "r": 143,
      "g": 223,
      "b": 87
    },
    {
      "x": 21,
      "y": 5,
      "z": 3,
      "r": 143,
      "g": 223,
      "b": 87
    },
    {
      "x": 22,
      "y": 4,
      "z": 3,
      "r": 143,
      "g": 223,
      "b": 87
    },
    {
      "x": 22,
      "y": 5,
      "z": 3,
      "r": 143,
      "g": 223,
      "b": 87
    },
    {
      "x": 23,
      "y": 5,
      "z": 3,
      "r": 143,
      "g": 223,
      "b": 87
    },
    {
      "x": 21,
      "y": 3,
      "z": 3,
      "r": 143,
      "g": 223,
      "b": 87
    },
    {
      "x": 22,
      "y": 2,
      "z": 3,
      "r": 143,
      "g": 223,
      "b": 87
    },
    {
      "x": 22,
      "y": 3,
      "z": 3,
      "r": 143,
      "g": 223,
      "b": 87
    },
    {
      "x": 23,
      "y": 2,
      "z": 3,
      "r": 143,
      "g": 223,
      "b": 87
    },
    {
      "x": 23,
      "y": 3,
      "z": 3,
      "r": 143,
      "g": 223,
      "b": 87
    },
    {
      "x": 23,
      "y": 4,
      "z": 3,
      "r": 143,
      "g": 223,
      "b": 87
    },
    {
      "x": 13,
      "y": 0,
      "z": 27,
      "r": 143,
      "g": 223,
      "b": 87
    },
    {
      "x": 13,
      "y": 0,
      "z": 28,
      "r": 143,
      "g": 223,
      "b": 87
    },
    {
      "x": 10,
      "y": 0,
      "z": 27,
      "r": 143,
      "g": 223,
      "b": 87
    },
    {
      "x": 10,
      "y": 0,
      "z": 28,
      "r": 143,
      "g": 223,
      "b": 87
    },
    {
      "x": 11,
      "y": 0,
      "z": 27,
      "r": 143,
      "g": 223,
      "b": 87
    },
    {
      "x": 11,
      "y": 0,
      "z": 28,
      "r": 143,
      "g": 223,
      "b": 87
    },
    {
      "x": 12,
      "y": 0,
      "z": 27,
      "r": 143,
      "g": 223,
      "b": 87
    },
    {
      "x": 12,
      "y": 0,
      "z": 28,
      "r": 143,
      "g": 223,
      "b": 87
    },
    {
      "x": 27,
      "y": 0,
      "z": 9,
      "r": 143,
      "g": 223,
      "b": 87
    },
    {
      "x": 27,
      "y": 0,
      "z": 10,
      "r": 143,
      "g": 223,
      "b": 87
    },
    {
      "x": 27,
      "y": 0,
      "z": 11,
      "r": 143,
      "g": 223,
      "b": 87
    },
    {
      "x": 27,
      "y": 0,
      "z": 12,
      "r": 143,
      "g": 223,
      "b": 87
    },
    {
      "x": 26,
      "y": 0,
      "z": 9,
      "r": 143,
      "g": 223,
      "b": 87
    },
    {
      "x": 26,
      "y": 0,
      "z": 10,
      "r": 143,
      "g": 223,
      "b": 87
    },
    {
      "x": 26,
      "y": 0,
      "z": 11,
      "r": 143,
      "g": 223,
      "b": 87
    },
    {
      "x": 26,
      "y": 0,
      "z": 12,
      "r": 143,
      "g": 223,
      "b": 87
    },
    {
      "x": 9,
      "y": 0,
      "z": 18,
      "r": 143,
      "g": 223,
      "b": 87
    },
    {
      "x": 10,
      "y": 5,
      "z": 18,
      "r": 143,
      "g": 223,
      "b": 87
    },
    {
      "x": 11,
      "y": 5,
      "z": 18,
      "r": 143,
      "g": 223,
      "b": 87
    },
    {
      "x": 12,
      "y": 5,
      "z": 18,
      "r": 143,
      "g": 223,
      "b": 87
    },
    {
      "x": 12,
      "y": 2,
      "z": 18,
      "r": 143,
      "g": 223,
      "b": 87
    },
    {
      "x": 12,
      "y": 3,
      "z": 18,
      "r": 143,
      "g": 223,
      "b": 87
    },
    {
      "x": 12,
      "y": 4,
      "z": 18,
      "r": 143,
      "g": 223,
      "b": 87
    },
    {
      "x": 13,
      "y": 0,
      "z": 18,
      "r": 143,
      "g": 223,
      "b": 87
    },
    {
      "x": 12,
      "y": 0,
      "z": 18,
      "r": 143,
      "g": 223,
      "b": 87
    },
    {
      "x": 12,
      "y": 1,
      "z": 18,
      "r": 143,
      "g": 223,
      "b": 87
    },
    {
      "x": 15,
      "y": 0,
      "z": 18,
      "r": 143,
      "g": 223,
      "b": 87
    },
    {
      "x": 15,
      "y": 0,
      "z": 19,
      "r": 143,
      "g": 223,
      "b": 87
    },
    {
      "x": 15,
      "y": 0,
      "z": 20,
      "r": 143,
      "g": 223,
      "b": 87
    },
    {
      "x": 15,
      "y": 1,
      "z": 18,
      "r": 143,
      "g": 223,
      "b": 87
    },
    {
      "x": 15,
      "y": 1,
      "z": 19,
      "r": 143,
      "g": 223,
      "b": 87
    },
    {
      "x": 15,
      "y": 1,
      "z": 20,
      "r": 143,
      "g": 223,
      "b": 87
    },
    {
      "x": 15,
      "y": 2,
      "z": 18,
      "r": 143,
      "g": 223,
      "b": 87
    },
    {
      "x": 15,
      "y": 2,
      "z": 19,
      "r": 143,
      "g": 223,
      "b": 87
    },
    {
      "x": 15,
      "y": 2,
      "z": 20,
      "r": 143,
      "g": 223,
      "b": 87
    },
    {
      "x": 15,
      "y": 3,
      "z": 19,
      "r": 143,
      "g": 223,
      "b": 87
    },
    {
      "x": 15,
      "y": 3,
      "z": 20,
      "r": 143,
      "g": 223,
      "b": 87
    },
    {
      "x": 15,
      "y": 4,
      "z": 20,
      "r": 143,
      "g": 223,
      "b": 87
    },
    {
      "x": 15,
      "y": 5,
      "z": 20,
      "r": 143,
      "g": 223,
      "b": 87
    },
    {
      "x": 15,
      "y": 3,
      "z": 18,
      "r": 143,
      "g": 223,
      "b": 87
    },
    {
      "x": 15,
      "y": 4,
      "z": 18,
      "r": 143,
      "g": 223,
      "b": 87
    },
    {
      "x": 15,
      "y": 4,
      "z": 19,
      "r": 143,
      "g": 223,
      "b": 87
    },
    {
      "x": 15,
      "y": 5,
      "z": 19,
      "r": 143,
      "g": 223,
      "b": 87
    },
    {
      "x": 9,
      "y": 1,
      "z": 25,
      "r": 143,
      "g": 223,
      "b": 87
    },
    {
      "x": 9,
      "y": 2,
      "z": 25,
      "r": 143,
      "g": 223,
      "b": 87
    },
    {
      "x": 9,
      "y": 3,
      "z": 25,
      "r": 143,
      "g": 223,
      "b": 87
    },
    {
      "x": 9,
      "y": 4,
      "z": 24,
      "r": 143,
      "g": 223,
      "b": 87
    },
    {
      "x": 9,
      "y": 4,
      "z": 25,
      "r": 143,
      "g": 223,
      "b": 87
    },
    {
      "x": 9,
      "y": 5,
      "z": 24,
      "r": 143,
      "g": 223,
      "b": 87
    },
    {
      "x": 9,
      "y": 5,
      "z": 25,
      "r": 143,
      "g": 223,
      "b": 87
    },
    {
      "x": 9,
      "y": 6,
      "z": 24,
      "r": 143,
      "g": 223,
      "b": 87
    },
    {
      "x": 9,
      "y": 6,
      "z": 25,
      "r": 143,
      "g": 223,
      "b": 87
    },
    {
      "x": 9,
      "y": 5,
      "z": 23,
      "r": 143,
      "g": 223,
      "b": 87
    },
    {
      "x": 9,
      "y": 6,
      "z": 23,
      "r": 143,
      "g": 223,
      "b": 87
    },
    {
      "x": 9,
      "y": 5,
      "z": 21,
      "r": 143,
      "g": 223,
      "b": 87
    },
    {
      "x": 9,
      "y": 5,
      "z": 22,
      "r": 143,
      "g": 223,
      "b": 87
    },
    {
      "x": 9,
      "y": 0,
      "z": 21,
      "r": 143,
      "g": 223,
      "b": 87
    },
    {
      "x": 9,
      "y": 1,
      "z": 21,
      "r": 143,
      "g": 223,
      "b": 87
    },
    {
      "x": 9,
      "y": 2,
      "z": 20,
      "r": 143,
      "g": 223,
      "b": 87
    },
    {
      "x": 9,
      "y": 2,
      "z": 21,
      "r": 143,
      "g": 223,
      "b": 87
    },
    {
      "x": 9,
      "y": 3,
      "z": 19,
      "r": 143,
      "g": 223,
      "b": 87
    },
    {
      "x": 9,
      "y": 3,
      "z": 20,
      "r": 143,
      "g": 223,
      "b": 87
    },
    {
      "x": 9,
      "y": 3,
      "z": 21,
      "r": 143,
      "g": 223,
      "b": 87
    },
    {
      "x": 9,
      "y": 4,
      "z": 19,
      "r": 143,
      "g": 223,
      "b": 87
    },
    {
      "x": 9,
      "y": 4,
      "z": 20,
      "r": 143,
      "g": 223,
      "b": 87
    },
    {
      "x": 9,
      "y": 4,
      "z": 21,
      "r": 143,
      "g": 223,
      "b": 87
    },
    {
      "x": 9,
      "y": 5,
      "z": 19,
      "r": 143,
      "g": 223,
      "b": 87
    },
    {
      "x": 9,
      "y": 5,
      "z": 20,
      "r": 143,
      "g": 223,
      "b": 87
    },
    {
      "x": 9,
      "y": 0,
      "z": 19,
      "r": 143,
      "g": 223,
      "b": 87
    },
    {
      "x": 9,
      "y": 0,
      "z": 20,
      "r": 143,
      "g": 223,
      "b": 87
    },
    {
      "x": 9,
      "y": 1,
      "z": 19,
      "r": 143,
      "g": 223,
      "b": 87
    },
    {
      "x": 9,
      "y": 1,
      "z": 20,
      "r": 143,
      "g": 223,
      "b": 87
    },
    {
      "x": 9,
      "y": 2,
      "z": 19,
      "r": 143,
      "g": 223,
      "b": 87
    },
    {
      "x": 9,
      "y": 0,
      "z": 24,
      "r": 143,
      "g": 223,
      "b": 87
    },
    {
      "x": 9,
      "y": 0,
      "z": 25,
      "r": 143,
      "g": 223,
      "b": 87
    },
    {
      "x": 9,
      "y": 1,
      "z": 24,
      "r": 143,
      "g": 223,
      "b": 87
    },
    {
      "x": 9,
      "y": 2,
      "z": 24,
      "r": 143,
      "g": 223,
      "b": 87
    },
    {
      "x": 9,
      "y": 3,
      "z": 24,
      "r": 143,
      "g": 223,
      "b": 87
    },
    {
      "x": 15,
      "y": 1,
      "z": 25,
      "r": 143,
      "g": 223,
      "b": 87
    },
    {
      "x": 15,
      "y": 2,
      "z": 25,
      "r": 143,
      "g": 223,
      "b": 87
    },
    {
      "x": 15,
      "y": 3,
      "z": 25,
      "r": 143,
      "g": 223,
      "b": 87
    },
    {
      "x": 15,
      "y": 4,
      "z": 24,
      "r": 143,
      "g": 223,
      "b": 87
    },
    {
      "x": 15,
      "y": 4,
      "z": 25,
      "r": 143,
      "g": 223,
      "b": 87
    },
    {
      "x": 15,
      "y": 5,
      "z": 24,
      "r": 143,
      "g": 223,
      "b": 87
    },
    {
      "x": 15,
      "y": 5,
      "z": 25,
      "r": 143,
      "g": 223,
      "b": 87
    },
    {
      "x": 15,
      "y": 6,
      "z": 24,
      "r": 143,
      "g": 223,
      "b": 87
    },
    {
      "x": 15,
      "y": 6,
      "z": 25,
      "r": 143,
      "g": 223,
      "b": 87
    },
    {
      "x": 15,
      "y": 0,
      "z": 24,
      "r": 143,
      "g": 223,
      "b": 87
    },
    {
      "x": 15,
      "y": 0,
      "z": 25,
      "r": 143,
      "g": 223,
      "b": 87
    },
    {
      "x": 15,
      "y": 1,
      "z": 24,
      "r": 143,
      "g": 223,
      "b": 87
    },
    {
      "x": 15,
      "y": 2,
      "z": 24,
      "r": 143,
      "g": 223,
      "b": 87
    },
    {
      "x": 15,
      "y": 3,
      "z": 24,
      "r": 143,
      "g": 223,
      "b": 87
    },
    {
      "x": 16,
      "y": 5,
      "z": 18,
      "r": 143,
      "g": 223,
      "b": 87
    },
    {
      "x": 17,
      "y": 5,
      "z": 18,
      "r": 143,
      "g": 223,
      "b": 87
    },
    {
      "x": 19,
      "y": 5,
      "z": 18,
      "r": 143,
      "g": 223,
      "b": 87
    },
    {
      "x": 13,
      "y": 3,
      "z": 4,
      "r": 143,
      "g": 223,
      "b": 87
    },
    {
      "x": 13,
      "y": 4,
      "z": 4,
      "r": 143,
      "g": 223,
      "b": 87
    },
    {
      "x": 13,
      "y": 5,
      "z": 4,
      "r": 143,
      "g": 223,
      "b": 87
    },
    {
      "x": 13,
      "y": 6,
      "z": 4,
      "r": 143,
      "g": 223,
      "b": 87
    },
    {
      "x": 15,
      "y": 0,
      "z": 17,
      "r": 143,
      "g": 223,
      "b": 87
    },
    {
      "x": 9,
      "y": 0,
      "z": 17,
      "r": 143,
      "g": 223,
      "b": 87
    },
    {
      "x": 9,
      "y": 1,
      "z": 17,
      "r": 143,
      "g": 223,
      "b": 87
    },
    {
      "x": 9,
      "y": 2,
      "z": 17,
      "r": 143,
      "g": 223,
      "b": 87
    },
    {
      "x": 9,
      "y": 3,
      "z": 17,
      "r": 143,
      "g": 223,
      "b": 87
    },
    {
      "x": 9,
      "y": 4,
      "z": 17,
      "r": 143,
      "g": 223,
      "b": 87
    },
    {
      "x": 9,
      "y": 5,
      "z": 17,
      "r": 143,
      "g": 223,
      "b": 87
    },
    {
      "x": 5,
      "y": 0,
      "z": 17,
      "r": 143,
      "g": 223,
      "b": 87
    },
    {
      "x": 5,
      "y": 1,
      "z": 17,
      "r": 143,
      "g": 223,
      "b": 87
    },
    {
      "x": 6,
      "y": 0,
      "z": 17,
      "r": 143,
      "g": 223,
      "b": 87
    },
    {
      "x": 6,
      "y": 1,
      "z": 17,
      "r": 143,
      "g": 223,
      "b": 87
    },
    {
      "x": 6,
      "y": 2,
      "z": 17,
      "r": 143,
      "g": 223,
      "b": 87
    },
    {
      "x": 7,
      "y": 0,
      "z": 17,
      "r": 143,
      "g": 223,
      "b": 87
    },
    {
      "x": 7,
      "y": 1,
      "z": 17,
      "r": 143,
      "g": 223,
      "b": 87
    },
    {
      "x": 7,
      "y": 2,
      "z": 17,
      "r": 143,
      "g": 223,
      "b": 87
    },
    {
      "x": 7,
      "y": 3,
      "z": 17,
      "r": 143,
      "g": 223,
      "b": 87
    },
    {
      "x": 7,
      "y": 4,
      "z": 17,
      "r": 143,
      "g": 223,
      "b": 87
    },
    {
      "x": 8,
      "y": 0,
      "z": 17,
      "r": 143,
      "g": 223,
      "b": 87
    },
    {
      "x": 8,
      "y": 1,
      "z": 17,
      "r": 143,
      "g": 223,
      "b": 87
    },
    {
      "x": 8,
      "y": 2,
      "z": 17,
      "r": 143,
      "g": 223,
      "b": 87
    },
    {
      "x": 8,
      "y": 3,
      "z": 17,
      "r": 143,
      "g": 223,
      "b": 87
    },
    {
      "x": 8,
      "y": 4,
      "z": 17,
      "r": 143,
      "g": 223,
      "b": 87
    },
    {
      "x": 8,
      "y": 5,
      "z": 17,
      "r": 143,
      "g": 223,
      "b": 87
    },
    {
      "x": 5,
      "y": 2,
      "z": 17,
      "r": 143,
      "g": 223,
      "b": 87
    },
    {
      "x": 5,
      "y": 3,
      "z": 17,
      "r": 143,
      "g": 223,
      "b": 87
    },
    {
      "x": 5,
      "y": 4,
      "z": 17,
      "r": 143,
      "g": 223,
      "b": 87
    },
    {
      "x": 5,
      "y": 5,
      "z": 17,
      "r": 143,
      "g": 223,
      "b": 87
    },
    {
      "x": 6,
      "y": 3,
      "z": 17,
      "r": 143,
      "g": 223,
      "b": 87
    },
    {
      "x": 6,
      "y": 4,
      "z": 17,
      "r": 143,
      "g": 223,
      "b": 87
    },
    {
      "x": 6,
      "y": 5,
      "z": 17,
      "r": 143,
      "g": 223,
      "b": 87
    },
    {
      "x": 7,
      "y": 5,
      "z": 17,
      "r": 143,
      "g": 223,
      "b": 87
    },
    {
      "x": 3,
      "y": 5,
      "z": 17,
      "r": 143,
      "g": 223,
      "b": 87
    },
    {
      "x": 4,
      "y": 5,
      "z": 17,
      "r": 143,
      "g": 223,
      "b": 87
    },
    {
      "x": 2,
      "y": 5,
      "z": 17,
      "r": 143,
      "g": 223,
      "b": 87
    },
    {
      "x": 1,
      "y": 0,
      "z": 17,
      "r": 143,
      "g": 223,
      "b": 87
    },
    {
      "x": 2,
      "y": 2,
      "z": 17,
      "r": 143,
      "g": 223,
      "b": 87
    },
    {
      "x": 2,
      "y": 3,
      "z": 17,
      "r": 143,
      "g": 223,
      "b": 87
    },
    {
      "x": 2,
      "y": 4,
      "z": 17,
      "r": 143,
      "g": 223,
      "b": 87
    },
    {
      "x": 2,
      "y": 0,
      "z": 17,
      "r": 143,
      "g": 223,
      "b": 87
    },
    {
      "x": 2,
      "y": 1,
      "z": 17,
      "r": 143,
      "g": 223,
      "b": 87
    },
    {
      "x": 3,
      "y": 0,
      "z": 17,
      "r": 143,
      "g": 223,
      "b": 87
    },
    {
      "x": 3,
      "y": 1,
      "z": 17,
      "r": 143,
      "g": 223,
      "b": 87
    },
    {
      "x": 3,
      "y": 2,
      "z": 17,
      "r": 143,
      "g": 223,
      "b": 87
    },
    {
      "x": 3,
      "y": 3,
      "z": 17,
      "r": 143,
      "g": 223,
      "b": 87
    },
    {
      "x": 3,
      "y": 4,
      "z": 17,
      "r": 143,
      "g": 223,
      "b": 87
    },
    {
      "x": 1,
      "y": 5,
      "z": 12,
      "r": 143,
      "g": 223,
      "b": 87
    },
    {
      "x": 1,
      "y": 6,
      "z": 4,
      "r": 143,
      "g": 223,
      "b": 87
    },
    {
      "x": 1,
      "y": 6,
      "z": 5,
      "r": 143,
      "g": 223,
      "b": 87
    },
    {
      "x": 1,
      "y": 6,
      "z": 9,
      "r": 143,
      "g": 223,
      "b": 87
    },
    {
      "x": 1,
      "y": 6,
      "z": 10,
      "r": 143,
      "g": 223,
      "b": 87
    },
    {
      "x": 1,
      "y": 6,
      "z": 11,
      "r": 143,
      "g": 223,
      "b": 87
    },
    {
      "x": 1,
      "y": 6,
      "z": 12,
      "r": 143,
      "g": 223,
      "b": 87
    },
    {
      "x": 1,
      "y": 5,
      "z": 9,
      "r": 143,
      "g": 223,
      "b": 87
    },
    {
      "x": 1,
      "y": 5,
      "z": 10,
      "r": 143,
      "g": 223,
      "b": 87
    },
    {
      "x": 1,
      "y": 5,
      "z": 11,
      "r": 143,
      "g": 223,
      "b": 87
    },
    {
      "x": 1,
      "y": 4,
      "z": 5,
      "r": 143,
      "g": 223,
      "b": 87
    },
    {
      "x": 1,
      "y": 5,
      "z": 3,
      "r": 143,
      "g": 223,
      "b": 87
    },
    {
      "x": 1,
      "y": 5,
      "z": 4,
      "r": 143,
      "g": 223,
      "b": 87
    },
    {
      "x": 1,
      "y": 5,
      "z": 5,
      "r": 143,
      "g": 223,
      "b": 87
    },
    {
      "x": 1,
      "y": 0,
      "z": 1,
      "r": 143,
      "g": 223,
      "b": 87
    },
    {
      "x": 1,
      "y": 1,
      "z": 2,
      "r": 143,
      "g": 223,
      "b": 87
    },
    {
      "x": 1,
      "y": 1,
      "z": 3,
      "r": 143,
      "g": 223,
      "b": 87
    },
    {
      "x": 1,
      "y": 1,
      "z": 4,
      "r": 143,
      "g": 223,
      "b": 87
    },
    {
      "x": 1,
      "y": 2,
      "z": 2,
      "r": 143,
      "g": 223,
      "b": 87
    },
    {
      "x": 1,
      "y": 2,
      "z": 3,
      "r": 143,
      "g": 223,
      "b": 87
    },
    {
      "x": 1,
      "y": 2,
      "z": 4,
      "r": 143,
      "g": 223,
      "b": 87
    },
    {
      "x": 1,
      "y": 2,
      "z": 5,
      "r": 143,
      "g": 223,
      "b": 87
    },
    {
      "x": 1,
      "y": 3,
      "z": 2,
      "r": 143,
      "g": 223,
      "b": 87
    },
    {
      "x": 1,
      "y": 3,
      "z": 3,
      "r": 143,
      "g": 223,
      "b": 87
    },
    {
      "x": 1,
      "y": 3,
      "z": 4,
      "r": 143,
      "g": 223,
      "b": 87
    },
    {
      "x": 1,
      "y": 3,
      "z": 5,
      "r": 143,
      "g": 223,
      "b": 87
    },
    {
      "x": 1,
      "y": 4,
      "z": 2,
      "r": 143,
      "g": 223,
      "b": 87
    },
    {
      "x": 1,
      "y": 4,
      "z": 3,
      "r": 143,
      "g": 223,
      "b": 87
    },
    {
      "x": 1,
      "y": 4,
      "z": 4,
      "r": 143,
      "g": 223,
      "b": 87
    },
    {
      "x": 1,
      "y": 5,
      "z": 2,
      "r": 143,
      "g": 223,
      "b": 87
    },
    {
      "x": 1,
      "y": 0,
      "z": 2,
      "r": 143,
      "g": 223,
      "b": 87
    },
    {
      "x": 1,
      "y": 1,
      "z": 5,
      "r": 143,
      "g": 223,
      "b": 87
    },
    {
      "x": 1,
      "y": 2,
      "z": 9,
      "r": 143,
      "g": 223,
      "b": 87
    },
    {
      "x": 1,
      "y": 3,
      "z": 9,
      "r": 143,
      "g": 223,
      "b": 87
    },
    {
      "x": 1,
      "y": 3,
      "z": 10,
      "r": 143,
      "g": 223,
      "b": 87
    },
    {
      "x": 1,
      "y": 1,
      "z": 6,
      "r": 143,
      "g": 223,
      "b": 87
    },
    {
      "x": 1,
      "y": 2,
      "z": 10,
      "r": 143,
      "g": 223,
      "b": 87
    },
    {
      "x": 1,
      "y": 2,
      "z": 11,
      "r": 143,
      "g": 223,
      "b": 87
    },
    {
      "x": 1,
      "y": 3,
      "z": 11,
      "r": 143,
      "g": 223,
      "b": 87
    },
    {
      "x": 1,
      "y": 3,
      "z": 12,
      "r": 143,
      "g": 223,
      "b": 87
    },
    {
      "x": 1,
      "y": 0,
      "z": 3,
      "r": 143,
      "g": 223,
      "b": 87
    },
    {
      "x": 1,
      "y": 0,
      "z": 4,
      "r": 143,
      "g": 223,
      "b": 87
    },
    {
      "x": 1,
      "y": 0,
      "z": 5,
      "r": 143,
      "g": 223,
      "b": 87
    },
    {
      "x": 1,
      "y": 0,
      "z": 6,
      "r": 143,
      "g": 223,
      "b": 87
    },
    {
      "x": 1,
      "y": 0,
      "z": 7,
      "r": 143,
      "g": 223,
      "b": 87
    },
    {
      "x": 1,
      "y": 0,
      "z": 8,
      "r": 143,
      "g": 223,
      "b": 87
    },
    {
      "x": 1,
      "y": 0,
      "z": 9,
      "r": 143,
      "g": 223,
      "b": 87
    },
    {
      "x": 1,
      "y": 0,
      "z": 10,
      "r": 143,
      "g": 223,
      "b": 87
    },
    {
      "x": 1,
      "y": 0,
      "z": 11,
      "r": 143,
      "g": 223,
      "b": 87
    },
    {
      "x": 1,
      "y": 0,
      "z": 12,
      "r": 143,
      "g": 223,
      "b": 87
    },
    {
      "x": 1,
      "y": 0,
      "z": 13,
      "r": 143,
      "g": 223,
      "b": 87
    },
    {
      "x": 1,
      "y": 0,
      "z": 14,
      "r": 143,
      "g": 223,
      "b": 87
    },
    {
      "x": 1,
      "y": 0,
      "z": 15,
      "r": 143,
      "g": 223,
      "b": 87
    },
    {
      "x": 1,
      "y": 0,
      "z": 16,
      "r": 143,
      "g": 223,
      "b": 87
    },
    {
      "x": 1,
      "y": 1,
      "z": 7,
      "r": 143,
      "g": 223,
      "b": 87
    },
    {
      "x": 1,
      "y": 1,
      "z": 8,
      "r": 143,
      "g": 223,
      "b": 87
    },
    {
      "x": 1,
      "y": 1,
      "z": 9,
      "r": 143,
      "g": 223,
      "b": 87
    },
    {
      "x": 1,
      "y": 1,
      "z": 10,
      "r": 143,
      "g": 223,
      "b": 87
    },
    {
      "x": 1,
      "y": 1,
      "z": 11,
      "r": 143,
      "g": 223,
      "b": 87
    },
    {
      "x": 1,
      "y": 1,
      "z": 12,
      "r": 143,
      "g": 223,
      "b": 87
    },
    {
      "x": 1,
      "y": 1,
      "z": 13,
      "r": 143,
      "g": 223,
      "b": 87
    },
    {
      "x": 1,
      "y": 1,
      "z": 14,
      "r": 143,
      "g": 223,
      "b": 87
    },
    {
      "x": 1,
      "y": 1,
      "z": 15,
      "r": 143,
      "g": 223,
      "b": 87
    },
    {
      "x": 1,
      "y": 1,
      "z": 16,
      "r": 143,
      "g": 223,
      "b": 87
    },
    {
      "x": 1,
      "y": 2,
      "z": 12,
      "r": 143,
      "g": 223,
      "b": 87
    },
    {
      "x": 1,
      "y": 2,
      "z": 16,
      "r": 143,
      "g": 223,
      "b": 87
    },
    {
      "x": 1,
      "y": 3,
      "z": 16,
      "r": 143,
      "g": 223,
      "b": 87
    },
    {
      "x": 1,
      "y": 4,
      "z": 16,
      "r": 143,
      "g": 223,
      "b": 87
    },
    {
      "x": 1,
      "y": 5,
      "z": 16,
      "r": 143,
      "g": 223,
      "b": 87
    },
    {
      "x": 1,
      "y": 6,
      "z": 1,
      "r": 143,
      "g": 223,
      "b": 87
    },
    {
      "x": 24,
      "y": 6,
      "z": 17,
      "r": 143,
      "g": 223,
      "b": 87
    },
    {
      "x": 22,
      "y": 5,
      "z": 17,
      "r": 143,
      "g": 223,
      "b": 87
    },
    {
      "x": 23,
      "y": 5,
      "z": 17,
      "r": 143,
      "g": 223,
      "b": 87
    },
    {
      "x": 21,
      "y": 0,
      "z": 17,
      "r": 143,
      "g": 223,
      "b": 87
    },
    {
      "x": 21,
      "y": 1,
      "z": 17,
      "r": 143,
      "g": 223,
      "b": 87
    },
    {
      "x": 21,
      "y": 2,
      "z": 17,
      "r": 143,
      "g": 223,
      "b": 87
    },
    {
      "x": 21,
      "y": 3,
      "z": 17,
      "r": 143,
      "g": 223,
      "b": 87
    },
    {
      "x": 21,
      "y": 4,
      "z": 17,
      "r": 143,
      "g": 223,
      "b": 87
    },
    {
      "x": 21,
      "y": 5,
      "z": 17,
      "r": 143,
      "g": 223,
      "b": 87
    },
    {
      "x": 22,
      "y": 1,
      "z": 17,
      "r": 143,
      "g": 223,
      "b": 87
    },
    {
      "x": 22,
      "y": 2,
      "z": 17,
      "r": 143,
      "g": 223,
      "b": 87
    },
    {
      "x": 22,
      "y": 3,
      "z": 17,
      "r": 143,
      "g": 223,
      "b": 87
    },
    {
      "x": 22,
      "y": 4,
      "z": 17,
      "r": 143,
      "g": 223,
      "b": 87
    },
    {
      "x": 23,
      "y": 3,
      "z": 17,
      "r": 143,
      "g": 223,
      "b": 87
    },
    {
      "x": 23,
      "y": 4,
      "z": 17,
      "r": 143,
      "g": 223,
      "b": 87
    },
    {
      "x": 23,
      "y": 2,
      "z": 17,
      "r": 143,
      "g": 223,
      "b": 87
    },
    {
      "x": 22,
      "y": 0,
      "z": 17,
      "r": 143,
      "g": 223,
      "b": 87
    },
    {
      "x": 23,
      "y": 0,
      "z": 17,
      "r": 143,
      "g": 223,
      "b": 87
    },
    {
      "x": 23,
      "y": 1,
      "z": 17,
      "r": 143,
      "g": 223,
      "b": 87
    },
    {
      "x": 24,
      "y": 0,
      "z": 17,
      "r": 143,
      "g": 223,
      "b": 87
    },
    {
      "x": 20,
      "y": 0,
      "z": 17,
      "r": 143,
      "g": 223,
      "b": 87
    },
    {
      "x": 20,
      "y": 1,
      "z": 17,
      "r": 143,
      "g": 223,
      "b": 87
    },
    {
      "x": 20,
      "y": 2,
      "z": 17,
      "r": 143,
      "g": 223,
      "b": 87
    },
    {
      "x": 20,
      "y": 3,
      "z": 17,
      "r": 143,
      "g": 223,
      "b": 87
    },
    {
      "x": 20,
      "y": 4,
      "z": 17,
      "r": 143,
      "g": 223,
      "b": 87
    },
    {
      "x": 20,
      "y": 5,
      "z": 17,
      "r": 143,
      "g": 223,
      "b": 87
    },
    {
      "x": 1,
      "y": 0,
      "z": 18,
      "r": 143,
      "g": 223,
      "b": 87
    },
    {
      "x": 2,
      "y": 0,
      "z": 18,
      "r": 143,
      "g": 223,
      "b": 87
    },
    {
      "x": 3,
      "y": 0,
      "z": 18,
      "r": 143,
      "g": 223,
      "b": 87
    },
    {
      "x": 3,
      "y": 1,
      "z": 18,
      "r": 143,
      "g": 223,
      "b": 87
    },
    {
      "x": 2,
      "y": 5,
      "z": 18,
      "r": 143,
      "g": 223,
      "b": 87
    },
    {
      "x": 3,
      "y": 2,
      "z": 18,
      "r": 143,
      "g": 223,
      "b": 87
    },
    {
      "x": 3,
      "y": 3,
      "z": 18,
      "r": 143,
      "g": 223,
      "b": 87
    },
    {
      "x": 3,
      "y": 4,
      "z": 18,
      "r": 143,
      "g": 223,
      "b": 87
    },
    {
      "x": 3,
      "y": 5,
      "z": 18,
      "r": 143,
      "g": 223,
      "b": 87
    },
    {
      "x": 4,
      "y": 5,
      "z": 18,
      "r": 143,
      "g": 223,
      "b": 87
    },
    {
      "x": 5,
      "y": 0,
      "z": 18,
      "r": 143,
      "g": 223,
      "b": 87
    },
    {
      "x": 5,
      "y": 1,
      "z": 18,
      "r": 143,
      "g": 223,
      "b": 87
    },
    {
      "x": 5,
      "y": 2,
      "z": 18,
      "r": 143,
      "g": 223,
      "b": 87
    },
    {
      "x": 5,
      "y": 3,
      "z": 18,
      "r": 143,
      "g": 223,
      "b": 87
    },
    {
      "x": 5,
      "y": 4,
      "z": 18,
      "r": 143,
      "g": 223,
      "b": 87
    },
    {
      "x": 12,
      "y": 0,
      "z": 17,
      "r": 143,
      "g": 223,
      "b": 87
    },
    {
      "x": 12,
      "y": 1,
      "z": 17,
      "r": 143,
      "g": 223,
      "b": 87
    },
    {
      "x": 12,
      "y": 2,
      "z": 17,
      "r": 143,
      "g": 223,
      "b": 87
    },
    {
      "x": 13,
      "y": 0,
      "z": 17,
      "r": 143,
      "g": 223,
      "b": 87
    },
    {
      "x": 13,
      "y": 1,
      "z": 17,
      "r": 143,
      "g": 223,
      "b": 87
    },
    {
      "x": 13,
      "y": 2,
      "z": 17,
      "r": 143,
      "g": 223,
      "b": 87
    },
    {
      "x": 13,
      "y": 3,
      "z": 17,
      "r": 143,
      "g": 223,
      "b": 87
    },
    {
      "x": 13,
      "y": 4,
      "z": 17,
      "r": 143,
      "g": 223,
      "b": 87
    },
    {
      "x": 14,
      "y": 0,
      "z": 17,
      "r": 143,
      "g": 223,
      "b": 87
    },
    {
      "x": 14,
      "y": 1,
      "z": 17,
      "r": 143,
      "g": 223,
      "b": 87
    },
    {
      "x": 14,
      "y": 2,
      "z": 17,
      "r": 143,
      "g": 223,
      "b": 87
    },
    {
      "x": 14,
      "y": 3,
      "z": 17,
      "r": 143,
      "g": 223,
      "b": 87
    },
    {
      "x": 14,
      "y": 4,
      "z": 17,
      "r": 143,
      "g": 223,
      "b": 87
    },
    {
      "x": 14,
      "y": 5,
      "z": 17,
      "r": 143,
      "g": 223,
      "b": 87
    },
    {
      "x": 12,
      "y": 3,
      "z": 17,
      "r": 143,
      "g": 223,
      "b": 87
    },
    {
      "x": 12,
      "y": 4,
      "z": 17,
      "r": 143,
      "g": 223,
      "b": 87
    },
    {
      "x": 12,
      "y": 5,
      "z": 17,
      "r": 143,
      "g": 223,
      "b": 87
    },
    {
      "x": 13,
      "y": 5,
      "z": 17,
      "r": 143,
      "g": 223,
      "b": 87
    },
    {
      "x": 10,
      "y": 5,
      "z": 17,
      "r": 143,
      "g": 223,
      "b": 87
    },
    {
      "x": 11,
      "y": 5,
      "z": 17,
      "r": 143,
      "g": 223,
      "b": 87
    },
    {
      "x": 14,
      "y": 3,
      "z": 18,
      "r": 143,
      "g": 223,
      "b": 87
    },
    {
      "x": 14,
      "y": 4,
      "z": 18,
      "r": 143,
      "g": 223,
      "b": 87
    },
    {
      "x": 14,
      "y": 2,
      "z": 18,
      "r": 143,
      "g": 223,
      "b": 87
    },
    {
      "x": 14,
      "y": 0,
      "z": 18,
      "r": 143,
      "g": 223,
      "b": 87
    },
    {
      "x": 14,
      "y": 1,
      "z": 18,
      "r": 143,
      "g": 223,
      "b": 87
    },
    {
      "x": 15,
      "y": 0,
      "z": 21,
      "r": 143,
      "g": 223,
      "b": 87
    },
    {
      "x": 15,
      "y": 1,
      "z": 21,
      "r": 143,
      "g": 223,
      "b": 87
    },
    {
      "x": 15,
      "y": 3,
      "z": 21,
      "r": 143,
      "g": 223,
      "b": 87
    },
    {
      "x": 15,
      "y": 4,
      "z": 21,
      "r": 143,
      "g": 223,
      "b": 87
    },
    {
      "x": 15,
      "y": 5,
      "z": 21,
      "r": 143,
      "g": 223,
      "b": 87
    },
    {
      "x": 15,
      "y": 5,
      "z": 22,
      "r": 143,
      "g": 223,
      "b": 87
    },
    {
      "x": 15,
      "y": 6,
      "z": 23,
      "r": 143,
      "g": 223,
      "b": 87
    },
    {
      "x": 15,
      "y": 0,
      "z": 23,
      "r": 143,
      "g": 223,
      "b": 87
    },
    {
      "x": 20,
      "y": 0,
      "z": 24,
      "r": 143,
      "g": 223,
      "b": 87
    },
    {
      "x": 20,
      "y": 0,
      "z": 25,
      "r": 143,
      "g": 223,
      "b": 87
    },
    {
      "x": 18,
      "y": 0,
      "z": 17,
      "r": 143,
      "g": 223,
      "b": 87
    },
    {
      "x": 19,
      "y": 0,
      "z": 17,
      "r": 143,
      "g": 223,
      "b": 87
    },
    {
      "x": 19,
      "y": 1,
      "z": 17,
      "r": 143,
      "g": 223,
      "b": 87
    },
    {
      "x": 19,
      "y": 2,
      "z": 17,
      "r": 143,
      "g": 223,
      "b": 87
    },
    {
      "x": 19,
      "y": 3,
      "z": 17,
      "r": 143,
      "g": 223,
      "b": 87
    },
    {
      "x": 19,
      "y": 4,
      "z": 17,
      "r": 143,
      "g": 223,
      "b": 87
    },
    {
      "x": 19,
      "y": 5,
      "z": 17,
      "r": 143,
      "g": 223,
      "b": 87
    },
    {
      "x": 24,
      "y": 5,
      "z": 14,
      "r": 143,
      "g": 223,
      "b": 87
    },
    {
      "x": 24,
      "y": 5,
      "z": 15,
      "r": 143,
      "g": 223,
      "b": 87
    },
    {
      "x": 24,
      "y": 5,
      "z": 16,
      "r": 143,
      "g": 223,
      "b": 87
    },
    {
      "x": 24,
      "y": 6,
      "z": 15,
      "r": 143,
      "g": 223,
      "b": 87
    },
    {
      "x": 24,
      "y": 6,
      "z": 16,
      "r": 143,
      "g": 223,
      "b": 87
    },
    {
      "x": 24,
      "y": 6,
      "z": 13,
      "r": 143,
      "g": 223,
      "b": 87
    },
    {
      "x": 24,
      "y": 6,
      "z": 14,
      "r": 143,
      "g": 223,
      "b": 87
    },
    {
      "x": 16,
      "y": 5,
      "z": 17,
      "r": 143,
      "g": 223,
      "b": 87
    },
    {
      "x": 17,
      "y": 5,
      "z": 17,
      "r": 143,
      "g": 223,
      "b": 87
    },
    {
      "x": 6,
      "y": 0,
      "z": 18,
      "r": 143,
      "g": 223,
      "b": 87
    },
    {
      "x": 7,
      "y": 0,
      "z": 18,
      "r": 143,
      "g": 223,
      "b": 87
    },
    {
      "x": 8,
      "y": 0,
      "z": 18,
      "r": 143,
      "g": 223,
      "b": 87
    },
    {
      "x": 7,
      "y": 1,
      "z": 18,
      "r": 143,
      "g": 223,
      "b": 87
    },
    {
      "x": 7,
      "y": 2,
      "z": 18,
      "r": 143,
      "g": 223,
      "b": 87
    },
    {
      "x": 7,
      "y": 3,
      "z": 18,
      "r": 143,
      "g": 223,
      "b": 87
    },
    {
      "x": 7,
      "y": 4,
      "z": 18,
      "r": 143,
      "g": 223,
      "b": 87
    },
    {
      "x": 7,
      "y": 5,
      "z": 18,
      "r": 143,
      "g": 223,
      "b": 87
    },
    {
      "x": 8,
      "y": 5,
      "z": 18,
      "r": 143,
      "g": 223,
      "b": 87
    },
    {
      "x": 1,
      "y": 6,
      "z": 23,
      "r": 143,
      "g": 223,
      "b": 87
    },
    {
      "x": 1,
      "y": 6,
      "z": 24,
      "r": 143,
      "g": 223,
      "b": 87
    },
    {
      "x": 1,
      "y": 6,
      "z": 25,
      "r": 143,
      "g": 223,
      "b": 87
    },
    {
      "x": 1,
      "y": 5,
      "z": 23,
      "r": 143,
      "g": 223,
      "b": 87
    },
    {
      "x": 1,
      "y": 3,
      "z": 23,
      "r": 143,
      "g": 223,
      "b": 87
    },
    {
      "x": 1,
      "y": 3,
      "z": 24,
      "r": 143,
      "g": 223,
      "b": 87
    },
    {
      "x": 1,
      "y": 3,
      "z": 25,
      "r": 143,
      "g": 223,
      "b": 87
    },
    {
      "x": 1,
      "y": 4,
      "z": 23,
      "r": 143,
      "g": 223,
      "b": 87
    },
    {
      "x": 1,
      "y": 0,
      "z": 19,
      "r": 143,
      "g": 223,
      "b": 87
    },
    {
      "x": 1,
      "y": 0,
      "z": 20,
      "r": 143,
      "g": 223,
      "b": 87
    },
    {
      "x": 1,
      "y": 1,
      "z": 20,
      "r": 143,
      "g": 223,
      "b": 87
    },
    {
      "x": 20,
      "y": 6,
      "z": 25,
      "r": 143,
      "g": 223,
      "b": 87
    },
    {
      "x": 20,
      "y": 6,
      "z": 24,
      "r": 143,
      "g": 223,
      "b": 87
    },
    {
      "x": 24,
      "y": 0,
      "z": 13,
      "r": 143,
      "g": 223,
      "b": 87
    },
    {
      "x": 24,
      "y": 0,
      "z": 14,
      "r": 143,
      "g": 223,
      "b": 87
    },
    {
      "x": 24,
      "y": 0,
      "z": 15,
      "r": 143,
      "g": 223,
      "b": 87
    },
    {
      "x": 24,
      "y": 0,
      "z": 16,
      "r": 143,
      "g": 223,
      "b": 87
    },
    {
      "x": 24,
      "y": 1,
      "z": 14,
      "r": 143,
      "g": 223,
      "b": 87
    },
    {
      "x": 24,
      "y": 1,
      "z": 15,
      "r": 143,
      "g": 223,
      "b": 87
    },
    {
      "x": 24,
      "y": 1,
      "z": 16,
      "r": 143,
      "g": 223,
      "b": 87
    },
    {
      "x": 24,
      "y": 2,
      "z": 14,
      "r": 143,
      "g": 223,
      "b": 87
    },
    {
      "x": 24,
      "y": 2,
      "z": 15,
      "r": 143,
      "g": 223,
      "b": 87
    },
    {
      "x": 24,
      "y": 2,
      "z": 16,
      "r": 143,
      "g": 223,
      "b": 87
    },
    {
      "x": 24,
      "y": 3,
      "z": 15,
      "r": 143,
      "g": 223,
      "b": 87
    },
    {
      "x": 24,
      "y": 3,
      "z": 16,
      "r": 143,
      "g": 223,
      "b": 87
    },
    {
      "x": 24,
      "y": 4,
      "z": 16,
      "r": 143,
      "g": 223,
      "b": 87
    },
    {
      "x": 24,
      "y": 3,
      "z": 14,
      "r": 143,
      "g": 223,
      "b": 87
    },
    {
      "x": 24,
      "y": 4,
      "z": 14,
      "r": 143,
      "g": 223,
      "b": 87
    },
    {
      "x": 24,
      "y": 4,
      "z": 15,
      "r": 143,
      "g": 223,
      "b": 87
    },
    {
      "x": 14,
      "y": 3,
      "z": 4,
      "r": 143,
      "g": 223,
      "b": 87
    },
    {
      "x": 14,
      "y": 4,
      "z": 4,
      "r": 143,
      "g": 223,
      "b": 87
    },
    {
      "x": 14,
      "y": 5,
      "z": 4,
      "r": 143,
      "g": 223,
      "b": 87
    },
    {
      "x": 14,
      "y": 6,
      "z": 4,
      "r": 143,
      "g": 223,
      "b": 87
    },
    {
      "x": 12,
      "y": 1,
      "z": 4,
      "r": 143,
      "g": 223,
      "b": 87
    },
    {
      "x": 12,
      "y": 2,
      "z": 4,
      "r": 143,
      "g": 223,
      "b": 87
    },
    {
      "x": 12,
      "y": 3,
      "z": 4,
      "r": 143,
      "g": 223,
      "b": 87
    },
    {
      "x": 12,
      "y": 4,
      "z": 4,
      "r": 143,
      "g": 223,
      "b": 87
    },
    {
      "x": 12,
      "y": 5,
      "z": 4,
      "r": 143,
      "g": 223,
      "b": 87
    },
    {
      "x": 12,
      "y": 6,
      "z": 4,
      "r": 143,
      "g": 223,
      "b": 87
    },
    {
      "x": 12,
      "y": 0,
      "z": 4,
      "r": 143,
      "g": 223,
      "b": 87
    },
    {
      "x": 24,
      "y": 0,
      "z": 4,
      "r": 143,
      "g": 223,
      "b": 87
    },
    {
      "x": 24,
      "y": 0,
      "z": 5,
      "r": 143,
      "g": 223,
      "b": 87
    },
    {
      "x": 24,
      "y": 0,
      "z": 6,
      "r": 143,
      "g": 223,
      "b": 87
    },
    {
      "x": 24,
      "y": 0,
      "z": 7,
      "r": 143,
      "g": 223,
      "b": 87
    },
    {
      "x": 24,
      "y": 0,
      "z": 8,
      "r": 143,
      "g": 223,
      "b": 87
    },
    {
      "x": 24,
      "y": 0,
      "z": 9,
      "r": 143,
      "g": 223,
      "b": 87
    },
    {
      "x": 24,
      "y": 1,
      "z": 5,
      "r": 143,
      "g": 223,
      "b": 87
    },
    {
      "x": 24,
      "y": 1,
      "z": 6,
      "r": 143,
      "g": 223,
      "b": 87
    },
    {
      "x": 24,
      "y": 1,
      "z": 7,
      "r": 143,
      "g": 223,
      "b": 87
    },
    {
      "x": 24,
      "y": 1,
      "z": 8,
      "r": 143,
      "g": 223,
      "b": 87
    },
    {
      "x": 24,
      "y": 1,
      "z": 9,
      "r": 143,
      "g": 223,
      "b": 87
    },
    {
      "x": 24,
      "y": 2,
      "z": 5,
      "r": 143,
      "g": 223,
      "b": 87
    },
    {
      "x": 24,
      "y": 2,
      "z": 6,
      "r": 143,
      "g": 223,
      "b": 87
    },
    {
      "x": 24,
      "y": 2,
      "z": 7,
      "r": 143,
      "g": 223,
      "b": 87
    },
    {
      "x": 24,
      "y": 2,
      "z": 8,
      "r": 143,
      "g": 223,
      "b": 87
    },
    {
      "x": 24,
      "y": 2,
      "z": 9,
      "r": 143,
      "g": 223,
      "b": 87
    },
    {
      "x": 24,
      "y": 3,
      "z": 6,
      "r": 143,
      "g": 223,
      "b": 87
    },
    {
      "x": 24,
      "y": 3,
      "z": 7,
      "r": 143,
      "g": 223,
      "b": 87
    },
    {
      "x": 24,
      "y": 3,
      "z": 8,
      "r": 143,
      "g": 223,
      "b": 87
    },
    {
      "x": 24,
      "y": 3,
      "z": 9,
      "r": 143,
      "g": 223,
      "b": 87
    },
    {
      "x": 24,
      "y": 4,
      "z": 7,
      "r": 143,
      "g": 223,
      "b": 87
    },
    {
      "x": 24,
      "y": 4,
      "z": 8,
      "r": 143,
      "g": 223,
      "b": 87
    },
    {
      "x": 24,
      "y": 4,
      "z": 9,
      "r": 143,
      "g": 223,
      "b": 87
    },
    {
      "x": 24,
      "y": 5,
      "z": 8,
      "r": 143,
      "g": 223,
      "b": 87
    },
    {
      "x": 24,
      "y": 5,
      "z": 9,
      "r": 143,
      "g": 223,
      "b": 87
    },
    {
      "x": 24,
      "y": 6,
      "z": 9,
      "r": 143,
      "g": 223,
      "b": 87
    },
    {
      "x": 24,
      "y": 3,
      "z": 5,
      "r": 143,
      "g": 223,
      "b": 87
    },
    {
      "x": 24,
      "y": 4,
      "z": 5,
      "r": 143,
      "g": 223,
      "b": 87
    },
    {
      "x": 24,
      "y": 4,
      "z": 6,
      "r": 143,
      "g": 223,
      "b": 87
    },
    {
      "x": 24,
      "y": 5,
      "z": 5,
      "r": 143,
      "g": 223,
      "b": 87
    },
    {
      "x": 24,
      "y": 5,
      "z": 6,
      "r": 143,
      "g": 223,
      "b": 87
    },
    {
      "x": 24,
      "y": 5,
      "z": 7,
      "r": 143,
      "g": 223,
      "b": 87
    },
    {
      "x": 24,
      "y": 6,
      "z": 5,
      "r": 143,
      "g": 223,
      "b": 87
    },
    {
      "x": 24,
      "y": 6,
      "z": 6,
      "r": 143,
      "g": 223,
      "b": 87
    },
    {
      "x": 24,
      "y": 6,
      "z": 7,
      "r": 143,
      "g": 223,
      "b": 87
    },
    {
      "x": 24,
      "y": 6,
      "z": 8,
      "r": 143,
      "g": 223,
      "b": 87
    },
    {
      "x": 24,
      "y": 6,
      "z": 10,
      "r": 143,
      "g": 223,
      "b": 87
    },
    {
      "x": 24,
      "y": 6,
      "z": 11,
      "r": 143,
      "g": 223,
      "b": 87
    },
    {
