{
  "resolution": 48,
  "gridSize": {
    "x": 17,
    "y": 48,
    "z": 17
  },
  "voxelCount": 703,
  "voxels": [
    {
      "x": 14,
      "y": 0,
      "z": 6,
      "r": 139,
      "g": 90,
      "b": 43
    },
    {
      "x": 15,
      "y": 0,
      "z": 6,
      "r": 139,
      "g": 90,
      "b": 43
    },
    {
      "x": 16,
      "y": 0,
      "z": 6,
      "r": 139,
      "g": 90,
      "b": 43
    },
    {
      "x": 14,
      "y": 0,
      "z": 7,
      "r": 139,
      "g": 90,
      "b": 43
    },
    {
      "x": 15,
      "y": 0,
      "z": 7,
      "r": 139,
      "g": 90,
      "b": 43
    },
    {
      "x": 16,
      "y": 0,
      "z": 7,
      "r": 139,
      "g": 90,
      "b": 43
    },
    {
      "x": 14,
      "y": 0,
      "z": 8,
      "r": 139,
      "g": 90,
      "b": 43
    },
    {
      "x": 15,
      "y": 0,
      "z": 8,
      "r": 139,
      "g": 90,
      "b": 43
    },
    {
      "x": 16,
      "y": 0,
      "z": 8,
      "r": 139,
      "g": 90,
      "b": 43
    },
    {
      "x": 14,
      "y": 0,
      "z": 9,
      "r": 139,
      "g": 90,
      "b": 43
    },
    {
      "x": 15,
      "y": 0,
      "z": 9,
      "r": 139,
      "g": 90,
      "b": 43
    },
    {
      "x": 16,
      "y": 0,
      "z": 9,
      "r": 139,
      "g": 90,
      "b": 43
    },
    {
      "x": 14,
      "y": 0,
      "z": 10,
      "r": 139,
      "g": 90,
      "b": 43
    },
    {
      "x": 15,
      "y": 0,
      "z": 10,
      "r": 139,
      "g": 90,
      "b": 43
    },
    {
      "x": 16,
      "y": 0,
      "z": 10,
      "r": 139,
      "g": 90,
      "b": 43
    },
    {
      "x": 14,
      "y": 1,
      "z": 7,
      "r": 139,
      "g": 90,
      "b": 43
    },
    {
      "x": 15,
      "y": 1,
      "z": 7,
      "r": 139,
      "g": 90,
      "b": 43
    },
    {
      "x": 16,
      "y": 1,
      "z": 8,
      "r": 139,
      "g": 90,
      "b": 43
    },
    {
      "x": 14,
      "y": 1,
      "z": 8,
      "r": 139,
      "g": 90,
      "b": 43
    },
    {
      "x": 15,
      "y": 1,
      "z": 8,
      "r": 139,
      "g": 90,
      "b": 43
    },
    {
      "x": 16,
      "y": 1,
      "z": 9,
      "r": 139,
      "g": 90,
      "b": 43
    },
    {
      "x": 14,
      "y": 1,
      "z": 9,
      "r": 139,
      "g": 90,
      "b": 43
    },
    {
      "x": 15,
      "y": 1,
      "z": 9,
      "r": 139,
      "g": 90,
      "b": 43
    },
    {
      "x": 16,
      "y": 1,
      "z": 10,
      "r": 139,
      "g": 90,
      "b": 43
    },
    {
      "x": 14,
      "y": 1,
      "z": 10,
      "r": 139,
      "g": 90,
      "b": 43
    },
    {
      "x": 15,
      "y": 1,
      "z": 10,
      "r": 139,
      "g": 90,
      "b": 43
    },
    {
      "x": 16,
      "y": 1,
      "z": 11,
      "r": 139,
      "g": 90,
      "b": 43
    },
    {
      "x": 13,
      "y": 1,
      "z": 11,
      "r": 139,
      "g": 90,
      "b": 43
    },
    {
      "x": 14,
      "y": 1,
      "z": 11,
      "r": 139,
      "g": 90,
      "b": 43
    },
    {
      "x": 15,
      "y": 1,
      "z": 12,
      "r": 139,
      "g": 90,
      "b": 43
    },
    {
      "x": 14,
      "y": 2,
      "z": 8,
      "r": 139,
      "g": 90,
      "b": 43
    },
    {
      "x": 15,
      "y": 2,
      "z": 9,
      "r": 139,
      "g": 90,
      "b": 43
    },
    {
      "x": 16,
      "y": 2,
      "z": 9,
      "r": 139,
      "g": 90,
      "b": 43
    },
    {
      "x": 14,
      "y": 2,
      "z": 9,
      "r": 139,
      "g": 90,
      "b": 43
    },
    {
      "x": 15,
      "y": 2,
      "z": 10,
      "r": 139,
      "g": 90,
      "b": 43
    },
    {
      "x": 16,
      "y": 2,
      "z": 10,
      "r": 139,
      "g": 90,
      "b": 43
    },
    {
      "x": 14,
      "y": 2,
      "z": 10,
      "r": 139,
      "g": 90,
      "b": 43
    },
    {
      "x": 14,
      "y": 2,
      "z": 11,
      "r": 139,
      "g": 90,
      "b": 43
    },
    {
      "x": 15,
      "y": 2,
      "z": 11,
      "r": 139,
      "g": 90,
      "b": 43
    },
    {
      "x": 13,
      "y": 2,
      "z": 11,
      "r": 139,
      "g": 90,
      "b": 43
    },
    {
      "x": 14,
      "y": 2,
      "z": 12,
      "r": 139,
      "g": 90,
      "b": 43
    },
    {
      "x": 15,
      "y": 2,
      "z": 12,
      "r": 139,
      "g": 90,
      "b": 43
    },
    {
      "x": 13,
      "y": 2,
      "z": 12,
      "r": 139,
      "g": 90,
      "b": 43
    },
    {
      "x": 14,
      "y": 2,
      "z": 13,
      "r": 139,
      "g": 90,
      "b": 43
    },
    {
      "x": 15,
      "y": 2,
      "z": 13,
      "r": 139,
      "g": 90,
      "b": 43
    },
    {
      "x": 14,
      "y": 3,
      "z": 10,
      "r": 139,
      "g": 90,
      "b": 43
    },
    {
      "x": 15,
      "y": 3,
      "z": 10,
      "r": 139,
      "g": 90,
      "b": 43
    },
    {
      "x": 16,
      "y": 3,
      "z": 11,
      "r": 139,
      "g": 90,
      "b": 43
    },
    {
      "x": 14,
      "y": 3,
      "z": 11,
      "r": 139,
      "g": 90,
      "b": 43
    },
    {
      "x": 15,
      "y": 3,
      "z": 12,
      "r": 139,
      "g": 90,
      "b": 43
    },
    {
      "x": 13,
      "y": 3,
      "z": 11,
      "r": 139,
      "g": 90,
      "b": 43
    },
    {
      "x": 14,
      "y": 3,
      "z": 12,
      "r": 139,
      "g": 90,
      "b": 43
    },
    {
      "x": 12,
      "y": 3,
      "z": 12,
      "r": 139,
      "g": 90,
      "b": 43
    },
    {
      "x": 13,
      "y": 3,
      "z": 13,
      "r": 139,
      "g": 90,
      "b": 43
    },
    {
      "x": 14,
      "y": 3,
      "z": 13,
      "r": 139,
      "g": 90,
      "b": 43
    },
    {
      "x": 12,
      "y": 3,
      "z": 13,
      "r": 139,
      "g": 90,
      "b": 43
    },
    {
      "x": 13,
      "y": 3,
      "z": 14,
      "r": 139,
      "g": 90,
      "b": 43
    },
    {
      "x": 14,
      "y": 3,
      "z": 14,
      "r": 139,
      "g": 90,
      "b": 43
    },
    {
      "x": 14,
      "y": 4,
      "z": 11,
      "r": 139,
      "g": 90,
      "b": 43
    },
    {
      "x": 14,
      "y": 4,
      "z": 12,
      "r": 139,
      "g": 90,
      "b": 43
    },
    {
      "x": 15,
      "y": 4,
      "z": 12,
      "r": 139,
      "g": 90,
      "b": 43
    },
    {
      "x": 13,
      "y": 4,
      "z": 12,
      "r": 139,
      "g": 90,
      "b": 43
    },
    {
      "x": 14,
      "y": 4,
      "z": 13,
      "r": 139,
      "g": 90,
      "b": 43
    },
    {
      "x": 12,
      "y": 4,
      "z": 12,
      "r": 139,
      "g": 90,
      "b": 43
    },
    {
      "x": 13,
      "y": 4,
      "z": 13,
      "r": 139,
      "g": 90,
      "b": 43
    },
    {
      "x": 14,
      "y": 4,
      "z": 14,
      "r": 139,
      "g": 90,
      "b": 43
    },
    {
      "x": 12,
      "y": 4,
      "z": 13,
      "r": 139,
      "g": 90,
      "b": 43
    },
    {
      "x": 12,
      "y": 4,
      "z": 14,
      "r": 139,
      "g": 90,
      "b": 43
    },
    {
      "x": 13,
      "y": 4,
      "z": 14,
      "r": 139,
      "g": 90,
      "b": 43
    },
    {
      "x": 11,
      "y": 4,
      "z": 14,
      "r": 139,
      "g": 90,
      "b": 43
    },
    {
      "x": 12,
      "y": 4,
      "z": 15,
      "r": 139,
      "g": 90,
      "b": 43
    },
    {
      "x": 13,
      "y": 5,
      "z": 12,
      "r": 139,
      "g": 90,
      "b": 43
    },
    {
      "x": 14,
      "y": 5,
      "z": 13,
      "r": 139,
      "g": 90,
      "b": 43
    },
    {
      "x": 14,
      "y": 5,
      "z": 14,
      "r": 139,
      "g": 90,
      "b": 43
    },
    {
      "x": 12,
      "y": 5,
      "z": 12,
      "r": 139,
      "g": 90,
      "b": 43
    },
    {
      "x": 13,
      "y": 5,
      "z": 13,
      "r": 139,
      "g": 90,
      "b": 43
    },
    {
      "x": 13,
      "y": 5,
      "z": 14,
      "r": 139,
      "g": 90,
      "b": 43
    },
    {
      "x": 11,
      "y": 5,
      "z": 13,
      "r": 139,
      "g": 90,
      "b": 43
    },
    {
      "x": 12,
      "y": 5,
      "z": 14,
      "r": 139,
      "g": 90,
      "b": 43
    },
    {
      "x": 12,
      "y": 5,
      "z": 15,
      "r": 139,
      "g": 90,
      "b": 43
    },
    {
      "x": 11,
      "y": 5,
      "z": 14,
      "r": 139,
      "g": 90,
      "b": 43
    },
    {
      "x": 10,
      "y": 5,
      "z": 14,
      "r": 139,
      "g": 90,
      "b": 43
    },
    {
      "x": 10,
      "y": 5,
      "z": 15,
      "r": 139,
      "g": 90,
      "b": 43
    },
    {
      "x": 11,
      "y": 5,
      "z": 16,
      "r": 139,
      "g": 90,
      "b": 43
    },
    {
      "x": 12,
      "y": 6,
      "z": 13,
      "r": 139,
      "g": 90,
      "b": 43
    },
    {
      "x": 13,
      "y": 6,
      "z": 14,
      "r": 139,
      "g": 90,
      "b": 43
    },
    {
      "x": 13,
      "y": 6,
      "z": 15,
      "r": 139,
      "g": 90,
      "b": 43
    },
    {
      "x": 11,
      "y": 6,
      "z": 13,
      "r": 139,
      "g": 90,
      "b": 43
    },
    {
      "x": 12,
      "y": 6,
      "z": 14,
      "r": 139,
      "g": 90,
      "b": 43
    },
    {
      "x": 12,
      "y": 6,
      "z": 15,
      "r": 139,
      "g": 90,
      "b": 43
    },
    {
      "x": 10,
      "y": 6,
      "z": 14,
      "r": 139,
      "g": 90,
      "b": 43
    },
    {
      "x": 11,
      "y": 6,
      "z": 14,
      "r": 139,
      "g": 90,
      "b": 43
    },
    {
      "x": 11,
      "y": 6,
      "z": 15,
      "r": 139,
      "g": 90,
      "b": 43
    },
    {
      "x": 9,
      "y": 6,
      "z": 14,
      "r": 139,
      "g": 90,
      "b": 43
    },
    {
      "x": 10,
      "y": 6,
      "z": 15,
      "r": 139,
      "g": 90,
      "b": 43
    },
    {
      "x": 10,
      "y": 6,
      "z": 16,
      "r": 139,
      "g": 90,
      "b": 43
    },
    {
      "x": 8,
      "y": 6,
      "z": 14,
      "r": 139,
      "g": 90,
      "b": 43
    },
    {
      "x": 9,
      "y": 6,
      "z": 15,
      "r": 139,
      "g": 90,
      "b": 43
    },
    {
      "x": 9,
      "y": 6,
      "z": 16,
      "r": 139,
      "g": 90,
      "b": 43
    },
    {
      "x": 11,
      "y": 7,
      "z": 13,
      "r": 139,
      "g": 90,
      "b": 43
    },
    {
      "x": 11,
      "y": 7,
      "z": 14,
      "r": 139,
      "g": 90,
      "b": 43
    },
    {
      "x": 12,
      "y": 7,
      "z": 15,
      "r": 139,
      "g": 90,
      "b": 43
    },
    {
      "x": 10,
      "y": 7,
      "z": 14,
      "r": 139,
      "g": 90,
      "b": 43
    },
    {
      "x": 10,
      "y": 7,
      "z": 15,
      "r": 139,
      "g": 90,
      "b": 43
    },
    {
      "x": 11,
      "y": 7,
      "z": 16,
      "r": 139,
      "g": 90,
      "b": 43
    },
    {
      "x": 9,
      "y": 7,
      "z": 14,
      "r": 139,
      "g": 90,
      "b": 43
    },
    {
      "x": 9,
      "y": 7,
      "z": 15,
      "r": 139,
      "g": 90,
      "b": 43
    },
    {
      "x": 10,
      "y": 7,
      "z": 16,
      "r": 139,
      "g": 90,
      "b": 43
    },
    {
      "x": 8,
      "y": 7,
      "z": 14,
      "r": 139,
      "g": 90,
      "b": 43
    },
    {
      "x": 8,
      "y": 7,
      "z": 15,
      "r": 139,
      "g": 90,
      "b": 43
    },
    {
      "x": 9,
      "y": 7,
      "z": 16,
      "r": 139,
      "g": 90,
      "b": 43
    },
    {
      "x": 7,
      "y": 7,
      "z": 14,
      "r": 139,
      "g": 90,
      "b": 43
    },
    {
      "x": 7,
      "y": 7,
      "z": 15,
      "r": 139,
      "g": 90,
      "b": 43
    },
    {
      "x": 8,
      "y": 7,
      "z": 16,
      "r": 139,
      "g": 90,
      "b": 43
    },
    {
      "x": 10,
      "y": 8,
      "z": 14,
      "r": 139,
      "g": 90,
      "b": 43
    },
    {
      "x": 10,
      "y": 8,
      "z": 15,
      "r": 139,
      "g": 90,
      "b": 43
    },
    {
      "x": 10,
      "y": 8,
      "z": 16,
      "r": 139,
      "g": 90,
      "b": 43
    },
    {
      "x": 9,
      "y": 8,
      "z": 14,
      "r": 139,
      "g": 90,
      "b": 43
    },
    {
      "x": 9,
      "y": 8,
      "z": 15,
      "r": 139,
      "g": 90,
      "b": 43
    },
    {
      "x": 9,
      "y": 8,
      "z": 16,
      "r": 139,
      "g": 90,
      "b": 43
    },
    {
      "x": 8,
      "y": 8,
      "z": 14,
      "r": 139,
      "g": 90,
      "b": 43
    },
    {
      "x": 8,
      "y": 8,
      "z": 15,
      "r": 139,
      "g": 90,
      "b": 43
    },
    {
      "x": 8,
      "y": 8,
      "z": 16,
      "r": 139,
      "g": 90,
      "b": 43
    },
    {
      "x": 7,
      "y": 8,
      "z": 14,
      "r": 139,
      "g": 90,
      "b": 43
    },
    {
      "x": 7,
      "y": 8,
      "z": 15,
      "r": 139,
      "g": 90,
      "b": 43
    },
    {
      "x": 7,
      "y": 8,
      "z": 16,
      "r": 139,
      "g": 90,
      "b": 43
    },
    {
      "x": 6,
      "y": 8,
      "z": 14,
      "r": 139,
      "g": 90,
      "b": 43
    },
    {
      "x": 6,
      "y": 8,
      "z": 15,
      "r": 139,
      "g": 90,
      "b": 43
    },
    {
      "x": 6,
      "y": 8,
      "z": 16,
      "r": 139,
      "g": 90,
      "b": 43
    },
    {
      "x": 9,
      "y": 9,
      "z": 14,
      "r": 139,
      "g": 90,
      "b": 43
    },
    {
      "x": 9,
      "y": 9,
      "z": 15,
      "r": 139,
      "g": 90,
      "b": 43
    },
    {
      "x": 8,
      "y": 9,
      "z": 16,
      "r": 139,
      "g": 90,
      "b": 43
    },
    {
      "x": 8,
      "y": 9,
      "z": 14,
      "r": 139,
      "g": 90,
      "b": 43
    },
    {
      "x": 8,
      "y": 9,
      "z": 15,
      "r": 139,
      "g": 90,
      "b": 43
    },
    {
      "x": 7,
      "y": 9,
      "z": 16,
      "r": 139,
      "g": 90,
      "b": 43
    },
    {
      "x": 7,
      "y": 9,
      "z": 14,
      "r": 139,
      "g": 90,
      "b": 43
    },
    {
      "x": 7,
      "y": 9,
      "z": 15,
      "r": 139,
      "g": 90,
      "b": 43
    },
    {
      "x": 6,
      "y": 9,
      "z": 16,
      "r": 139,
      "g": 90,
      "b": 43
    },
    {
      "x": 6,
      "y": 9,
      "z": 14,
      "r": 139,
      "g": 90,
      "b": 43
    },
    {
      "x": 6,
      "y": 9,
      "z": 15,
      "r": 139,
      "g": 90,
      "b": 43
    },
    {
      "x": 5,
      "y": 9,
      "z": 16,
      "r": 139,
      "g": 90,
      "b": 43
    },
    {
      "x": 5,
      "y": 9,
      "z": 13,
      "r": 139,
      "g": 90,
      "b": 43
    },
    {
      "x": 5,
      "y": 9,
      "z": 14,
      "r": 139,
      "g": 90,
      "b": 43
    },
    {
      "x": 4,
      "y": 9,
      "z": 15,
      "r": 139,
      "g": 90,
      "b": 43
    },
    {
      "x": 8,
      "y": 10,
      "z": 14,
      "r": 139,
      "g": 90,
      "b": 43
    },
    {
      "x": 7,
      "y": 10,
      "z": 15,
      "r": 139,
      "g": 90,
      "b": 43
    },
    {
      "x": 7,
      "y": 10,
      "z": 16,
      "r": 139,
      "g": 90,
      "b": 43
    },
    {
      "x": 7,
      "y": 10,
      "z": 14,
      "r": 139,
      "g": 90,
      "b": 43
    },
    {
      "x": 6,
      "y": 10,
      "z": 15,
      "r": 139,
      "g": 90,
      "b": 43
    },
    {
      "x": 6,
      "y": 10,
      "z": 16,
      "r": 139,
      "g": 90,
      "b": 43
    },
    {
      "x": 6,
      "y": 10,
      "z": 14,
      "r": 139,
      "g": 90,
      "b": 43
    },
    {
      "x": 5,
      "y": 10,
      "z": 14,
      "r": 139,
      "g": 90,
      "b": 43
    },
    {
      "x": 5,
      "y": 10,
      "z": 15,
      "r": 139,
      "g": 90,
      "b": 43
    },
    {
      "x": 5,
      "y": 10,
      "z": 13,
      "r": 139,
      "g": 90,
      "b": 43
    },
    {
      "x": 4,
      "y": 10,
      "z": 14,
      "r": 139,
      "g": 90,
      "b": 43
    },
    {
      "x": 4,
      "y": 10,
      "z": 15,
      "r": 139,
      "g": 90,
      "b": 43
    },
    {
      "x": 4,
      "y": 10,
      "z": 13,
      "r": 139,
      "g": 90,
      "b": 43
    },
    {
      "x": 3,
      "y": 10,
      "z": 14,
      "r": 139,
      "g": 90,
      "b": 43
    },
    {
      "x": 3,
      "y": 10,
      "z": 15,
      "r": 139,
      "g": 90,
      "b": 43
    },
    {
      "x": 6,
      "y": 11,
      "z": 14,
      "r": 139,
      "g": 90,
      "b": 43
    },
    {
      "x": 6,
      "y": 11,
      "z": 15,
      "r": 139,
      "g": 90,
      "b": 43
    },
    {
      "x": 5,
      "y": 11,
      "z": 16,
      "r": 139,
      "g": 90,
      "b": 43
    },
    {
      "x": 5,
      "y": 11,
      "z": 14,
      "r": 139,
      "g": 90,
      "b": 43
    },
    {
      "x": 4,
      "y": 11,
      "z": 15,
      "r": 139,
      "g": 90,
      "b": 43
    },
    {
      "x": 5,
      "y": 11,
      "z": 13,
      "r": 139,
      "g": 90,
      "b": 43
    },
    {
      "x": 4,
      "y": 11,
      "z": 14,
      "r": 139,
      "g": 90,
      "b": 43
    },
    {
      "x": 4,
      "y": 11,
      "z": 12,
      "r": 139,
      "g": 90,
      "b": 43
    },
    {
      "x": 3,
      "y": 11,
      "z": 13,
      "r": 139,
      "g": 90,
      "b": 43
    },
    {
      "x": 3,
      "y": 11,
      "z": 14,
      "r": 139,
      "g": 90,
      "b": 43
    },
    {
      "x": 3,
      "y": 11,
      "z": 12,
      "r": 139,
      "g": 90,
      "b": 43
    },
    {
      "x": 2,
      "y": 11,
      "z": 13,
      "r": 139,
      "g": 90,
      "b": 43
    },
    {
      "x": 2,
      "y": 11,
      "z": 14,
      "r": 139,
      "g": 90,
      "b": 43
    },
    {
      "x": 5,
      "y": 12,
      "z": 14,
      "r": 139,
      "g": 90,
      "b": 43
    },
    {
      "x": 4,
      "y": 12,
      "z": 14,
      "r": 139,
      "g": 90,
      "b": 43
    },
    {
      "x": 4,
      "y": 12,
      "z": 15,
      "r": 139,
      "g": 90,
      "b": 43
    },
    {
      "x": 4,
      "y": 12,
      "z": 13,
      "r": 139,
      "g": 90,
      "b": 43
    },
    {
      "x": 3,
      "y": 12,
      "z": 14,
      "r": 139,
      "g": 90,
      "b": 43
    },
    {
      "x": 4,
      "y": 12,
      "z": 12,
      "r": 139,
      "g": 90,
      "b": 43
    },
    {
      "x": 3,
      "y": 12,
      "z": 13,
      "r": 139,
      "g": 90,
      "b": 43
    },
    {
      "x": 2,
      "y": 12,
      "z": 14,
      "r": 139,
      "g": 90,
      "b": 43
    },
    {
      "x": 3,
      "y": 12,
      "z": 12,
      "r": 139,
      "g": 90,
      "b": 43
    },
    {
      "x": 2,
      "y": 12,
      "z": 12,
      "r": 139,
      "g": 90,
      "b": 43
    },
    {
      "x": 2,
      "y": 12,
      "z": 13,
      "r": 139,
      "g": 90,
      "b": 43
    },
    {
      "x": 2,
      "y": 12,
      "z": 11,
      "r": 139,
      "g": 90,
      "b": 43
    },
    {
      "x": 1,
      "y": 12,
      "z": 12,
      "r": 139,
      "g": 90,
      "b": 43
    },
    {
      "x": 4,
      "y": 13,
      "z": 13,
      "r": 139,
      "g": 90,
      "b": 43
    },
    {
      "x": 3,
      "y": 13,
      "z": 14,
      "r": 139,
      "g": 90,
      "b": 43
    },
    {
      "x": 2,
      "y": 13,
      "z": 14,
      "r": 139,
      "g": 90,
      "b": 43
    },
    {
      "x": 4,
      "y": 13,
      "z": 12,
      "r": 139,
      "g": 90,
      "b": 43
    },
    {
      "x": 3,
      "y": 13,
      "z": 13,
      "r": 139,
      "g": 90,
      "b": 43
    },
    {
      "x": 2,
      "y": 13,
      "z": 13,
      "r": 139,
      "g": 90,
      "b": 43
    },
    {
      "x": 3,
      "y": 13,
      "z": 11,
      "r": 139,
      "g": 90,
      "b": 43
    },
    {
      "x": 2,
      "y": 13,
      "z": 12,
      "r": 139,
      "g": 90,
      "b": 43
    },
    {
      "x": 1,
      "y": 13,
      "z": 12,
      "r": 139,
      "g": 90,
      "b": 43
    },
    {
      "x": 2,
      "y": 13,
      "z": 11,
      "r": 139,
      "g": 90,
      "b": 43
    },
    {
      "x": 2,
      "y": 13,
      "z": 10,
      "r": 139,
      "g": 90,
      "b": 43
    },
    {
      "x": 1,
      "y": 13,
      "z": 10,
      "r": 139,
      "g": 90,
      "b": 43
    },
    {
      "x": 0,
      "y": 13,
      "z": 11,
      "r": 139,
      "g": 90,
      "b": 43
    },
    {
      "x": 3,
      "y": 14,
      "z": 12,
      "r": 139,
      "g": 90,
      "b": 43
    },
    {
      "x": 2,
      "y": 14,
      "z": 13,
      "r": 139,
      "g": 90,
      "b": 43
    },
    {
      "x": 1,
      "y": 14,
      "z": 13,
      "r": 139,
      "g": 90,
      "b": 43
    },
    {
      "x": 3,
      "y": 14,
      "z": 11,
      "r": 139,
      "g": 90,
      "b": 43
    },
    {
      "x": 2,
      "y": 14,
      "z": 12,
      "r": 139,
      "g": 90,
      "b": 43
    },
    {
      "x": 1,
      "y": 14,
      "z": 12,
      "r": 139,
      "g": 90,
      "b": 43
    },
    {
      "x": 2,
      "y": 14,
      "z": 10,
      "r": 139,
      "g": 90,
      "b": 43
    },
    {
      "x": 2,
      "y": 14,
      "z": 11,
      "r": 139,
      "g": 90,
      "b": 43
    },
    {
      "x": 1,
      "y": 14,
      "z": 11,
      "r": 139,
      "g": 90,
      "b": 43
    },
    {
      "x": 2,
      "y": 14,
      "z": 9,
      "r": 139,
      "g": 90,
      "b": 43
    },
    {
      "x": 1,
      "y": 14,
      "z": 10,
      "r": 139,
      "g": 90,
      "b": 43
    },
    {
      "x": 0,
      "y": 14,
      "z": 10,
      "r": 139,
      "g": 90,
      "b": 43
    },
    {
      "x": 2,
      "y": 14,
      "z": 8,
      "r": 139,
      "g": 90,
      "b": 43
    },
    {
      "x": 1,
      "y": 14,
      "z": 9,
      "r": 139,
      "g": 90,
      "b": 43
    },
    {
      "x": 0,
      "y": 14,
      "z": 9,
      "r": 139,
      "g": 90,
      "b": 43
    },
    {
      "x": 3,
      "y": 15,
      "z": 11,
      "r": 139,
      "g": 90,
      "b": 43
    },
    {
      "x": 2,
      "y": 15,
      "z": 11,
      "r": 139,
      "g": 90,
      "b": 43
    },
    {
      "x": 1,
      "y": 15,
      "z": 12,
      "r": 139,
      "g": 90,
      "b": 43
    },
    {
      "x": 2,
      "y": 15,
      "z": 10,
      "r": 139,
      "g": 90,
      "b": 43
    },
    {
      "x": 1,
      "y": 15,
      "z": 10,
      "r": 139,
      "g": 90,
      "b": 43
    },
    {
      "x": 0,
      "y": 15,
      "z": 11,
      "r": 139,
      "g": 90,
      "b": 43
    },
    {
      "x": 2,
      "y": 15,
      "z": 9,
      "r": 139,
      "g": 90,
      "b": 43
    },
    {
      "x": 1,
      "y": 15,
      "z": 9,
      "r": 139,
      "g": 90,
      "b": 43
    },
    {
      "x": 0,
      "y": 15,
      "z": 10,
      "r": 139,
      "g": 90,
      "b": 43
    },
    {
      "x": 2,
      "y": 15,
      "z": 8,
      "r": 139,
      "g": 90,
      "b": 43
    },
    {
      "x": 1,
      "y": 15,
      "z": 8,
      "r": 139,
      "g": 90,
      "b": 43
    },
    {
      "x": 0,
      "y": 15,
      "z": 9,
      "r": 139,
      "g": 90,
      "b": 43
    },
    {
      "x": 2,
      "y": 15,
      "z": 7,
      "r": 139,
      "g": 90,
      "b": 43
    },
    {
      "x": 1,
      "y": 15,
      "z": 7,
      "r": 139,
      "g": 90,
      "b": 43
    },
    {
      "x": 0,
      "y": 15,
      "z": 8,
      "r": 139,
      "g": 90,
      "b": 43
    },
    {
      "x": 2,
      "y": 16,
      "z": 10,
      "r": 139,
      "g": 90,
      "b": 43
    },
    {
      "x": 1,
      "y": 16,
      "z": 10,
      "r": 139,
      "g": 90,
      "b": 43
    },
    {
      "x": 0,
      "y": 16,
      "z": 10,
      "r": 139,
      "g": 90,
      "b": 43
    },
    {
      "x": 2,
      "y": 16,
      "z": 9,
      "r": 139,
      "g": 90,
      "b": 43
    },
    {
      "x": 1,
      "y": 16,
      "z": 9,
      "r": 139,
      "g": 90,
      "b": 43
    },
    {
      "x": 0,
      "y": 16,
      "z": 9,
      "r": 139,
      "g": 90,
      "b": 43
    },
    {
      "x": 2,
      "y": 16,
      "z": 8,
      "r": 139,
      "g": 90,
      "b": 43
    },
    {
      "x": 1,
      "y": 16,
      "z": 8,
      "r": 139,
      "g": 90,
      "b": 43
    },
    {
      "x": 0,
      "y": 16,
      "z": 8,
      "r": 139,
      "g": 90,
      "b": 43
    },
    {
      "x": 2,
      "y": 16,
      "z": 7,
      "r": 139,
      "g": 90,
      "b": 43
    },
    {
      "x": 1,
      "y": 16,
      "z": 7,
      "r": 139,
      "g": 90,
      "b": 43
    },
    {
      "x": 0,
      "y": 16,
      "z": 7,
      "r": 139,
      "g": 90,
      "b": 43
    },
    {
      "x": 2,
      "y": 16,
      "z": 6,
      "r": 139,
      "g": 90,
      "b": 43
    },
    {
      "x": 1,
      "y": 16,
      "z": 6,
      "r": 139,
      "g": 90,
      "b": 43
    },
    {
      "x": 0,
      "y": 16,
      "z": 6,
      "r": 139,
      "g": 90,
      "b": 43
    },
    {
      "x": 2,
      "y": 17,
      "z": 9,
      "r": 139,
      "g": 90,
      "b": 43
    },
    {
      "x": 1,
      "y": 17,
      "z": 9,
      "r": 139,
      "g": 90,
      "b": 43
    },
    {
      "x": 0,
      "y": 17,
      "z": 8,
      "r": 139,
      "g": 90,
      "b": 43
    },
    {
      "x": 2,
      "y": 17,
      "z": 8,
      "r": 139,
      "g": 90,
      "b": 43
    },
    {
      "x": 1,
      "y": 17,
      "z": 8,
      "r": 139,
      "g": 90,
      "b": 43
    },
    {
      "x": 0,
      "y": 17,
      "z": 7,
      "r": 139,
      "g": 90,
      "b": 43
    },
    {
      "x": 2,
      "y": 17,
      "z": 7,
      "r": 139,
      "g": 90,
      "b": 43
    },
    {
      "x": 1,
      "y": 17,
      "z": 7,
      "r": 139,
      "g": 90,
      "b": 43
    },
    {
      "x": 0,
      "y": 17,
      "z": 6,
      "r": 139,
      "g": 90,
      "b": 43
    },
    {
      "x": 2,
      "y": 17,
      "z": 6,
      "r": 139,
      "g": 90,
      "b": 43
    },
    {
      "x": 1,
      "y": 17,
      "z": 6,
      "r": 139,
      "g": 90,
      "b": 43
    },
    {
      "x": 0,
      "y": 17,
      "z": 5,
      "r": 139,
      "g": 90,
      "b": 43
    },
    {
      "x": 3,
      "y": 17,
      "z": 5,
      "r": 139,
      "g": 90,
      "b": 43
    },
    {
      "x": 2,
      "y": 17,
      "z": 5,
      "r": 139,
      "g": 90,
      "b": 43
    },
    {
      "x": 1,
      "y": 17,
      "z": 4,
      "r": 139,
      "g": 90,
      "b": 43
    },
    {
      "x": 2,
      "y": 18,
      "z": 8,
      "r": 139,
      "g": 90,
      "b": 43
    },
    {
      "x": 1,
      "y": 18,
      "z": 7,
      "r": 139,
      "g": 90,
      "b": 43
    },
    {
      "x": 0,
      "y": 18,
      "z": 7,
      "r": 139,
      "g": 90,
      "b": 43
    },
    {
      "x": 2,
      "y": 18,
      "z": 7,
      "r": 139,
      "g": 90,
      "b": 43
    },
    {
      "x": 1,
      "y": 18,
      "z": 6,
      "r": 139,
      "g": 90,
      "b": 43
    },
    {
      "x": 0,
      "y": 18,
      "z": 6,
      "r": 139,
      "g": 90,
      "b": 43
    },
    {
      "x": 2,
      "y": 18,
      "z": 6,
      "r": 139,
      "g": 90,
      "b": 43
    },
    {
      "x": 2,
      "y": 18,
      "z": 5,
      "r": 139,
      "g": 90,
      "b": 43
    },
    {
      "x": 1,
      "y": 18,
      "z": 5,
      "r": 139,
      "g": 90,
      "b": 43
    },
    {
      "x": 3,
      "y": 18,
      "z": 5,
      "r": 139,
      "g": 90,
      "b": 43
    },
    {
      "x": 2,
      "y": 18,
      "z": 4,
      "r": 139,
      "g": 90,
      "b": 43
    },
    {
      "x": 1,
      "y": 18,
      "z": 4,
      "r": 139,
      "g": 90,
      "b": 43
    },
    {
      "x": 3,
      "y": 18,
      "z": 4,
      "r": 139,
      "g": 90,
      "b": 43
    },
    {
      "x": 2,
      "y": 18,
      "z": 3,
      "r": 139,
      "g": 90,
      "b": 43
    },
    {
      "x": 1,
      "y": 18,
      "z": 3,
      "r": 139,
      "g": 90,
      "b": 43
    },
    {
      "x": 2,
      "y": 19,
      "z": 6,
      "r": 139,
      "g": 90,
      "b": 43
    },
    {
      "x": 1,
      "y": 19,
      "z": 6,
      "r": 139,
      "g": 90,
      "b": 43
    },
    {
      "x": 0,
      "y": 19,
      "z": 5,
      "r": 139,
      "g": 90,
      "b": 43
    },
    {
      "x": 2,
      "y": 19,
      "z": 5,
      "r": 139,
      "g": 90,
      "b": 43
    },
    {
      "x": 1,
      "y": 19,
      "z": 4,
      "r": 139,
      "g": 90,
      "b": 43
    },
    {
      "x": 3,
      "y": 19,
      "z": 5,
      "r": 139,
      "g": 90,
      "b": 43
    },
    {
      "x": 2,
      "y": 19,
      "z": 4,
      "r": 139,
      "g": 90,
      "b": 43
    },
    {
      "x": 4,
      "y": 19,
      "z": 4,
      "r": 139,
      "g": 90,
      "b": 43
    },
    {
      "x": 3,
      "y": 19,
      "z": 3,
      "r": 139,
      "g": 90,
      "b": 43
    },
    {
      "x": 2,
      "y": 19,
      "z": 3,
      "r": 139,
      "g": 90,
      "b": 43
    },
    {
      "x": 4,
      "y": 19,
      "z": 3,
      "r": 139,
      "g": 90,
      "b": 43
    },
    {
      "x": 3,
      "y": 19,
      "z": 2,
      "r": 139,
      "g": 90,
      "b": 43
    },
    {
      "x": 2,
      "y": 19,
      "z": 2,
      "r": 139,
      "g": 90,
      "b": 43
    },
    {
      "x": 2,
      "y": 20,
      "z": 5,
      "r": 139,
      "g": 90,
      "b": 43
    },
    {
      "x": 2,
      "y": 20,
      "z": 4,
      "r": 139,
      "g": 90,
      "b": 43
    },
    {
      "x": 1,
      "y": 20,
      "z": 4,
      "r": 139,
      "g": 90,
      "b": 43
    },
    {
      "x": 3,
      "y": 20,
      "z": 4,
      "r": 139,
      "g": 90,
      "b": 43
    },
    {
      "x": 2,
      "y": 20,
      "z": 3,
      "r": 139,
      "g": 90,
      "b": 43
    },
    {
      "x": 4,
      "y": 20,
      "z": 4,
      "r": 139,
      "g": 90,
      "b": 43
    },
    {
      "x": 3,
      "y": 20,
      "z": 3,
      "r": 139,
      "g": 90,
      "b": 43
    },
    {
      "x": 2,
      "y": 20,
      "z": 2,
      "r": 139,
      "g": 90,
      "b": 43
    },
    {
      "x": 4,
      "y": 20,
      "z": 3,
      "r": 139,
      "g": 90,
      "b": 43
    },
    {
      "x": 4,
      "y": 20,
      "z": 2,
      "r": 139,
      "g": 90,
      "b": 43
    },
    {
      "x": 3,
      "y": 20,
      "z": 2,
      "r": 139,
      "g": 90,
      "b": 43
    },
    {
      "x": 5,
      "y": 20,
      "z": 2,
      "r": 139,
      "g": 90,
      "b": 43
    },
    {
      "x": 4,
      "y": 20,
      "z": 1,
      "r": 139,
      "g": 90,
      "b": 43
    },
    {
      "x": 3,
      "y": 21,
      "z": 4,
      "r": 139,
      "g": 90,
      "b": 43
    },
    {
      "x": 2,
      "y": 21,
      "z": 3,
      "r": 139,
      "g": 90,
      "b": 43
    },
    {
      "x": 2,
      "y": 21,
      "z": 2,
      "r": 139,
      "g": 90,
      "b": 43
    },
    {
      "x": 4,
      "y": 21,
      "z": 4,
      "r": 139,
      "g": 90,
      "b": 43
    },
    {
      "x": 3,
      "y": 21,
      "z": 3,
      "r": 139,
      "g": 90,
      "b": 43
    },
    {
      "x": 3,
      "y": 21,
      "z": 2,
      "r": 139,
      "g": 90,
      "b": 43
    },
    {
      "x": 5,
      "y": 21,
      "z": 3,
      "r": 139,
      "g": 90,
      "b": 43
    },
    {
      "x": 4,
      "y": 21,
      "z": 2,
      "r": 139,
      "g": 90,
      "b": 43
    },
    {
      "x": 4,
      "y": 21,
      "z": 1,
      "r": 139,
      "g": 90,
      "b": 43
    },
    {
      "x": 5,
      "y": 21,
      "z": 2,
      "r": 139,
      "g": 90,
      "b": 43
    },
    {
      "x": 6,
      "y": 21,
      "z": 2,
      "r": 139,
      "g": 90,
      "b": 43
    },
    {
      "x": 6,
      "y": 21,
      "z": 1,
      "r": 139,
      "g": 90,
      "b": 43
    },
    {
      "x": 5,
      "y": 21,
      "z": 0,
      "r": 139,
      "g": 90,
      "b": 43
    },
    {
      "x": 4,
      "y": 22,
      "z": 3,
      "r": 139,
      "g": 90,
      "b": 43
    },
    {
      "x": 3,
      "y": 22,
      "z": 2,
      "r": 139,
      "g": 90,
      "b": 43
    },
    {
      "x": 3,
      "y": 22,
      "z": 1,
      "r": 139,
      "g": 90,
      "b": 43
    },
    {
      "x": 5,
      "y": 22,
      "z": 3,
      "r": 139,
      "g": 90,
      "b": 43
    },
    {
      "x": 4,
      "y": 22,
      "z": 2,
      "r": 139,
      "g": 90,
      "b": 43
    },
    {
      "x": 4,
      "y": 22,
      "z": 1,
      "r": 139,
      "g": 90,
      "b": 43
    },
    {
      "x": 6,
      "y": 22,
      "z": 2,
      "r": 139,
      "g": 90,
      "b": 43
    },
    {
      "x": 5,
      "y": 22,
      "z": 2,
      "r": 139,
      "g": 90,
      "b": 43
    },
    {
      "x": 5,
      "y": 22,
      "z": 1,
      "r": 139,
      "g": 90,
      "b": 43
    },
    {
      "x": 7,
      "y": 22,
      "z": 2,
      "r": 139,
      "g": 90,
      "b": 43
    },
    {
      "x": 6,
      "y": 22,
      "z": 1,
      "r": 139,
      "g": 90,
      "b": 43
    },
    {
      "x": 6,
      "y": 22,
      "z": 0,
      "r": 139,
      "g": 90,
      "b": 43
    },
    {
      "x": 8,
      "y": 22,
      "z": 2,
      "r": 139,
      "g": 90,
      "b": 43
    },
    {
      "x": 7,
      "y": 22,
      "z": 1,
      "r": 139,
      "g": 90,
      "b": 43
    },
    {
      "x": 7,
      "y": 22,
      "z": 0,
      "r": 139,
      "g": 90,
      "b": 43
    },
    {
      "x": 5,
      "y": 23,
      "z": 3,
      "r": 139,
      "g": 90,
      "b": 43
    },
    {
      "x": 5,
      "y": 23,
      "z": 2,
      "r": 139,
      "g": 90,
      "b": 43
    },
    {
      "x": 4,
      "y": 23,
      "z": 1,
      "r": 139,
      "g": 90,
      "b": 43
    },
    {
      "x": 6,
      "y": 23,
      "z": 2,
      "r": 139,
      "g": 90,
      "b": 43
    },
    {
      "x": 6,
      "y": 23,
      "z": 1,
      "r": 139,
      "g": 90,
      "b": 43
    },
    {
      "x": 5,
      "y": 23,
      "z": 0,
      "r": 139,
      "g": 90,
      "b": 43
    },
    {
      "x": 7,
      "y": 23,
      "z": 2,
      "r": 139,
      "g": 90,
      "b": 43
    },
    {
      "x": 7,
      "y": 23,
      "z": 1,
      "r": 139,
      "g": 90,
      "b": 43
    },
    {
      "x": 6,
      "y": 23,
      "z": 0,
      "r": 139,
      "g": 90,
      "b": 43
    },
    {
      "x": 8,
      "y": 23,
      "z": 2,
      "r": 139,
      "g": 90,
      "b": 43
    },
    {
      "x": 8,
      "y": 23,
      "z": 1,
      "r": 139,
      "g": 90,
      "b": 43
    },
    {
      "x": 7,
      "y": 23,
      "z": 0,
      "r": 139,
      "g": 90,
      "b": 43
    },
    {
      "x": 9,
      "y": 23,
      "z": 2,
      "r": 139,
      "g": 90,
      "b": 43
    },
    {
      "x": 9,
      "y": 23,
      "z": 1,
      "r": 139,
      "g": 90,
      "b": 43
    },
    {
      "x": 8,
      "y": 23,
      "z": 0,
      "r": 139,
      "g": 90,
      "b": 43
    },
    {
      "x": 6,
      "y": 24,
      "z": 2,
      "r": 139,
      "g": 90,
      "b": 43
    },
    {
      "x": 6,
      "y": 24,
      "z": 1,
      "r": 139,
      "g": 90,
      "b": 43
    },
    {
      "x": 6,
      "y": 24,
      "z": 0,
      "r": 139,
      "g": 90,
      "b": 43
    },
    {
      "x": 7,
      "y": 24,
      "z": 2,
      "r": 139,
      "g": 90,
      "b": 43
    },
    {
      "x": 7,
      "y": 24,
      "z": 1,
      "r": 139,
      "g": 90,
      "b": 43
    },
    {
      "x": 7,
      "y": 24,
      "z": 0,
      "r": 139,
      "g": 90,
      "b": 43
    },
    {
      "x": 8,
      "y": 24,
      "z": 2,
      "r": 139,
      "g": 90,
      "b": 43
    },
    {
      "x": 8,
      "y": 24,
      "z": 1,
      "r": 139,
      "g": 90,
      "b": 43
    },
    {
      "x": 8,
      "y": 24,
      "z": 0,
      "r": 139,
      "g": 90,
      "b": 43
    },
    {
      "x": 9,
      "y": 24,
      "z": 2,
      "r": 139,
      "g": 90,
      "b": 43
    },
    {
      "x": 9,
      "y": 24,
      "z": 1,
      "r": 139,
      "g": 90,
      "b": 43
    },
    {
      "x": 9,
      "y": 24,
      "z": 0,
      "r": 139,
      "g": 90,
      "b": 43
    },
    {
      "x": 10,
      "y": 24,
      "z": 2,
      "r": 139,
      "g": 90,
      "b": 43
    },
    {
      "x": 10,
      "y": 24,
      "z": 1,
      "r": 139,
      "g": 90,
      "b": 43
    },
    {
      "x": 10,
      "y": 24,
      "z": 0,
      "r": 139,
      "g": 90,
      "b": 43
    },
    {
      "x": 7,
      "y": 25,
      "z": 2,
      "r": 139,
      "g": 90,
      "b": 43
    },
    {
      "x": 7,
      "y": 25,
      "z": 1,
      "r": 139,
      "g": 90,
      "b": 43
    },
    {
      "x": 8,
      "y": 25,
      "z": 0,
      "r": 139,
      "g": 90,
      "b": 43
    },
    {
      "x": 8,
      "y": 25,
      "z": 2,
      "r": 139,
      "g": 90,
      "b": 43
    },
    {
      "x": 8,
      "y": 25,
      "z": 1,
      "r": 139,
      "g": 90,
      "b": 43
    },
    {
      "x": 9,
      "y": 25,
      "z": 0,
      "r": 139,
      "g": 90,
      "b": 43
    },
    {
      "x": 9,
      "y": 25,
      "z": 2,
      "r": 139,
      "g": 90,
      "b": 43
    },
    {
      "x": 9,
      "y": 25,
      "z": 1,
      "r": 139,
      "g": 90,
      "b": 43
    },
    {
      "x": 10,
      "y": 25,
      "z": 0,
      "r": 139,
      "g": 90,
      "b": 43
    },
    {
      "x": 10,
      "y": 25,
      "z": 2,
      "r": 139,
      "g": 90,
      "b": 43
    },
    {
      "x": 10,
      "y": 25,
      "z": 1,
      "r": 139,
      "g": 90,
      "b": 43
    },
    {
      "x": 11,
      "y": 25,
      "z": 0,
      "r": 139,
      "g": 90,
      "b": 43
    },
    {
      "x": 11,
      "y": 25,
      "z": 3,
      "r": 139,
      "g": 90,
      "b": 43
    },
    {
      "x": 11,
      "y": 25,
      "z": 2,
      "r": 139,
      "g": 90,
      "b": 43
    },
    {
      "x": 12,
      "y": 25,
      "z": 1,
      "r": 139,
      "g": 90,
      "b": 43
    },
    {
      "x": 8,
      "y": 26,
      "z": 2,
      "r": 139,
      "g": 90,
      "b": 43
    },
    {
      "x": 9,
      "y": 26,
      "z": 1,
      "r": 139,
      "g": 90,
      "b": 43
    },
    {
      "x": 9,
      "y": 26,
      "z": 0,
      "r": 139,
      "g": 90,
      "b": 43
    },
    {
      "x": 9,
      "y": 26,
      "z": 2,
      "r": 139,
      "g": 90,
      "b": 43
    },
    {
      "x": 10,
      "y": 26,
      "z": 1,
      "r": 139,
      "g": 90,
      "b": 43
    },
    {
      "x": 10,
      "y": 26,
      "z": 0,
      "r": 139,
      "g": 90,
      "b": 43
    },
    {
      "x": 10,
      "y": 26,
      "z": 2,
      "r": 139,
      "g": 90,
      "b": 43
    },
    {
      "x": 11,
      "y": 26,
      "z": 2,
      "r": 139,
      "g": 90,
      "b": 43
    },
    {
      "x": 11,
      "y": 26,
      "z": 1,
      "r": 139,
      "g": 90,
      "b": 43
    },
    {
      "x": 11,
      "y": 26,
      "z": 3,
      "r": 139,
      "g": 90,
      "b": 43
    },
    {
      "x": 12,
      "y": 26,
      "z": 2,
      "r": 139,
      "g": 90,
      "b": 43
    },
    {
      "x": 12,
      "y": 26,
      "z": 1,
      "r": 139,
      "g": 90,
      "b": 43
    },
    {
      "x": 12,
      "y": 26,
      "z": 3,
      "r": 139,
      "g": 90,
      "b": 43
    },
    {
      "x": 13,
      "y": 26,
      "z": 2,
      "r": 139,
      "g": 90,
      "b": 43
    },
    {
      "x": 13,
      "y": 26,
      "z": 1,
      "r": 139,
      "g": 90,
      "b": 43
    },
    {
      "x": 10,
      "y": 27,
      "z": 2,
      "r": 139,
      "g": 90,
      "b": 43
    },
    {
      "x": 10,
      "y": 27,
      "z": 1,
      "r": 139,
      "g": 90,
      "b": 43
    },
    {
      "x": 11,
      "y": 27,
      "z": 0,
      "r": 139,
      "g": 90,
      "b": 43
    },
    {
      "x": 11,
      "y": 27,
      "z": 2,
      "r": 139,
      "g": 90,
      "b": 43
    },
    {
      "x": 12,
      "y": 27,
      "z": 1,
      "r": 139,
      "g": 90,
      "b": 43
    },
    {
      "x": 11,
      "y": 27,
      "z": 3,
      "r": 139,
      "g": 90,
      "b": 43
    },
    {
      "x": 12,
      "y": 27,
      "z": 2,
      "r": 139,
      "g": 90,
      "b": 43
    },
    {
      "x": 12,
      "y": 27,
      "z": 4,
      "r": 139,
      "g": 90,
      "b": 43
    },
    {
      "x": 13,
      "y": 27,
      "z": 3,
      "r": 139,
      "g": 90,
      "b": 43
    },
    {
      "x": 13,
      "y": 27,
      "z": 2,
      "r": 139,
      "g": 90,
      "b": 43
    },
    {
      "x": 13,
      "y": 27,
      "z": 4,
      "r": 139,
      "g": 90,
      "b": 43
    },
    {
      "x": 14,
      "y": 27,
      "z": 3,
      "r": 139,
      "g": 90,
      "b": 43
    },
    {
      "x": 14,
      "y": 27,
      "z": 2,
      "r": 139,
      "g": 90,
      "b": 43
    },
    {
      "x": 11,
      "y": 28,
      "z": 2,
      "r": 139,
      "g": 90,
      "b": 43
    },
    {
      "x": 12,
      "y": 28,
      "z": 2,
      "r": 139,
      "g": 90,
      "b": 43
    },
    {
      "x": 12,
      "y": 28,
      "z": 1,
      "r": 139,
      "g": 90,
      "b": 43
    },
    {
      "x": 12,
      "y": 28,
      "z": 3,
      "r": 139,
      "g": 90,
      "b": 43
    },
    {
      "x": 13,
      "y": 28,
      "z": 2,
      "r": 139,
      "g": 90,
      "b": 43
    },
    {
      "x": 12,
      "y": 28,
      "z": 4,
      "r": 139,
      "g": 90,
      "b": 43
    },
    {
      "x": 13,
      "y": 28,
      "z": 3,
      "r": 139,
      "g": 90,
      "b": 43
    },
    {
      "x": 14,
      "y": 28,
      "z": 2,
      "r": 139,
      "g": 90,
      "b": 43
    },
    {
      "x": 13,
      "y": 28,
      "z": 4,
      "r": 139,
      "g": 90,
      "b": 43
    },
    {
      "x": 14,
      "y": 28,
      "z": 4,
      "r": 139,
      "g": 90,
      "b": 43
    },
    {
      "x": 14,
      "y": 28,
      "z": 3,
      "r": 139,
      "g": 90,
      "b": 43
    },
    {
      "x": 14,
      "y": 28,
      "z": 5,
      "r": 139,
      "g": 90,
      "b": 43
    },
    {
      "x": 15,
      "y": 28,
      "z": 4,
      "r": 139,
      "g": 90,
      "b": 43
    },
    {
      "x": 12,
      "y": 29,
      "z": 3,
      "r": 139,
      "g": 90,
      "b": 43
    },
    {
      "x": 13,
      "y": 29,
      "z": 2,
      "r": 139,
      "g": 90,
      "b": 43
    },
    {
      "x": 14,
      "y": 29,
      "z": 2,
      "r": 139,
      "g": 90,
      "b": 43
    },
    {
      "x": 12,
      "y": 29,
      "z": 4,
      "r": 139,
      "g": 90,
      "b": 43
    },
    {
      "x": 13,
      "y": 29,
      "z": 3,
      "r": 139,
      "g": 90,
      "b": 43
    },
    {
      "x": 14,
      "y": 29,
      "z": 3,
      "r": 139,
      "g": 90,
      "b": 43
    },
    {
      "x": 13,
      "y": 29,
      "z": 5,
      "r": 139,
      "g": 90,
      "b": 43
    },
    {
      "x": 14,
      "y": 29,
      "z": 4,
      "r": 139,
      "g": 90,
      "b": 43
    },
    {
      "x": 15,
      "y": 29,
      "z": 4,
      "r": 139,
      "g": 90,
      "b": 43
    },
    {
      "x": 14,
      "y": 29,
      "z": 5,
      "r": 139,
      "g": 90,
      "b": 43
    },
    {
      "x": 14,
      "y": 29,
      "z": 6,
      "r": 139,
      "g": 90,
      "b": 43
    },
    {
      "x": 15,
      "y": 29,
      "z": 6,
      "r": 139,
      "g": 90,
      "b": 43
    },
    {
      "x": 16,
      "y": 29,
      "z": 5,
      "r": 139,
      "g": 90,
      "b": 43
    },
    {
      "x": 13,
      "y": 30,
      "z": 4,
      "r": 139,
      "g": 90,
      "b": 43
    },
    {
      "x": 14,
      "y": 30,
      "z": 3,
      "r": 139,
      "g": 90,
      "b": 43
    },
    {
      "x": 15,
      "y": 30,
      "z": 3,
      "r": 139,
      "g": 90,
      "b": 43
    },
    {
      "x": 13,
      "y": 30,
      "z": 5,
      "r": 139,
      "g": 90,
      "b": 43
    },
    {
      "x": 14,
      "y": 30,
      "z": 4,
      "r": 139,
      "g": 90,
      "b": 43
    },
    {
      "x": 15,
      "y": 30,
      "z": 4,
      "r": 139,
      "g": 90,
      "b": 43
    },
    {
      "x": 14,
      "y": 30,
      "z": 6,
      "r": 139,
      "g": 90,
      "b": 43
    },
    {
      "x": 14,
      "y": 30,
      "z": 5,
      "r": 139,
      "g": 90,
      "b": 43
    },
    {
      "x": 15,
      "y": 30,
      "z": 5,
      "r": 139,
      "g": 90,
      "b": 43
    },
    {
      "x": 14,
      "y": 30,
      "z": 7,
      "r": 139,
      "g": 90,
      "b": 43
    },
    {
      "x": 15,
      "y": 30,
      "z": 6,
      "r": 139,
      "g": 90,
      "b": 43
    },
    {
      "x": 16,
      "y": 30,
      "z": 6,
      "r": 139,
      "g": 90,
      "b": 43
    },
    {
      "x": 14,
      "y": 30,
      "z": 8,
      "r": 139,
      "g": 90,
      "b": 43
    },
    {
      "x": 15,
      "y": 30,
      "z": 7,
      "r": 139,
      "g": 90,
      "b": 43
    },
    {
      "x": 16,
      "y": 30,
      "z": 7,
      "r": 139,
      "g": 90,
      "b": 43
    },
    {
      "x": 13,
      "y": 31,
      "z": 5,
      "r": 139,
      "g": 90,
      "b": 43
    },
    {
      "x": 14,
      "y": 31,
      "z": 5,
      "r": 139,
      "g": 90,
      "b": 43
    },
    {
      "x": 15,
      "y": 31,
      "z": 4,
      "r": 139,
      "g": 90,
      "b": 43
    },
    {
      "x": 14,
      "y": 31,
      "z": 6,
      "r": 139,
      "g": 90,
      "b": 43
    },
    {
      "x": 15,
      "y": 31,
      "z": 6,
      "r": 139,
      "g": 90,
      "b": 43
    },
    {
      "x": 16,
      "y": 31,
      "z": 5,
      "r": 139,
      "g": 90,
      "b": 43
    },
    {
      "x": 14,
      "y": 31,
      "z": 7,
      "r": 139,
      "g": 90,
      "b": 43
    },
    {
      "x": 15,
      "y": 31,
      "z": 7,
      "r": 139,
      "g": 90,
      "b": 43
    },
    {
      "x": 16,
      "y": 31,
      "z": 6,
      "r": 139,
      "g": 90,
      "b": 43
    },
    {
      "x": 14,
      "y": 31,
      "z": 8,
      "r": 139,
      "g": 90,
      "b": 43
    },
    {
      "x": 15,
      "y": 31,
      "z": 8,
      "r": 139,
      "g": 90,
      "b": 43
    },
    {
      "x": 16,
      "y": 31,
      "z": 7,
      "r": 139,
      "g": 90,
      "b": 43
    },
    {
      "x": 14,
      "y": 31,
      "z": 9,
      "r": 139,
      "g": 90,
      "b": 43
    },
    {
      "x": 15,
      "y": 31,
      "z": 9,
      "r": 139,
      "g": 90,
      "b": 43
    },
    {
      "x": 16,
      "y": 31,
      "z": 8,
      "r": 139,
      "g": 90,
      "b": 43
    },
    {
      "x": 14,
      "y": 32,
      "z": 6,
      "r": 139,
      "g": 90,
      "b": 43
    },
    {
      "x": 15,
      "y": 32,
      "z": 6,
      "r": 139,
      "g": 90,
      "b": 43
    },
    {
      "x": 16,
      "y": 32,
      "z": 6,
      "r": 139,
      "g": 90,
      "b": 43
    },
    {
      "x": 14,
      "y": 32,
      "z": 7,
      "r": 139,
      "g": 90,
      "b": 43
    },
    {
      "x": 15,
      "y": 32,
      "z": 7,
      "r": 139,
      "g": 90,
      "b": 43
    },
    {
      "x": 16,
      "y": 32,
      "z": 7,
      "r": 139,
      "g": 90,
      "b": 43
    },
    {
      "x": 14,
      "y": 32,
      "z": 8,
      "r": 139,
      "g": 90,
      "b": 43
    },
    {
      "x": 15,
      "y": 32,
      "z": 8,
      "r": 139,
      "g": 90,
      "b": 43
    },
    {
      "x": 16,
      "y": 32,
      "z": 8,
      "r": 139,
      "g": 90,
      "b": 43
    },
    {
      "x": 14,
      "y": 32,
      "z": 9,
      "r": 139,
      "g": 90,
      "b": 43
    },
    {
      "x": 15,
      "y": 32,
      "z": 9,
      "r": 139,
      "g": 90,
      "b": 43
    },
    {
      "x": 16,
      "y": 32,
      "z": 9,
      "r": 139,
      "g": 90,
      "b": 43
    },
    {
      "x": 14,
      "y": 32,
      "z": 10,
      "r": 139,
      "g": 90,
      "b": 43
    },
    {
      "x": 15,
      "y": 32,
      "z": 10,
      "r": 139,
      "g": 90,
      "b": 43
    },
    {
      "x": 16,
      "y": 32,
      "z": 10,
      "r": 139,
      "g": 90,
      "b": 43
    },
    {
      "x": 14,
      "y": 33,
      "z": 7,
      "r": 139,
      "g": 90,
      "b": 43
    },
    {
      "x": 15,
      "y": 33,
      "z": 7,
      "r": 139,
      "g": 90,
      "b": 43
    },
    {
      "x": 16,
      "y": 33,
      "z": 8,
      "r": 139,
      "g": 90,
      "b": 43
    },
    {
      "x": 14,
      "y": 33,
      "z": 8,
      "r": 139,
      "g": 90,
      "b": 43
    },
    {
      "x": 15,
      "y": 33,
      "z": 8,
      "r": 139,
      "g": 90,
      "b": 43
    },
    {
      "x": 16,
      "y": 33,
      "z": 9,
      "r": 139,
      "g": 90,
      "b": 43
    },
    {
      "x": 14,
      "y": 33,
      "z": 9,
      "r": 139,
      "g": 90,
      "b": 43
    },
    {
      "x": 15,
      "y": 33,
      "z": 9,
      "r": 139,
      "g": 90,
      "b": 43
    },
    {
      "x": 16,
      "y": 33,
      "z": 10,
      "r": 139,
      "g": 90,
      "b": 43
    },
    {
      "x": 14,
      "y": 33,
      "z": 10,
      "r": 139,
      "g": 90,
      "b": 43
    },
    {
      "x": 15,
      "y": 33,
      "z": 10,
      "r": 139,
      "g": 90,
      "b": 43
    },
    {
      "x": 16,
      "y": 33,
      "z": 11,
      "r": 139,
      "g": 90,
      "b": 43
    },
    {
      "x": 13,
      "y": 33,
      "z": 11,
      "r": 139,
      "g": 90,
      "b": 43
    },
    {
      "x": 14,
      "y": 33,
      "z": 11,
      "r": 139,
      "g": 90,
      "b": 43
    },
    {
      "x": 15,
      "y": 33,
      "z": 12,
      "r": 139,
      "g": 90,
      "b": 43
    },
    {
      "x": 14,
      "y": 34,
      "z": 8,
      "r": 139,
      "g": 90,
      "b": 43
    },
    {
      "x": 15,
      "y": 34,
      "z": 9,
      "r": 139,
      "g": 90,
      "b": 43
    },
    {
      "x": 16,
      "y": 34,
      "z": 9,
      "r": 139,
      "g": 90,
      "b": 43
    },
    {
      "x": 14,
      "y": 34,
      "z": 9,
      "r": 139,
      "g": 90,
      "b": 43
    },
    {
      "x": 15,
      "y": 34,
      "z": 10,
      "r": 139,
      "g": 90,
      "b": 43
    },
    {
      "x": 16,
      "y": 34,
      "z": 10,
      "r": 139,
      "g": 90,
      "b": 43
    },
    {
      "x": 14,
      "y": 34,
      "z": 10,
      "r": 139,
      "g": 90,
      "b": 43
    },
    {
      "x": 14,
      "y": 34,
      "z": 11,
      "r": 139,
      "g": 90,
      "b": 43
    },
    {
      "x": 15,
      "y": 34,
      "z": 11,
      "r": 139,
      "g": 90,
      "b": 43
    },
    {
      "x": 13,
      "y": 34,
      "z": 11,
      "r": 139,
      "g": 90,
      "b": 43
    },
    {
      "x": 14,
      "y": 34,
      "z": 12,
      "r": 139,
      "g": 90,
      "b": 43
    },
    {
      "x": 15,
      "y": 34,
      "z": 12,
      "r": 139,
      "g": 90,
      "b": 43
    },
    {
      "x": 13,
      "y": 34,
      "z": 12,
      "r": 139,
      "g": 90,
      "b": 43
    },
    {
      "x": 14,
      "y": 34,
      "z": 13,
      "r": 139,
      "g": 90,
      "b": 43
    },
    {
      "x": 15,
      "y": 34,
      "z": 13,
      "r": 139,
      "g": 90,
      "b": 43
    },
    {
      "x": 14,
      "y": 35,
      "z": 10,
      "r": 139,
      "g": 90,
      "b": 43
    },
    {
      "x": 15,
      "y": 35,
      "z": 10,
      "r": 139,
      "g": 90,
      "b": 43
    },
    {
      "x": 16,
      "y": 35,
      "z": 11,
      "r": 139,
      "g": 90,
      "b": 43
    },
    {
      "x": 14,
      "y": 35,
      "z": 11,
      "r": 139,
      "g": 90,
      "b": 43
    },
    {
      "x": 15,
      "y": 35,
      "z": 12,
      "r": 139,
      "g": 90,
      "b": 43
    },
    {
      "x": 13,
      "y": 35,
      "z": 11,
      "r": 139,
      "g": 90,
      "b": 43
    },
    {
      "x": 14,
      "y": 35,
      "z": 12,
      "r": 139,
      "g": 90,
      "b": 43
    },
    {
      "x": 12,
      "y": 35,
      "z": 12,
      "r": 139,
      "g": 90,
      "b": 43
    },
    {
      "x": 13,
      "y": 35,
      "z": 13,
      "r": 139,
      "g": 90,
      "b": 43
    },
    {
      "x": 14,
      "y": 35,
      "z": 13,
      "r": 139,
      "g": 90,
      "b": 43
    },
    {
      "x": 12,
      "y": 35,
      "z": 13,
      "r": 139,
      "g": 90,
      "b": 43
    },
    {
      "x": 13,
      "y": 35,
      "z": 14,
      "r": 139,
      "g": 90,
      "b": 43
    },
    {
      "x": 14,
      "y": 35,
      "z": 14,
      "r": 139,
      "g": 90,
      "b": 43
    },
    {
      "x": 14,
      "y": 36,
      "z": 11,
      "r": 139,
      "g": 90,
      "b": 43
    },
    {
      "x": 14,
      "y": 36,
      "z": 12,
      "r": 139,
      "g": 90,
      "b": 43
    },
    {
      "x": 15,
      "y": 36,
      "z": 12,
      "r": 139,
      "g": 90,
      "b": 43
    },
    {
      "x": 13,
      "y": 36,
      "z": 12,
      "r": 139,
      "g": 90,
      "b": 43
    },
    {
      "x": 14,
      "y": 36,
      "z": 13,
      "r": 139,
      "g": 90,
      "b": 43
    },
    {
      "x": 12,
      "y": 36,
      "z": 12,
      "r": 139,
      "g": 90,
      "b": 43
    },
    {
      "x": 13,
      "y": 36,
      "z": 13,
      "r": 139,
      "g": 90,
      "b": 43
    },
    {
      "x": 14,
      "y": 36,
      "z": 14,
      "r": 139,
      "g": 90,
      "b": 43
    },
    {
      "x": 12,
      "y": 36,
      "z": 13,
      "r": 139,
      "g": 90,
      "b": 43
    },
    {
      "x": 12,
      "y": 36,
      "z": 14,
      "r": 139,
      "g": 90,
      "b": 43
    },
    {
      "x": 13,
      "y": 36,
      "z": 14,
      "r": 139,
      "g": 90,
      "b": 43
    },
    {
      "x": 11,
      "y": 36,
      "z": 14,
      "r": 139,
      "g": 90,
      "b": 43
    },
    {
      "x": 12,
      "y": 36,
      "z": 15,
      "r": 139,
      "g": 90,
      "b": 43
    },
    {
      "x": 13,
      "y": 37,
      "z": 12,
      "r": 139,
      "g": 90,
      "b": 43
    },
    {
      "x": 14,
      "y": 37,
      "z": 13,
      "r": 139,
      "g": 90,
      "b": 43
    },
    {
      "x": 14,
      "y": 37,
      "z": 14,
      "r": 139,
      "g": 90,
      "b": 43
    },
    {
      "x": 12,
      "y": 37,
      "z": 12,
      "r": 139,
      "g": 90,
      "b": 43
    },
    {
      "x": 13,
      "y": 37,
      "z": 13,
      "r": 139,
      "g": 90,
      "b": 43
    },
    {
      "x": 13,
      "y": 37,
      "z": 14,
      "r": 139,
      "g": 90,
      "b": 43
    },
    {
      "x": 11,
      "y": 37,
      "z": 13,
      "r": 139,
      "g": 90,
      "b": 43
    },
    {
      "x": 12,
      "y": 37,
      "z": 14,
      "r": 139,
      "g": 90,
      "b": 43
    },
    {
      "x": 12,
      "y": 37,
      "z": 15,
      "r": 139,
      "g": 90,
      "b": 43
    },
    {
      "x": 11,
      "y": 37,
      "z": 14,
      "r": 139,
      "g": 90,
      "b": 43
    },
    {
      "x": 10,
      "y": 37,
      "z": 14,
      "r": 139,
      "g": 90,
      "b": 43
    },
    {
      "x": 10,
      "y": 37,
      "z": 15,
      "r": 139,
      "g": 90,
      "b": 43
    },
    {
      "x": 11,
      "y": 37,
      "z": 16,
      "r": 139,
      "g": 90,
      "b": 43
    },
    {
      "x": 12,
      "y": 38,
      "z": 13,
      "r": 139,
      "g": 90,
      "b": 43
    },
    {
      "x": 13,
      "y": 38,
      "z": 14,
      "r": 139,
      "g": 90,
      "b": 43
    },
    {
      "x": 13,
      "y": 38,
      "z": 15,
      "r": 139,
      "g": 90,
      "b": 43
    },
    {
      "x": 11,
      "y": 38,
      "z": 13,
      "r": 139,
      "g": 90,
      "b": 43
    },
    {
      "x": 12,
      "y": 38,
      "z": 14,
      "r": 139,
      "g": 90,
      "b": 43
    },
    {
      "x": 12,
      "y": 38,
      "z": 15,
      "r": 139,
      "g": 90,
      "b": 43
    },
    {
      "x": 10,
      "y": 38,
      "z": 14,
      "r": 139,
      "g": 90,
      "b": 43
    },
    {
      "x": 11,
      "y": 38,
      "z": 14,
      "r": 139,
      "g": 90,
      "b": 43
    },
    {
      "x": 11,
      "y": 38,
      "z": 15,
      "r": 139,
      "g": 90,
      "b": 43
    },
    {
      "x": 9,
      "y": 38,
      "z": 14,
      "r": 139,
      "g": 90,
      "b": 43
    },
    {
      "x": 10,
      "y": 38,
      "z": 15,
      "r": 139,
      "g": 90,
      "b": 43
    },
    {
      "x": 10,
      "y": 38,
      "z": 16,
      "r": 139,
      "g": 90,
      "b": 43
    },
    {
      "x": 8,
      "y": 38,
      "z": 14,
      "r": 139,
      "g": 90,
      "b": 43
    },
    {
      "x": 9,
      "y": 38,
      "z": 15,
      "r": 139,
      "g": 90,
      "b": 43
    },
    {
      "x": 9,
      "y": 38,
      "z": 16,
      "r": 139,
      "g": 90,
      "b": 43
    },
    {
      "x": 11,
      "y": 39,
      "z": 13,
      "r": 139,
      "g": 90,
      "b": 43
    },
    {
      "x": 11,
      "y": 39,
      "z": 14,
      "r": 139,
      "g": 90,
      "b": 43
    },
    {
      "x": 12,
      "y": 39,
      "z": 15,
      "r": 139,
      "g": 90,
      "b": 43
    },
    {
      "x": 10,
      "y": 39,
      "z": 14,
      "r": 139,
      "g": 90,
      "b": 43
    },
    {
      "x": 10,
      "y": 39,
      "z": 15,
      "r": 139,
      "g": 90,
      "b": 43
    },
    {
      "x": 11,
      "y": 39,
      "z": 16,
      "r": 139,
      "g": 90,
      "b": 43
    },
    {
      "x": 9,
      "y": 39,
      "z": 14,
      "r": 139,
      "g": 90,
      "b": 43
    },
    {
      "x": 9,
      "y": 39,
      "z": 15,
      "r": 139,
      "g": 90,
      "b": 43
    },
    {
      "x": 10,
      "y": 39,
      "z": 16,
      "r": 139,
      "g": 90,
      "b": 43
    },
    {
      "x": 8,
      "y": 39,
      "z": 14,
      "r": 139,
      "g": 90,
      "b": 43
    },
    {
      "x": 8,
      "y": 39,
      "z": 15,
      "r": 139,
      "g": 90,
      "b": 43
    },
    {
      "x": 9,
      "y": 39,
      "z": 16,
      "r": 139,
      "g": 90,
      "b": 43
    },
    {
      "x": 7,
      "y": 39,
      "z": 14,
      "r": 139,
      "g": 90,
      "b": 43
    },
    {
      "x": 7,
      "y": 39,
      "z": 15,
      "r": 139,
      "g": 90,
      "b": 43
    },
    {
      "x": 8,
      "y": 39,
      "z": 16,
      "r": 139,
      "g": 90,
      "b": 43
    },
    {
      "x": 10,
      "y": 40,
      "z": 14,
      "r": 139,
      "g": 90,
      "b": 43
    },
    {
      "x": 10,
      "y": 40,
      "z": 15,
      "r": 139,
      "g": 90,
      "b": 43
    },
    {
      "x": 10,
      "y": 40,
      "z": 16,
      "r": 139,
      "g": 90,
      "b": 43
    },
    {
      "x": 9,
      "y": 40,
      "z": 14,
      "r": 139,
      "g": 90,
      "b": 43
    },
    {
      "x": 9,
      "y": 40,
      "z": 15,
      "r": 139,
      "g": 90,
      "b": 43
    },
    {
      "x": 9,
      "y": 40,
      "z": 16,
      "r": 139,
      "g": 90,
      "b": 43
    },
    {
      "x": 8,
      "y": 40,
      "z": 14,
      "r": 139,
      "g": 90,
      "b": 43
    },
    {
      "x": 8,
      "y": 40,
      "z": 15,
      "r": 139,
      "g": 90,
      "b": 43
    },
    {
      "x": 8,
      "y": 40,
      "z": 16,
      "r": 139,
      "g": 90,
      "b": 43
    },
    {
      "x": 7,
      "y": 40,
      "z": 14,
      "r": 139,
      "g": 90,
      "b": 43
    },
    {
      "x": 7,
      "y": 40,
      "z": 15,
      "r": 139,
      "g": 90,
      "b": 43
    },
    {
      "x": 7,
      "y": 40,
      "z": 16,
      "r": 139,
      "g": 90,
      "b": 43
    },
    {
      "x": 6,
      "y": 40,
      "z": 14,
      "r": 139,
      "g": 90,
      "b": 43
    },
    {
      "x": 6,
      "y": 40,
      "z": 15,
      "r": 139,
      "g": 90,
      "b": 43
    },
    {
      "x": 6,
      "y": 40,
      "z": 16,
      "r": 139,
      "g": 90,
      "b": 43
    },
    {
      "x": 9,
      "y": 41,
      "z": 14,
      "r": 139,
      "g": 90,
      "b": 43
    },
    {
      "x": 9,
      "y": 41,
      "z": 15,
      "r": 139,
      "g": 90,
      "b": 43
    },
    {
      "x": 8,
      "y": 41,
      "z": 16,
      "r": 139,
      "g": 90,
      "b": 43
    },
    {
      "x": 8,
      "y": 41,
      "z": 14,
      "r": 139,
      "g": 90,
      "b": 43
    },
    {
      "x": 8,
      "y": 41,
      "z": 15,
      "r": 139,
      "g": 90,
      "b": 43
    },
    {
      "x": 7,
      "y": 41,
      "z": 16,
      "r": 139,
      "g": 90,
      "b": 43
    },
    {
      "x": 7,
      "y": 41,
      "z": 14,
      "r": 139,
      "g": 90,
      "b": 43
    },
    {
      "x": 7,
      "y": 41,
      "z": 15,
      "r": 139,
      "g": 90,
      "b": 43
    },
    {
      "x": 6,
      "y": 41,
      "z": 16,
      "r": 139,
      "g": 90,
      "b": 43
    },
    {
      "x": 6,
      "y": 41,
      "z": 14,
      "r": 139,
      "g": 90,
      "b": 43
    },
    {
      "x": 6,
      "y": 41,
      "z": 15,
      "r": 139,
      "g": 90,
      "b": 43
    },
    {
      "x": 5,
      "y": 41,
      "z": 16,
      "r": 139,
      "g": 90,
      "b": 43
    },
    {
      "x": 5,
      "y": 41,
      "z": 13,
      "r": 139,
      "g": 90,
      "b": 43
    },
    {
      "x": 5,
      "y": 41,
      "z": 14,
      "r": 139,
      "g": 90,
      "b": 43
    },
    {
      "x": 4,
      "y": 41,
      "z": 15,
      "r": 139,
      "g": 90,
      "b": 43
    },
    {
      "x": 8,
      "y": 42,
      "z": 14,
      "r": 139,
      "g": 90,
      "b": 43
    },
    {
      "x": 7,
      "y": 42,
      "z": 15,
      "r": 139,
      "g": 90,
      "b": 43
    },
    {
      "x": 7,
      "y": 42,
      "z": 16,
      "r": 139,
      "g": 90,
      "b": 43
    },
    {
      "x": 7,
      "y": 42,
      "z": 14,
      "r": 139,
      "g": 90,
      "b": 43
    },
    {
      "x": 6,
      "y": 42,
      "z": 15,
      "r": 139,
      "g": 90,
      "b": 43
    },
    {
      "x": 6,
      "y": 42,
      "z": 16,
      "r": 139,
      "g": 90,
      "b": 43
    },
    {
      "x": 6,
      "y": 42,
      "z": 14,
      "r": 139,
      "g": 90,
      "b": 43
    },
    {
      "x": 5,
      "y": 42,
      "z": 14,
      "r": 139,
      "g": 90,
      "b": 43
    },
    {
      "x": 5,
      "y": 42,
      "z": 15,
      "r": 139,
      "g": 90,
      "b": 43
    },
    {
      "x": 5,
      "y": 42,
      "z": 13,
      "r": 139,
      "g": 90,
      "b": 43
    },
    {
      "x": 4,
      "y": 42,
      "z": 14,
      "r": 139,
      "g": 90,
      "b": 43
    },
    {
      "x": 4,
      "y": 42,
      "z": 15,
      "r": 139,
      "g": 90,
      "b": 43
    },
    {
      "x": 4,
      "y": 42,
      "z": 13,
      "r": 139,
      "g": 90,
      "b": 43
    },
    {
      "x": 3,
      "y": 42,
      "z": 14,
      "r": 139,
      "g": 90,
      "b": 43
    },
    {
      "x": 3,
      "y": 42,
      "z": 15,
      "r": 139,
      "g": 90,
      "b": 43
    },
    {
      "x": 6,
      "y": 43,
      "z": 14,
      "r": 139,
      "g": 90,
      "b": 43
    },
    {
      "x": 6,
      "y": 43,
      "z": 15,
      "r": 139,
      "g": 90,
      "b": 43
    },
    {
      "x": 5,
      "y": 43,
      "z": 16,
      "r": 139,
      "g": 90,
      "b": 43
    },
    {
      "x": 5,
      "y": 43,
      "z": 14,
      "r": 139,
      "g": 90,
      "b": 43
    },
    {
      "x": 4,
      "y": 43,
      "z": 15,
      "r": 139,
      "g": 90,
      "b": 43
    },
    {
      "x": 5,
      "y": 43,
      "z": 13,
      "r": 139,
      "g": 90,
      "b": 43
    },
    {
      "x": 4,
      "y": 43,
      "z": 14,
      "r": 139,
      "g": 90,
      "b": 43
    },
    {
      "x": 4,
      "y": 43,
      "z": 12,
      "r": 139,
      "g": 90,
      "b": 43
    },
    {
      "x": 3,
      "y": 43,
      "z": 13,
      "r": 139,
      "g": 90,
      "b": 43
    },
    {
      "x": 3,
      "y": 43,
      "z": 14,
      "r": 139,
      "g": 90,
      "b": 43
    },
    {
      "x": 3,
      "y": 43,
      "z": 12,
      "r": 139,
      "g": 90,
      "b": 43
    },
    {
      "x": 2,
      "y": 43,
      "z": 13,
      "r": 139,
      "g": 90,
      "b": 43
    },
    {
      "x": 2,
      "y": 43,
      "z": 14,
      "r": 139,
      "g": 90,
      "b": 43
    },
    {
      "x": 5,
      "y": 44,
      "z": 14,
      "r": 139,
      "g": 90,
      "b": 43
    },
    {
      "x": 4,
      "y": 44,
      "z": 14,
      "r": 139,
      "g": 90,
      "b": 43
    },
    {
      "x": 4,
      "y": 44,
      "z": 15,
      "r": 139,
      "g": 90,
      "b": 43
    },
    {
      "x": 4,
      "y": 44,
      "z": 13,
      "r": 139,
      "g": 90,
      "b": 43
    },
    {
      "x": 3,
      "y": 44,
      "z": 14,
      "r": 139,
      "g": 90,
      "b": 43
    },
    {
      "x": 4,
      "y": 44,
      "z": 12,
      "r": 139,
      "g": 90,
      "b": 43
    },
    {
      "x": 3,
      "y": 44,
      "z": 13,
      "r": 139,
      "g": 90,
      "b": 43
    },
    {
      "x": 2,
      "y": 44,
      "z": 14,
      "r": 139,
      "g": 90,
      "b": 43
    },
    {
      "x": 3,
      "y": 44,
      "z": 12,
      "r": 139,
      "g": 90,
      "b": 43
    },
    {
      "x": 2,
      "y": 44,
      "z": 12,
      "r": 139,
      "g": 90,
      "b": 43
    },
    {
      "x": 2,
      "y": 44,
      "z": 13,
      "r": 139,
      "g": 90,
      "b": 43
    },
    {
      "x": 2,
      "y": 44,
      "z": 11,
      "r": 139,
      "g": 90,
      "b": 43
    },
    {
      "x": 1,
      "y": 44,
      "z": 12,
      "r": 139,
      "g": 90,
      "b": 43
    },
    {
      "x": 4,
      "y": 45,
      "z": 13,
      "r": 139,
      "g": 90,
      "b": 43
    },
    {
      "x": 3,
      "y": 45,
      "z": 14,
      "r": 139,
      "g": 90,
      "b": 43
    },
    {
      "x": 2,
      "y": 45,
      "z": 14,
      "r": 139,
      "g": 90,
      "b": 43
    },
    {
      "x": 4,
      "y": 45,
      "z": 12,
      "r": 139,
      "g": 90,
      "b": 43
    },
    {
      "x": 3,
      "y": 45,
      "z": 13,
      "r": 139,
      "g": 90,
      "b": 43
    },
    {
      "x": 2,
      "y": 45,
      "z": 13,
      "r": 139,
      "g": 90,
      "b": 43
    },
    {
      "x": 3,
      "y": 45,
      "z": 11,
      "r": 139,
      "g": 90,
      "b": 43
    },
    {
      "x": 2,
      "y": 45,
      "z": 12,
      "r": 139,
      "g": 90,
      "b": 43
    },
    {
      "x": 1,
      "y": 45,
      "z": 12,
      "r": 139,
      "g": 90,
      "b": 43
    },
    {
      "x": 2,
      "y": 45,
      "z": 11,
      "r": 139,
      "g": 90,
      "b": 43
    },
    {
      "x": 2,
      "y": 45,
      "z": 10,
      "r": 139,
      "g": 90,
      "b": 43
    },
    {
      "x": 1,
      "y": 45,
      "z": 10,
      "r": 139,
      "g": 90,
      "b": 43
    },
    {
      "x": 0,
      "y": 45,
      "z": 11,
      "r": 139,
      "g": 90,
      "b": 43
    },
    {
      "x": 3,
      "y": 46,
      "z": 12,
      "r": 139,
      "g": 90,
      "b": 43
    },
    {
      "x": 2,
      "y": 46,
      "z": 13,
      "r": 139,
      "g": 90,
      "b": 43
    },
    {
      "x": 1,
      "y": 46,
      "z": 13,
      "r": 139,
      "g": 90,
      "b": 43
    },
    {
      "x": 3,
      "y": 46,
      "z": 11,
      "r": 139,
      "g": 90,
      "b": 43
    },
    {
      "x": 2,
      "y": 46,
      "z": 12,
      "r": 139,
      "g": 90,
      "b": 43
    },
    {
      "x": 1,
      "y": 46,
      "z": 12,
      "r": 139,
      "g": 90,
      "b": 43
    },
    {
      "x": 2,
      "y": 46,
      "z": 10,
      "r": 139,
      "g": 90,
      "b": 43
    },
    {
      "x": 2,
      "y": 46,
      "z": 11,
      "r": 139,
      "g": 90,
      "b": 43
    },
    {
      "x": 1,
      "y": 46,
      "z": 11,
      "r": 139,
      "g": 90,
      "b": 43
    },
    {
      "x": 2,
      "y": 46,
      "z": 9,
      "r": 139,
      "g": 90,
      "b": 43
    },
    {
      "x": 1,
      "y": 46,
      "z": 10,
      "r": 139,
      "g": 90,
      "b": 43
    },
    {
      "x": 0,
      "y": 46,
      "z": 10,
      "r": 139,
      "g": 90,
      "b": 43
    },
    {
      "x": 2,
      "y": 46,
      "z": 8,
      "r": 139,
      "g": 90,
      "b": 43
    },
    {
      "x": 1,
      "y": 46,
      "z": 9,
      "r": 139,
      "g": 90,
      "b": 43
    },
    {
      "x": 0,
      "y": 46,
      "z": 9,
      "r": 139,
      "g": 90,
      "b": 43
    },
    {
      "x": 3,
      "y": 47,
      "z": 11,
      "r": 139,
      "g": 90,
      "b": 43
    },
    {
      "x": 2,
      "y": 47,
      "z": 11,
      "r": 139,
      "g": 90,
      "b": 43
    },
    {
      "x": 1,
      "y": 47,
      "z": 12,
      "r": 139,
      "g": 90,
      "b": 43
    },
    {
      "x": 2,
      "y": 47,
      "z": 10,
      "r": 139,
      "g": 90,
      "b": 43
    },
    {
      "x": 1,
      "y": 47,
      "z": 10,
      "r": 139,
      "g": 90,
      "b": 43
    },
    {
      "x": 0,
      "y": 47,
      "z": 11,
      "r": 139,
      "g": 90,
      "b": 43
    },
    {
      "x": 2,
      "y": 47,
      "z": 9,
      "r": 139,
      "g": 90,
      "b": 43
    },
    {
      "x": 1,
      "y": 47,
      "z": 9,
      "r": 139,
      "g": 90,
      "b": 43
    },
    {
      "x": 0,
      "y": 47,
      "z": 10,
      "r": 139,
      "g": 90,
      "b": 43
    },
    {
      "x": 2,
      "y": 47,
      "z": 8,
      "r": 139,
      "g": 90,
      "b": 43
    },
    {
      "x": 1,
      "y": 47,
      "z": 8,
      "r": 139,
      "g": 90,
      "b": 43
    },
    {
      "x": 0,
      "y": 47,
      "z": 9,
      "r": 139,
      "g": 90,
      "b": 43
    },
    {
      "x": 2,
      "y": 47,
      "z": 7,
      "r": 139,
      "g": 90,
      "b": 43
    },
    {
      "x": 1,
      "y": 47,
      "z": 7,
      "r": 139,
      "g": 90,
      "b": 43
    },
    {
      "x": 0,
      "y": 47,
      "z": 8,
      "r": 139,
      "g": 90,
      "b": 43
    },
    {
      "x": 6,
      "y": 47,
      "z": 10,
      "r": 139,
      "g": 90,
      "b": 43
    },
    {
      "x": 6,
      "y": 47,
      "z": 9,
      "r": 139,
      "g": 90,
      "b": 43
    },
    {
      "x": 6,
      "y": 47,
      "z": 8,
      "r": 139,
      "g": 90,
      "b": 43
    },
    {
      "x": 6,
      "y": 47,
      "z": 7,
      "r": 139,
      "g": 90,
      "b": 43
    },
    {
      "x": 6,
      "y": 47,
      "z": 6,
      "r": 139,
      "g": 90,
      "b": 43
    },
    {
      "x": 5,
      "y": 47,
      "z": 11,
      "r": 139,
      "g": 90,
      "b": 43
    },
    {
      "x": 5,
      "y": 47,
      "z": 10,
      "r": 139,
      "g": 90,
      "b": 43
    },
    {
      "x": 5,
      "y": 47,
      "z": 9,
      "r": 139,
      "g": 90,
      "b": 43
    },
    {
      "x": 5,
      "y": 47,
      "z": 8,
      "r": 139,
      "g": 90,
      "b": 43
    },
    {
      "x": 5,
      "y": 47,
      "z": 7,
      "r": 139,
      "g": 90,
      "b": 43
    },
    {
      "x": 4,
      "y": 47,
      "z": 11,
      "r": 139,
      "g": 90,
      "b": 43
    },
    {
      "x": 4,
      "y": 47,
      "z": 10,
      "r": 139,
      "g": 90,
      "b": 43
    },
    {
      "x": 4,
      "y": 47,
      "z": 9,
      "r": 139,
      "g": 90,
      "b": 43
    },
    {
      "x": 4,
      "y": 47,
      "z": 8,
      "r": 139,
      "g": 90,
      "b": 43
    },
    {
      "x": 4,
      "y": 47,
      "z": 7,
      "r": 139,
      "g": 90,
      "b": 43
    },
    {
      "x": 3,
      "y": 47,
      "z": 10,
      "r": 139,
      "g": 90,
      "b": 43
    },
    {
      "x": 3,
      "y": 47,
      "z": 9,
      "r": 139,
      "g": 90,
      "b": 43
    },
    {
      "x": 3,
      "y": 47,
      "z": 8,
      "r": 139,
      "g": 90,
      "b": 43
    },
    {
      "x": 3,
      "y": 47,
      "z": 7,
      "r": 139,
      "g": 90,
      "b": 43
    }
  ]
}