{
  "resolution": 48,
  "gridSize": {
    "x": 11,
    "y": 48,
    "z": 13
  },
  "voxelCount": 1895,
  "voxels": [
    {
      "x": 5,
      "y": 4,
      "z": 0,
      "r": 200,
      "g": 50,
      "b": 50
    },
    {
      "x": 5,
      "y": 4,
      "z": 1,
      "r": 200,
      "g": 50,
      "b": 50
    },
    {
      "x": 5,
      "y": 5,
      "z": 1,
      "r": 200,
      "g": 50,
      "b": 50
    },
    {
      "x": 5,
      "y": 6,
      "z": 1,
      "r": 255,
      "g": 255,
      "b": 255
    },
    {
      "x": 5,
      "y": 7,
      "z": 1,
      "r": 255,
      "g": 255,
      "b": 255
    },
    {
      "x": 5,
      "y": 8,
      "z": 1,
      "r": 255,
      "g": 255,
      "b": 255
    },
    {
      "x": 5,
      "y": 9,
      "z": 1,
      "r": 255,
      "g": 255,
      "b": 255
    },
    {
      "x": 6,
      "y": 4,
      "z": 1,
      "r": 200,
      "g": 50,
      "b": 50
    },
    {
      "x": 6,
      "y": 4,
      "z": 2,
      "r": 200,
      "g": 50,
      "b": 50
    },
    {
      "x": 6,
      "y": 5,
      "z": 1,
      "r": 200,
      "g": 50,
      "b": 50
    },
    {
      "x": 6,
      "y": 5,
      "z": 2,
      "r": 200,
      "g": 50,
      "b": 50
    },
    {
      "x": 6,
      "y": 6,
      "z": 1,
      "r": 255,
      "g": 255,
      "b": 255
    },
    {
      "x": 6,
      "y": 6,
      "z": 2,
      "r": 255,
      "g": 255,
      "b": 255
    },
    {
      "x": 6,
      "y": 7,
      "z": 1,
      "r": 255,
      "g": 255,
      "b": 255
    },
    {
      "x": 6,
      "y": 7,
      "z": 2,
      "r": 255,
      "g": 255,
      "b": 255
    },
    {
      "x": 6,
      "y": 8,
      "z": 1,
      "r": 255,
      "g": 255,
      "b": 255
    },
    {
      "x": 7,
      "y": 4,
      "z": 1,
      "r": 200,
      "g": 50,
      "b": 50
    },
    {
      "x": 7,
      "y": 4,
      "z": 2,
      "r": 200,
      "g": 50,
      "b": 50
    },
    {
      "x": 7,
      "y": 5,
      "z": 2,
      "r": 200,
      "g": 50,
      "b": 50
    },
    {
      "x": 7,
      "y": 6,
      "z": 2,
      "r": 255,
      "g": 255,
      "b": 255
    },
    {
      "x": 7,
      "y": 7,
      "z": 2,
      "r": 255,
      "g": 255,
      "b": 255
    },
    {
      "x": 8,
      "y": 4,
      "z": 2,
      "r": 200,
      "g": 50,
      "b": 50
    },
    {
      "x": 8,
      "y": 4,
      "z": 3,
      "r": 200,
      "g": 50,
      "b": 50
    },
    {
      "x": 8,
      "y": 5,
      "z": 2,
      "r": 200,
      "g": 50,
      "b": 50
    },
    {
      "x": 8,
      "y": 5,
      "z": 3,
      "r": 200,
      "g": 50,
      "b": 50
    },
    {
      "x": 8,
      "y": 6,
      "z": 2,
      "r": 255,
      "g": 255,
      "b": 255
    },
    {
      "x": 9,
      "y": 4,
      "z": 3,
      "r": 200,
      "g": 50,
      "b": 50
    },
    {
      "x": 9,
      "y": 5,
      "z": 3,
      "r": 200,
      "g": 50,
      "b": 50
    },
    {
      "x": 6,
      "y": 8,
      "z": 2,
      "r": 255,
      "g": 255,
      "b": 255
    },
    {
      "x": 6,
      "y": 9,
      "z": 1,
      "r": 255,
      "g": 255,
      "b": 255
    },
    {
      "x": 6,
      "y": 9,
      "z": 2,
      "r": 255,
      "g": 255,
      "b": 255
    },
    {
      "x": 7,
      "y": 8,
      "z": 2,
      "r": 255,
      "g": 255,
      "b": 255
    },
    {
      "x": 7,
      "y": 9,
      "z": 2,
      "r": 255,
      "g": 255,
      "b": 255
    },
    {
      "x": 7,
      "y": 9,
      "z": 3,
      "r": 255,
      "g": 255,
      "b": 255
    },
    {
      "x": 8,
      "y": 6,
      "z": 3,
      "r": 255,
      "g": 255,
      "b": 255
    },
    {
      "x": 8,
      "y": 7,
      "z": 2,
      "r": 255,
      "g": 255,
      "b": 255
    },
    {
      "x": 8,
      "y": 7,
      "z": 3,
      "r": 255,
      "g": 255,
      "b": 255
    },
    {
      "x": 8,
      "y": 8,
      "z": 2,
      "r": 255,
      "g": 255,
      "b": 255
    },
    {
      "x": 8,
      "y": 8,
      "z": 3,
      "r": 255,
      "g": 255,
      "b": 255
    },
    {
      "x": 8,
      "y": 9,
      "z": 2,
      "r": 255,
      "g": 255,
      "b": 255
    },
    {
      "x": 8,
      "y": 9,
      "z": 3,
      "r": 255,
      "g": 255,
      "b": 255
    },
    {
      "x": 9,
      "y": 6,
      "z": 3,
      "r": 255,
      "g": 255,
      "b": 255
    },
    {
      "x": 9,
      "y": 7,
      "z": 3,
      "r": 255,
      "g": 255,
      "b": 255
    },
    {
      "x": 9,
      "y": 8,
      "z": 3,
      "r": 255,
      "g": 255,
      "b": 255
    },
    {
      "x": 9,
      "y": 9,
      "z": 3,
      "r": 255,
      "g": 255,
      "b": 255
    },
    {
      "x": 0,
      "y": 4,
      "z": 3,
      "r": 200,
      "g": 50,
      "b": 50
    },
    {
      "x": 0,
      "y": 5,
      "z": 3,
      "r": 200,
      "g": 50,
      "b": 50
    },
    {
      "x": 1,
      "y": 4,
      "z": 2,
      "r": 200,
      "g": 50,
      "b": 50
    },
    {
      "x": 1,
      "y": 4,
      "z": 3,
      "r": 200,
      "g": 50,
      "b": 50
    },
    {
      "x": 1,
      "y": 5,
      "z": 2,
      "r": 200,
      "g": 50,
      "b": 50
    },
    {
      "x": 1,
      "y": 5,
      "z": 3,
      "r": 200,
      "g": 50,
      "b": 50
    },
    {
      "x": 1,
      "y": 6,
      "z": 3,
      "r": 255,
      "g": 255,
      "b": 255
    },
    {
      "x": 1,
      "y": 7,
      "z": 3,
      "r": 255,
      "g": 255,
      "b": 255
    },
    {
      "x": 1,
      "y": 8,
      "z": 3,
      "r": 255,
      "g": 255,
      "b": 255
    },
    {
      "x": 1,
      "y": 9,
      "z": 3,
      "r": 255,
      "g": 255,
      "b": 255
    },
    {
      "x": 2,
      "y": 4,
      "z": 2,
      "r": 200,
      "g": 50,
      "b": 50
    },
    {
      "x": 2,
      "y": 5,
      "z": 2,
      "r": 200,
      "g": 50,
      "b": 50
    },
    {
      "x": 2,
      "y": 5,
      "z": 3,
      "r": 200,
      "g": 50,
      "b": 50
    },
    {
      "x": 2,
      "y": 6,
      "z": 2,
      "r": 255,
      "g": 255,
      "b": 255
    },
    {
      "x": 2,
      "y": 6,
      "z": 3,
      "r": 255,
      "g": 255,
      "b": 255
    },
    {
      "x": 2,
      "y": 7,
      "z": 2,
      "r": 255,
      "g": 255,
      "b": 255
    },
    {
      "x": 2,
      "y": 7,
      "z": 3,
      "r": 255,
      "g": 255,
      "b": 255
    },
    {
      "x": 2,
      "y": 8,
      "z": 3,
      "r": 255,
      "g": 255,
      "b": 255
    },
    {
      "x": 3,
      "y": 4,
      "z": 1,
      "r": 200,
      "g": 50,
      "b": 50
    },
    {
      "x": 3,
      "y": 4,
      "z": 2,
      "r": 200,
      "g": 50,
      "b": 50
    },
    {
      "x": 3,
      "y": 5,
      "z": 1,
      "r": 200,
      "g": 50,
      "b": 50
    },
    {
      "x": 3,
      "y": 5,
      "z": 2,
      "r": 200,
      "g": 50,
      "b": 50
    },
    {
      "x": 3,
      "y": 6,
      "z": 1,
      "r": 255,
      "g": 255,
      "b": 255
    },
    {
      "x": 3,
      "y": 6,
      "z": 2,
      "r": 255,
      "g": 255,
      "b": 255
    },
    {
      "x": 3,
      "y": 7,
      "z": 2,
      "r": 255,
      "g": 255,
      "b": 255
    },
    {
      "x": 4,
      "y": 4,
      "z": 1,
      "r": 200,
      "g": 50,
      "b": 50
    },
    {
      "x": 4,
      "y": 5,
      "z": 1,
      "r": 200,
      "g": 50,
      "b": 50
    },
    {
      "x": 2,
      "y": 8,
      "z": 2,
      "r": 255,
      "g": 255,
      "b": 255
    },
    {
      "x": 2,
      "y": 9,
      "z": 2,
      "r": 255,
      "g": 255,
      "b": 255
    },
    {
      "x": 2,
      "y": 9,
      "z": 3,
      "r": 255,
      "g": 255,
      "b": 255
    },
    {
      "x": 3,
      "y": 8,
      "z": 2,
      "r": 255,
      "g": 255,
      "b": 255
    },
    {
      "x": 3,
      "y": 9,
      "z": 2,
      "r": 255,
      "g": 255,
      "b": 255
    },
    {
      "x": 4,
      "y": 6,
      "z": 1,
      "r": 255,
      "g": 255,
      "b": 255
    },
    {
      "x": 4,
      "y": 6,
      "z": 2,
      "r": 255,
      "g": 255,
      "b": 255
    },
    {
      "x": 4,
      "y": 7,
      "z": 1,
      "r": 255,
      "g": 255,
      "b": 255
    },
    {
      "x": 4,
      "y": 7,
      "z": 2,
      "r": 255,
      "g": 255,
      "b": 255
    },
    {
      "x": 4,
      "y": 8,
      "z": 1,
      "r": 255,
      "g": 255,
      "b": 255
    },
    {
      "x": 4,
      "y": 8,
      "z": 2,
      "r": 255,
      "g": 255,
      "b": 255
    },
    {
      "x": 4,
      "y": 9,
      "z": 1,
      "r": 255,
      "g": 255,
      "b": 255
    },
    {
      "x": 4,
      "y": 9,
      "z": 2,
      "r": 255,
      "g": 255,
      "b": 255
    },
    {
      "x": 0,
      "y": 4,
      "z": 8,
      "r": 200,
      "g": 50,
      "b": 50
    },
    {
      "x": 1,
      "y": 4,
      "z": 8,
      "r": 200,
      "g": 50,
      "b": 50
    },
    {
      "x": 1,
      "y": 4,
      "z": 9,
      "r": 200,
      "g": 50,
      "b": 50
    },
    {
      "x": 1,
      "y": 5,
      "z": 9,
      "r": 200,
      "g": 50,
      "b": 50
    },
    {
      "x": 2,
      "y": 4,
      "z": 9,
      "r": 200,
      "g": 50,
      "b": 50
    },
    {
      "x": 2,
      "y": 5,
      "z": 9,
      "r": 200,
      "g": 50,
      "b": 50
    },
    {
      "x": 2,
      "y": 6,
      "z": 9,
      "r": 255,
      "g": 255,
      "b": 255
    },
    {
      "x": 3,
      "y": 4,
      "z": 9,
      "r": 200,
      "g": 50,
      "b": 50
    },
    {
      "x": 3,
      "y": 4,
      "z": 10,
      "r": 200,
      "g": 50,
      "b": 50
    },
    {
      "x": 3,
      "y": 5,
      "z": 9,
      "r": 200,
      "g": 50,
      "b": 50
    },
    {
      "x": 3,
      "y": 5,
      "z": 10,
      "r": 200,
      "g": 50,
      "b": 50
    },
    {
      "x": 3,
      "y": 6,
      "z": 9,
      "r": 255,
      "g": 255,
      "b": 255
    },
    {
      "x": 3,
      "y": 6,
      "z": 10,
      "r": 255,
      "g": 255,
      "b": 255
    },
    {
      "x": 3,
      "y": 7,
      "z": 9,
      "r": 255,
      "g": 255,
      "b": 255
    },
    {
      "x": 3,
      "y": 7,
      "z": 10,
      "r": 255,
      "g": 255,
      "b": 255
    },
    {
      "x": 4,
      "y": 4,
      "z": 10,
      "r": 200,
      "g": 50,
      "b": 50
    },
    {
      "x": 4,
      "y": 4,
      "z": 11,
      "r": 200,
      "g": 50,
      "b": 50
    },
    {
      "x": 4,
      "y": 5,
      "z": 10,
      "r": 200,
      "g": 50,
      "b": 50
    },
    {
      "x": 4,
      "y": 5,
      "z": 11,
      "r": 200,
      "g": 50,
      "b": 50
    },
    {
      "x": 4,
      "y": 6,
      "z": 10,
      "r": 255,
      "g": 255,
      "b": 255
    },
    {
      "x": 4,
      "y": 7,
      "z": 10,
      "r": 255,
      "g": 255,
      "b": 255
    },
    {
      "x": 4,
      "y": 8,
      "z": 10,
      "r": 255,
      "g": 255,
      "b": 255
    },
    {
      "x": 5,
      "y": 4,
      "z": 11,
      "r": 200,
      "g": 50,
      "b": 50
    },
    {
      "x": 5,
      "y": 5,
      "z": 10,
      "r": 200,
      "g": 50,
      "b": 50
    },
    {
      "x": 5,
      "y": 5,
      "z": 11,
      "r": 200,
      "g": 50,
      "b": 50
    },
    {
      "x": 5,
      "y": 6,
      "z": 10,
      "r": 255,
      "g": 255,
      "b": 255
    },
    {
      "x": 5,
      "y": 6,
      "z": 11,
      "r": 255,
      "g": 255,
      "b": 255
    },
    {
      "x": 5,
      "y": 7,
      "z": 10,
      "r": 255,
      "g": 255,
      "b": 255
    },
    {
      "x": 5,
      "y": 7,
      "z": 11,
      "r": 255,
      "g": 255,
      "b": 255
    },
    {
      "x": 5,
      "y": 8,
      "z": 10,
      "r": 255,
      "g": 255,
      "b": 255
    },
    {
      "x": 5,
      "y": 9,
      "z": 10,
      "r": 255,
      "g": 255,
      "b": 255
    },
    {
      "x": 0,
      "y": 5,
      "z": 8,
      "r": 200,
      "g": 50,
      "b": 50
    },
    {
      "x": 1,
      "y": 5,
      "z": 8,
      "r": 200,
      "g": 50,
      "b": 50
    },
    {
      "x": 1,
      "y": 6,
      "z": 8,
      "r": 255,
      "g": 255,
      "b": 255
    },
    {
      "x": 1,
      "y": 6,
      "z": 9,
      "r": 255,
      "g": 255,
      "b": 255
    },
    {
      "x": 1,
      "y": 7,
      "z": 8,
      "r": 255,
      "g": 255,
      "b": 255
    },
    {
      "x": 1,
      "y": 7,
      "z": 9,
      "r": 255,
      "g": 255,
      "b": 255
    },
    {
      "x": 1,
      "y": 8,
      "z": 8,
      "r": 255,
      "g": 255,
      "b": 255
    },
    {
      "x": 1,
      "y": 9,
      "z": 8,
      "r": 255,
      "g": 255,
      "b": 255
    },
    {
      "x": 2,
      "y": 7,
      "z": 8,
      "r": 255,
      "g": 255,
      "b": 255
    },
    {
      "x": 2,
      "y": 7,
      "z": 9,
      "r": 255,
      "g": 255,
      "b": 255
    },
    {
      "x": 2,
      "y": 8,
      "z": 8,
      "r": 255,
      "g": 255,
      "b": 255
    },
    {
      "x": 2,
      "y": 8,
      "z": 9,
      "r": 255,
      "g": 255,
      "b": 255
    },
    {
      "x": 2,
      "y": 9,
      "z": 8,
      "r": 255,
      "g": 255,
      "b": 255
    },
    {
      "x": 2,
      "y": 9,
      "z": 9,
      "r": 255,
      "g": 255,
      "b": 255
    },
    {
      "x": 3,
      "y": 8,
      "z": 9,
      "r": 255,
      "g": 255,
      "b": 255
    },
    {
      "x": 3,
      "y": 8,
      "z": 10,
      "r": 255,
      "g": 255,
      "b": 255
    },
    {
      "x": 3,
      "y": 9,
      "z": 9,
      "r": 255,
      "g": 255,
      "b": 255
    },
    {
      "x": 3,
      "y": 9,
      "z": 10,
      "r": 255,
      "g": 255,
      "b": 255
    },
    {
      "x": 4,
      "y": 9,
      "z": 10,
      "r": 255,
      "g": 255,
      "b": 255
    },
    {
      "x": 9,
      "y": 4,
      "z": 4,
      "r": 200,
      "g": 50,
      "b": 50
    },
    {
      "x": 9,
      "y": 4,
      "z": 5,
      "r": 200,
      "g": 50,
      "b": 50
    },
    {
      "x": 9,
      "y": 4,
      "z": 6,
      "r": 200,
      "g": 50,
      "b": 50
    },
    {
      "x": 9,
      "y": 4,
      "z": 7,
      "r": 200,
      "g": 50,
      "b": 50
    },
    {
      "x": 9,
      "y": 4,
      "z": 8,
      "r": 200,
      "g": 50,
      "b": 50
    },
    {
      "x": 9,
      "y": 5,
      "z": 4,
      "r": 200,
      "g": 50,
      "b": 50
    },
    {
      "x": 9,
      "y": 5,
      "z": 5,
      "r": 200,
      "g": 50,
      "b": 50
    },
    {
      "x": 9,
      "y": 5,
      "z": 6,
      "r": 200,
      "g": 50,
      "b": 50
    },
    {
      "x": 9,
      "y": 5,
      "z": 7,
      "r": 200,
      "g": 50,
      "b": 50
    },
    {
      "x": 9,
      "y": 5,
      "z": 8,
      "r": 200,
      "g": 50,
      "b": 50
    },
    {
      "x": 9,
      "y": 6,
      "z": 4,
      "r": 255,
      "g": 255,
      "b": 255
    },
    {
      "x": 9,
      "y": 6,
      "z": 5,
      "r": 255,
      "g": 255,
      "b": 255
    },
    {
      "x": 9,
      "y": 6,
      "z": 6,
      "r": 255,
      "g": 255,
      "b": 255
    },
    {
      "x": 9,
      "y": 6,
      "z": 7,
      "r": 255,
      "g": 255,
      "b": 255
    },
    {
      "x": 9,
      "y": 7,
      "z": 4,
      "r": 255,
      "g": 255,
      "b": 255
    },
    {
      "x": 9,
      "y": 7,
      "z": 5,
      "r": 255,
      "g": 255,
      "b": 255
    },
    {
      "x": 9,
      "y": 7,
      "z": 6,
      "r": 255,
      "g": 255,
      "b": 255
    },
    {
      "x": 9,
      "y": 8,
      "z": 4,
      "r": 255,
      "g": 255,
      "b": 255
    },
    {
      "x": 9,
      "y": 8,
      "z": 5,
      "r": 255,
      "g": 255,
      "b": 255
    },
    {
      "x": 9,
      "y": 9,
      "z": 4,
      "r": 255,
      "g": 255,
      "b": 255
    },
    {
      "x": 9,
      "y": 6,
      "z": 8,
      "r": 255,
      "g": 255,
      "b": 255
    },
    {
      "x": 9,
      "y": 7,
      "z": 7,
      "r": 255,
      "g": 255,
      "b": 255
    },
    {
      "x": 9,
      "y": 7,
      "z": 8,
      "r": 255,
      "g": 255,
      "b": 255
    },
    {
      "x": 9,
      "y": 8,
      "z": 6,
      "r": 255,
      "g": 255,
      "b": 255
    },
    {
      "x": 9,
      "y": 8,
      "z": 7,
      "r": 255,
      "g": 255,
      "b": 255
    },
    {
      "x": 9,
      "y": 8,
      "z": 8,
      "r": 255,
      "g": 255,
      "b": 255
    },
    {
      "x": 9,
      "y": 9,
      "z": 5,
      "r": 255,
      "g": 255,
      "b": 255
    },
    {
      "x": 9,
      "y": 9,
      "z": 6,
      "r": 255,
      "g": 255,
      "b": 255
    },
    {
      "x": 9,
      "y": 9,
      "z": 7,
      "r": 255,
      "g": 255,
      "b": 255
    },
    {
      "x": 9,
      "y": 9,
      "z": 8,
      "r": 255,
      "g": 255,
      "b": 255
    },
    {
      "x": 0,
      "y": 4,
      "z": 4,
      "r": 200,
      "g": 50,
      "b": 50
    },
    {
      "x": 0,
      "y": 4,
      "z": 5,
      "r": 200,
      "g": 50,
      "b": 50
    },
    {
      "x": 0,
      "y": 4,
      "z": 6,
      "r": 200,
      "g": 50,
      "b": 50
    },
    {
      "x": 0,
      "y": 4,
      "z": 7,
      "r": 200,
      "g": 50,
      "b": 50
    },
    {
      "x": 0,
      "y": 5,
      "z": 4,
      "r": 200,
      "g": 50,
      "b": 50
    },
    {
      "x": 0,
      "y": 5,
      "z": 5,
      "r": 200,
      "g": 50,
      "b": 50
    },
    {
      "x": 0,
      "y": 5,
      "z": 6,
      "r": 200,
      "g": 50,
      "b": 50
    },
    {
      "x": 0,
      "y": 5,
      "z": 7,
      "r": 200,
      "g": 50,
      "b": 50
    },
    {
      "x": 1,
      "y": 5,
      "z": 5,
      "r": 200,
      "g": 50,
      "b": 50
    },
    {
      "x": 1,
      "y": 5,
      "z": 6,
      "r": 200,
      "g": 50,
      "b": 50
    },
    {
      "x": 1,
      "y": 5,
      "z": 7,
      "r": 200,
      "g": 50,
      "b": 50
    },
    {
      "x": 1,
      "y": 6,
      "z": 5,
      "r": 255,
      "g": 255,
      "b": 255
    },
    {
      "x": 1,
      "y": 6,
      "z": 6,
      "r": 255,
      "g": 255,
      "b": 255
    },
    {
      "x": 1,
      "y": 6,
      "z": 7,
      "r": 255,
      "g": 255,
      "b": 255
    },
    {
      "x": 1,
      "y": 7,
      "z": 6,
      "r": 255,
      "g": 255,
      "b": 255
    },
    {
      "x": 1,
      "y": 7,
      "z": 7,
      "r": 255,
      "g": 255,
      "b": 255
    },
    {
      "x": 1,
      "y": 8,
      "z": 7,
      "r": 255,
      "g": 255,
      "b": 255
    },
    {
      "x": 1,
      "y": 5,
      "z": 4,
      "r": 200,
      "g": 50,
      "b": 50
    },
    {
      "x": 1,
      "y": 6,
      "z": 4,
      "r": 255,
      "g": 255,
      "b": 255
    },
    {
      "x": 1,
      "y": 7,
      "z": 4,
      "r": 255,
      "g": 255,
      "b": 255
    },
    {
      "x": 1,
      "y": 7,
      "z": 5,
      "r": 255,
      "g": 255,
      "b": 255
    },
    {
      "x": 1,
      "y": 8,
      "z": 4,
      "r": 255,
      "g": 255,
      "b": 255
    },
    {
      "x": 1,
      "y": 8,
      "z": 5,
      "r": 255,
      "g": 255,
      "b": 255
    },
    {
      "x": 1,
      "y": 8,
      "z": 6,
      "r": 255,
      "g": 255,
      "b": 255
    },
    {
      "x": 1,
      "y": 9,
      "z": 4,
      "r": 255,
      "g": 255,
      "b": 255
    },
    {
      "x": 1,
      "y": 9,
      "z": 5,
      "r": 255,
      "g": 255,
      "b": 255
    },
    {
      "x": 1,
      "y": 9,
      "z": 6,
      "r": 255,
      "g": 255,
      "b": 255
    },
    {
      "x": 1,
      "y": 9,
      "z": 7,
      "r": 255,
      "g": 255,
      "b": 255
    },
    {
      "x": 5,
      "y": 4,
      "z": 10,
      "r": 200,
      "g": 50,
      "b": 50
    },
    {
      "x": 6,
      "y": 4,
      "z": 10,
      "r": 200,
      "g": 50,
      "b": 50
    },
    {
      "x": 6,
      "y": 5,
      "z": 10,
      "r": 200,
      "g": 50,
      "b": 50
    },
    {
      "x": 6,
      "y": 6,
      "z": 10,
      "r": 255,
      "g": 255,
      "b": 255
    },
    {
      "x": 7,
      "y": 4,
      "z": 9,
      "r": 200,
      "g": 50,
      "b": 50
    },
    {
      "x": 7,
      "y": 4,
      "z": 10,
      "r": 200,
      "g": 50,
      "b": 50
    },
    {
      "x": 7,
      "y": 5,
      "z": 9,
      "r": 200,
      "g": 50,
      "b": 50
    },
    {
      "x": 7,
      "y": 5,
      "z": 10,
      "r": 200,
      "g": 50,
      "b": 50
    },
    {
      "x": 7,
      "y": 6,
      "z": 9,
      "r": 255,
      "g": 255,
      "b": 255
    },
    {
      "x": 7,
      "y": 6,
      "z": 10,
      "r": 255,
      "g": 255,
      "b": 255
    },
    {
      "x": 7,
      "y": 7,
      "z": 9,
      "r": 255,
      "g": 255,
      "b": 255
    },
    {
      "x": 8,
      "y": 4,
      "z": 9,
      "r": 200,
      "g": 50,
      "b": 50
    },
    {
      "x": 8,
      "y": 5,
      "z": 9,
      "r": 200,
      "g": 50,
      "b": 50
    },
    {
      "x": 8,
      "y": 6,
      "z": 8,
      "r": 255,
      "g": 255,
      "b": 255
    },
    {
      "x": 8,
      "y": 6,
      "z": 9,
      "r": 255,
      "g": 255,
      "b": 255
    },
    {
      "x": 8,
      "y": 7,
      "z": 8,
      "r": 255,
      "g": 255,
      "b": 255
    },
    {
      "x": 8,
      "y": 7,
      "z": 9,
      "r": 255,
      "g": 255,
      "b": 255
    },
    {
      "x": 8,
      "y": 8,
      "z": 8,
      "r": 255,
      "g": 255,
      "b": 255
    },
    {
      "x": 8,
      "y": 8,
      "z": 9,
      "r": 255,
      "g": 255,
      "b": 255
    },
    {
      "x": 9,
      "y": 4,
      "z": 9,
      "r": 200,
      "g": 50,
      "b": 50
    },
    {
      "x": 9,
      "y": 5,
      "z": 9,
      "r": 200,
      "g": 50,
      "b": 50
    },
    {
      "x": 9,
      "y": 6,
      "z": 9,
      "r": 255,
      "g": 255,
      "b": 255
    },
    {
      "x": 6,
      "y": 7,
      "z": 9,
      "r": 255,
      "g": 255,
      "b": 255
    },
    {
      "x": 6,
      "y": 7,
      "z": 10,
      "r": 255,
      "g": 255,
      "b": 255
    },
    {
      "x": 6,
      "y": 8,
      "z": 9,
      "r": 255,
      "g": 255,
      "b": 255
    },
    {
      "x": 6,
      "y": 8,
      "z": 10,
      "r": 255,
      "g": 255,
      "b": 255
    },
    {
      "x": 6,
      "y": 9,
      "z": 9,
      "r": 255,
      "g": 255,
      "b": 255
    },
    {
      "x": 6,
      "y": 9,
      "z": 10,
      "r": 255,
      "g": 255,
      "b": 255
    },
    {
      "x": 7,
      "y": 7,
      "z": 10,
      "r": 255,
      "g": 255,
      "b": 255
    },
    {
      "x": 7,
      "y": 8,
      "z": 9,
      "r": 255,
      "g": 255,
      "b": 255
    },
    {
      "x": 7,
      "y": 9,
      "z": 9,
      "r": 255,
      "g": 255,
      "b": 255
    },
    {
      "x": 8,
      "y": 9,
      "z": 8,
      "r": 255,
      "g": 255,
      "b": 255
    },
    {
      "x": 8,
      "y": 9,
      "z": 9,
      "r": 255,
      "g": 255,
      "b": 255
    },
    {
      "x": 2,
      "y": 33,
      "z": 3,
      "r": 255,
      "g": 255,
      "b": 255
    },
    {
      "x": 2,
      "y": 33,
      "z": 4,
      "r": 255,
      "g": 255,
      "b": 255
    },
    {
      "x": 3,
      "y": 33,
      "z": 3,
      "r": 255,
      "g": 255,
      "b": 255
    },
    {
      "x": 3,
      "y": 33,
      "z": 4,
      "r": 255,
      "g": 255,
      "b": 255
    },
    {
      "x": 4,
      "y": 33,
      "z": 2,
      "r": 255,
      "g": 255,
      "b": 255
    },
    {
      "x": 4,
      "y": 33,
      "z": 3,
      "r": 255,
      "g": 255,
      "b": 255
    },
    {
      "x": 4,
      "y": 33,
      "z": 4,
      "r": 255,
      "g": 255,
      "b": 255
    },
    {
      "x": 5,
      "y": 33,
      "z": 2,
      "r": 255,
      "g": 255,
      "b": 255
    },
    {
      "x": 5,
      "y": 33,
      "z": 3,
      "r": 255,
      "g": 255,
      "b": 255
    },
    {
      "x": 5,
      "y": 33,
      "z": 4,
      "r": 255,
      "g": 255,
      "b": 255
    },
    {
      "x": 6,
      "y": 33,
      "z": 2,
      "r": 255,
      "g": 255,
      "b": 255
    },
    {
      "x": 6,
      "y": 33,
      "z": 3,
      "r": 255,
      "g": 255,
      "b": 255
    },
    {
      "x": 6,
      "y": 33,
      "z": 4,
      "r": 255,
      "g": 255,
      "b": 255
    },
    {
      "x": 7,
      "y": 33,
      "z": 3,
      "r": 255,
      "g": 255,
      "b": 255
    },
    {
      "x": 7,
      "y": 33,
      "z": 4,
      "r": 255,
      "g": 255,
      "b": 255
    },
    {
      "x": 8,
      "y": 33,
      "z": 4,
      "r": 255,
      "g": 255,
      "b": 255
    },
    {
      "x": 2,
      "y": 33,
      "z": 5,
      "r": 255,
      "g": 255,
      "b": 255
    },
    {
      "x": 2,
      "y": 33,
      "z": 6,
      "r": 255,
      "g": 255,
      "b": 255
    },
    {
      "x": 2,
      "y": 33,
      "z": 7,
      "r": 255,
      "g": 255,
      "b": 255
    },
    {
      "x": 3,
      "y": 33,
      "z": 5,
      "r": 255,
      "g": 255,
      "b": 255
    },
    {
      "x": 3,
      "y": 33,
      "z": 6,
      "r": 255,
      "g": 255,
      "b": 255
    },
    {
      "x": 3,
      "y": 33,
      "z": 7,
      "r": 255,
      "g": 255,
      "b": 255
    },
    {
      "x": 4,
      "y": 33,
      "z": 5,
      "r": 255,
      "g": 255,
      "b": 255
    },
    {
      "x": 4,
      "y": 33,
      "z": 6,
      "r": 255,
      "g": 255,
      "b": 255
    },
    {
      "x": 5,
      "y": 33,
      "z": 5,
      "r": 255,
      "g": 255,
      "b": 255
    },
    {
      "x": 5,
      "y": 33,
      "z": 6,
      "r": 255,
      "g": 255,
      "b": 255
    },
    {
      "x": 6,
      "y": 33,
      "z": 5,
      "r": 255,
      "g": 255,
      "b": 255
    },
    {
      "x": 7,
      "y": 33,
      "z": 5,
      "r": 255,
      "g": 255,
      "b": 255
    },
    {
      "x": 2,
      "y": 33,
      "z": 8,
      "r": 255,
      "g": 255,
      "b": 255
    },
    {
      "x": 3,
      "y": 33,
      "z": 8,
      "r": 255,
      "g": 255,
      "b": 255
    },
    {
      "x": 4,
      "y": 33,
      "z": 7,
      "r": 255,
      "g": 255,
      "b": 255
    },
    {
      "x": 4,
      "y": 33,
      "z": 8,
      "r": 255,
      "g": 255,
      "b": 255
    },
    {
      "x": 4,
      "y": 33,
      "z": 9,
      "r": 255,
      "g": 255,
      "b": 255
    },
    {
      "x": 5,
      "y": 33,
      "z": 7,
      "r": 255,
      "g": 255,
      "b": 255
    },
    {
      "x": 5,
      "y": 33,
      "z": 8,
      "r": 255,
      "g": 255,
      "b": 255
    },
    {
      "x": 5,
      "y": 33,
      "z": 9,
      "r": 255,
      "g": 255,
      "b": 255
    },
    {
      "x": 6,
      "y": 33,
      "z": 6,
      "r": 255,
      "g": 255,
      "b": 255
    },
    {
      "x": 6,
      "y": 33,
      "z": 7,
      "r": 255,
      "g": 255,
      "b": 255
    },
    {
      "x": 6,
      "y": 33,
      "z": 8,
      "r": 255,
      "g": 255,
      "b": 255
    },
    {
      "x": 7,
      "y": 33,
      "z": 6,
      "r": 255,
      "g": 255,
      "b": 255
    },
    {
      "x": 8,
      "y": 33,
      "z": 5,
      "r": 255,
      "g": 255,
      "b": 255
    },
    {
      "x": 6,
      "y": 33,
      "z": 9,
      "r": 255,
      "g": 255,
      "b": 255
    },
    {
      "x": 7,
      "y": 33,
      "z": 7,
      "r": 255,
      "g": 255,
      "b": 255
    },
    {
      "x": 7,
      "y": 33,
      "z": 8,
      "r": 255,
      "g": 255,
      "b": 255
    },
    {
      "x": 8,
      "y": 33,
      "z": 6,
      "r": 255,
      "g": 255,
      "b": 255
    },
    {
      "x": 8,
      "y": 33,
      "z": 7,
      "r": 255,
      "g": 255,
      "b": 255
    },
    {
      "x": 8,
      "y": 33,
      "z": 8,
      "r": 255,
      "g": 255,
      "b": 255
    },
    {
      "x": 5,
      "y": 17,
      "z": 1,
      "r": 200,
      "g": 50,
      "b": 50
    },
    {
      "x": 5,
      "y": 17,
      "z": 2,
      "r": 200,
      "g": 50,
      "b": 50
    },
    {
      "x": 5,
      "y": 18,
      "z": 1,
      "r": 255,
      "g": 255,
      "b": 255
    },
    {
      "x": 5,
      "y": 18,
      "z": 2,
      "r": 255,
      "g": 255,
      "b": 255
    },
    {
      "x": 5,
      "y": 19,
      "z": 1,
      "r": 255,
      "g": 255,
      "b": 255
    },
    {
      "x": 5,
      "y": 19,
      "z": 2,
      "r": 255,
      "g": 255,
      "b": 255
    },
    {
      "x": 5,
      "y": 20,
      "z": 1,
      "r": 255,
      "g": 255,
      "b": 255
    },
    {
      "x": 5,
      "y": 20,
      "z": 2,
      "r": 255,
      "g": 255,
      "b": 255
    },
    {
      "x": 5,
      "y": 21,
      "z": 2,
      "r": 255,
      "g": 255,
      "b": 255
    },
    {
      "x": 5,
      "y": 22,
      "z": 2,
      "r": 255,
      "g": 255,
      "b": 255
    },
    {
      "x": 5,
      "y": 23,
      "z": 2,
      "r": 255,
      "g": 255,
      "b": 255
    },
    {
      "x": 5,
      "y": 24,
      "z": 2,
      "r": 200,
      "g": 50,
      "b": 50
    },
    {
      "x": 5,
      "y": 25,
      "z": 2,
      "r": 200,
      "g": 50,
      "b": 50
    },
    {
      "x": 6,
      "y": 17,
      "z": 2,
      "r": 200,
      "g": 50,
      "b": 50
    },
    {
      "x": 6,
      "y": 18,
      "z": 2,
      "r": 255,
      "g": 255,
      "b": 255
    },
    {
      "x": 6,
      "y": 19,
      "z": 2,
      "r": 255,
      "g": 255,
      "b": 255
    },
    {
      "x": 6,
      "y": 20,
      "z": 2,
      "r": 255,
      "g": 255,
      "b": 255
    },
    {
      "x": 6,
      "y": 21,
      "z": 2,
      "r": 255,
      "g": 255,
      "b": 255
    },
    {
      "x": 6,
      "y": 21,
      "z": 3,
      "r": 255,
      "g": 255,
      "b": 255
    },
    {
      "x": 6,
      "y": 22,
      "z": 2,
      "r": 255,
      "g": 255,
      "b": 255
    },
    {
      "x": 6,
      "y": 22,
      "z": 3,
      "r": 255,
      "g": 255,
      "b": 255
    },
    {
      "x": 6,
      "y": 23,
      "z": 2,
      "r": 255,
      "g": 255,
      "b": 255
    },
    {
      "x": 6,
      "y": 24,
      "z": 2,
      "r": 200,
      "g": 50,
      "b": 50
    },
    {
      "x": 7,
      "y": 17,
      "z": 2,
      "r": 200,
      "g": 50,
      "b": 50
    },
    {
      "x": 7,
      "y": 17,
      "z": 3,
      "r": 200,
      "g": 50,
      "b": 50
    },
    {
      "x": 7,
      "y": 18,
      "z": 2,
      "r": 255,
      "g": 255,
      "b": 255
    },
    {
      "x": 7,
      "y": 18,
      "z": 3,
      "r": 255,
      "g": 255,
      "b": 255
    },
    {
      "x": 7,
      "y": 19,
      "z": 2,
      "r": 255,
      "g": 255,
      "b": 255
    },
    {
      "x": 7,
      "y": 19,
      "z": 3,
      "r": 255,
      "g": 255,
      "b": 255
    },
    {
      "x": 7,
      "y": 20,
      "z": 2,
      "r": 255,
      "g": 255,
      "b": 255
    },
    {
      "x": 7,
      "y": 20,
      "z": 3,
      "r": 255,
      "g": 255,
      "b": 255
    },
    {
      "x": 7,
      "y": 21,
      "z": 2,
      "r": 255,
      "g": 255,
      "b": 255
    },
    {
      "x": 7,
      "y": 21,
      "z": 3,
      "r": 255,
      "g": 255,
      "b": 255
    },
    {
      "x": 7,
      "y": 22,
      "z": 3,
      "r": 255,
      "g": 255,
      "b": 255
    },
    {
      "x": 8,
      "y": 17,
      "z": 3,
      "r": 200,
      "g": 50,
      "b": 50
    },
    {
      "x": 8,
      "y": 18,
      "z": 3,
      "r": 255,
      "g": 255,
      "b": 255
    },
    {
      "x": 8,
      "y": 19,
      "z": 3,
      "r": 255,
      "g": 255,
      "b": 255
    },
    {
      "x": 8,
      "y": 20,
      "z": 3,
      "r": 255,
      "g": 255,
      "b": 255
    },
    {
      "x": 9,
      "y": 17,
      "z": 3,
      "r": 200,
      "g": 50,
      "b": 50
    },
    {
      "x": 9,
      "y": 17,
      "z": 4,
      "r": 200,
      "g": 50,
      "b": 50
    },
    {
      "x": 6,
      "y": 23,
      "z": 3,
      "r": 255,
      "g": 255,
      "b": 255
    },
    {
      "x": 6,
      "y": 24,
      "z": 3,
      "r": 200,
      "g": 50,
      "b": 50
    },
    {
      "x": 6,
      "y": 25,
      "z": 2,
      "r": 200,
      "g": 50,
      "b": 50
    },
    {
      "x": 6,
      "y": 25,
      "z": 3,
      "r": 200,
      "g": 50,
      "b": 50
    },
    {
      "x": 7,
      "y": 23,
      "z": 3,
      "r": 255,
      "g": 255,
      "b": 255
    },
    {
      "x": 7,
      "y": 24,
      "z": 3,
      "r": 200,
      "g": 50,
      "b": 50
    },
    {
      "x": 7,
      "y": 25,
      "z": 3,
      "r": 200,
      "g": 50,
      "b": 50
    },
    {
      "x": 8,
      "y": 18,
      "z": 4,
      "r": 255,
      "g": 255,
      "b": 255
    },
    {
      "x": 8,
      "y": 19,
      "z": 4,
      "r": 255,
      "g": 255,
      "b": 255
    },
    {
      "x": 8,
      "y": 20,
      "z": 4,
      "r": 255,
      "g": 255,
      "b": 255
    },
    {
      "x": 8,
      "y": 21,
      "z": 3,
      "r": 255,
      "g": 255,
      "b": 255
    },
    {
      "x": 8,
      "y": 21,
      "z": 4,
      "r": 255,
      "g": 255,
      "b": 255
    },
    {
      "x": 8,
      "y": 22,
      "z": 3,
      "r": 255,
      "g": 255,
      "b": 255
    },
    {
      "x": 8,
      "y": 22,
      "z": 4,
      "r": 255,
      "g": 255,
      "b": 255
    },
    {
      "x": 8,
      "y": 23,
      "z": 3,
      "r": 255,
      "g": 255,
      "b": 255
    },
    {
      "x": 8,
      "y": 23,
      "z": 4,
      "r": 255,
      "g": 255,
      "b": 255
    },
    {
      "x": 8,
      "y": 24,
      "z": 3,
      "r": 200,
      "g": 50,
      "b": 50
    },
    {
      "x": 8,
      "y": 24,
      "z": 4,
      "r": 200,
      "g": 50,
      "b": 50
    },
    {
      "x": 8,
      "y": 25,
      "z": 3,
      "r": 200,
      "g": 50,
      "b": 50
    },
    {
      "x": 8,
      "y": 25,
      "z": 4,
      "r": 200,
      "g": 50,
      "b": 50
    },
    {
      "x": 9,
      "y": 18,
      "z": 3,
      "r": 255,
      "g": 255,
      "b": 255
    },
    {
      "x": 9,
      "y": 18,
      "z": 4,
      "r": 255,
      "g": 255,
      "b": 255
    },
    {
      "x": 5,
      "y": 17,
      "z": 10,
      "r": 200,
      "g": 50,
      "b": 50
    },
    {
      "x": 5,
      "y": 18,
      "z": 9,
      "r": 255,
      "g": 255,
      "b": 255
    },
    {
      "x": 5,
      "y": 18,
      "z": 10,
      "r": 255,
      "g": 255,
      "b": 255
    },
    {
      "x": 5,
      "y": 19,
      "z": 9,
      "r": 255,
      "g": 255,
      "b": 255
    },
    {
      "x": 5,
      "y": 19,
      "z": 10,
      "r": 255,
      "g": 255,
      "b": 255
    },
    {
      "x": 6,
      "y": 17,
      "z": 9,
      "r": 200,
      "g": 50,
      "b": 50
    },
    {
      "x": 6,
      "y": 17,
      "z": 10,
      "r": 200,
      "g": 50,
      "b": 50
    },
    {
      "x": 6,
      "y": 18,
      "z": 9,
      "r": 255,
      "g": 255,
      "b": 255
    },
    {
      "x": 6,
      "y": 18,
      "z": 10,
      "r": 255,
      "g": 255,
      "b": 255
    },
    {
      "x": 6,
      "y": 19,
      "z": 9,
      "r": 255,
      "g": 255,
      "b": 255
    },
    {
      "x": 6,
      "y": 20,
      "z": 9,
      "r": 255,
      "g": 255,
      "b": 255
    },
    {
      "x": 6,
      "y": 21,
      "z": 9,
      "r": 255,
      "g": 255,
      "b": 255
    },
    {
      "x": 7,
      "y": 17,
      "z": 8,
      "r": 200,
      "g": 50,
      "b": 50
    },
    {
      "x": 7,
      "y": 17,
      "z": 9,
      "r": 200,
      "g": 50,
      "b": 50
    },
    {
      "x": 7,
      "y": 18,
      "z": 8,
      "r": 255,
      "g": 255,
      "b": 255
    },
    {
      "x": 7,
      "y": 18,
      "z": 9,
      "r": 255,
      "g": 255,
      "b": 255
    },
    {
      "x": 7,
      "y": 19,
      "z": 8,
      "r": 255,
      "g": 255,
      "b": 255
    },
    {
      "x": 7,
      "y": 19,
      "z": 9,
      "r": 255,
      "g": 255,
      "b": 255
    },
    {
      "x": 7,
      "y": 20,
      "z": 8,
      "r": 255,
      "g": 255,
      "b": 255
    },
    {
      "x": 7,
      "y": 20,
      "z": 9,
      "r": 255,
      "g": 255,
      "b": 255
    },
    {
      "x": 7,
      "y": 21,
      "z": 8,
      "r": 255,
      "g": 255,
      "b": 255
    },
    {
      "x": 7,
      "y": 21,
      "z": 9,
      "r": 255,
      "g": 255,
      "b": 255
    },
    {
      "x": 7,
      "y": 22,
      "z": 8,
      "r": 255,
      "g": 255,
      "b": 255
    },
    {
      "x": 7,
      "y": 22,
      "z": 9,
      "r": 255,
      "g": 255,
      "b": 255
    },
    {
      "x": 7,
      "y": 23,
      "z": 8,
      "r": 255,
      "g": 255,
      "b": 255
    },
    {
      "x": 7,
      "y": 24,
      "z": 8,
      "r": 200,
      "g": 50,
      "b": 50
    },
    {
      "x": 8,
      "y": 17,
      "z": 8,
      "r": 200,
      "g": 50,
      "b": 50
    },
    {
      "x": 8,
      "y": 18,
      "z": 8,
      "r": 255,
      "g": 255,
      "b": 255
    },
    {
      "x": 8,
      "y": 19,
      "z": 8,
      "r": 255,
      "g": 255,
      "b": 255
    },
    {
      "x": 8,
      "y": 20,
      "z": 8,
      "r": 255,
      "g": 255,
      "b": 255
    },
    {
      "x": 8,
      "y": 21,
      "z": 8,
      "r": 255,
      "g": 255,
      "b": 255
    },
    {
      "x": 8,
      "y": 22,
      "z": 8,
      "r": 255,
      "g": 255,
      "b": 255
    },
    {
      "x": 8,
      "y": 23,
      "z": 8,
      "r": 255,
      "g": 255,
      "b": 255
    },
    {
      "x": 8,
      "y": 24,
      "z": 8,
      "r": 200,
      "g": 50,
      "b": 50
    },
    {
      "x": 8,
      "y": 25,
      "z": 8,
      "r": 200,
      "g": 50,
      "b": 50
    },
    {
      "x": 9,
      "y": 17,
      "z": 8,
      "r": 200,
      "g": 50,
      "b": 50
    },
    {
      "x": 9,
      "y": 18,
      "z": 8,
      "r": 255,
      "g": 255,
      "b": 255
    },
    {
      "x": 5,
      "y": 20,
      "z": 9,
      "r": 255,
      "g": 255,
      "b": 255
    },
    {
      "x": 5,
      "y": 20,
      "z": 10,
      "r": 255,
      "g": 255,
      "b": 255
    },
    {
      "x": 5,
      "y": 21,
      "z": 9,
      "r": 255,
      "g": 255,
      "b": 255
    },
    {
      "x": 5,
      "y": 21,
      "z": 10,
      "r": 255,
      "g": 255,
      "b": 255
    },
    {
      "x": 5,
      "y": 22,
      "z": 9,
      "r": 255,
      "g": 255,
      "b": 255
    },
    {
      "x": 5,
      "y": 22,
      "z": 10,
      "r": 255,
      "g": 255,
      "b": 255
    },
    {
      "x": 5,
      "y": 23,
      "z": 9,
      "r": 255,
      "g": 255,
      "b": 255
    },
    {
      "x": 5,
      "y": 23,
      "z": 10,
      "r": 255,
      "g": 255,
      "b": 255
    },
    {
      "x": 5,
      "y": 24,
      "z": 9,
      "r": 200,
      "g": 50,
      "b": 50
    },
    {
      "x": 5,
      "y": 24,
      "z": 10,
      "r": 200,
      "g": 50,
      "b": 50
    },
    {
      "x": 5,
      "y": 25,
      "z": 9,
      "r": 200,
      "g": 50,
      "b": 50
    },
    {
      "x": 5,
      "y": 25,
      "z": 10,
      "r": 200,
      "g": 50,
      "b": 50
    },
    {
      "x": 6,
      "y": 22,
      "z": 9,
      "r": 255,
      "g": 255,
      "b": 255
    },
    {
      "x": 6,
      "y": 23,
      "z": 9,
      "r": 255,
      "g": 255,
      "b": 255
    },
    {
      "x": 6,
      "y": 24,
      "z": 9,
      "r": 200,
      "g": 50,
      "b": 50
    },
    {
      "x": 6,
      "y": 25,
      "z": 9,
      "r": 200,
      "g": 50,
      "b": 50
    },
    {
      "x": 7,
      "y": 23,
      "z": 9,
      "r": 255,
      "g": 255,
      "b": 255
    },
    {
      "x": 7,
      "y": 24,
      "z": 9,
      "r": 200,
      "g": 50,
      "b": 50
    },
    {
      "x": 7,
      "y": 25,
      "z": 8,
      "r": 200,
      "g": 50,
      "b": 50
    },
    {
      "x": 7,
      "y": 25,
      "z": 9,
      "r": 200,
      "g": 50,
      "b": 50
    },
    {
      "x": 1,
      "y": 17,
      "z": 4,
      "r": 200,
      "g": 50,
      "b": 50
    },
    {
      "x": 1,
      "y": 17,
      "z": 5,
      "r": 200,
      "g": 50,
      "b": 50
    },
    {
      "x": 1,
      "y": 17,
      "z": 6,
      "r": 200,
      "g": 50,
      "b": 50
    },
    {
      "x": 1,
      "y": 17,
      "z": 7,
      "r": 200,
      "g": 50,
      "b": 50
    },
    {
      "x": 1,
      "y": 17,
      "z": 8,
      "r": 200,
      "g": 50,
      "b": 50
    },
    {
      "x": 1,
      "y": 18,
      "z": 4,
      "r": 255,
      "g": 255,
      "b": 255
    },
    {
      "x": 1,
      "y": 18,
      "z": 5,
      "r": 255,
      "g": 255,
      "b": 255
    },
    {
      "x": 1,
      "y": 18,
      "z": 6,
      "r": 255,
      "g": 255,
      "b": 255
    },
    {
      "x": 1,
      "y": 18,
      "z": 7,
      "r": 255,
      "g": 255,
      "b": 255
    },
    {
      "x": 1,
      "y": 18,
      "z": 8,
      "r": 255,
      "g": 255,
      "b": 255
    },
    {
      "x": 1,
      "y": 19,
      "z": 4,
      "r": 255,
      "g": 255,
      "b": 255
    },
    {
      "x": 1,
      "y": 19,
      "z": 5,
      "r": 255,
      "g": 255,
      "b": 255
    },
    {
      "x": 1,
      "y": 19,
      "z": 6,
      "r": 255,
      "g": 255,
      "b": 255
    },
    {
      "x": 1,
      "y": 19,
      "z": 7,
      "r": 255,
      "g": 255,
      "b": 255
    },
    {
      "x": 1,
      "y": 19,
      "z": 8,
      "r": 255,
      "g": 255,
      "b": 255
    },
    {
      "x": 1,
      "y": 20,
      "z": 5,
      "r": 255,
      "g": 255,
      "b": 255
    },
    {
      "x": 1,
      "y": 20,
      "z": 6,
      "r": 255,
      "g": 255,
      "b": 255
    },
    {
      "x": 1,
      "y": 20,
      "z": 7,
      "r": 255,
      "g": 255,
      "b": 255
    },
    {
      "x": 1,
      "y": 20,
      "z": 8,
      "r": 255,
      "g": 255,
      "b": 255
    },
    {
      "x": 1,
      "y": 21,
      "z": 5,
      "r": 255,
      "g": 255,
      "b": 255
    },
    {
      "x": 1,
      "y": 21,
      "z": 6,
      "r": 255,
      "g": 255,
      "b": 255
    },
    {
      "x": 1,
      "y": 21,
      "z": 7,
      "r": 255,
      "g": 255,
      "b": 255
    },
    {
      "x": 1,
      "y": 21,
      "z": 8,
      "r": 255,
      "g": 255,
      "b": 255
    },
    {
      "x": 1,
      "y": 22,
      "z": 6,
      "r": 255,
      "g": 255,
      "b": 255
    },
    {
      "x": 1,
      "y": 22,
      "z": 7,
      "r": 255,
      "g": 255,
      "b": 255
    },
    {
      "x": 1,
      "y": 22,
      "z": 8,
      "r": 255,
      "g": 255,
      "b": 255
    },
    {
      "x": 1,
      "y": 23,
      "z": 6,
      "r": 255,
      "g": 255,
      "b": 255
    },
    {
      "x": 1,
      "y": 23,
      "z": 7,
      "r": 255,
      "g": 255,
      "b": 255
    },
    {
      "x": 1,
      "y": 23,
      "z": 8,
      "r": 255,
      "g": 255,
      "b": 255
    },
    {
      "x": 1,
      "y": 24,
      "z": 7,
      "r": 200,
      "g": 50,
      "b": 50
    },
    {
      "x": 1,
      "y": 24,
      "z": 8,
      "r": 200,
      "g": 50,
      "b": 50
    },
    {
      "x": 1,
      "y": 25,
      "z": 7,
      "r": 200,
      "g": 50,
      "b": 50
    },
    {
      "x": 1,
      "y": 25,
      "z": 8,
      "r": 200,
      "g": 50,
      "b": 50
    },
    {
      "x": 1,
      "y": 20,
      "z": 4,
      "r": 255,
      "g": 255,
      "b": 255
    },
    {
      "x": 1,
      "y": 21,
      "z": 4,
      "r": 255,
      "g": 255,
      "b": 255
    },
    {
      "x": 1,
      "y": 22,
      "z": 4,
      "r": 255,
      "g": 255,
      "b": 255
    },
    {
      "x": 1,
      "y": 22,
      "z": 5,
      "r": 255,
      "g": 255,
      "b": 255
    },
    {
      "x": 1,
      "y": 23,
      "z": 4,
      "r": 255,
      "g": 255,
      "b": 255
    },
    {
      "x": 1,
      "y": 23,
      "z": 5,
      "r": 255,
      "g": 255,
      "b": 255
    },
    {
      "x": 1,
      "y": 24,
      "z": 4,
      "r": 200,
      "g": 50,
      "b": 50
    },
    {
      "x": 1,
      "y": 24,
      "z": 5,
      "r": 200,
      "g": 50,
      "b": 50
    },
    {
      "x": 1,
      "y": 24,
      "z": 6,
      "r": 200,
      "g": 50,
      "b": 50
    },
    {
      "x": 1,
      "y": 25,
      "z": 4,
      "r": 200,
      "g": 50,
      "b": 50
    },
    {
      "x": 1,
      "y": 25,
      "z": 5,
      "r": 200,
      "g": 50,
      "b": 50
    },
    {
      "x": 1,
      "y": 25,
      "z": 6,
      "r": 200,
      "g": 50,
      "b": 50
    },
    {
      "x": 8,
      "y": 18,
      "z": 5,
      "r": 255,
      "g": 255,
      "b": 255
    },
    {
      "x": 8,
      "y": 18,
      "z": 6,
      "r": 255,
      "g": 255,
      "b": 255
    },
    {
      "x": 8,
      "y": 18,
      "z": 7,
      "r": 255,
      "g": 255,
      "b": 255
    },
    {
      "x": 8,
      "y": 19,
      "z": 5,
      "r": 255,
      "g": 255,
      "b": 255
    },
    {
      "x": 8,
      "y": 19,
      "z": 6,
      "r": 255,
      "g": 255,
      "b": 255
    },
    {
      "x": 8,
      "y": 19,
      "z": 7,
      "r": 255,
      "g": 255,
      "b": 255
    },
    {
      "x": 8,
      "y": 20,
      "z": 5,
      "r": 255,
      "g": 255,
      "b": 255
    },
    {
      "x": 8,
      "y": 20,
      "z": 6,
      "r": 255,
      "g": 255,
      "b": 255
    },
    {
      "x": 8,
      "y": 20,
      "z": 7,
      "r": 255,
      "g": 255,
      "b": 255
    },
    {
      "x": 8,
      "y": 21,
      "z": 5,
      "r": 255,
      "g": 255,
      "b": 255
    },
    {
      "x": 8,
      "y": 21,
      "z": 6,
      "r": 255,
      "g": 255,
      "b": 255
    },
    {
      "x": 8,
      "y": 22,
      "z": 5,
      "r": 255,
      "g": 255,
      "b": 255
    },
    {
      "x": 8,
      "y": 22,
      "z": 6,
      "r": 255,
      "g": 255,
      "b": 255
    },
    {
      "x": 8,
      "y": 23,
      "z": 5,
      "r": 255,
      "g": 255,
      "b": 255
    },
    {
      "x": 8,
      "y": 24,
      "z": 5,
      "r": 200,
      "g": 50,
      "b": 50
    },
    {
      "x": 9,
      "y": 17,
      "z": 5,
      "r": 200,
      "g": 50,
      "b": 50
    },
    {
      "x": 9,
      "y": 17,
      "z": 6,
      "r": 200,
      "g": 50,
      "b": 50
    },
    {
      "x": 9,
      "y": 17,
      "z": 7,
      "r": 200,
      "g": 50,
      "b": 50
    },
    {
      "x": 9,
      "y": 18,
      "z": 5,
      "r": 255,
      "g": 255,
      "b": 255
    },
    {
      "x": 9,
      "y": 18,
      "z": 6,
      "r": 255,
      "g": 255,
      "b": 255
    },
    {
      "x": 9,
      "y": 18,
      "z": 7,
      "r": 255,
      "g": 255,
      "b": 255
    },
    {
      "x": 8,
      "y": 21,
      "z": 7,
      "r": 255,
      "g": 255,
      "b": 255
    },
    {
      "x": 8,
      "y": 22,
      "z": 7,
      "r": 255,
      "g": 255,
      "b": 255
    },
    {
      "x": 8,
      "y": 23,
      "z": 6,
      "r": 255,
      "g": 255,
      "b": 255
    },
    {
      "x": 8,
      "y": 23,
      "z": 7,
      "r": 255,
      "g": 255,
      "b": 255
    },
    {
      "x": 8,
      "y": 24,
      "z": 6,
      "r": 200,
      "g": 50,
      "b": 50
    },
    {
      "x": 8,
      "y": 24,
      "z": 7,
      "r": 200,
      "g": 50,
      "b": 50
    },
    {
      "x": 8,
      "y": 25,
      "z": 5,
      "r": 200,
      "g": 50,
      "b": 50
    },
    {
      "x": 8,
      "y": 25,
      "z": 6,
      "r": 200,
      "g": 50,
      "b": 50
    },
    {
      "x": 8,
      "y": 25,
      "z": 7,
      "r": 200,
      "g": 50,
      "b": 50
    },
    {
      "x": 2,
      "y": 17,
      "z": 8,
      "r": 200,
      "g": 50,
      "b": 50
    },
    {
      "x": 2,
      "y": 17,
      "z": 9,
      "r": 200,
      "g": 50,
      "b": 50
    },
    {
      "x": 2,
      "y": 18,
      "z": 8,
      "r": 255,
      "g": 255,
      "b": 255
    },
    {
      "x": 2,
      "y": 18,
      "z": 9,
      "r": 255,
      "g": 255,
      "b": 255
    },
    {
      "x": 2,
      "y": 19,
      "z": 8,
      "r": 255,
      "g": 255,
      "b": 255
    },
    {
      "x": 2,
      "y": 19,
      "z": 9,
      "r": 255,
      "g": 255,
      "b": 255
    },
    {
      "x": 2,
      "y": 20,
      "z": 8,
      "r": 255,
      "g": 255,
      "b": 255
    },
    {
      "x": 3,
      "y": 17,
      "z": 9,
      "r": 200,
      "g": 50,
      "b": 50
    },
    {
      "x": 3,
      "y": 18,
      "z": 9,
      "r": 255,
      "g": 255,
      "b": 255
    },
    {
      "x": 3,
      "y": 19,
      "z": 8,
      "r": 255,
      "g": 255,
      "b": 255
    },
    {
      "x": 3,
      "y": 19,
      "z": 9,
      "r": 255,
      "g": 255,
      "b": 255
    },
    {
      "x": 3,
      "y": 20,
      "z": 8,
      "r": 255,
      "g": 255,
      "b": 255
    },
    {
      "x": 3,
      "y": 20,
      "z": 9,
      "r": 255,
      "g": 255,
      "b": 255
    },
    {
      "x": 3,
      "y": 21,
      "z": 8,
      "r": 255,
      "g": 255,
      "b": 255
    },
    {
      "x": 3,
      "y": 21,
      "z": 9,
      "r": 255,
      "g": 255,
      "b": 255
    },
    {
      "x": 3,
      "y": 22,
      "z": 9,
      "r": 255,
      "g": 255,
      "b": 255
    },
    {
      "x": 4,
      "y": 17,
      "z": 9,
      "r": 200,
      "g": 50,
      "b": 50
    },
    {
      "x": 4,
      "y": 17,
      "z": 10,
      "r": 200,
      "g": 50,
      "b": 50
    },
    {
      "x": 4,
      "y": 18,
      "z": 9,
      "r": 255,
      "g": 255,
      "b": 255
    },
    {
      "x": 4,
      "y": 18,
      "z": 10,
      "r": 255,
      "g": 255,
      "b": 255
    },
    {
      "x": 4,
      "y": 19,
      "z": 9,
      "r": 255,
      "g": 255,
      "b": 255
    },
    {
      "x": 4,
      "y": 19,
      "z": 10,
      "r": 255,
      "g": 255,
      "b": 255
    },
    {
      "x": 4,
      "y": 20,
      "z": 9,
      "r": 255,
      "g": 255,
      "b": 255
    },
    {
      "x": 4,
      "y": 20,
      "z": 10,
      "r": 255,
      "g": 255,
      "b": 255
    },
    {
      "x": 4,
      "y": 21,
      "z": 9,
      "r": 255,
      "g": 255,
      "b": 255
    },
    {
      "x": 4,
      "y": 21,
      "z": 10,
      "r": 255,
      "g": 255,
      "b": 255
    },
    {
      "x": 4,
      "y": 22,
      "z": 9,
      "r": 255,
      "g": 255,
      "b": 255
    },
    {
      "x": 4,
      "y": 22,
      "z": 10,
      "r": 255,
      "g": 255,
      "b": 255
    },
    {
      "x": 4,
      "y": 23,
      "z": 9,
      "r": 255,
      "g": 255,
      "b": 255
    },
    {
      "x": 4,
      "y": 24,
      "z": 9,
      "r": 200,
      "g": 50,
      "b": 50
    },
    {
      "x": 4,
      "y": 25,
      "z": 9,
      "r": 200,
      "g": 50,
      "b": 50
    },
    {
      "x": 2,
      "y": 21,
      "z": 8,
      "r": 255,
      "g": 255,
      "b": 255
    },
    {
      "x": 2,
      "y": 22,
      "z": 8,
      "r": 255,
      "g": 255,
      "b": 255
    },
    {
      "x": 2,
      "y": 23,
      "z": 8,
      "r": 255,
      "g": 255,
      "b": 255
    },
    {
      "x": 2,
      "y": 24,
      "z": 8,
      "r": 200,
      "g": 50,
      "b": 50
    },
    {
      "x": 2,
      "y": 25,
      "z": 8,
      "r": 200,
      "g": 50,
      "b": 50
    },
    {
      "x": 3,
      "y": 22,
      "z": 8,
      "r": 255,
      "g": 255,
      "b": 255
    },
    {
      "x": 3,
      "y": 23,
      "z": 8,
      "r": 255,
      "g": 255,
      "b": 255
    },
    {
      "x": 3,
      "y": 23,
      "z": 9,
      "r": 255,
      "g": 255,
      "b": 255
    },
    {
      "x": 3,
      "y": 24,
      "z": 8,
      "r": 200,
      "g": 50,
      "b": 50
    },
    {
      "x": 3,
      "y": 24,
      "z": 9,
      "r": 200,
      "g": 50,
      "b": 50
    },
    {
      "x": 3,
      "y": 25,
      "z": 8,
      "r": 200,
      "g": 50,
      "b": 50
    },
    {
      "x": 3,
      "y": 25,
      "z": 9,
      "r": 200,
      "g": 50,
      "b": 50
    },
    {
      "x": 1,
      "y": 17,
      "z": 3,
      "r": 200,
      "g": 50,
      "b": 50
    },
    {
      "x": 1,
      "y": 18,
      "z": 3,
      "r": 255,
      "g": 255,
      "b": 255
    },
    {
      "x": 1,
      "y": 19,
      "z": 3,
      "r": 255,
      "g": 255,
      "b": 255
    },
    {
      "x": 1,
      "y": 20,
      "z": 3,
      "r": 255,
      "g": 255,
      "b": 255
    },
    {
      "x": 1,
      "y": 21,
      "z": 3,
      "r": 255,
      "g": 255,
      "b": 255
    },
    {
      "x": 1,
      "y": 22,
      "z": 3,
      "r": 255,
      "g": 255,
      "b": 255
    },
    {
      "x": 2,
      "y": 17,
      "z": 3,
      "r": 200,
      "g": 50,
      "b": 50
    },
    {
      "x": 2,
      "y": 18,
      "z": 3,
      "r": 255,
      "g": 255,
      "b": 255
    },
    {
      "x": 2,
      "y": 19,
      "z": 3,
      "r": 255,
      "g": 255,
      "b": 255
    },
    {
      "x": 2,
      "y": 20,
      "z": 3,
      "r": 255,
      "g": 255,
      "b": 255
    },
    {
      "x": 2,
      "y": 21,
      "z": 3,
      "r": 255,
      "g": 255,
      "b": 255
    },
    {
      "x": 2,
      "y": 22,
      "z": 3,
      "r": 255,
      "g": 255,
      "b": 255
    },
    {
      "x": 2,
      "y": 22,
      "z": 4,
      "r": 255,
      "g": 255,
      "b": 255
    },
    {
      "x": 2,
      "y": 23,
      "z": 3,
      "r": 255,
      "g": 255,
      "b": 255
    },
    {
      "x": 2,
      "y": 23,
      "z": 4,
      "r": 255,
      "g": 255,
      "b": 255
    },
    {
      "x": 2,
      "y": 24,
      "z": 3,
      "r": 200,
      "g": 50,
      "b": 50
    },
    {
      "x": 2,
      "y": 24,
      "z": 4,
      "r": 200,
      "g": 50,
      "b": 50
    },
    {
      "x": 2,
      "y": 25,
      "z": 3,
      "r": 200,
      "g": 50,
      "b": 50
    },
    {
      "x": 2,
      "y": 25,
      "z": 4,
      "r": 200,
      "g": 50,
      "b": 50
    },
    {
      "x": 3,
      "y": 17,
      "z": 2,
      "r": 200,
      "g": 50,
      "b": 50
    },
    {
      "x": 3,
      "y": 17,
      "z": 3,
      "r": 200,
      "g": 50,
      "b": 50
    },
    {
      "x": 3,
      "y": 18,
      "z": 2,
      "r": 255,
      "g": 255,
      "b": 255
    },
    {
      "x": 3,
      "y": 18,
      "z": 3,
      "r": 255,
      "g": 255,
      "b": 255
    },
    {
      "x": 3,
      "y": 19,
      "z": 2,
      "r": 255,
      "g": 255,
      "b": 255
    },
    {
      "x": 3,
      "y": 19,
      "z": 3,
      "r": 255,
      "g": 255,
      "b": 255
    },
    {
      "x": 3,
      "y": 20,
      "z": 2,
      "r": 255,
      "g": 255,
      "b": 255
    },
    {
      "x": 3,
      "y": 20,
      "z": 3,
      "r": 255,
      "g": 255,
      "b": 255
    },
    {
      "x": 3,
      "y": 21,
      "z": 2,
      "r": 255,
      "g": 255,
      "b": 255
    },
    {
      "x": 3,
      "y": 21,
      "z": 3,
      "r": 255,
      "g": 255,
      "b": 255
    },
    {
      "x": 3,
      "y": 22,
      "z": 3,
      "r": 255,
      "g": 255,
      "b": 255
    },
    {
      "x": 3,
      "y": 23,
      "z": 3,
      "r": 255,
      "g": 255,
      "b": 255
    },
    {
      "x": 4,
      "y": 17,
      "z": 2,
      "r": 200,
      "g": 50,
      "b": 50
    },
    {
      "x": 4,
      "y": 18,
      "z": 2,
      "r": 255,
      "g": 255,
      "b": 255
    },
    {
      "x": 4,
      "y": 19,
      "z": 2,
      "r": 255,
      "g": 255,
      "b": 255
    },
    {
      "x": 4,
      "y": 20,
      "z": 2,
      "r": 255,
      "g": 255,
      "b": 255
    },
    {
      "x": 3,
      "y": 22,
      "z": 2,
      "r": 255,
      "g": 255,
      "b": 255
    },
    {
      "x": 3,
      "y": 23,
      "z": 2,
      "r": 255,
      "g": 255,
      "b": 255
    },
    {
      "x": 3,
      "y": 24,
      "z": 2,
      "r": 200,
      "g": 50,
      "b": 50
    },
    {
      "x": 3,
      "y": 24,
      "z": 3,
      "r": 200,
      "g": 50,
      "b": 50
    },
    {
      "x": 3,
      "y": 25,
      "z": 2,
      "r": 200,
      "g": 50,
      "b": 50
    },
    {
      "x": 3,
      "y": 25,
      "z": 3,
      "r": 200,
      "g": 50,
      "b": 50
    },
    {
      "x": 4,
      "y": 21,
      "z": 2,
      "r": 255,
      "g": 255,
      "b": 255
    },
    {
      "x": 4,
      "y": 22,
      "z": 2,
      "r": 255,
      "g": 255,
      "b": 255
    },
    {
      "x": 4,
      "y": 23,
      "z": 2,
      "r": 255,
      "g": 255,
      "b": 255
    },
    {
      "x": 4,
      "y": 24,
      "z": 2,
      "r": 200,
      "g": 50,
      "b": 50
    },
    {
      "x": 4,
      "y": 25,
      "z": 2,
      "r": 200,
      "g": 50,
      "b": 50
    },
    {
      "x": 5,
      "y": 3,
      "z": 0,
      "r": 200,
      "g": 50,
      "b": 50
    },
    {
      "x": 6,
      "y": 3,
      "z": 0,
      "r": 200,
      "g": 50,
      "b": 50
    },
    {
      "x": 6,
      "y": 4,
      "z": 0,
      "r": 200,
      "g": 50,
      "b": 50
    },
    {
      "x": 7,
      "y": 3,
      "z": 0,
      "r": 200,
      "g": 50,
      "b": 50
    },
    {
      "x": 7,
      "y": 3,
      "z": 1,
      "r": 200,
      "g": 50,
      "b": 50
    },
    {
      "x": 7,
      "y": 4,
      "z": 0,
      "r": 200,
      "g": 50,
      "b": 50
    },
    {
      "x": 8,
      "y": 3,
      "z": 1,
      "r": 200,
      "g": 50,
      "b": 50
    },
    {
      "x": 8,
      "y": 3,
      "z": 2,
      "r": 200,
      "g": 50,
      "b": 50
    },
    {
      "x": 8,
      "y": 4,
      "z": 1,
      "r": 200,
      "g": 50,
      "b": 50
    },
    {
      "x": 9,
      "y": 3,
      "z": 2,
      "r": 200,
      "g": 50,
      "b": 50
    },
    {
      "x": 9,
      "y": 4,
      "z": 2,
      "r": 200,
      "g": 50,
      "b": 50
    },
    {
      "x": 10,
      "y": 4,
      "z": 2,
      "r": 200,
      "g": 50,
      "b": 50
    },
    {
      "x": 10,
      "y": 4,
      "z": 3,
      "r": 200,
      "g": 50,
      "b": 50
    },
    {
      "x": 10,
      "y": 3,
      "z": 2,
      "r": 200,
      "g": 50,
      "b": 50
    },
    {
      "x": 10,
      "y": 3,
      "z": 3,
      "r": 200,
      "g": 50,
      "b": 50
    },
    {
      "x": 10,
      "y": 3,
      "z": 4,
      "r": 200,
      "g": 50,
      "b": 50
    },
    {
      "x": 10,
      "y": 3,
      "z": 5,
      "r": 200,
      "g": 50,
      "b": 50
    },
    {
      "x": 10,
      "y": 3,
      "z": 6,
      "r": 200,
      "g": 50,
      "b": 50
    },
    {
      "x": 10,
      "y": 3,
      "z": 7,
      "r": 200,
      "g": 50,
      "b": 50
    },
    {
      "x": 10,
      "y": 4,
      "z": 4,
      "r": 200,
      "g": 50,
      "b": 50
    },
    {
      "x": 10,
      "y": 4,
      "z": 5,
      "r": 200,
      "g": 50,
      "b": 50
    },
    {
      "x": 10,
      "y": 4,
      "z": 6,
      "r": 200,
      "g": 50,
      "b": 50
    },
    {
      "x": 10,
      "y": 4,
      "z": 7,
      "r": 200,
      "g": 50,
      "b": 50
    },
    {
      "x": 10,
      "y": 4,
      "z": 8,
      "r": 200,
      "g": 50,
      "b": 50
    },
    {
      "x": 10,
      "y": 4,
      "z": 9,
      "r": 200,
      "g": 50,
      "b": 50
    },
    {
      "x": 10,
      "y": 3,
      "z": 8,
      "r": 200,
      "g": 50,
      "b": 50
    },
    {
      "x": 10,
      "y": 3,
      "z": 9,
      "r": 200,
      "g": 50,
      "b": 50
    },
    {
      "x": 5,
      "y": 4,
      "z": 12,
      "r": 200,
      "g": 50,
      "b": 50
    },
    {
      "x": 6,
      "y": 3,
      "z": 11,
      "r": 200,
      "g": 50,
      "b": 50
    },
    {
      "x": 6,
      "y": 4,
      "z": 11,
      "r": 200,
      "g": 50,
      "b": 50
    },
    {
      "x": 7,
      "y": 3,
      "z": 10,
      "r": 200,
      "g": 50,
      "b": 50
    },
    {
      "x": 7,
      "y": 3,
      "z": 11,
      "r": 200,
      "g": 50,
      "b": 50
    },
    {
      "x": 7,
      "y": 4,
      "z": 11,
      "r": 200,
      "g": 50,
      "b": 50
    },
    {
      "x": 8,
      "y": 3,
      "z": 10,
      "r": 200,
      "g": 50,
      "b": 50
    },
    {
      "x": 8,
      "y": 4,
      "z": 10,
      "r": 200,
      "g": 50,
      "b": 50
    },
    {
      "x": 9,
      "y": 3,
      "z": 9,
      "r": 200,
      "g": 50,
      "b": 50
    },
    {
      "x": 9,
      "y": 3,
      "z": 10,
      "r": 200,
      "g": 50,
      "b": 50
    },
    {
      "x": 9,
      "y": 4,
      "z": 10,
      "r": 200,
      "g": 50,
      "b": 50
    },
    {
      "x": 5,
      "y": 3,
      "z": 11,
      "r": 200,
      "g": 50,
      "b": 50
    },
    {
      "x": 5,
      "y": 3,
      "z": 12,
      "r": 200,
      "g": 50,
      "b": 50
    },
    {
      "x": 0,
      "y": 4,
      "z": 9,
      "r": 200,
      "g": 50,
      "b": 50
    },
    {
      "x": 1,
      "y": 3,
      "z": 9,
      "r": 200,
      "g": 50,
      "b": 50
    },
    {
      "x": 1,
      "y": 3,
      "z": 10,
      "r": 200,
      "g": 50,
      "b": 50
    },
    {
      "x": 1,
      "y": 4,
      "z": 10,
      "r": 200,
      "g": 50,
      "b": 50
    },
    {
      "x": 2,
      "y": 3,
      "z": 10,
      "r": 200,
      "g": 50,
      "b": 50
    },
    {
      "x": 2,
      "y": 4,
      "z": 10,
      "r": 200,
      "g": 50,
      "b": 50
    },
    {
      "x": 3,
      "y": 3,
      "z": 10,
      "r": 200,
      "g": 50,
      "b": 50
    },
    {
      "x": 3,
      "y": 3,
      "z": 11,
      "r": 200,
      "g": 50,
      "b": 50
    },
    {
      "x": 3,
      "y": 4,
      "z": 11,
      "r": 200,
      "g": 50,
      "b": 50
    },
    {
      "x": 4,
      "y": 3,
      "z": 11,
      "r": 200,
      "g": 50,
      "b": 50
    },
    {
      "x": 4,
      "y": 3,
      "z": 12,
      "r": 200,
      "g": 50,
      "b": 50
    },
    {
      "x": 4,
      "y": 4,
      "z": 12,
      "r": 200,
      "g": 50,
      "b": 50
    },
    {
      "x": 0,
      "y": 3,
      "z": 9,
      "r": 200,
      "g": 50,
      "b": 50
    },
    {
      "x": 0,
      "y": 3,
      "z": 4,
      "r": 200,
      "g": 50,
      "b": 50
    },
    {
      "x": 0,
      "y": 3,
      "z": 5,
      "r": 200,
      "g": 50,
      "b": 50
    },
    {
      "x": 0,
      "y": 3,
      "z": 6,
      "r": 200,
      "g": 50,
      "b": 50
    },
    {
      "x": 0,
      "y": 3,
      "z": 7,
      "r": 200,
      "g": 50,
      "b": 50
    },
    {
      "x": 0,
      "y": 3,
      "z": 8,
      "r": 200,
      "g": 50,
      "b": 50
    },
    {
      "x": 0,
      "y": 3,
      "z": 3,
      "r": 200,
      "g": 50,
      "b": 50
    },
    {
      "x": 0,
      "y": 3,
      "z": 2,
      "r": 200,
      "g": 50,
      "b": 50
    },
    {
      "x": 0,
      "y": 4,
      "z": 2,
      "r": 200,
      "g": 50,
      "b": 50
    },
    {
      "x": 1,
      "y": 3,
      "z": 1,
      "r": 200,
      "g": 50,
      "b": 50
    },
    {
      "x": 1,
      "y": 3,
      "z": 2,
      "r": 200,
      "g": 50,
      "b": 50
    },
    {
      "x": 1,
      "y": 4,
      "z": 1,
      "r": 200,
      "g": 50,
      "b": 50
    },
    {
      "x": 2,
      "y": 3,
      "z": 1,
      "r": 200,
      "g": 50,
      "b": 50
    },
    {
      "x": 2,
      "y": 4,
      "z": 1,
      "r": 200,
      "g": 50,
      "b": 50
    },
    {
      "x": 3,
      "y": 3,
      "z": 0,
      "r": 200,
      "g": 50,
      "b": 50
    },
    {
      "x": 3,
      "y": 3,
      "z": 1,
      "r": 200,
      "g": 50,
      "b": 50
    },
    {
      "x": 3,
      "y": 4,
      "z": 0,
      "r": 200,
      "g": 50,
      "b": 50
    },
    {
      "x": 4,
      "y": 3,
      "z": 0,
      "r": 200,
      "g": 50,
      "b": 50
    },
    {
      "x": 4,
      "y": 4,
      "z": 0,
      "r": 200,
      "g": 50,
      "b": 50
    },
    {
      "x": 10,
      "y": 0,
      "z": 7,
      "r": 200,
      "g": 50,
      "b": 50
    },
    {
      "x": 10,
      "y": 0,
      "z": 8,
      "r": 200,
      "g": 50,
      "b": 50
    },
    {
      "x": 10,
      "y": 0,
      "z": 9,
      "r": 200,
      "g": 50,
      "b": 50
    },
    {
      "x": 10,
      "y": 1,
      "z": 5,
      "r": 200,
      "g": 50,
      "b": 50
    },
    {
      "x": 10,
      "y": 1,
      "z": 6,
      "r": 200,
      "g": 50,
      "b": 50
    },
    {
      "x": 10,
      "y": 1,
      "z": 7,
      "r": 200,
      "g": 50,
      "b": 50
    },
    {
      "x": 10,
      "y": 1,
      "z": 8,
      "r": 200,
      "g": 50,
      "b": 50
    },
    {
      "x": 10,
      "y": 1,
      "z": 9,
      "r": 200,
      "g": 50,
      "b": 50
    },
    {
      "x": 10,
      "y": 2,
      "z": 3,
      "r": 200,
      "g": 50,
      "b": 50
    },
    {
      "x": 10,
      "y": 2,
      "z": 4,
      "r": 200,
      "g": 50,
      "b": 50
    },
    {
      "x": 10,
      "y": 2,
      "z": 5,
      "r": 200,
      "g": 50,
      "b": 50
    },
    {
      "x": 10,
      "y": 2,
      "z": 6,
      "r": 200,
      "g": 50,
      "b": 50
    },
    {
      "x": 10,
      "y": 2,
      "z": 7,
      "r": 200,
      "g": 50,
      "b": 50
    },
    {
      "x": 10,
      "y": 2,
      "z": 8,
      "r": 200,
      "g": 50,
      "b": 50
    },
    {
      "x": 10,
      "y": 2,
      "z": 9,
      "r": 200,
      "g": 50,
      "b": 50
    },
    {
      "x": 10,
      "y": 0,
      "z": 3,
      "r": 200,
      "g": 50,
      "b": 50
    },
    {
      "x": 10,
      "y": 0,
      "z": 4,
      "r": 200,
      "g": 50,
      "b": 50
    },
    {
      "x": 10,
      "y": 0,
      "z": 5,
      "r": 200,
      "g": 50,
      "b": 50
    },
    {
      "x": 10,
      "y": 0,
      "z": 6,
      "r": 200,
      "g": 50,
      "b": 50
    },
    {
      "x": 10,
      "y": 1,
      "z": 3,
      "r": 200,
      "g": 50,
      "b": 50
    },
    {
      "x": 10,
      "y": 1,
      "z": 4,
      "r": 200,
      "g": 50,
      "b": 50
    },
    {
      "x": 0,
      "y": 9,
      "z": 5,
      "r": 255,
      "g": 255,
      "b": 255
    },
    {
      "x": 0,
      "y": 9,
      "z": 6,
      "r": 255,
      "g": 255,
      "b": 255
    },
    {
      "x": 0,
      "y": 9,
      "z": 7,
      "r": 255,
      "g": 255,
      "b": 255
    },
    {
      "x": 0,
      "y": 9,
      "z": 8,
      "r": 255,
      "g": 255,
      "b": 255
    },
    {
      "x": 0,
      "y": 9,
      "z": 3,
      "r": 255,
      "g": 255,
      "b": 255
    },
    {
      "x": 0,
      "y": 9,
      "z": 4,
      "r": 255,
      "g": 255,
      "b": 255
    },
    {
      "x": 1,
      "y": 9,
      "z": 2,
      "r": 255,
      "g": 255,
      "b": 255
    },
    {
      "x": 2,
      "y": 9,
      "z": 1,
      "r": 255,
      "g": 255,
      "b": 255
    },
    {
      "x": 3,
      "y": 9,
      "z": 1,
      "r": 255,
      "g": 255,
      "b": 255
    },
    {
      "x": 4,
      "y": 9,
      "z": 0,
      "r": 255,
      "g": 255,
      "b": 255
    },
    {
      "x": 5,
      "y": 9,
      "z": 0,
      "r": 255,
      "g": 255,
      "b": 255
    },
    {
      "x": 7,
      "y": 9,
      "z": 10,
      "r": 255,
      "g": 255,
      "b": 255
    },
    {
      "x": 9,
      "y": 9,
      "z": 9,
      "r": 255,
      "g": 255,
      "b": 255
    },
    {
      "x": 10,
      "y": 9,
      "z": 8,
      "r": 255,
      "g": 255,
      "b": 255
    },
    {
      "x": 5,
      "y": 9,
      "z": 11,
      "r": 255,
      "g": 255,
      "b": 255
    },
    {
      "x": 6,
      "y": 9,
      "z": 11,
      "r": 255,
      "g": 255,
      "b": 255
    },
    {
      "x": 8,
      "y": 9,
      "z": 10,
      "r": 255,
      "g": 255,
      "b": 255
    },
    {
      "x": 7,
      "y": 9,
      "z": 1,
      "r": 255,
      "g": 255,
      "b": 255
    },
    {
      "x": 9,
      "y": 9,
      "z": 2,
      "r": 255,
      "g": 255,
      "b": 255
    },
    {
      "x": 10,
      "y": 9,
      "z": 3,
      "r": 255,
      "g": 255,
      "b": 255
    },
    {
      "x": 1,
      "y": 9,
      "z": 9,
      "r": 255,
      "g": 255,
      "b": 255
    },
    {
      "x": 4,
      "y": 9,
      "z": 11,
      "r": 255,
      "g": 255,
      "b": 255
    },
    {
      "x": 0,
      "y": 9,
      "z": 9,
      "r": 255,
      "g": 255,
      "b": 255
    },
    {
      "x": 2,
      "y": 9,
      "z": 10,
      "r": 255,
      "g": 255,
      "b": 255
    },
    {
      "x": 10,
      "y": 9,
      "z": 4,
      "r": 255,
      "g": 255,
      "b": 255
    },
    {
      "x": 10,
      "y": 9,
      "z": 5,
      "r": 255,
      "g": 255,
      "b": 255
    },
    {
      "x": 10,
      "y": 9,
      "z": 6,
      "r": 255,
      "g": 255,
      "b": 255
    },
    {
      "x": 10,
      "y": 9,
      "z": 7,
      "r": 255,
      "g": 255,
      "b": 255
    },
    {
      "x": 4,
      "y": 9,
      "z": 9,
      "r": 255,
      "g": 255,
      "b": 255
    },
    {
      "x": 5,
      "y": 0,
      "z": 0,
      "r": 200,
      "g": 50,
      "b": 50
    },
    {
      "x": 5,
      "y": 0,
      "z": 1,
      "r": 200,
      "g": 50,
      "b": 50
    },
    {
      "x": 6,
      "y": 0,
      "z": 0,
      "r": 200,
      "g": 50,
      "b": 50
    },
    {
      "x": 6,
      "y": 0,
      "z": 1,
      "r": 200,
      "g": 50,
      "b": 50
    },
    {
      "x": 6,
      "y": 0,
      "z": 2,
      "r": 200,
      "g": 50,
      "b": 50
    },
    {
      "x": 7,
      "y": 0,
      "z": 0,
      "r": 200,
      "g": 50,
      "b": 50
    },
    {
      "x": 7,
      "y": 0,
      "z": 1,
      "r": 200,
      "g": 50,
      "b": 50
    },
    {
      "x": 7,
      "y": 0,
      "z": 2,
      "r": 200,
      "g": 50,
      "b": 50
    },
    {
      "x": 7,
      "y": 0,
      "z": 3,
      "r": 200,
      "g": 50,
      "b": 50
    },
    {
      "x": 7,
      "y": 0,
      "z": 4,
      "r": 200,
      "g": 50,
      "b": 50
    },
    {
      "x": 8,
      "y": 0,
      "z": 1,
      "r": 200,
      "g": 50,
      "b": 50
    },
    {
      "x": 8,
      "y": 0,
      "z": 2,
      "r": 200,
      "g": 50,
      "b": 50
    },
    {
      "x": 8,
      "y": 0,
      "z": 3,
      "r": 200,
      "g": 50,
      "b": 50
    },
    {
      "x": 8,
      "y": 0,
      "z": 4,
      "r": 200,
      "g": 50,
      "b": 50
    },
    {
      "x": 8,
      "y": 0,
      "z": 5,
      "r": 200,
      "g": 50,
      "b": 50
    },
    {
      "x": 8,
      "y": 0,
      "z": 6,
      "r": 200,
      "g": 50,
      "b": 50
    },
    {
      "x": 9,
      "y": 0,
      "z": 2,
      "r": 200,
      "g": 50,
      "b": 50
    },
    {
      "x": 9,
      "y": 0,
      "z": 3,
      "r": 200,
      "g": 50,
      "b": 50
    },
    {
      "x": 9,
      "y": 0,
      "z": 4,
      "r": 200,
      "g": 50,
      "b": 50
    },
    {
      "x": 9,
      "y": 0,
      "z": 5,
      "r": 200,
      "g": 50,
      "b": 50
    },
    {
      "x": 9,
      "y": 0,
      "z": 6,
      "r": 200,
      "g": 50,
      "b": 50
    },
    {
      "x": 9,
      "y": 0,
      "z": 7,
      "r": 200,
      "g": 50,
      "b": 50
    },
    {
      "x": 9,
      "y": 0,
      "z": 8,
      "r": 200,
      "g": 50,
      "b": 50
    },
    {
      "x": 10,
      "y": 0,
      "z": 2,
      "r": 200,
      "g": 50,
      "b": 50
    },
    {
      "x": 5,
      "y": 0,
      "z": 2,
      "r": 200,
      "g": 50,
      "b": 50
    },
    {
      "x": 5,
      "y": 0,
      "z": 3,
      "r": 200,
      "g": 50,
      "b": 50
    },
    {
      "x": 5,
      "y": 0,
      "z": 4,
      "r": 200,
      "g": 50,
      "b": 50
    },
    {
      "x": 5,
      "y": 0,
      "z": 5,
      "r": 200,
      "g": 50,
      "b": 50
    },
    {
      "x": 5,
      "y": 0,
      "z": 6,
      "r": 200,
      "g": 50,
      "b": 50
    },
    {
      "x": 5,
      "y": 0,
      "z": 7,
      "r": 200,
      "g": 50,
      "b": 50
    },
    {
      "x": 5,
      "y": 0,
      "z": 8,
      "r": 200,
      "g": 50,
      "b": 50
    },
    {
      "x": 5,
      "y": 0,
      "z": 9,
      "r": 200,
      "g": 50,
      "b": 50
    },
    {
      "x": 5,
      "y": 0,
      "z": 10,
      "r": 200,
      "g": 50,
      "b": 50
    },
    {
      "x": 5,
      "y": 0,
      "z": 11,
      "r": 200,
      "g": 50,
      "b": 50
    },
    {
      "x": 5,
      "y": 0,
      "z": 12,
      "r": 200,
      "g": 50,
      "b": 50
    },
    {
      "x": 6,
      "y": 0,
      "z": 3,
      "r": 200,
      "g": 50,
      "b": 50
    },
    {
      "x": 6,
      "y": 0,
      "z": 4,
      "r": 200,
      "g": 50,
      "b": 50
    },
    {
      "x": 6,
      "y": 0,
      "z": 5,
      "r": 200,
      "g": 50,
      "b": 50
    },
    {
      "x": 6,
      "y": 0,
      "z": 6,
      "r": 200,
      "g": 50,
      "b": 50
    },
    {
      "x": 6,
      "y": 0,
      "z": 7,
      "r": 200,
      "g": 50,
      "b": 50
    },
    {
      "x": 6,
      "y": 0,
      "z": 8,
      "r": 200,
      "g": 50,
      "b": 50
    },
    {
      "x": 6,
      "y": 0,
      "z": 9,
      "r": 200,
      "g": 50,
      "b": 50
    },
    {
      "x": 6,
      "y": 0,
      "z": 10,
      "r": 200,
      "g": 50,
      "b": 50
    },
    {
      "x": 6,
      "y": 0,
      "z": 11,
      "r": 200,
      "g": 50,
      "b": 50
    },
    {
      "x": 7,
      "y": 0,
      "z": 5,
      "r": 200,
      "g": 50,
      "b": 50
    },
    {
      "x": 7,
      "y": 0,
      "z": 6,
      "r": 200,
      "g": 50,
      "b": 50
    },
    {
      "x": 7,
      "y": 0,
      "z": 7,
      "r": 200,
      "g": 50,
      "b": 50
    },
    {
      "x": 7,
      "y": 0,
      "z": 8,
      "r": 200,
      "g": 50,
      "b": 50
    },
    {
      "x": 7,
      "y": 0,
      "z": 9,
      "r": 200,
      "g": 50,
      "b": 50
    },
    {
      "x": 7,
      "y": 0,
      "z": 10,
      "r": 200,
      "g": 50,
      "b": 50
    },
    {
      "x": 7,
      "y": 0,
      "z": 11,
      "r": 200,
      "g": 50,
      "b": 50
    },
    {
      "x": 8,
      "y": 0,
      "z": 7,
      "r": 200,
      "g": 50,
      "b": 50
    },
    {
      "x": 8,
      "y": 0,
      "z": 8,
      "r": 200,
      "g": 50,
      "b": 50
    },
    {
      "x": 8,
      "y": 0,
      "z": 9,
      "r": 200,
      "g": 50,
      "b": 50
    },
    {
      "x": 8,
      "y": 0,
      "z": 10,
      "r": 200,
      "g": 50,
      "b": 50
    },
    {
      "x": 9,
      "y": 0,
      "z": 9,
      "r": 200,
      "g": 50,
      "b": 50
    },
    {
      "x": 9,
      "y": 0,
      "z": 10,
      "r": 200,
      "g": 50,
      "b": 50
    },
    {
      "x": 0,
      "y": 0,
      "z": 7,
      "r": 200,
      "g": 50,
      "b": 50
    },
    {
      "x": 0,
      "y": 0,
      "z": 8,
      "r": 200,
      "g": 50,
      "b": 50
    },
    {
      "x": 0,
      "y": 0,
      "z": 9,
      "r": 200,
      "g": 50,
      "b": 50
    },
    {
      "x": 1,
      "y": 0,
      "z": 5,
      "r": 200,
      "g": 50,
      "b": 50
    },
    {
      "x": 1,
      "y": 0,
      "z": 6,
      "r": 200,
      "g": 50,
      "b": 50
    },
    {
      "x": 1,
      "y": 0,
      "z": 7,
      "r": 200,
      "g": 50,
      "b": 50
    },
    {
      "x": 1,
      "y": 0,
      "z": 8,
      "r": 200,
      "g": 50,
      "b": 50
    },
    {
      "x": 1,
      "y": 0,
      "z": 9,
      "r": 200,
      "g": 50,
      "b": 50
    },
    {
      "x": 1,
      "y": 0,
      "z": 10,
      "r": 200,
      "g": 50,
      "b": 50
    },
    {
      "x": 2,
      "y": 0,
      "z": 4,
      "r": 200,
      "g": 50,
      "b": 50
    },
    {
      "x": 2,
      "y": 0,
      "z": 5,
      "r": 200,
      "g": 50,
      "b": 50
    },
    {
      "x": 2,
      "y": 0,
      "z": 6,
      "r": 200,
      "g": 50,
      "b": 50
    },
    {
      "x": 2,
      "y": 0,
      "z": 7,
      "r": 200,
      "g": 50,
      "b": 50
    },
    {
      "x": 2,
      "y": 0,
      "z": 8,
      "r": 200,
      "g": 50,
      "b": 50
    },
    {
      "x": 2,
      "y": 0,
      "z": 9,
      "r": 200,
      "g": 50,
      "b": 50
    },
    {
      "x": 2,
      "y": 0,
      "z": 10,
      "r": 200,
      "g": 50,
      "b": 50
    },
    {
      "x": 3,
      "y": 0,
      "z": 2,
      "r": 200,
      "g": 50,
      "b": 50
    },
    {
      "x": 3,
      "y": 0,
      "z": 3,
      "r": 200,
      "g": 50,
      "b": 50
    },
    {
      "x": 3,
      "y": 0,
      "z": 4,
      "r": 200,
      "g": 50,
      "b": 50
    },
    {
      "x": 3,
      "y": 0,
      "z": 5,
      "r": 200,
      "g": 50,
      "b": 50
    },
    {
      "x": 3,
      "y": 0,
      "z": 6,
      "r": 200,
      "g": 50,
      "b": 50
    },
    {
      "x": 3,
      "y": 0,
      "z": 7,
      "r": 200,
      "g": 50,
      "b": 50
    },
    {
      "x": 3,
      "y": 0,
      "z": 8,
      "r": 200,
      "g": 50,
      "b": 50
    },
    {
      "x": 3,
      "y": 0,
      "z": 9,
      "r": 200,
      "g": 50,
      "b": 50
    },
    {
      "x": 3,
      "y": 0,
      "z": 10,
      "r": 200,
      "g": 50,
      "b": 50
    },
    {
      "x": 3,
      "y": 0,
      "z": 11,
      "r": 200,
      "g": 50,
      "b": 50
    },
    {
      "x": 4,
      "y": 0,
      "z": 0,
      "r": 200,
      "g": 50,
      "b": 50
    },
    {
      "x": 4,
      "y": 0,
      "z": 1,
      "r": 200,
      "g": 50,
      "b": 50
    },
    {
      "x": 4,
      "y": 0,
      "z": 2,
      "r": 200,
      "g": 50,
      "b": 50
    },
    {
      "x": 4,
      "y": 0,
      "z": 3,
      "r": 200,
      "g": 50,
      "b": 50
    },
    {
      "x": 4,
      "y": 0,
      "z": 4,
      "r": 200,
      "g": 50,
      "b": 50
    },
    {
      "x": 4,
      "y": 0,
      "z": 5,
      "r": 200,
      "g": 50,
      "b": 50
    },
    {
      "x": 4,
      "y": 0,
      "z": 6,
      "r": 200,
      "g": 50,
      "b": 50
    },
    {
      "x": 4,
      "y": 0,
      "z": 7,
      "r": 200,
      "g": 50,
      "b": 50
    },
    {
      "x": 4,
      "y": 0,
      "z": 8,
      "r": 200,
      "g": 50,
      "b": 50
    },
    {
      "x": 4,
      "y": 0,
      "z": 9,
      "r": 200,
      "g": 50,
      "b": 50
    },
    {
      "x": 4,
      "y": 0,
      "z": 10,
      "r": 200,
      "g": 50,
      "b": 50
    },
    {
      "x": 4,
      "y": 0,
      "z": 11,
      "r": 200,
      "g": 50,
      "b": 50
    },
    {
      "x": 4,
      "y": 0,
      "z": 12,
      "r": 200,
      "g": 50,
      "b": 50
    },
    {
      "x": 0,
      "y": 0,
      "z": 2,
      "r": 200,
      "g": 50,
      "b": 50
    },
    {
      "x": 0,
      "y": 0,
      "z": 3,
      "r": 200,
      "g": 50,
      "b": 50
    },
    {
      "x": 0,
      "y": 0,
      "z": 4,
      "r": 200,
      "g": 50,
      "b": 50
    },
    {
      "x": 0,
      "y": 0,
      "z": 5,
      "r": 200,
      "g": 50,
      "b": 50
    },
    {
      "x": 0,
      "y": 0,
      "z": 6,
      "r": 200,
      "g": 50,
      "b": 50
    },
    {
      "x": 1,
      "y": 0,
      "z": 1,
      "r": 200,
      "g": 50,
      "b": 50
    },
    {
      "x": 1,
      "y": 0,
      "z": 2,
      "r": 200,
      "g": 50,
      "b": 50
    },
    {
      "x": 1,
      "y": 0,
      "z": 3,
      "r": 200,
      "g": 50,
      "b": 50
    },
    {
      "x": 1,
      "y": 0,
      "z": 4,
      "r": 200,
      "g": 50,
      "b": 50
    },
    {
      "x": 2,
      "y": 0,
      "z": 1,
      "r": 200,
      "g": 50,
      "b": 50
    },
    {
      "x": 2,
      "y": 0,
      "z": 2,
      "r": 200,
      "g": 50,
      "b": 50
    },
    {
      "x": 2,
      "y": 0,
      "z": 3,
      "r": 200,
      "g": 50,
      "b": 50
    },
    {
      "x": 3,
      "y": 0,
      "z": 0,
      "r": 200,
      "g": 50,
      "b": 50
    },
    {
      "x": 3,
      "y": 0,
      "z": 1,
      "r": 200,
      "g": 50,
      "b": 50
    },
    {
      "x": 0,
      "y": 1,
      "z": 3,
      "r": 200,
      "g": 50,
      "b": 50
    },
    {
      "x": 0,
      "y": 1,
      "z": 4,
      "r": 200,
      "g": 50,
      "b": 50
    },
    {
      "x": 0,
      "y": 1,
      "z": 5,
      "r": 200,
      "g": 50,
      "b": 50
    },
    {
      "x": 0,
      "y": 1,
      "z": 6,
      "r": 200,
      "g": 50,
      "b": 50
    },
    {
      "x": 0,
      "y": 1,
      "z": 7,
      "r": 200,
      "g": 50,
      "b": 50
    },
    {
      "x": 0,
      "y": 2,
      "z": 3,
      "r": 200,
      "g": 50,
      "b": 50
    },
    {
      "x": 0,
      "y": 2,
      "z": 4,
      "r": 200,
      "g": 50,
      "b": 50
    },
    {
      "x": 0,
      "y": 2,
      "z": 5,
      "r": 200,
      "g": 50,
      "b": 50
    },
    {
      "x": 0,
      "y": 2,
      "z": 6,
      "r": 200,
      "g": 50,
      "b": 50
    },
    {
      "x": 0,
      "y": 2,
      "z": 7,
      "r": 200,
      "g": 50,
      "b": 50
    },
    {
      "x": 0,
      "y": 2,
      "z": 8,
      "r": 200,
      "g": 50,
      "b": 50
    },
    {
      "x": 0,
      "y": 2,
      "z": 9,
      "r": 200,
      "g": 50,
      "b": 50
    },
    {
      "x": 0,
      "y": 1,
      "z": 8,
      "r": 200,
      "g": 50,
      "b": 50
    },
    {
      "x": 0,
      "y": 1,
      "z": 9,
      "r": 200,
      "g": 50,
      "b": 50
    },
    {
      "x": 5,
      "y": 2,
      "z": 0,
      "r": 200,
      "g": 50,
      "b": 50
    },
    {
      "x": 6,
      "y": 2,
      "z": 0,
      "r": 200,
      "g": 50,
      "b": 50
    },
    {
      "x": 7,
      "y": 1,
      "z": 1,
      "r": 200,
      "g": 50,
      "b": 50
    },
    {
      "x": 7,
      "y": 2,
      "z": 0,
      "r": 200,
      "g": 50,
      "b": 50
    },
    {
      "x": 7,
      "y": 2,
      "z": 1,
      "r": 200,
      "g": 50,
      "b": 50
    },
    {
      "x": 8,
      "y": 1,
      "z": 1,
      "r": 200,
      "g": 50,
      "b": 50
    },
    {
      "x": 8,
      "y": 1,
      "z": 2,
      "r": 200,
      "g": 50,
      "b": 50
    },
    {
      "x": 8,
      "y": 2,
      "z": 1,
      "r": 200,
      "g": 50,
      "b": 50
    },
    {
      "x": 8,
      "y": 2,
      "z": 2,
      "r": 200,
      "g": 50,
      "b": 50
    },
    {
      "x": 9,
      "y": 1,
      "z": 2,
      "r": 200,
      "g": 50,
      "b": 50
    },
    {
      "x": 9,
      "y": 2,
      "z": 2,
      "r": 200,
      "g": 50,
      "b": 50
    },
    {
      "x": 10,
      "y": 1,
      "z": 2,
      "r": 200,
      "g": 50,
      "b": 50
    },
    {
      "x": 10,
      "y": 2,
      "z": 2,
      "r": 200,
      "g": 50,
      "b": 50
    },
    {
      "x": 5,
      "y": 1,
      "z": 0,
      "r": 200,
      "g": 50,
      "b": 50
    },
    {
      "x": 6,
      "y": 1,
      "z": 0,
      "r": 200,
      "g": 50,
      "b": 50
    },
    {
      "x": 7,
      "y": 1,
      "z": 0,
      "r": 200,
      "g": 50,
      "b": 50
    },
    {
      "x": 5,
      "y": 1,
      "z": 11,
      "r": 200,
      "g": 50,
      "b": 50
    },
    {
      "x": 5,
      "y": 1,
      "z": 12,
      "r": 200,
      "g": 50,
      "b": 50
    },
    {
      "x": 5,
      "y": 2,
      "z": 11,
      "r": 200,
      "g": 50,
      "b": 50
    },
    {
      "x": 5,
      "y": 2,
      "z": 12,
      "r": 200,
      "g": 50,
      "b": 50
    },
    {
      "x": 6,
      "y": 1,
      "z": 11,
      "r": 200,
      "g": 50,
      "b": 50
    },
    {
      "x": 6,
      "y": 2,
      "z": 11,
      "r": 200,
      "g": 50,
      "b": 50
    },
    {
      "x": 7,
      "y": 1,
      "z": 10,
      "r": 200,
      "g": 50,
      "b": 50
    },
    {
      "x": 7,
      "y": 1,
      "z": 11,
      "r": 200,
      "g": 50,
      "b": 50
    },
    {
      "x": 7,
      "y": 2,
      "z": 10,
      "r": 200,
      "g": 50,
      "b": 50
    },
    {
      "x": 7,
      "y": 2,
      "z": 11,
      "r": 200,
      "g": 50,
      "b": 50
    },
    {
      "x": 8,
      "y": 1,
      "z": 10,
      "r": 200,
      "g": 50,
      "b": 50
    },
    {
      "x": 8,
      "y": 2,
      "z": 10,
      "r": 200,
      "g": 50,
      "b": 50
    },
    {
      "x": 9,
      "y": 2,
      "z": 9,
      "r": 200,
      "g": 50,
      "b": 50
    },
    {
      "x": 9,
      "y": 2,
      "z": 10,
      "r": 200,
      "g": 50,
      "b": 50
    },
    {
      "x": 9,
      "y": 1,
      "z": 9,
      "r": 200,
      "g": 50,
      "b": 50
    },
    {
      "x": 9,
      "y": 1,
      "z": 10,
      "r": 200,
      "g": 50,
      "b": 50
    },
    {
      "x": 0,
      "y": 2,
      "z": 2,
      "r": 200,
      "g": 50,
      "b": 50
    },
    {
      "x": 1,
      "y": 1,
      "z": 1,
      "r": 200,
      "g": 50,
      "b": 50
    },
    {
      "x": 1,
      "y": 1,
      "z": 2,
      "r": 200,
      "g": 50,
      "b": 50
    },
    {
      "x": 1,
      "y": 2,
      "z": 1,
      "r": 200,
      "g": 50,
      "b": 50
    },
    {
      "x": 1,
      "y": 2,
      "z": 2,
      "r": 200,
      "g": 50,
      "b": 50
    },
    {
      "x": 2,
      "y": 1,
      "z": 1,
      "r": 200,
      "g": 50,
      "b": 50
    },
    {
      "x": 2,
      "y": 2,
      "z": 1,
      "r": 200,
      "g": 50,
      "b": 50
    },
    {
      "x": 3,
      "y": 1,
      "z": 0,
      "r": 200,
      "g": 50,
      "b": 50
    },
    {
      "x": 3,
      "y": 1,
      "z": 1,
      "r": 200,
      "g": 50,
      "b": 50
    },
    {
      "x": 3,
      "y": 2,
      "z": 0,
      "r": 200,
      "g": 50,
      "b": 50
    },
    {
      "x": 3,
      "y": 2,
      "z": 1,
      "r": 200,
      "g": 50,
      "b": 50
    },
    {
      "x": 4,
      "y": 1,
      "z": 0,
      "r": 200,
      "g": 50,
      "b": 50
    },
    {
      "x": 4,
      "y": 2,
      "z": 0,
      "r": 200,
      "g": 50,
      "b": 50
    },
    {
      "x": 0,
      "y": 1,
      "z": 2,
      "r": 200,
      "g": 50,
      "b": 50
    },
    {
      "x": 1,
      "y": 1,
      "z": 9,
      "r": 200,
      "g": 50,
      "b": 50
    },
    {
      "x": 1,
      "y": 1,
      "z": 10,
      "r": 200,
      "g": 50,
      "b": 50
    },
    {
      "x": 1,
      "y": 2,
      "z": 9,
      "r": 200,
      "g": 50,
      "b": 50
    },
    {
      "x": 1,
      "y": 2,
      "z": 10,
      "r": 200,
      "g": 50,
      "b": 50
    },
    {
      "x": 2,
      "y": 1,
      "z": 10,
      "r": 200,
      "g": 50,
      "b": 50
    },
    {
      "x": 2,
      "y": 2,
      "z": 10,
      "r": 200,
      "g": 50,
      "b": 50
    },
    {
      "x": 3,
      "y": 1,
      "z": 10,
      "r": 200,
      "g": 50,
      "b": 50
    },
    {
      "x": 3,
      "y": 1,
      "z": 11,
      "r": 200,
      "g": 50,
      "b": 50
    },
    {
      "x": 3,
      "y": 2,
      "z": 10,
      "r": 200,
      "g": 50,
      "b": 50
    },
    {
      "x": 3,
      "y": 2,
      "z": 11,
      "r": 200,
      "g": 50,
      "b": 50
    },
    {
      "x": 4,
      "y": 2,
      "z": 11,
      "r": 200,
      "g": 50,
      "b": 50
    },
    {
      "x": 4,
      "y": 2,
      "z": 12,
      "r": 200,
      "g": 50,
      "b": 50
    },
    {
      "x": 4,
      "y": 1,
      "z": 11,
      "r": 200,
      "g": 50,
      "b": 50
    },
    {
      "x": 4,
      "y": 1,
      "z": 12,
      "r": 200,
      "g": 50,
      "b": 50
    },
    {
      "x": 1,
      "y": 26,
      "z": 4,
      "r": 200,
      "g": 50,
      "b": 50
    },
    {
      "x": 1,
      "y": 27,
      "z": 4,
      "r": 200,
      "g": 50,
      "b": 50
    },
    {
      "x": 2,
      "y": 26,
      "z": 3,
      "r": 200,
      "g": 50,
      "b": 50
    },
    {
      "x": 2,
      "y": 26,
      "z": 4,
      "r": 200,
      "g": 50,
      "b": 50
    },
    {
      "x": 2,
      "y": 27,
      "z": 3,
      "r": 200,
      "g": 50,
      "b": 50
    },
    {
      "x": 2,
      "y": 27,
      "z": 4,
      "r": 200,
      "g": 50,
      "b": 50
    },
    {
      "x": 2,
      "y": 28,
      "z": 3,
      "r": 200,
      "g": 50,
      "b": 50
    },
    {
      "x": 2,
      "y": 28,
      "z": 4,
      "r": 200,
      "g": 50,
      "b": 50
    },
    {
      "x": 2,
      "y": 29,
      "z": 3,
      "r": 200,
      "g": 50,
      "b": 50
    },
    {
      "x": 2,
      "y": 29,
      "z": 4,
      "r": 200,
      "g": 50,
      "b": 50
    },
    {
      "x": 2,
      "y": 30,
      "z": 3,
      "r": 255,
      "g": 255,
      "b": 255
    },
    {
      "x": 2,
      "y": 30,
      "z": 4,
      "r": 255,
      "g": 255,
      "b": 255
    },
    {
      "x": 2,
      "y": 31,
      "z": 3,
      "r": 255,
      "g": 255,
      "b": 255
    },
    {
      "x": 2,
      "y": 31,
      "z": 4,
      "r": 255,
      "g": 255,
      "b": 255
    },
    {
      "x": 2,
      "y": 32,
      "z": 3,
      "r": 255,
      "g": 255,
      "b": 255
    },
    {
      "x": 2,
      "y": 32,
      "z": 4,
      "r": 255,
      "g": 255,
      "b": 255
    },
    {
      "x": 3,
      "y": 26,
      "z": 3,
      "r": 200,
      "g": 50,
      "b": 50
    },
    {
      "x": 3,
      "y": 27,
      "z": 3,
      "r": 200,
      "g": 50,
      "b": 50
    },
    {
      "x": 3,
      "y": 28,
      "z": 3,
      "r": 200,
      "g": 50,
      "b": 50
    },
    {
      "x": 3,
      "y": 29,
      "z": 3,
      "r": 200,
      "g": 50,
      "b": 50
    },
    {
      "x": 3,
      "y": 30,
      "z": 3,
      "r": 255,
      "g": 255,
      "b": 255
    },
    {
      "x": 3,
      "y": 31,
      "z": 3,
      "r": 255,
      "g": 255,
      "b": 255
    },
    {
      "x": 4,
      "y": 25,
      "z": 3,
      "r": 200,
      "g": 50,
      "b": 50
    },
    {
      "x": 4,
      "y": 26,
      "z": 2,
      "r": 200,
      "g": 50,
      "b": 50
    },
    {
      "x": 4,
      "y": 26,
      "z": 3,
      "r": 200,
      "g": 50,
      "b": 50
    },
    {
      "x": 4,
      "y": 27,
      "z": 2,
      "r": 200,
      "g": 50,
      "b": 50
    },
    {
      "x": 4,
      "y": 27,
      "z": 3,
      "r": 200,
      "g": 50,
      "b": 50
    },
    {
      "x": 4,
      "y": 28,
      "z": 2,
      "r": 200,
      "g": 50,
      "b": 50
    },
    {
      "x": 4,
      "y": 28,
      "z": 3,
      "r": 200,
      "g": 50,
      "b": 50
    },
    {
      "x": 4,
      "y": 29,
      "z": 3,
      "r": 200,
      "g": 50,
      "b": 50
    },
    {
      "x": 5,
      "y": 26,
      "z": 2,
      "r": 200,
      "g": 50,
      "b": 50
    },
    {
      "x": 3,
      "y": 32,
      "z": 3,
      "r": 255,
      "g": 255,
      "b": 255
    },
    {
      "x": 4,
      "y": 29,
      "z": 2,
      "r": 200,
      "g": 50,
      "b": 50
    },
    {
      "x": 4,
      "y": 30,
      "z": 2,
      "r": 255,
      "g": 255,
      "b": 255
    },
    {
      "x": 4,
      "y": 30,
      "z": 3,
      "r": 255,
      "g": 255,
      "b": 255
    },
    {
      "x": 4,
      "y": 31,
      "z": 2,
      "r": 255,
      "g": 255,
      "b": 255
    },
    {
      "x": 4,
      "y": 31,
      "z": 3,
      "r": 255,
      "g": 255,
      "b": 255
    },
    {
      "x": 4,
      "y": 32,
      "z": 2,
      "r": 255,
      "g": 255,
      "b": 255
    },
    {
      "x": 4,
      "y": 32,
      "z": 3,
      "r": 255,
      "g": 255,
      "b": 255
    },
    {
      "x": 5,
      "y": 27,
      "z": 2,
      "r": 200,
      "g": 50,
      "b": 50
    },
    {
      "x": 5,
      "y": 28,
      "z": 2,
      "r": 200,
      "g": 50,
      "b": 50
    },
    {
      "x": 5,
      "y": 29,
      "z": 2,
      "r": 200,
      "g": 50,
      "b": 50
    },
    {
      "x": 5,
      "y": 30,
      "z": 2,
      "r": 255,
      "g": 255,
      "b": 255
    },
    {
      "x": 5,
      "y": 31,
      "z": 2,
      "r": 255,
      "g": 255,
      "b": 255
    },
    {
      "x": 5,
      "y": 32,
      "z": 2,
      "r": 255,
      "g": 255,
      "b": 255
    },
    {
      "x": 2,
      "y": 26,
      "z": 8,
      "r": 200,
      "g": 50,
      "b": 50
    },
    {
      "x": 2,
      "y": 27,
      "z": 8,
      "r": 200,
      "g": 50,
      "b": 50
    },
    {
      "x": 2,
      "y": 28,
      "z": 8,
      "r": 200,
      "g": 50,
      "b": 50
    },
    {
      "x": 3,
      "y": 26,
      "z": 8,
      "r": 200,
      "g": 50,
      "b": 50
    },
    {
      "x": 3,
      "y": 26,
      "z": 9,
      "r": 200,
      "g": 50,
      "b": 50
    },
    {
      "x": 3,
      "y": 27,
      "z": 8,
      "r": 200,
      "g": 50,
      "b": 50
    },
    {
      "x": 3,
      "y": 27,
      "z": 9,
      "r": 200,
      "g": 50,
      "b": 50
    },
    {
      "x": 3,
      "y": 28,
      "z": 8,
      "r": 200,
      "g": 50,
      "b": 50
    },
    {
      "x": 3,
      "y": 28,
      "z": 9,
      "r": 200,
      "g": 50,
      "b": 50
    },
    {
      "x": 3,
      "y": 29,
      "z": 8,
      "r": 200,
      "g": 50,
      "b": 50
    },
    {
      "x": 3,
      "y": 29,
      "z": 9,
      "r": 200,
      "g": 50,
      "b": 50
    },
    {
      "x": 3,
      "y": 30,
      "z": 8,
      "r": 255,
      "g": 255,
      "b": 255
    },
    {
      "x": 3,
      "y": 30,
      "z": 9,
      "r": 255,
      "g": 255,
      "b": 255
    },
    {
      "x": 4,
      "y": 26,
      "z": 9,
      "r": 200,
      "g": 50,
      "b": 50
    },
    {
      "x": 4,
      "y": 27,
      "z": 9,
      "r": 200,
      "g": 50,
      "b": 50
    },
    {
      "x": 4,
      "y": 28,
      "z": 9,
      "r": 200,
      "g": 50,
      "b": 50
    },
    {
      "x": 4,
      "y": 29,
      "z": 9,
      "r": 200,
      "g": 50,
      "b": 50
    },
    {
      "x": 4,
      "y": 30,
      "z": 9,
      "r": 255,
      "g": 255,
      "b": 255
    },
    {
      "x": 4,
      "y": 31,
      "z": 9,
      "r": 255,
      "g": 255,
      "b": 255
    },
    {
      "x": 4,
      "y": 32,
      "z": 9,
      "r": 255,
      "g": 255,
      "b": 255
    },
    {
      "x": 5,
      "y": 26,
      "z": 9,
      "r": 200,
      "g": 50,
      "b": 50
    },
    {
      "x": 5,
      "y": 26,
      "z": 10,
      "r": 200,
      "g": 50,
      "b": 50
    },
    {
      "x": 5,
      "y": 27,
      "z": 9,
      "r": 200,
      "g": 50,
      "b": 50
    },
    {
      "x": 5,
      "y": 28,
      "z": 9,
      "r": 200,
      "g": 50,
      "b": 50
    },
    {
      "x": 5,
      "y": 29,
      "z": 9,
      "r": 200,
      "g": 50,
      "b": 50
    },
    {
      "x": 5,
      "y": 30,
      "z": 9,
      "r": 255,
      "g": 255,
      "b": 255
    },
    {
      "x": 5,
      "y": 31,
      "z": 9,
      "r": 255,
      "g": 255,
      "b": 255
    },
    {
      "x": 5,
      "y": 32,
      "z": 9,
      "r": 255,
      "g": 255,
      "b": 255
    },
    {
      "x": 1,
      "y": 26,
      "z": 8,
      "r": 200,
      "g": 50,
      "b": 50
    },
    {
      "x": 1,
      "y": 27,
      "z": 8,
      "r": 200,
      "g": 50,
      "b": 50
    },
    {
      "x": 2,
      "y": 29,
      "z": 7,
      "r": 200,
      "g": 50,
      "b": 50
    },
    {
      "x": 2,
      "y": 29,
      "z": 8,
      "r": 200,
      "g": 50,
      "b": 50
    },
    {
      "x": 2,
      "y": 30,
      "z": 7,
      "r": 255,
      "g": 255,
      "b": 255
    },
    {
      "x": 2,
      "y": 30,
      "z": 8,
      "r": 255,
      "g": 255,
      "b": 255
    },
    {
      "x": 2,
      "y": 31,
      "z": 7,
      "r": 255,
      "g": 255,
      "b": 255
    },
    {
      "x": 2,
      "y": 31,
      "z": 8,
      "r": 255,
      "g": 255,
      "b": 255
    },
    {
      "x": 2,
      "y": 32,
      "z": 7,
      "r": 255,
      "g": 255,
      "b": 255
    },
    {
      "x": 2,
      "y": 32,
      "z": 8,
      "r": 255,
      "g": 255,
      "b": 255
    },
    {
      "x": 3,
      "y": 31,
      "z": 8,
      "r": 255,
      "g": 255,
      "b": 255
    },
    {
      "x": 3,
      "y": 31,
      "z": 9,
      "r": 255,
      "g": 255,
      "b": 255
    },
    {
      "x": 3,
      "y": 32,
      "z": 8,
      "r": 255,
      "g": 255,
      "b": 255
    },
    {
      "x": 4,
      "y": 31,
      "z": 8,
      "r": 255,
      "g": 255,
      "b": 255
    },
    {
      "x": 4,
      "y": 32,
      "z": 8,
      "r": 255,
      "g": 255,
      "b": 255
    },
    {
      "x": 8,
      "y": 26,
      "z": 4,
      "r": 200,
      "g": 50,
      "b": 50
    },
    {
      "x": 8,
      "y": 26,
      "z": 5,
      "r": 200,
      "g": 50,
      "b": 50
    },
    {
      "x": 8,
      "y": 26,
      "z": 6,
      "r": 200,
      "g": 50,
      "b": 50
    },
    {
      "x": 8,
      "y": 26,
      "z": 7,
      "r": 200,
      "g": 50,
      "b": 50
    },
    {
      "x": 8,
      "y": 27,
      "z": 4,
      "r": 200,
      "g": 50,
      "b": 50
    },
    {
      "x": 8,
      "y": 27,
      "z": 5,
      "r": 200,
      "g": 50,
      "b": 50
    },
    {
      "x": 8,
      "y": 27,
      "z": 6,
      "r": 200,
      "g": 50,
      "b": 50
    },
    {
      "x": 8,
      "y": 27,
      "z": 7,
      "r": 200,
      "g": 50,
      "b": 50
    },
    {
      "x": 8,
      "y": 28,
      "z": 4,
      "r": 200,
      "g": 50,
      "b": 50
    },
    {
      "x": 8,
      "y": 28,
      "z": 5,
      "r": 200,
      "g": 50,
      "b": 50
    },
    {
      "x": 8,
      "y": 28,
      "z": 6,
      "r": 200,
      "g": 50,
      "b": 50
    },
    {
      "x": 8,
      "y": 28,
      "z": 7,
      "r": 200,
      "g": 50,
      "b": 50
    },
    {
      "x": 8,
      "y": 29,
      "z": 4,
      "r": 200,
      "g": 50,
      "b": 50
    },
    {
      "x": 8,
      "y": 29,
      "z": 5,
      "r": 200,
      "g": 50,
      "b": 50
    },
    {
      "x": 8,
      "y": 29,
      "z": 6,
      "r": 200,
      "g": 50,
      "b": 50
    },
    {
      "x": 8,
      "y": 30,
      "z": 4,
      "r": 255,
      "g": 255,
      "b": 255
    },
    {
      "x": 8,
      "y": 30,
      "z": 5,
      "r": 255,
      "g": 255,
      "b": 255
    },
    {
      "x": 8,
      "y": 30,
      "z": 6,
      "r": 255,
      "g": 255,
      "b": 255
    },
    {
      "x": 8,
      "y": 31,
      "z": 4,
      "r": 255,
      "g": 255,
      "b": 255
    },
    {
      "x": 8,
      "y": 31,
      "z": 5,
      "r": 255,
      "g": 255,
      "b": 255
    },
    {
      "x": 8,
      "y": 32,
      "z": 4,
      "r": 255,
      "g": 255,
      "b": 255
    },
    {
      "x": 8,
      "y": 32,
      "z": 5,
      "r": 255,
      "g": 255,
      "b": 255
    },
    {
      "x": 8,
      "y": 26,
      "z": 8,
      "r": 200,
      "g": 50,
      "b": 50
    },
    {
      "x": 8,
      "y": 27,
      "z": 8,
      "r": 200,
      "g": 50,
      "b": 50
    },
    {
      "x": 8,
      "y": 28,
      "z": 8,
      "r": 200,
      "g": 50,
      "b": 50
    },
    {
      "x": 8,
      "y": 29,
      "z": 7,
      "r": 200,
      "g": 50,
      "b": 50
    },
    {
      "x": 8,
      "y": 29,
      "z": 8,
      "r": 200,
      "g": 50,
      "b": 50
    },
    {
      "x": 8,
      "y": 30,
      "z": 7,
      "r": 255,
      "g": 255,
      "b": 255
    },
    {
      "x": 8,
      "y": 31,
      "z": 6,
      "r": 255,
      "g": 255,
      "b": 255
    },
    {
      "x": 8,
      "y": 31,
      "z": 7,
      "r": 255,
      "g": 255,
      "b": 255
    },
    {
      "x": 8,
      "y": 32,
      "z": 6,
      "r": 255,
      "g": 255,
      "b": 255
    },
    {
      "x": 8,
      "y": 32,
      "z": 7,
      "r": 255,
      "g": 255,
      "b": 255
    },
    {
      "x": 1,
      "y": 26,
      "z": 5,
      "r": 200,
      "g": 50,
      "b": 50
    },
    {
      "x": 1,
      "y": 26,
      "z": 6,
      "r": 200,
      "g": 50,
      "b": 50
    },
    {
      "x": 1,
      "y": 26,
