{
  "resolution": 32,
  "gridSize": {
    "x": 32,
    "y": 28,
    "z": 22
  },
  "voxelCount": 434,
  "voxels": [
    {
      "x": 13,
      "y": 27,
      "z": 12,
      "r": 95,
      "g": 90,
      "b": 85
    },
    {
      "x": 13,
      "y": 27,
      "z": 13,
      "r": 95,
      "g": 90,
      "b": 85
    },
    {
      "x": 14,
      "y": 27,
      "z": 11,
      "r": 95,
      "g": 90,
      "b": 85
    },
    {
      "x": 14,
      "y": 27,
      "z": 12,
      "r": 95,
      "g": 90,
      "b": 85
    },
    {
      "x": 14,
      "y": 27,
      "z": 13,
      "r": 95,
      "g": 90,
      "b": 85
    },
    {
      "x": 15,
      "y": 27,
      "z": 10,
      "r": 95,
      "g": 90,
      "b": 85
    },
    {
      "x": 15,
      "y": 27,
      "z": 11,
      "r": 95,
      "g": 90,
      "b": 85
    },
    {
      "x": 15,
      "y": 27,
      "z": 12,
      "r": 95,
      "g": 90,
      "b": 85
    },
    {
      "x": 15,
      "y": 27,
      "z": 13,
      "r": 95,
      "g": 90,
      "b": 85
    },
    {
      "x": 16,
      "y": 27,
      "z": 9,
      "r": 95,
      "g": 90,
      "b": 85
    },
    {
      "x": 16,
      "y": 27,
      "z": 10,
      "r": 95,
      "g": 90,
      "b": 85
    },
    {
      "x": 16,
      "y": 27,
      "z": 11,
      "r": 95,
      "g": 90,
      "b": 85
    },
    {
      "x": 16,
      "y": 27,
      "z": 12,
      "r": 95,
      "g": 90,
      "b": 85
    },
    {
      "x": 16,
      "y": 27,
      "z": 13,
      "r": 95,
      "g": 90,
      "b": 85
    },
    {
      "x": 17,
      "y": 27,
      "z": 8,
      "r": 95,
      "g": 90,
      "b": 85
    },
    {
      "x": 17,
      "y": 27,
      "z": 9,
      "r": 95,
      "g": 90,
      "b": 85
    },
    {
      "x": 17,
      "y": 27,
      "z": 10,
      "r": 95,
      "g": 90,
      "b": 85
    },
    {
      "x": 17,
      "y": 27,
      "z": 11,
      "r": 95,
      "g": 90,
      "b": 85
    },
    {
      "x": 17,
      "y": 27,
      "z": 12,
      "r": 95,
      "g": 90,
      "b": 85
    },
    {
      "x": 17,
      "y": 27,
      "z": 13,
      "r": 95,
      "g": 90,
      "b": 85
    },
    {
      "x": 18,
      "y": 27,
      "z": 8,
      "r": 95,
      "g": 90,
      "b": 85
    },
    {
      "x": 18,
      "y": 27,
      "z": 9,
      "r": 95,
      "g": 90,
      "b": 85
    },
    {
      "x": 18,
      "y": 27,
      "z": 10,
      "r": 95,
      "g": 90,
      "b": 85
    },
    {
      "x": 18,
      "y": 27,
      "z": 11,
      "r": 95,
      "g": 90,
      "b": 85
    },
    {
      "x": 18,
      "y": 27,
      "z": 12,
      "r": 95,
      "g": 90,
      "b": 85
    },
    {
      "x": 18,
      "y": 27,
      "z": 13,
      "r": 95,
      "g": 90,
      "b": 85
    },
    {
      "x": 13,
      "y": 27,
      "z": 8,
      "r": 95,
      "g": 90,
      "b": 85
    },
    {
      "x": 13,
      "y": 27,
      "z": 9,
      "r": 95,
      "g": 90,
      "b": 85
    },
    {
      "x": 13,
      "y": 27,
      "z": 10,
      "r": 95,
      "g": 90,
      "b": 85
    },
    {
      "x": 13,
      "y": 27,
      "z": 11,
      "r": 95,
      "g": 90,
      "b": 85
    },
    {
      "x": 14,
      "y": 27,
      "z": 8,
      "r": 95,
      "g": 90,
      "b": 85
    },
    {
      "x": 14,
      "y": 27,
      "z": 9,
      "r": 95,
      "g": 90,
      "b": 85
    },
    {
      "x": 14,
      "y": 27,
      "z": 10,
      "r": 95,
      "g": 90,
      "b": 85
    },
    {
      "x": 15,
      "y": 27,
      "z": 8,
      "r": 95,
      "g": 90,
      "b": 85
    },
    {
      "x": 15,
      "y": 27,
      "z": 9,
      "r": 95,
      "g": 90,
      "b": 85
    },
    {
      "x": 16,
      "y": 27,
      "z": 8,
      "r": 95,
      "g": 90,
      "b": 85
    },
    {
      "x": 18,
      "y": 26,
      "z": 13,
      "r": 95,
      "g": 90,
      "b": 85
    },
    {
      "x": 18,
      "y": 26,
      "z": 12,
      "r": 95,
      "g": 90,
      "b": 85
    },
    {
      "x": 18,
      "y": 26,
      "z": 11,
      "r": 95,
      "g": 90,
      "b": 85
    },
    {
      "x": 18,
      "y": 26,
      "z": 10,
      "r": 95,
      "g": 90,
      "b": 85
    },
    {
      "x": 18,
      "y": 26,
      "z": 9,
      "r": 95,
      "g": 90,
      "b": 85
    },
    {
      "x": 18,
      "y": 26,
      "z": 8,
      "r": 95,
      "g": 90,
      "b": 85
    },
    {
      "x": 13,
      "y": 26,
      "z": 8,
      "r": 95,
      "g": 90,
      "b": 85
    },
    {
      "x": 13,
      "y": 26,
      "z": 9,
      "r": 95,
      "g": 90,
      "b": 85
    },
    {
      "x": 13,
      "y": 26,
      "z": 10,
      "r": 95,
      "g": 90,
      "b": 85
    },
    {
      "x": 13,
      "y": 26,
      "z": 11,
      "r": 95,
      "g": 90,
      "b": 85
    },
    {
      "x": 13,
      "y": 26,
      "z": 12,
      "r": 95,
      "g": 90,
      "b": 85
    },
    {
      "x": 13,
      "y": 26,
      "z": 13,
      "r": 95,
      "g": 90,
      "b": 85
    },
    {
      "x": 17,
      "y": 26,
      "z": 8,
      "r": 95,
      "g": 90,
      "b": 85
    },
    {
      "x": 16,
      "y": 26,
      "z": 8,
      "r": 95,
      "g": 90,
      "b": 85
    },
    {
      "x": 15,
      "y": 26,
      "z": 8,
      "r": 95,
      "g": 90,
      "b": 85
    },
    {
      "x": 14,
      "y": 26,
      "z": 8,
      "r": 95,
      "g": 90,
      "b": 85
    },
    {
      "x": 14,
      "y": 26,
      "z": 13,
      "r": 95,
      "g": 90,
      "b": 85
    },
    {
      "x": 15,
      "y": 26,
      "z": 13,
      "r": 95,
      "g": 90,
      "b": 85
    },
    {
      "x": 16,
      "y": 26,
      "z": 13,
      "r": 95,
      "g": 90,
      "b": 85
    },
    {
      "x": 17,
      "y": 26,
      "z": 13,
      "r": 95,
      "g": 90,
      "b": 85
    },
    {
      "x": 14,
      "y": 24,
      "z": 10,
      "r": 95,
      "g": 90,
      "b": 85
    },
    {
      "x": 17,
      "y": 24,
      "z": 10,
      "r": 95,
      "g": 90,
      "b": 85
    },
    {
      "x": 16,
      "y": 24,
      "z": 9,
      "r": 95,
      "g": 90,
      "b": 85
    },
    {
      "x": 14,
      "y": 24,
      "z": 9,
      "r": 95,
      "g": 90,
      "b": 85
    },
    {
      "x": 15,
      "y": 24,
      "z": 9,
      "r": 95,
      "g": 90,
      "b": 85
    },
    {
      "x": 17,
      "y": 24,
      "z": 12,
      "r": 95,
      "g": 90,
      "b": 85
    },
    {
      "x": 14,
      "y": 24,
      "z": 12,
      "r": 95,
      "g": 90,
      "b": 85
    },
    {
      "x": 15,
      "y": 13,
      "z": 9,
      "r": 95,
      "g": 90,
      "b": 85
    },
    {
      "x": 15,
      "y": 14,
      "z": 9,
      "r": 95,
      "g": 90,
      "b": 85
    },
    {
      "x": 15,
      "y": 15,
      "z": 9,
      "r": 95,
      "g": 90,
      "b": 85
    },
    {
      "x": 15,
      "y": 16,
      "z": 9,
      "r": 95,
      "g": 90,
      "b": 85
    },
    {
      "x": 15,
      "y": 17,
      "z": 9,
      "r": 95,
      "g": 90,
      "b": 85
    },
    {
      "x": 15,
      "y": 18,
      "z": 9,
      "r": 95,
      "g": 90,
      "b": 85
    },
    {
      "x": 15,
      "y": 19,
      "z": 9,
      "r": 95,
      "g": 90,
      "b": 85
    },
    {
      "x": 15,
      "y": 20,
      "z": 9,
      "r": 95,
      "g": 90,
      "b": 85
    },
    {
      "x": 15,
      "y": 21,
      "z": 9,
      "r": 95,
      "g": 90,
      "b": 85
    },
    {
      "x": 15,
      "y": 22,
      "z": 9,
      "r": 95,
      "g": 90,
      "b": 85
    },
    {
      "x": 15,
      "y": 23,
      "z": 9,
      "r": 95,
      "g": 90,
      "b": 85
    },
    {
      "x": 14,
      "y": 13,
      "z": 9,
      "r": 95,
      "g": 90,
      "b": 85
    },
    {
      "x": 14,
      "y": 14,
      "z": 9,
      "r": 95,
      "g": 90,
      "b": 85
    },
    {
      "x": 14,
      "y": 15,
      "z": 9,
      "r": 95,
      "g": 90,
      "b": 85
    },
    {
      "x": 14,
      "y": 16,
      "z": 9,
      "r": 95,
      "g": 90,
      "b": 85
    },
    {
      "x": 14,
      "y": 17,
      "z": 9,
      "r": 95,
      "g": 90,
      "b": 85
    },
    {
      "x": 14,
      "y": 18,
      "z": 9,
      "r": 95,
      "g": 90,
      "b": 85
    },
    {
      "x": 14,
      "y": 19,
      "z": 9,
      "r": 95,
      "g": 90,
      "b": 85
    },
    {
      "x": 14,
      "y": 20,
      "z": 9,
      "r": 95,
      "g": 90,
      "b": 85
    },
    {
      "x": 14,
      "y": 21,
      "z": 9,
      "r": 95,
      "g": 90,
      "b": 85
    },
    {
      "x": 14,
      "y": 22,
      "z": 9,
      "r": 95,
      "g": 90,
      "b": 85
    },
    {
      "x": 14,
      "y": 23,
      "z": 9,
      "r": 95,
      "g": 90,
      "b": 85
    },
    {
      "x": 17,
      "y": 13,
      "z": 9,
      "r": 95,
      "g": 90,
      "b": 85
    },
    {
      "x": 17,
      "y": 13,
      "z": 10,
      "r": 95,
      "g": 90,
      "b": 85
    },
    {
      "x": 17,
      "y": 14,
      "z": 9,
      "r": 95,
      "g": 90,
      "b": 85
    },
    {
      "x": 17,
      "y": 14,
      "z": 10,
      "r": 95,
      "g": 90,
      "b": 85
    },
    {
      "x": 17,
      "y": 15,
      "z": 9,
      "r": 95,
      "g": 90,
      "b": 85
    },
    {
      "x": 17,
      "y": 15,
      "z": 10,
      "r": 95,
      "g": 90,
      "b": 85
    },
    {
      "x": 17,
      "y": 16,
      "z": 9,
      "r": 95,
      "g": 90,
      "b": 85
    },
    {
      "x": 17,
      "y": 16,
      "z": 10,
      "r": 95,
      "g": 90,
      "b": 85
    },
    {
      "x": 17,
      "y": 17,
      "z": 9,
      "r": 95,
      "g": 90,
      "b": 85
    },
    {
      "x": 17,
      "y": 17,
      "z": 10,
      "r": 95,
      "g": 90,
      "b": 85
    },
    {
      "x": 17,
      "y": 18,
      "z": 9,
      "r": 95,
      "g": 90,
      "b": 85
    },
    {
      "x": 17,
      "y": 18,
      "z": 10,
      "r": 95,
      "g": 90,
      "b": 85
    },
    {
      "x": 17,
      "y": 19,
      "z": 9,
      "r": 95,
      "g": 90,
      "b": 85
    },
    {
      "x": 17,
      "y": 19,
      "z": 10,
      "r": 95,
      "g": 90,
      "b": 85
    },
    {
      "x": 17,
      "y": 20,
      "z": 9,
      "r": 95,
      "g": 90,
      "b": 85
    },
    {
      "x": 17,
      "y": 20,
      "z": 10,
      "r": 95,
      "g": 90,
      "b": 85
    },
    {
      "x": 17,
      "y": 21,
      "z": 9,
      "r": 95,
      "g": 90,
      "b": 85
    },
    {
      "x": 17,
      "y": 21,
      "z": 10,
      "r": 95,
      "g": 90,
      "b": 85
    },
    {
      "x": 17,
      "y": 22,
      "z": 9,
      "r": 95,
      "g": 90,
      "b": 85
    },
    {
      "x": 17,
      "y": 23,
      "z": 9,
      "r": 95,
      "g": 90,
      "b": 85
    },
    {
      "x": 17,
      "y": 24,
      "z": 9,
      "r": 95,
      "g": 90,
      "b": 85
    },
    {
      "x": 17,
      "y": 22,
      "z": 10,
      "r": 95,
      "g": 90,
      "b": 85
    },
    {
      "x": 17,
      "y": 23,
      "z": 10,
      "r": 95,
      "g": 90,
      "b": 85
    },
    {
      "x": 14,
      "y": 13,
      "z": 11,
      "r": 95,
      "g": 90,
      "b": 85
    },
    {
      "x": 14,
      "y": 14,
      "z": 11,
      "r": 95,
      "g": 90,
      "b": 85
    },
    {
      "x": 14,
      "y": 15,
      "z": 11,
      "r": 95,
      "g": 90,
      "b": 85
    },
    {
      "x": 14,
      "y": 16,
      "z": 11,
      "r": 95,
      "g": 90,
      "b": 85
    },
    {
      "x": 14,
      "y": 17,
      "z": 11,
      "r": 95,
      "g": 90,
      "b": 85
    },
    {
      "x": 14,
      "y": 18,
      "z": 11,
      "r": 95,
      "g": 90,
      "b": 85
    },
    {
      "x": 14,
      "y": 19,
      "z": 11,
      "r": 95,
      "g": 90,
      "b": 85
    },
    {
      "x": 14,
      "y": 20,
      "z": 11,
      "r": 95,
      "g": 90,
      "b": 85
    },
    {
      "x": 14,
      "y": 21,
      "z": 11,
      "r": 95,
      "g": 90,
      "b": 85
    },
    {
      "x": 14,
      "y": 22,
      "z": 11,
      "r": 95,
      "g": 90,
      "b": 85
    },
    {
      "x": 14,
      "y": 23,
      "z": 11,
      "r": 95,
      "g": 90,
      "b": 85
    },
    {
      "x": 14,
      "y": 24,
      "z": 11,
      "r": 95,
      "g": 90,
      "b": 85
    },
    {
      "x": 14,
      "y": 13,
      "z": 12,
      "r": 95,
      "g": 90,
      "b": 85
    },
    {
      "x": 14,
      "y": 14,
      "z": 12,
      "r": 95,
      "g": 90,
      "b": 85
    },
    {
      "x": 14,
      "y": 15,
      "z": 12,
      "r": 95,
      "g": 90,
      "b": 85
    },
    {
      "x": 14,
      "y": 16,
      "z": 12,
      "r": 95,
      "g": 90,
      "b": 85
    },
    {
      "x": 14,
      "y": 17,
      "z": 12,
      "r": 95,
      "g": 90,
      "b": 85
    },
    {
      "x": 14,
      "y": 18,
      "z": 12,
      "r": 95,
      "g": 90,
      "b": 85
    },
    {
      "x": 14,
      "y": 19,
      "z": 12,
      "r": 95,
      "g": 90,
      "b": 85
    },
    {
      "x": 14,
      "y": 20,
      "z": 12,
      "r": 95,
      "g": 90,
      "b": 85
    },
    {
      "x": 14,
      "y": 21,
      "z": 12,
      "r": 95,
      "g": 90,
      "b": 85
    },
    {
      "x": 14,
      "y": 22,
      "z": 12,
      "r": 95,
      "g": 90,
      "b": 85
    },
    {
      "x": 14,
      "y": 23,
      "z": 12,
      "r": 95,
      "g": 90,
      "b": 85
    },
    {
      "x": 16,
      "y": 13,
      "z": 12,
      "r": 95,
      "g": 90,
      "b": 85
    },
    {
      "x": 16,
      "y": 14,
      "z": 12,
      "r": 95,
      "g": 90,
      "b": 85
    },
    {
      "x": 16,
      "y": 15,
      "z": 12,
      "r": 95,
      "g": 90,
      "b": 85
    },
    {
      "x": 16,
      "y": 16,
      "z": 12,
      "r": 95,
      "g": 90,
      "b": 85
    },
    {
      "x": 16,
      "y": 17,
      "z": 12,
      "r": 95,
      "g": 90,
      "b": 85
    },
    {
      "x": 16,
      "y": 18,
      "z": 12,
      "r": 95,
      "g": 90,
      "b": 85
    },
    {
      "x": 16,
      "y": 19,
      "z": 12,
      "r": 95,
      "g": 90,
      "b": 85
    },
    {
      "x": 16,
      "y": 20,
      "z": 12,
      "r": 95,
      "g": 90,
      "b": 85
    },
    {
      "x": 16,
      "y": 21,
      "z": 12,
      "r": 95,
      "g": 90,
      "b": 85
    },
    {
      "x": 16,
      "y": 22,
      "z": 12,
      "r": 95,
      "g": 90,
      "b": 85
    },
    {
      "x": 16,
      "y": 23,
      "z": 12,
      "r": 95,
      "g": 90,
      "b": 85
    },
    {
      "x": 16,
      "y": 24,
      "z": 12,
      "r": 95,
      "g": 90,
      "b": 85
    },
    {
      "x": 17,
      "y": 13,
      "z": 12,
      "r": 95,
      "g": 90,
      "b": 85
    },
    {
      "x": 17,
      "y": 14,
      "z": 12,
      "r": 95,
      "g": 90,
      "b": 85
    },
    {
      "x": 17,
      "y": 15,
      "z": 12,
      "r": 95,
      "g": 90,
      "b": 85
    },
    {
      "x": 17,
      "y": 16,
      "z": 12,
      "r": 95,
      "g": 90,
      "b": 85
    },
    {
      "x": 17,
      "y": 17,
      "z": 12,
      "r": 95,
      "g": 90,
      "b": 85
    },
    {
      "x": 17,
      "y": 18,
      "z": 12,
      "r": 95,
      "g": 90,
      "b": 85
    },
    {
      "x": 17,
      "y": 19,
      "z": 12,
      "r": 95,
      "g": 90,
      "b": 85
    },
    {
      "x": 17,
      "y": 20,
      "z": 12,
      "r": 95,
      "g": 90,
      "b": 85
    },
    {
      "x": 17,
      "y": 21,
      "z": 12,
      "r": 95,
      "g": 90,
      "b": 85
    },
    {
      "x": 17,
      "y": 22,
      "z": 12,
      "r": 95,
      "g": 90,
      "b": 85
    },
    {
      "x": 17,
      "y": 23,
      "z": 12,
      "r": 95,
      "g": 90,
      "b": 85
    },
    {
      "x": 17,
      "y": 13,
      "z": 11,
      "r": 95,
      "g": 90,
      "b": 85
    },
    {
      "x": 17,
      "y": 14,
      "z": 11,
      "r": 95,
      "g": 90,
      "b": 85
    },
    {
      "x": 17,
      "y": 15,
      "z": 11,
      "r": 95,
      "g": 90,
      "b": 85
    },
    {
      "x": 17,
      "y": 16,
      "z": 11,
      "r": 95,
      "g": 90,
      "b": 85
    },
    {
      "x": 17,
      "y": 17,
      "z": 11,
      "r": 95,
      "g": 90,
      "b": 85
    },
    {
      "x": 17,
      "y": 18,
      "z": 11,
      "r": 95,
      "g": 90,
      "b": 85
    },
    {
      "x": 17,
      "y": 19,
      "z": 11,
      "r": 95,
      "g": 90,
      "b": 85
    },
    {
      "x": 17,
      "y": 20,
      "z": 11,
      "r": 95,
      "g": 90,
      "b": 85
    },
    {
      "x": 17,
      "y": 21,
      "z": 11,
      "r": 95,
      "g": 90,
      "b": 85
    },
    {
      "x": 17,
      "y": 22,
      "z": 11,
      "r": 95,
      "g": 90,
      "b": 85
    },
    {
      "x": 17,
      "y": 23,
      "z": 11,
      "r": 95,
      "g": 90,
      "b": 85
    },
    {
      "x": 17,
      "y": 24,
      "z": 11,
      "r": 95,
      "g": 90,
      "b": 85
    },
    {
      "x": 16,
      "y": 20,
      "z": 9,
      "r": 95,
      "g": 90,
      "b": 85
    },
    {
      "x": 16,
      "y": 21,
      "z": 9,
      "r": 95,
      "g": 90,
      "b": 85
    },
    {
      "x": 16,
      "y": 22,
      "z": 9,
      "r": 95,
      "g": 90,
      "b": 85
    },
    {
      "x": 16,
      "y": 23,
      "z": 9,
      "r": 95,
      "g": 90,
      "b": 85
    },
    {
      "x": 16,
      "y": 13,
      "z": 9,
      "r": 95,
      "g": 90,
      "b": 85
    },
    {
      "x": 16,
      "y": 14,
      "z": 9,
      "r": 95,
      "g": 90,
      "b": 85
    },
    {
      "x": 16,
      "y": 15,
      "z": 9,
      "r": 95,
      "g": 90,
      "b": 85
    },
    {
      "x": 16,
      "y": 16,
      "z": 9,
      "r": 95,
      "g": 90,
      "b": 85
    },
    {
      "x": 16,
      "y": 17,
      "z": 9,
      "r": 95,
      "g": 90,
      "b": 85
    },
    {
      "x": 16,
      "y": 18,
      "z": 9,
      "r": 95,
      "g": 90,
      "b": 85
    },
    {
      "x": 16,
      "y": 19,
      "z": 9,
      "r": 95,
      "g": 90,
      "b": 85
    },
    {
      "x": 15,
      "y": 23,
      "z": 12,
      "r": 95,
      "g": 90,
      "b": 85
    },
    {
      "x": 15,
      "y": 24,
      "z": 12,
      "r": 95,
      "g": 90,
      "b": 85
    },
    {
      "x": 15,
      "y": 13,
      "z": 12,
      "r": 95,
      "g": 90,
      "b": 85
    },
    {
      "x": 15,
      "y": 14,
      "z": 12,
      "r": 95,
      "g": 90,
      "b": 85
    },
    {
      "x": 15,
      "y": 15,
      "z": 12,
      "r": 95,
      "g": 90,
      "b": 85
    },
    {
      "x": 15,
      "y": 16,
      "z": 12,
      "r": 95,
      "g": 90,
      "b": 85
    },
    {
      "x": 15,
      "y": 17,
      "z": 12,
      "r": 95,
      "g": 90,
      "b": 85
    },
    {
      "x": 15,
      "y": 18,
      "z": 12,
      "r": 95,
      "g": 90,
      "b": 85
    },
    {
      "x": 15,
      "y": 19,
      "z": 12,
      "r": 95,
      "g": 90,
      "b": 85
    },
    {
      "x": 15,
      "y": 20,
      "z": 12,
      "r": 95,
      "g": 90,
      "b": 85
    },
    {
      "x": 15,
      "y": 21,
      "z": 12,
      "r": 95,
      "g": 90,
      "b": 85
    },
    {
      "x": 15,
      "y": 22,
      "z": 12,
      "r": 95,
      "g": 90,
      "b": 85
    },
    {
      "x": 14,
      "y": 16,
      "z": 10,
      "r": 95,
      "g": 90,
      "b": 85
    },
    {
      "x": 14,
      "y": 17,
      "z": 10,
      "r": 95,
      "g": 90,
      "b": 85
    },
    {
      "x": 14,
      "y": 18,
      "z": 10,
      "r": 95,
      "g": 90,
      "b": 85
    },
    {
      "x": 14,
      "y": 19,
      "z": 10,
      "r": 95,
      "g": 90,
      "b": 85
    },
    {
      "x": 14,
      "y": 20,
      "z": 10,
      "r": 95,
      "g": 90,
      "b": 85
    },
    {
      "x": 14,
      "y": 21,
      "z": 10,
      "r": 95,
      "g": 90,
      "b": 85
    },
    {
      "x": 14,
      "y": 22,
      "z": 10,
      "r": 95,
      "g": 90,
      "b": 85
    },
    {
      "x": 14,
      "y": 23,
      "z": 10,
      "r": 95,
      "g": 90,
      "b": 85
    },
    {
      "x": 14,
      "y": 13,
      "z": 10,
      "r": 95,
      "g": 90,
      "b": 85
    },
    {
      "x": 14,
      "y": 14,
      "z": 10,
      "r": 95,
      "g": 90,
      "b": 85
    },
    {
      "x": 14,
      "y": 15,
      "z": 10,
      "r": 95,
      "g": 90,
      "b": 85
    },
    {
      "x": 15,
      "y": 24,
      "z": 8,
      "r": 95,
      "g": 90,
      "b": 85
    },
    {
      "x": 14,
      "y": 25,
      "z": 10,
      "r": 95,
      "g": 90,
      "b": 85
    },
    {
      "x": 17,
      "y": 25,
      "z": 11,
      "r": 95,
      "g": 90,
      "b": 85
    },
    {
      "x": 15,
      "y": 25,
      "z": 9,
      "r": 95,
      "g": 90,
      "b": 85
    },
    {
      "x": 14,
      "y": 25,
      "z": 11,
      "r": 95,
      "g": 90,
      "b": 85
    },
    {
      "x": 17,
      "y": 25,
      "z": 10,
      "r": 95,
      "g": 90,
      "b": 85
    },
    {
      "x": 14,
      "y": 25,
      "z": 9,
      "r": 95,
      "g": 90,
      "b": 85
    },
    {
      "x": 14,
      "y": 25,
      "z": 12,
      "r": 95,
      "g": 90,
      "b": 85
    },
    {
      "x": 17,
      "y": 25,
      "z": 9,
      "r": 95,
      "g": 90,
      "b": 85
    },
    {
      "x": 17,
      "y": 25,
      "z": 12,
      "r": 95,
      "g": 90,
      "b": 85
    },
    {
      "x": 16,
      "y": 25,
      "z": 9,
      "r": 95,
      "g": 90,
      "b": 85
    },
    {
      "x": 16,
      "y": 25,
      "z": 12,
      "r": 95,
      "g": 90,
      "b": 85
    },
    {
      "x": 15,
      "y": 25,
      "z": 12,
      "r": 95,
      "g": 90,
      "b": 85
    },
    {
      "x": 13,
      "y": 24,
      "z": 11,
      "r": 95,
      "g": 90,
      "b": 85
    },
    {
      "x": 13,
      "y": 24,
      "z": 10,
      "r": 95,
      "g": 90,
      "b": 85
    },
    {
      "x": 15,
      "y": 25,
      "z": 13,
      "r": 95,
      "g": 90,
      "b": 85
    },
    {
      "x": 13,
      "y": 25,
      "z": 10,
      "r": 95,
      "g": 90,
      "b": 85
    },
    {
      "x": 16,
      "y": 25,
      "z": 8,
      "r": 95,
      "g": 90,
      "b": 85
    },
    {
      "x": 13,
      "y": 25,
      "z": 11,
      "r": 95,
      "g": 90,
      "b": 85
    },
    {
      "x": 15,
      "y": 25,
      "z": 8,
      "r": 95,
      "g": 90,
      "b": 85
    },
    {
      "x": 15,
      "y": 26,
      "z": 12,
      "r": 95,
      "g": 90,
      "b": 85
    },
    {
      "x": 18,
      "y": 25,
      "z": 10,
      "r": 95,
      "g": 90,
      "b": 85
    },
    {
      "x": 18,
      "y": 25,
      "z": 11,
      "r": 95,
      "g": 90,
      "b": 85
    },
    {
      "x": 13,
      "y": 25,
      "z": 9,
      "r": 95,
      "g": 90,
      "b": 85
    },
    {
      "x": 14,
      "y": 26,
      "z": 10,
      "r": 95,
      "g": 90,
      "b": 85
    },
    {
      "x": 17,
      "y": 26,
      "z": 12,
      "r": 95,
      "g": 90,
      "b": 85
    },
    {
      "x": 16,
      "y": 26,
      "z": 9,
      "r": 95,
      "g": 90,
      "b": 85
    },
    {
      "x": 17,
      "y": 26,
      "z": 11,
      "r": 95,
      "g": 90,
      "b": 85
    },
    {
      "x": 16,
      "y": 26,
      "z": 12,
      "r": 95,
      "g": 90,
      "b": 85
    },
    {
      "x": 14,
      "y": 26,
      "z": 11,
      "r": 95,
      "g": 90,
      "b": 85
    },
    {
      "x": 17,
      "y": 26,
      "z": 10,
      "r": 95,
      "g": 90,
      "b": 85
    },
    {
      "x": 15,
      "y": 26,
      "z": 9,
      "r": 95,
      "g": 90,
      "b": 85
    },
    {
      "x": 14,
      "y": 26,
      "z": 12,
      "r": 95,
      "g": 90,
      "b": 85
    },
    {
      "x": 14,
      "y": 26,
      "z": 9,
      "r": 95,
      "g": 90,
      "b": 85
    },
    {
      "x": 17,
      "y": 26,
      "z": 9,
      "r": 95,
      "g": 90,
      "b": 85
    },
    {
      "x": 17,
      "y": 25,
      "z": 8,
      "r": 95,
      "g": 90,
      "b": 85
    },
    {
      "x": 16,
      "y": 25,
      "z": 13,
      "r": 95,
      "g": 90,
      "b": 85
    },
    {
      "x": 14,
      "y": 25,
      "z": 8,
      "r": 95,
      "g": 90,
      "b": 85
    },
    {
      "x": 16,
      "y": 24,
      "z": 8,
      "r": 95,
      "g": 90,
      "b": 85
    },
    {
      "x": 13,
      "y": 0,
      "z": 8,
      "r": 95,
      "g": 90,
      "b": 85
    },
    {
      "x": 13,
      "y": 0,
      "z": 9,
      "r": 95,
      "g": 90,
      "b": 85
    },
    {
      "x": 13,
      "y": 0,
      "z": 10,
      "r": 95,
      "g": 90,
      "b": 85
    },
    {
      "x": 13,
      "y": 0,
      "z": 11,
      "r": 95,
      "g": 90,
      "b": 85
    },
    {
      "x": 13,
      "y": 0,
      "z": 12,
      "r": 95,
      "g": 90,
      "b": 85
    },
    {
      "x": 13,
      "y": 0,
      "z": 13,
      "r": 95,
      "g": 90,
      "b": 85
    },
    {
      "x": 14,
      "y": 0,
      "z": 8,
      "r": 95,
      "g": 90,
      "b": 85
    },
    {
      "x": 14,
      "y": 0,
      "z": 9,
      "r": 95,
      "g": 90,
      "b": 85
    },
    {
      "x": 14,
      "y": 0,
      "z": 10,
      "r": 95,
      "g": 90,
      "b": 85
    },
    {
      "x": 14,
      "y": 0,
      "z": 11,
      "r": 95,
      "g": 90,
      "b": 85
    },
    {
      "x": 14,
      "y": 0,
      "z": 12,
      "r": 95,
      "g": 90,
      "b": 85
    },
    {
      "x": 15,
      "y": 0,
      "z": 8,
      "r": 95,
      "g": 90,
      "b": 85
    },
    {
      "x": 15,
      "y": 0,
      "z": 9,
      "r": 95,
      "g": 90,
      "b": 85
    },
    {
      "x": 15,
      "y": 0,
      "z": 10,
      "r": 95,
      "g": 90,
      "b": 85
    },
    {
      "x": 15,
      "y": 0,
      "z": 11,
      "r": 95,
      "g": 90,
      "b": 85
    },
    {
      "x": 16,
      "y": 0,
      "z": 8,
      "r": 95,
      "g": 90,
      "b": 85
    },
    {
      "x": 16,
      "y": 0,
      "z": 9,
      "r": 95,
      "g": 90,
      "b": 85
    },
    {
      "x": 16,
      "y": 0,
      "z": 10,
      "r": 95,
      "g": 90,
      "b": 85
    },
    {
      "x": 17,
      "y": 0,
      "z": 8,
      "r": 95,
      "g": 90,
      "b": 85
    },
    {
      "x": 17,
      "y": 0,
      "z": 9,
      "r": 95,
      "g": 90,
      "b": 85
    },
    {
      "x": 18,
      "y": 0,
      "z": 8,
      "r": 95,
      "g": 90,
      "b": 85
    },
    {
      "x": 14,
      "y": 0,
      "z": 13,
      "r": 95,
      "g": 90,
      "b": 85
    },
    {
      "x": 15,
      "y": 0,
      "z": 12,
      "r": 95,
      "g": 90,
      "b": 85
    },
    {
      "x": 15,
      "y": 0,
      "z": 13,
      "r": 95,
      "g": 90,
      "b": 85
    },
    {
      "x": 16,
      "y": 0,
      "z": 11,
      "r": 95,
      "g": 90,
      "b": 85
    },
    {
      "x": 16,
      "y": 0,
      "z": 12,
      "r": 95,
      "g": 90,
      "b": 85
    },
    {
      "x": 16,
      "y": 0,
      "z": 13,
      "r": 95,
      "g": 90,
      "b": 85
    },
    {
      "x": 17,
      "y": 0,
      "z": 10,
      "r": 95,
      "g": 90,
      "b": 85
    },
    {
      "x": 17,
      "y": 0,
      "z": 11,
      "r": 95,
      "g": 90,
      "b": 85
    },
    {
      "x": 17,
      "y": 0,
      "z": 12,
      "r": 95,
      "g": 90,
      "b": 85
    },
    {
      "x": 17,
      "y": 0,
      "z": 13,
      "r": 95,
      "g": 90,
      "b": 85
    },
    {
      "x": 18,
      "y": 0,
      "z": 9,
      "r": 95,
      "g": 90,
      "b": 85
    },
    {
      "x": 18,
      "y": 0,
      "z": 10,
      "r": 95,
      "g": 90,
      "b": 85
    },
    {
      "x": 18,
      "y": 0,
      "z": 11,
      "r": 95,
      "g": 90,
      "b": 85
    },
    {
      "x": 18,
      "y": 0,
      "z": 12,
      "r": 95,
      "g": 90,
      "b": 85
    },
    {
      "x": 18,
      "y": 0,
      "z": 13,
      "r": 95,
      "g": 90,
      "b": 85
    },
    {
      "x": 14,
      "y": 2,
      "z": 10,
      "r": 95,
      "g": 90,
      "b": 85
    },
    {
      "x": 17,
      "y": 2,
      "z": 10,
      "r": 95,
      "g": 90,
      "b": 85
    },
    {
      "x": 16,
      "y": 2,
      "z": 9,
      "r": 95,
      "g": 90,
      "b": 85
    },
    {
      "x": 14,
      "y": 2,
      "z": 9,
      "r": 95,
      "g": 90,
      "b": 85
    },
    {
      "x": 15,
      "y": 2,
      "z": 9,
      "r": 95,
      "g": 90,
      "b": 85
    },
    {
      "x": 17,
      "y": 2,
      "z": 12,
      "r": 95,
      "g": 90,
      "b": 85
    },
    {
      "x": 14,
      "y": 2,
      "z": 12,
      "r": 95,
      "g": 90,
      "b": 85
    },
    {
      "x": 15,
      "y": 3,
      "z": 9,
      "r": 95,
      "g": 90,
      "b": 85
    },
    {
      "x": 15,
      "y": 4,
      "z": 9,
      "r": 95,
      "g": 90,
      "b": 85
    },
    {
      "x": 15,
      "y": 5,
      "z": 9,
      "r": 95,
      "g": 90,
      "b": 85
    },
    {
      "x": 15,
      "y": 6,
      "z": 9,
      "r": 95,
      "g": 90,
      "b": 85
    },
    {
      "x": 15,
      "y": 7,
      "z": 9,
      "r": 95,
      "g": 90,
      "b": 85
    },
    {
      "x": 15,
      "y": 8,
      "z": 9,
      "r": 95,
      "g": 90,
      "b": 85
    },
    {
      "x": 15,
      "y": 9,
      "z": 9,
      "r": 95,
      "g": 90,
      "b": 85
    },
    {
      "x": 15,
      "y": 10,
      "z": 9,
      "r": 95,
      "g": 90,
      "b": 85
    },
    {
      "x": 15,
      "y": 11,
      "z": 9,
      "r": 95,
      "g": 90,
      "b": 85
    },
    {
      "x": 15,
      "y": 12,
      "z": 9,
      "r": 95,
      "g": 90,
      "b": 85
    },
    {
      "x": 14,
      "y": 3,
      "z": 9,
      "r": 95,
      "g": 90,
      "b": 85
    },
    {
      "x": 14,
      "y": 4,
      "z": 9,
      "r": 95,
      "g": 90,
      "b": 85
    },
    {
      "x": 14,
      "y": 5,
      "z": 9,
      "r": 95,
      "g": 90,
      "b": 85
    },
    {
      "x": 14,
      "y": 6,
      "z": 9,
      "r": 95,
      "g": 90,
      "b": 85
    },
    {
      "x": 14,
      "y": 7,
      "z": 9,
      "r": 95,
      "g": 90,
      "b": 85
    },
    {
      "x": 14,
      "y": 8,
      "z": 9,
      "r": 95,
      "g": 90,
      "b": 85
    },
    {
      "x": 14,
      "y": 9,
      "z": 9,
      "r": 95,
      "g": 90,
      "b": 85
    },
    {
      "x": 14,
      "y": 10,
      "z": 9,
      "r": 95,
      "g": 90,
      "b": 85
    },
    {
      "x": 14,
      "y": 11,
      "z": 9,
      "r": 95,
      "g": 90,
      "b": 85
    },
    {
      "x": 14,
      "y": 12,
      "z": 9,
      "r": 95,
      "g": 90,
      "b": 85
    },
    {
      "x": 17,
      "y": 2,
      "z": 9,
      "r": 95,
      "g": 90,
      "b": 85
    },
    {
      "x": 17,
      "y": 3,
      "z": 9,
      "r": 95,
      "g": 90,
      "b": 85
    },
    {
      "x": 17,
      "y": 3,
      "z": 10,
      "r": 95,
      "g": 90,
      "b": 85
    },
    {
      "x": 17,
      "y": 4,
      "z": 9,
      "r": 95,
      "g": 90,
      "b": 85
    },
    {
      "x": 17,
      "y": 4,
      "z": 10,
      "r": 95,
      "g": 90,
      "b": 85
    },
    {
      "x": 17,
      "y": 5,
      "z": 9,
      "r": 95,
      "g": 90,
      "b": 85
    },
    {
      "x": 17,
      "y": 5,
      "z": 10,
      "r": 95,
      "g": 90,
      "b": 85
    },
    {
      "x": 17,
      "y": 6,
      "z": 10,
      "r": 95,
      "g": 90,
      "b": 85
    },
    {
      "x": 17,
      "y": 7,
      "z": 10,
      "r": 95,
      "g": 90,
      "b": 85
    },
    {
      "x": 17,
      "y": 8,
      "z": 10,
      "r": 95,
      "g": 90,
      "b": 85
    },
    {
      "x": 17,
      "y": 9,
      "z": 10,
      "r": 95,
      "g": 90,
      "b": 85
    },
    {
      "x": 17,
      "y": 10,
      "z": 10,
      "r": 95,
      "g": 90,
      "b": 85
    },
    {
      "x": 17,
      "y": 11,
      "z": 10,
      "r": 95,
      "g": 90,
      "b": 85
    },
    {
      "x": 17,
      "y": 12,
      "z": 10,
      "r": 95,
      "g": 90,
      "b": 85
    },
    {
      "x": 17,
      "y": 6,
      "z": 9,
      "r": 95,
      "g": 90,
      "b": 85
    },
    {
      "x": 17,
      "y": 7,
      "z": 9,
      "r": 95,
      "g": 90,
      "b": 85
    },
    {
      "x": 17,
      "y": 8,
      "z": 9,
      "r": 95,
      "g": 90,
      "b": 85
    },
    {
      "x": 17,
      "y": 9,
      "z": 9,
      "r": 95,
      "g": 90,
      "b": 85
    },
    {
      "x": 17,
      "y": 10,
      "z": 9,
      "r": 95,
      "g": 90,
      "b": 85
    },
    {
      "x": 17,
      "y": 11,
      "z": 9,
      "r": 95,
      "g": 90,
      "b": 85
    },
    {
      "x": 17,
      "y": 12,
      "z": 9,
      "r": 95,
      "g": 90,
      "b": 85
    },
    {
      "x": 14,
      "y": 2,
      "z": 11,
      "r": 95,
      "g": 90,
      "b": 85
    },
    {
      "x": 14,
      "y": 3,
      "z": 11,
      "r": 95,
      "g": 90,
      "b": 85
    },
    {
      "x": 14,
      "y": 4,
      "z": 11,
      "r": 95,
      "g": 90,
      "b": 85
    },
    {
      "x": 14,
      "y": 5,
      "z": 11,
      "r": 95,
      "g": 90,
      "b": 85
    },
    {
      "x": 14,
      "y": 6,
      "z": 11,
      "r": 95,
      "g": 90,
      "b": 85
    },
    {
      "x": 14,
      "y": 7,
      "z": 11,
      "r": 95,
      "g": 90,
      "b": 85
    },
    {
      "x": 14,
      "y": 8,
      "z": 11,
      "r": 95,
      "g": 90,
      "b": 85
    },
    {
      "x": 14,
      "y": 9,
      "z": 11,
      "r": 95,
      "g": 90,
      "b": 85
    },
    {
      "x": 14,
      "y": 10,
      "z": 11,
      "r": 95,
      "g": 90,
      "b": 85
    },
    {
      "x": 14,
      "y": 11,
      "z": 11,
      "r": 95,
      "g": 90,
      "b": 85
    },
    {
      "x": 14,
      "y": 12,
      "z": 11,
      "r": 95,
      "g": 90,
      "b": 85
    },
    {
      "x": 14,
      "y": 3,
      "z": 12,
      "r": 95,
      "g": 90,
      "b": 85
    },
    {
      "x": 14,
      "y": 4,
      "z": 12,
      "r": 95,
      "g": 90,
      "b": 85
    },
    {
      "x": 14,
      "y": 5,
      "z": 12,
      "r": 95,
      "g": 90,
      "b": 85
    },
    {
      "x": 14,
      "y": 6,
      "z": 12,
      "r": 95,
      "g": 90,
      "b": 85
    },
    {
      "x": 14,
      "y": 7,
      "z": 12,
      "r": 95,
      "g": 90,
      "b": 85
    },
    {
      "x": 14,
      "y": 8,
      "z": 12,
      "r": 95,
      "g": 90,
      "b": 85
    },
    {
      "x": 14,
      "y": 9,
      "z": 12,
      "r": 95,
      "g": 90,
      "b": 85
    },
    {
      "x": 14,
      "y": 10,
      "z": 12,
      "r": 95,
      "g": 90,
      "b": 85
    },
    {
      "x": 14,
      "y": 11,
      "z": 12,
      "r": 95,
      "g": 90,
      "b": 85
    },
    {
      "x": 14,
      "y": 12,
      "z": 12,
      "r": 95,
      "g": 90,
      "b": 85
    },
    {
      "x": 16,
      "y": 2,
      "z": 12,
      "r": 95,
      "g": 90,
      "b": 85
    },
    {
      "x": 16,
      "y": 3,
      "z": 12,
      "r": 95,
      "g": 90,
      "b": 85
    },
    {
      "x": 16,
      "y": 4,
      "z": 12,
      "r": 95,
      "g": 90,
      "b": 85
    },
    {
      "x": 16,
      "y": 5,
      "z": 12,
      "r": 95,
      "g": 90,
      "b": 85
    },
    {
      "x": 16,
      "y": 6,
      "z": 12,
      "r": 95,
      "g": 90,
      "b": 85
    },
    {
      "x": 16,
      "y": 7,
      "z": 12,
      "r": 95,
      "g": 90,
      "b": 85
    },
    {
      "x": 16,
      "y": 8,
      "z": 12,
      "r": 95,
      "g": 90,
      "b": 85
    },
    {
      "x": 16,
      "y": 9,
      "z": 12,
      "r": 95,
      "g": 90,
      "b": 85
    },
    {
      "x": 16,
      "y": 10,
      "z": 12,
      "r": 95,
      "g": 90,
      "b": 85
    },
    {
      "x": 16,
      "y": 11,
      "z": 12,
      "r": 95,
      "g": 90,
      "b": 85
    },
    {
      "x": 16,
      "y": 12,
      "z": 12,
      "r": 95,
      "g": 90,
      "b": 85
    },
    {
      "x": 17,
      "y": 3,
      "z": 12,
      "r": 95,
      "g": 90,
      "b": 85
    },
    {
      "x": 17,
      "y": 4,
      "z": 12,
      "r": 95,
      "g": 90,
      "b": 85
    },
    {
      "x": 17,
      "y": 5,
      "z": 12,
      "r": 95,
      "g": 90,
      "b": 85
    },
    {
      "x": 17,
      "y": 6,
      "z": 12,
      "r": 95,
      "g": 90,
      "b": 85
    },
    {
      "x": 17,
      "y": 7,
      "z": 12,
      "r": 95,
      "g": 90,
      "b": 85
    },
    {
      "x": 17,
      "y": 8,
      "z": 12,
      "r": 95,
      "g": 90,
      "b": 85
    },
    {
      "x": 17,
      "y": 9,
      "z": 12,
      "r": 95,
      "g": 90,
      "b": 85
    },
    {
      "x": 17,
      "y": 10,
      "z": 12,
      "r": 95,
      "g": 90,
      "b": 85
    },
    {
      "x": 17,
      "y": 11,
      "z": 12,
      "r": 95,
      "g": 90,
      "b": 85
    },
    {
      "x": 17,
      "y": 12,
      "z": 12,
      "r": 95,
      "g": 90,
      "b": 85
    },
    {
      "x": 17,
      "y": 2,
      "z": 11,
      "r": 95,
      "g": 90,
      "b": 85
    },
    {
      "x": 17,
      "y": 3,
      "z": 11,
      "r": 95,
      "g": 90,
      "b": 85
    },
    {
      "x": 17,
      "y": 4,
      "z": 11,
      "r": 95,
      "g": 90,
      "b": 85
    },
    {
      "x": 17,
      "y": 5,
      "z": 11,
      "r": 95,
      "g": 90,
      "b": 85
    },
    {
      "x": 17,
      "y": 6,
      "z": 11,
      "r": 95,
      "g": 90,
      "b": 85
    },
    {
      "x": 17,
      "y": 7,
      "z": 11,
      "r": 95,
      "g": 90,
      "b": 85
    },
    {
      "x": 17,
      "y": 8,
      "z": 11,
      "r": 95,
      "g": 90,
      "b": 85
    },
    {
      "x": 17,
      "y": 9,
      "z": 11,
      "r": 95,
      "g": 90,
      "b": 85
    },
    {
      "x": 17,
      "y": 10,
      "z": 11,
      "r": 95,
      "g": 90,
      "b": 85
    },
    {
      "x": 17,
      "y": 11,
      "z": 11,
      "r": 95,
      "g": 90,
      "b": 85
    },
    {
      "x": 17,
      "y": 12,
      "z": 11,
      "r": 95,
      "g": 90,
      "b": 85
    },
    {
      "x": 16,
      "y": 3,
      "z": 9,
      "r": 95,
      "g": 90,
      "b": 85
    },
    {
      "x": 16,
      "y": 4,
      "z": 9,
      "r": 95,
      "g": 90,
      "b": 85
    },
    {
      "x": 16,
      "y": 5,
      "z": 9,
      "r": 95,
      "g": 90,
      "b": 85
    },
    {
      "x": 16,
      "y": 6,
      "z": 9,
      "r": 95,
      "g": 90,
      "b": 85
    },
    {
      "x": 16,
      "y": 7,
      "z": 9,
      "r": 95,
      "g": 90,
      "b": 85
    },
    {
      "x": 16,
      "y": 8,
      "z": 9,
      "r": 95,
      "g": 90,
      "b": 85
    },
    {
      "x": 16,
      "y": 9,
      "z": 9,
      "r": 95,
      "g": 90,
      "b": 85
    },
    {
      "x": 16,
      "y": 10,
      "z": 9,
      "r": 95,
      "g": 90,
      "b": 85
    },
    {
      "x": 16,
      "y": 11,
      "z": 9,
      "r": 95,
      "g": 90,
      "b": 85
    },
    {
      "x": 16,
      "y": 12,
      "z": 9,
      "r": 95,
      "g": 90,
      "b": 85
    },
    {
      "x": 15,
      "y": 2,
      "z": 12,
      "r": 95,
      "g": 90,
      "b": 85
    },
    {
      "x": 15,
      "y": 3,
      "z": 12,
      "r": 95,
      "g": 90,
      "b": 85
    },
    {
      "x": 15,
      "y": 4,
      "z": 12,
      "r": 95,
      "g": 90,
      "b": 85
    },
    {
      "x": 15,
      "y": 5,
      "z": 12,
      "r": 95,
      "g": 90,
      "b": 85
    },
    {
      "x": 15,
      "y": 6,
      "z": 12,
      "r": 95,
      "g": 90,
      "b": 85
    },
    {
      "x": 15,
      "y": 7,
      "z": 12,
      "r": 95,
      "g": 90,
      "b": 85
    },
    {
      "x": 15,
      "y": 8,
      "z": 12,
      "r": 95,
      "g": 90,
      "b": 85
    },
    {
      "x": 15,
      "y": 9,
      "z": 12,
      "r": 95,
      "g": 90,
      "b": 85
    },
    {
      "x": 15,
      "y": 10,
      "z": 12,
      "r": 95,
      "g": 90,
      "b": 85
    },
    {
      "x": 15,
      "y": 11,
      "z": 12,
      "r": 95,
      "g": 90,
      "b": 85
    },
    {
      "x": 15,
      "y": 12,
      "z": 12,
      "r": 95,
      "g": 90,
      "b": 85
    },
    {
      "x": 14,
      "y": 3,
      "z": 10,
      "r": 95,
      "g": 90,
      "b": 85
    },
    {
      "x": 14,
      "y": 4,
      "z": 10,
      "r": 95,
      "g": 90,
      "b": 85
    },
    {
      "x": 14,
      "y": 5,
      "z": 10,
      "r": 95,
      "g": 90,
      "b": 85
    },
    {
      "x": 14,
      "y": 6,
      "z": 10,
      "r": 95,
      "g": 90,
      "b": 85
    },
    {
      "x": 14,
      "y": 7,
      "z": 10,
      "r": 95,
      "g": 90,
      "b": 85
    },
    {
      "x": 14,
      "y": 8,
      "z": 10,
      "r": 95,
      "g": 90,
      "b": 85
    },
    {
      "x": 14,
      "y": 9,
      "z": 10,
      "r": 95,
      "g": 90,
      "b": 85
    },
    {
      "x": 14,
      "y": 10,
      "z": 10,
      "r": 95,
      "g": 90,
      "b": 85
    },
    {
      "x": 14,
      "y": 11,
      "z": 10,
      "r": 95,
      "g": 90,
      "b": 85
    },
    {
      "x": 14,
      "y": 12,
      "z": 10,
      "r": 95,
      "g": 90,
      "b": 85
    },
    {
      "x": 15,
      "y": 2,
      "z": 8,
      "r": 95,
      "g": 90,
      "b": 85
    },
    {
      "x": 15,
      "y": 1,
      "z": 12,
      "r": 95,
      "g": 90,
      "b": 85
    },
    {
      "x": 16,
      "y": 1,
      "z": 12,
      "r": 95,
      "g": 90,
      "b": 85
    },
    {
      "x": 17,
      "y": 1,
      "z": 12,
      "r": 95,
      "g": 90,
      "b": 85
    },
    {
      "x": 17,
      "y": 1,
      "z": 11,
      "r": 95,
      "g": 90,
      "b": 85
    },
    {
      "x": 17,
      "y": 1,
      "z": 10,
      "r": 95,
      "g": 90,
      "b": 85
    },
    {
      "x": 17,
      "y": 1,
      "z": 9,
      "r": 95,
      "g": 90,
      "b": 85
    },
    {
      "x": 16,
      "y": 1,
      "z": 9,
      "r": 95,
      "g": 90,
      "b": 85
    },
    {
      "x": 15,
      "y": 1,
      "z": 9,
      "r": 95,
      "g": 90,
      "b": 85
    },
    {
      "x": 14,
      "y": 1,
      "z": 9,
      "r": 95,
      "g": 90,
      "b": 85
    },
    {
      "x": 14,
      "y": 1,
      "z": 10,
      "r": 95,
      "g": 90,
      "b": 85
    },
    {
      "x": 14,
      "y": 1,
      "z": 11,
      "r": 95,
      "g": 90,
      "b": 85
    },
    {
      "x": 14,
      "y": 1,
      "z": 12,
      "r": 95,
      "g": 90,
      "b": 85
    },
    {
      "x": 13,
      "y": 2,
      "z": 11,
      "r": 95,
      "g": 90,
      "b": 85
    },
    {
      "x": 13,
      "y": 2,
      "z": 10,
      "r": 95,
      "g": 90,
      "b": 85
    },
    {
      "x": 15,
      "y": 1,
      "z": 13,
      "r": 95,
      "g": 90,
      "b": 85
    },
    {
      "x": 13,
      "y": 1,
      "z": 10,
      "r": 95,
      "g": 90,
      "b": 85
    },
    {
      "x": 16,
      "y": 1,
      "z": 8,
      "r": 95,
      "g": 90,
      "b": 85
    },
    {
      "x": 13,
      "y": 1,
      "z": 11,
      "r": 95,
      "g": 90,
      "b": 85
    },
    {
      "x": 15,
      "y": 1,
      "z": 8,
      "r": 95,
      "g": 90,
      "b": 85
    },
    {
      "x": 18,
      "y": 1,
      "z": 10,
      "r": 95,
      "g": 90,
      "b": 85
    },
    {
      "x": 18,
      "y": 1,
      "z": 11,
      "r": 95,
      "g": 90,
      "b": 85
    },
    {
      "x": 13,
      "y": 1,
      "z": 9,
      "r": 95,
      "g": 90,
      "b": 85
    },
    {
      "x": 17,
      "y": 1,
      "z": 8,
      "r": 95,
      "g": 90,
      "b": 85
    },
    {
      "x": 16,
      "y": 1,
      "z": 13,
      "r": 95,
      "g": 90,
      "b": 85
    },
    {
      "x": 14,
      "y": 1,
      "z": 8,
      "r": 95,
      "g": 90,
      "b": 85
    },
    {
      "x": 16,
      "y": 2,
      "z": 8,
      "r": 95,
      "g": 90,
      "b": 85
    }
  ]
}