{
  "resolution": 96,
  "gridSize": {
    "x": 46,
    "y": 83,
    "z": 96
  },
  "voxelCount": 15567,
  "voxels": [
    {
      "x": 20,
      "y": 21,
      "z": 17,
      "r": 80,
      "g": 50,
      "b": 30
    },
    {
      "x": 20,
      "y": 22,
      "z": 17,
      "r": 80,
      "g": 50,
      "b": 30
    },
    {
      "x": 21,
      "y": 22,
      "z": 17,
      "r": 80,
      "g": 50,
      "b": 30
    },
    {
      "x": 21,
      "y": 23,
      "z": 17,
      "r": 80,
      "g": 50,
      "b": 30
    },
    {
      "x": 22,
      "y": 23,
      "z": 17,
      "r": 80,
      "g": 50,
      "b": 30
    },
    {
      "x": 23,
      "y": 23,
      "z": 17,
      "r": 80,
      "g": 50,
      "b": 30
    },
    {
      "x": 23,
      "y": 22,
      "z": 17,
      "r": 80,
      "g": 50,
      "b": 30
    },
    {
      "x": 24,
      "y": 22,
      "z": 17,
      "r": 80,
      "g": 50,
      "b": 30
    },
    {
      "x": 24,
      "y": 21,
      "z": 17,
      "r": 80,
      "g": 50,
      "b": 30
    },
    {
      "x": 24,
      "y": 20,
      "z": 17,
      "r": 80,
      "g": 50,
      "b": 30
    },
    {
      "x": 23,
      "y": 19,
      "z": 17,
      "r": 80,
      "g": 50,
      "b": 30
    },
    {
      "x": 23,
      "y": 20,
      "z": 17,
      "r": 80,
      "g": 50,
      "b": 30
    },
    {
      "x": 22,
      "y": 19,
      "z": 17,
      "r": 80,
      "g": 50,
      "b": 30
    },
    {
      "x": 21,
      "y": 19,
      "z": 17,
      "r": 80,
      "g": 50,
      "b": 30
    },
    {
      "x": 21,
      "y": 20,
      "z": 17,
      "r": 80,
      "g": 50,
      "b": 30
    },
    {
      "x": 20,
      "y": 20,
      "z": 17,
      "r": 80,
      "g": 50,
      "b": 30
    },
    {
      "x": 20,
      "y": 21,
      "z": 16,
      "r": 80,
      "g": 50,
      "b": 30
    },
    {
      "x": 20,
      "y": 22,
      "z": 16,
      "r": 80,
      "g": 50,
      "b": 30
    },
    {
      "x": 21,
      "y": 22,
      "z": 16,
      "r": 80,
      "g": 50,
      "b": 30
    },
    {
      "x": 21,
      "y": 23,
      "z": 16,
      "r": 80,
      "g": 50,
      "b": 30
    },
    {
      "x": 22,
      "y": 23,
      "z": 16,
      "r": 80,
      "g": 50,
      "b": 30
    },
    {
      "x": 23,
      "y": 23,
      "z": 16,
      "r": 80,
      "g": 50,
      "b": 30
    },
    {
      "x": 23,
      "y": 22,
      "z": 16,
      "r": 80,
      "g": 50,
      "b": 30
    },
    {
      "x": 24,
      "y": 22,
      "z": 16,
      "r": 80,
      "g": 50,
      "b": 30
    },
    {
      "x": 24,
      "y": 21,
      "z": 16,
      "r": 80,
      "g": 50,
      "b": 30
    },
    {
      "x": 24,
      "y": 20,
      "z": 16,
      "r": 80,
      "g": 50,
      "b": 30
    },
    {
      "x": 23,
      "y": 19,
      "z": 16,
      "r": 80,
      "g": 50,
      "b": 30
    },
    {
      "x": 23,
      "y": 20,
      "z": 16,
      "r": 80,
      "g": 50,
      "b": 30
    },
    {
      "x": 24,
      "y": 19,
      "z": 16,
      "r": 80,
      "g": 50,
      "b": 30
    },
    {
      "x": 22,
      "y": 19,
      "z": 16,
      "r": 80,
      "g": 50,
      "b": 30
    },
    {
      "x": 21,
      "y": 19,
      "z": 16,
      "r": 80,
      "g": 50,
      "b": 30
    },
    {
      "x": 20,
      "y": 20,
      "z": 16,
      "r": 80,
      "g": 50,
      "b": 30
    },
    {
      "x": 21,
      "y": 20,
      "z": 16,
      "r": 80,
      "g": 50,
      "b": 30
    },
    {
      "x": 20,
      "y": 23,
      "z": 16,
      "r": 80,
      "g": 50,
      "b": 30
    },
    {
      "x": 24,
      "y": 23,
      "z": 16,
      "r": 80,
      "g": 50,
      "b": 30
    },
    {
      "x": 20,
      "y": 19,
      "z": 16,
      "r": 80,
      "g": 50,
      "b": 30
    },
    {
      "x": 20,
      "y": 23,
      "z": 17,
      "r": 80,
      "g": 50,
      "b": 30
    },
    {
      "x": 24,
      "y": 23,
      "z": 17,
      "r": 80,
      "g": 50,
      "b": 30
    },
    {
      "x": 24,
      "y": 19,
      "z": 17,
      "r": 80,
      "g": 50,
      "b": 30
    },
    {
      "x": 20,
      "y": 19,
      "z": 17,
      "r": 80,
      "g": 50,
      "b": 30
    },
    {
      "x": 22,
      "y": 21,
      "z": 17,
      "r": 80,
      "g": 50,
      "b": 30
    },
    {
      "x": 23,
      "y": 21,
      "z": 17,
      "r": 80,
      "g": 50,
      "b": 30
    },
    {
      "x": 22,
      "y": 21,
      "z": 16,
      "r": 80,
      "g": 50,
      "b": 30
    },
    {
      "x": 23,
      "y": 21,
      "z": 16,
      "r": 80,
      "g": 50,
      "b": 30
    },
    {
      "x": 22,
      "y": 22,
      "z": 17,
      "r": 80,
      "g": 50,
      "b": 30
    },
    {
      "x": 22,
      "y": 22,
      "z": 16,
      "r": 80,
      "g": 50,
      "b": 30
    },
    {
      "x": 19,
      "y": 21,
      "z": 17,
      "r": 80,
      "g": 50,
      "b": 30
    },
    {
      "x": 19,
      "y": 21,
      "z": 16,
      "r": 80,
      "g": 50,
      "b": 30
    },
    {
      "x": 19,
      "y": 20,
      "z": 17,
      "r": 80,
      "g": 50,
      "b": 30
    },
    {
      "x": 19,
      "y": 20,
      "z": 16,
      "r": 80,
      "g": 50,
      "b": 30
    },
    {
      "x": 20,
      "y": 18,
      "z": 17,
      "r": 80,
      "g": 50,
      "b": 30
    },
    {
      "x": 20,
      "y": 18,
      "z": 16,
      "r": 80,
      "g": 50,
      "b": 30
    },
    {
      "x": 22,
      "y": 18,
      "z": 17,
      "r": 80,
      "g": 50,
      "b": 30
    },
    {
      "x": 22,
      "y": 18,
      "z": 16,
      "r": 80,
      "g": 50,
      "b": 30
    },
    {
      "x": 25,
      "y": 19,
      "z": 17,
      "r": 80,
      "g": 50,
      "b": 30
    },
    {
      "x": 24,
      "y": 18,
      "z": 17,
      "r": 80,
      "g": 50,
      "b": 30
    },
    {
      "x": 24,
      "y": 18,
      "z": 16,
      "r": 80,
      "g": 50,
      "b": 30
    },
    {
      "x": 25,
      "y": 21,
      "z": 17,
      "r": 80,
      "g": 50,
      "b": 30
    },
    {
      "x": 25,
      "y": 21,
      "z": 16,
      "r": 80,
      "g": 50,
      "b": 30
    },
    {
      "x": 25,
      "y": 20,
      "z": 17,
      "r": 80,
      "g": 50,
      "b": 30
    },
    {
      "x": 25,
      "y": 20,
      "z": 16,
      "r": 80,
      "g": 50,
      "b": 30
    },
    {
      "x": 25,
      "y": 23,
      "z": 17,
      "r": 80,
      "g": 50,
      "b": 30
    },
    {
      "x": 22,
      "y": 24,
      "z": 17,
      "r": 80,
      "g": 50,
      "b": 30
    },
    {
      "x": 22,
      "y": 24,
      "z": 16,
      "r": 80,
      "g": 50,
      "b": 30
    },
    {
      "x": 22,
      "y": 15,
      "z": 18,
      "r": 80,
      "g": 50,
      "b": 30
    },
    {
      "x": 22,
      "y": 16,
      "z": 18,
      "r": 80,
      "g": 50,
      "b": 30
    },
    {
      "x": 22,
      "y": 17,
      "z": 18,
      "r": 80,
      "g": 50,
      "b": 30
    },
    {
      "x": 22,
      "y": 18,
      "z": 18,
      "r": 80,
      "g": 50,
      "b": 30
    },
    {
      "x": 22,
      "y": 19,
      "z": 18,
      "r": 80,
      "g": 50,
      "b": 30
    },
    {
      "x": 22,
      "y": 20,
      "z": 18,
      "r": 80,
      "g": 50,
      "b": 30
    },
    {
      "x": 22,
      "y": 21,
      "z": 18,
      "r": 80,
      "g": 50,
      "b": 30
    },
    {
      "x": 22,
      "y": 14,
      "z": 18,
      "r": 80,
      "g": 50,
      "b": 30
    },
    {
      "x": 21,
      "y": 21,
      "z": 17,
      "r": 80,
      "g": 50,
      "b": 30
    },
    {
      "x": 21,
      "y": 21,
      "z": 16,
      "r": 80,
      "g": 50,
      "b": 30
    },
    {
      "x": 22,
      "y": 20,
      "z": 17,
      "r": 80,
      "g": 50,
      "b": 30
    },
    {
      "x": 22,
      "y": 20,
      "z": 16,
      "r": 80,
      "g": 50,
      "b": 30
    },
    {
      "x": 32,
      "y": 18,
      "z": 69,
      "r": 148,
      "g": 98,
      "b": 52
    },
    {
      "x": 32,
      "y": 18,
      "z": 70,
      "r": 148,
      "g": 98,
      "b": 52
    },
    {
      "x": 32,
      "y": 17,
      "z": 69,
      "r": 148,
      "g": 98,
      "b": 52
    },
    {
      "x": 32,
      "y": 16,
      "z": 69,
      "r": 148,
      "g": 98,
      "b": 52
    },
    {
      "x": 31,
      "y": 16,
      "z": 69,
      "r": 148,
      "g": 98,
      "b": 52
    },
    {
      "x": 31,
      "y": 17,
      "z": 69,
      "r": 148,
      "g": 98,
      "b": 52
    },
    {
      "x": 31,
      "y": 16,
      "z": 70,
      "r": 148,
      "g": 98,
      "b": 52
    },
    {
      "x": 31,
      "y": 17,
      "z": 70,
      "r": 148,
      "g": 98,
      "b": 52
    },
    {
      "x": 31,
      "y": 17,
      "z": 71,
      "r": 148,
      "g": 98,
      "b": 52
    },
    {
      "x": 31,
      "y": 18,
      "z": 71,
      "r": 148,
      "g": 98,
      "b": 52
    },
    {
      "x": 31,
      "y": 18,
      "z": 70,
      "r": 148,
      "g": 98,
      "b": 52
    },
    {
      "x": 32,
      "y": 17,
      "z": 70,
      "r": 148,
      "g": 98,
      "b": 52
    },
    {
      "x": 31,
      "y": 18,
      "z": 69,
      "r": 148,
      "g": 98,
      "b": 52
    },
    {
      "x": 12,
      "y": 18,
      "z": 69,
      "r": 148,
      "g": 98,
      "b": 52
    },
    {
      "x": 12,
      "y": 18,
      "z": 70,
      "r": 148,
      "g": 98,
      "b": 52
    },
    {
      "x": 13,
      "y": 18,
      "z": 69,
      "r": 148,
      "g": 98,
      "b": 52
    },
    {
      "x": 13,
      "y": 18,
      "z": 70,
      "r": 148,
      "g": 98,
      "b": 52
    },
    {
      "x": 12,
      "y": 17,
      "z": 69,
      "r": 148,
      "g": 98,
      "b": 52
    },
    {
      "x": 13,
      "y": 17,
      "z": 69,
      "r": 148,
      "g": 98,
      "b": 52
    },
    {
      "x": 13,
      "y": 16,
      "z": 69,
      "r": 148,
      "g": 98,
      "b": 52
    },
    {
      "x": 13,
      "y": 16,
      "z": 70,
      "r": 148,
      "g": 98,
      "b": 52
    },
    {
      "x": 13,
      "y": 17,
      "z": 70,
      "r": 148,
      "g": 98,
      "b": 52
    },
    {
      "x": 13,
      "y": 17,
      "z": 71,
      "r": 148,
      "g": 98,
      "b": 52
    },
    {
      "x": 13,
      "y": 18,
      "z": 71,
      "r": 148,
      "g": 98,
      "b": 52
    },
    {
      "x": 14,
      "y": 16,
      "z": 70,
      "r": 148,
      "g": 98,
      "b": 52
    },
    {
      "x": 14,
      "y": 17,
      "z": 70,
      "r": 148,
      "g": 98,
      "b": 52
    },
    {
      "x": 14,
      "y": 17,
      "z": 71,
      "r": 148,
      "g": 98,
      "b": 52
    },
    {
      "x": 14,
      "y": 18,
      "z": 70,
      "r": 148,
      "g": 98,
      "b": 52
    },
    {
      "x": 14,
      "y": 18,
      "z": 71,
      "r": 148,
      "g": 98,
      "b": 52
    },
    {
      "x": 13,
      "y": 13,
      "z": 7,
      "r": 120,
      "g": 80,
      "b": 40
    },
    {
      "x": 13,
      "y": 13,
      "z": 8,
      "r": 120,
      "g": 80,
      "b": 40
    },
    {
      "x": 13,
      "y": 13,
      "z": 9,
      "r": 120,
      "g": 80,
      "b": 40
    },
    {
      "x": 14,
      "y": 12,
      "z": 6,
      "r": 120,
      "g": 80,
      "b": 40
    },
    {
      "x": 14,
      "y": 12,
      "z": 7,
      "r": 120,
      "g": 80,
      "b": 40
    },
    {
      "x": 14,
      "y": 13,
      "z": 6,
      "r": 120,
      "g": 80,
      "b": 40
    },
    {
      "x": 14,
      "y": 13,
      "z": 7,
      "r": 120,
      "g": 80,
      "b": 40
    },
    {
      "x": 14,
      "y": 13,
      "z": 8,
      "r": 120,
      "g": 80,
      "b": 40
    },
    {
      "x": 15,
      "y": 12,
      "z": 5,
      "r": 120,
      "g": 80,
      "b": 40
    },
    {
      "x": 15,
      "y": 12,
      "z": 6,
      "r": 120,
      "g": 80,
      "b": 40
    },
    {
      "x": 15,
      "y": 13,
      "z": 5,
      "r": 120,
      "g": 80,
      "b": 40
    },
    {
      "x": 15,
      "y": 13,
      "z": 6,
      "r": 120,
      "g": 80,
      "b": 40
    },
    {
      "x": 13,
      "y": 12,
      "z": 8,
      "r": 120,
      "g": 80,
      "b": 40
    },
    {
      "x": 13,
      "y": 12,
      "z": 9,
      "r": 120,
      "g": 80,
      "b": 40
    },
    {
      "x": 14,
      "y": 12,
      "z": 8,
      "r": 120,
      "g": 80,
      "b": 40
    },
    {
      "x": 15,
      "y": 13,
      "z": 4,
      "r": 120,
      "g": 80,
      "b": 40
    },
    {
      "x": 16,
      "y": 12,
      "z": 4,
      "r": 120,
      "g": 80,
      "b": 40
    },
    {
      "x": 16,
      "y": 13,
      "z": 4,
      "r": 120,
      "g": 80,
      "b": 40
    },
    {
      "x": 17,
      "y": 12,
      "z": 4,
      "r": 120,
      "g": 80,
      "b": 40
    },
    {
      "x": 17,
      "y": 13,
      "z": 3,
      "r": 120,
      "g": 80,
      "b": 40
    },
    {
      "x": 17,
      "y": 13,
      "z": 4,
      "r": 120,
      "g": 80,
      "b": 40
    },
    {
      "x": 18,
      "y": 12,
      "z": 4,
      "r": 120,
      "g": 80,
      "b": 40
    },
    {
      "x": 18,
      "y": 13,
      "z": 3,
      "r": 120,
      "g": 80,
      "b": 40
    },
    {
      "x": 18,
      "y": 13,
      "z": 4,
      "r": 120,
      "g": 80,
      "b": 40
    },
    {
      "x": 16,
      "y": 12,
      "z": 5,
      "r": 120,
      "g": 80,
      "b": 40
    },
    {
      "x": 16,
      "y": 13,
      "z": 5,
      "r": 120,
      "g": 80,
      "b": 40
    },
    {
      "x": 18,
      "y": 12,
      "z": 3,
      "r": 120,
      "g": 80,
      "b": 40
    },
    {
      "x": 19,
      "y": 12,
      "z": 3,
      "r": 120,
      "g": 80,
      "b": 40
    },
    {
      "x": 19,
      "y": 13,
      "z": 3,
      "r": 120,
      "g": 80,
      "b": 40
    },
    {
      "x": 20,
      "y": 12,
      "z": 3,
      "r": 120,
      "g": 80,
      "b": 40
    },
    {
      "x": 20,
      "y": 13,
      "z": 3,
      "r": 120,
      "g": 80,
      "b": 40
    },
    {
      "x": 21,
      "y": 12,
      "z": 3,
      "r": 120,
      "g": 80,
      "b": 40
    },
    {
      "x": 21,
      "y": 13,
      "z": 3,
      "r": 120,
      "g": 80,
      "b": 40
    },
    {
      "x": 22,
      "y": 12,
      "z": 3,
      "r": 120,
      "g": 80,
      "b": 40
    },
    {
      "x": 22,
      "y": 13,
      "z": 3,
      "r": 120,
      "g": 80,
      "b": 40
    },
    {
      "x": 19,
      "y": 12,
      "z": 4,
      "r": 120,
      "g": 80,
      "b": 40
    },
    {
      "x": 23,
      "y": 12,
      "z": 3,
      "r": 120,
      "g": 80,
      "b": 40
    },
    {
      "x": 24,
      "y": 12,
      "z": 3,
      "r": 120,
      "g": 80,
      "b": 40
    },
    {
      "x": 23,
      "y": 13,
      "z": 3,
      "r": 120,
      "g": 80,
      "b": 40
    },
    {
      "x": 24,
      "y": 13,
      "z": 3,
      "r": 120,
      "g": 80,
      "b": 40
    },
    {
      "x": 25,
      "y": 12,
      "z": 3,
      "r": 120,
      "g": 80,
      "b": 40
    },
    {
      "x": 25,
      "y": 13,
      "z": 3,
      "r": 120,
      "g": 80,
      "b": 40
    },
    {
      "x": 26,
      "y": 12,
      "z": 3,
      "r": 120,
      "g": 80,
      "b": 40
    },
    {
      "x": 26,
      "y": 13,
      "z": 3,
      "r": 120,
      "g": 80,
      "b": 40
    },
    {
      "x": 27,
      "y": 13,
      "z": 3,
      "r": 120,
      "g": 80,
      "b": 40
    },
    {
      "x": 26,
      "y": 12,
      "z": 4,
      "r": 120,
      "g": 80,
      "b": 40
    },
    {
      "x": 26,
      "y": 13,
      "z": 4,
      "r": 120,
      "g": 80,
      "b": 40
    },
    {
      "x": 27,
      "y": 12,
      "z": 4,
      "r": 120,
      "g": 80,
      "b": 40
    },
    {
      "x": 27,
      "y": 13,
      "z": 4,
      "r": 120,
      "g": 80,
      "b": 40
    },
    {
      "x": 28,
      "y": 12,
      "z": 4,
      "r": 120,
      "g": 80,
      "b": 40
    },
    {
      "x": 28,
      "y": 12,
      "z": 5,
      "r": 120,
      "g": 80,
      "b": 40
    },
    {
      "x": 29,
      "y": 12,
      "z": 5,
      "r": 120,
      "g": 80,
      "b": 40
    },
    {
      "x": 28,
      "y": 13,
      "z": 4,
      "r": 120,
      "g": 80,
      "b": 40
    },
    {
      "x": 29,
      "y": 13,
      "z": 4,
      "r": 120,
      "g": 80,
      "b": 40
    },
    {
      "x": 29,
      "y": 13,
      "z": 5,
      "r": 120,
      "g": 80,
      "b": 40
    },
    {
      "x": 29,
      "y": 12,
      "z": 4,
      "r": 120,
      "g": 80,
      "b": 40
    },
    {
      "x": 29,
      "y": 12,
      "z": 6,
      "r": 120,
      "g": 80,
      "b": 40
    },
    {
      "x": 29,
      "y": 13,
      "z": 6,
      "r": 120,
      "g": 80,
      "b": 40
    },
    {
      "x": 30,
      "y": 12,
      "z": 6,
      "r": 120,
      "g": 80,
      "b": 40
    },
    {
      "x": 30,
      "y": 12,
      "z": 7,
      "r": 120,
      "g": 80,
      "b": 40
    },
    {
      "x": 30,
      "y": 13,
      "z": 5,
      "r": 120,
      "g": 80,
      "b": 40
    },
    {
      "x": 30,
      "y": 13,
      "z": 6,
      "r": 120,
      "g": 80,
      "b": 40
    },
    {
      "x": 30,
      "y": 13,
      "z": 7,
      "r": 120,
      "g": 80,
      "b": 40
    },
    {
      "x": 31,
      "y": 13,
      "z": 7,
      "r": 120,
      "g": 80,
      "b": 40
    },
    {
      "x": 31,
      "y": 13,
      "z": 8,
      "r": 120,
      "g": 80,
      "b": 40
    },
    {
      "x": 30,
      "y": 12,
      "z": 8,
      "r": 120,
      "g": 80,
      "b": 40
    },
    {
      "x": 31,
      "y": 12,
      "z": 7,
      "r": 120,
      "g": 80,
      "b": 40
    },
    {
      "x": 31,
      "y": 12,
      "z": 8,
      "r": 120,
      "g": 80,
      "b": 40
    },
    {
      "x": 31,
      "y": 12,
      "z": 9,
      "r": 120,
      "g": 80,
      "b": 40
    },
    {
      "x": 31,
      "y": 13,
      "z": 9,
      "r": 120,
      "g": 80,
      "b": 40
    },
    {
      "x": 34,
      "y": 13,
      "z": 18,
      "r": 120,
      "g": 80,
      "b": 40
    },
    {
      "x": 34,
      "y": 13,
      "z": 19,
      "r": 120,
      "g": 80,
      "b": 40
    },
    {
      "x": 34,
      "y": 13,
      "z": 20,
      "r": 120,
      "g": 80,
      "b": 40
    },
    {
      "x": 34,
      "y": 13,
      "z": 21,
      "r": 120,
      "g": 80,
      "b": 40
    },
    {
      "x": 34,
      "y": 13,
      "z": 22,
      "r": 120,
      "g": 80,
      "b": 40
    },
    {
      "x": 35,
      "y": 13,
      "z": 21,
      "r": 120,
      "g": 80,
      "b": 40
    },
    {
      "x": 35,
      "y": 13,
      "z": 22,
      "r": 120,
      "g": 80,
      "b": 40
    },
    {
      "x": 35,
      "y": 13,
      "z": 23,
      "r": 120,
      "g": 80,
      "b": 40
    },
    {
      "x": 35,
      "y": 13,
      "z": 24,
      "r": 120,
      "g": 80,
      "b": 40
    },
    {
      "x": 35,
      "y": 13,
      "z": 25,
      "r": 120,
      "g": 80,
      "b": 40
    },
    {
      "x": 35,
      "y": 13,
      "z": 26,
      "r": 120,
      "g": 80,
      "b": 40
    },
    {
      "x": 35,
      "y": 14,
      "z": 22,
      "r": 120,
      "g": 80,
      "b": 40
    },
    {
      "x": 35,
      "y": 14,
      "z": 23,
      "r": 120,
      "g": 80,
      "b": 40
    },
    {
      "x": 35,
      "y": 14,
      "z": 24,
      "r": 120,
      "g": 80,
      "b": 40
    },
    {
      "x": 35,
      "y": 14,
      "z": 25,
      "r": 120,
      "g": 80,
      "b": 40
    },
    {
      "x": 35,
      "y": 14,
      "z": 26,
      "r": 120,
      "g": 80,
      "b": 40
    },
    {
      "x": 36,
      "y": 14,
      "z": 26,
      "r": 120,
      "g": 80,
      "b": 40
    },
    {
      "x": 34,
      "y": 13,
      "z": 17,
      "r": 120,
      "g": 80,
      "b": 40
    },
    {
      "x": 34,
      "y": 14,
      "z": 17,
      "r": 120,
      "g": 80,
      "b": 40
    },
    {
      "x": 34,
      "y": 14,
      "z": 18,
      "r": 120,
      "g": 80,
      "b": 40
    },
    {
      "x": 34,
      "y": 14,
      "z": 19,
      "r": 120,
      "g": 80,
      "b": 40
    },
    {
      "x": 34,
      "y": 14,
      "z": 20,
      "r": 120,
      "g": 80,
      "b": 40
    },
    {
      "x": 34,
      "y": 14,
      "z": 21,
      "r": 120,
      "g": 80,
      "b": 40
    },
    {
      "x": 35,
      "y": 14,
      "z": 21,
      "r": 120,
      "g": 80,
      "b": 40
    },
    {
      "x": 31,
      "y": 12,
      "z": 10,
      "r": 120,
      "g": 80,
      "b": 40
    },
    {
      "x": 32,
      "y": 12,
      "z": 10,
      "r": 120,
      "g": 80,
      "b": 40
    },
    {
      "x": 32,
      "y": 12,
      "z": 11,
      "r": 120,
      "g": 80,
      "b": 40
    },
    {
      "x": 32,
      "y": 12,
      "z": 12,
      "r": 120,
      "g": 80,
      "b": 40
    },
    {
      "x": 32,
      "y": 12,
      "z": 13,
      "r": 120,
      "g": 80,
      "b": 40
    },
    {
      "x": 32,
      "y": 13,
      "z": 13,
      "r": 120,
      "g": 80,
      "b": 40
    },
    {
      "x": 32,
      "y": 13,
      "z": 14,
      "r": 120,
      "g": 80,
      "b": 40
    },
    {
      "x": 33,
      "y": 13,
      "z": 13,
      "r": 120,
      "g": 80,
      "b": 40
    },
    {
      "x": 33,
      "y": 13,
      "z": 14,
      "r": 120,
      "g": 80,
      "b": 40
    },
    {
      "x": 33,
      "y": 13,
      "z": 15,
      "r": 120,
      "g": 80,
      "b": 40
    },
    {
      "x": 33,
      "y": 13,
      "z": 16,
      "r": 120,
      "g": 80,
      "b": 40
    },
    {
      "x": 33,
      "y": 13,
      "z": 17,
      "r": 120,
      "g": 80,
      "b": 40
    },
    {
      "x": 32,
      "y": 13,
      "z": 11,
      "r": 120,
      "g": 80,
      "b": 40
    },
    {
      "x": 32,
      "y": 13,
      "z": 12,
      "r": 120,
      "g": 80,
      "b": 40
    },
    {
      "x": 31,
      "y": 13,
      "z": 10,
      "r": 120,
      "g": 80,
      "b": 40
    },
    {
      "x": 32,
      "y": 13,
      "z": 9,
      "r": 120,
      "g": 80,
      "b": 40
    },
    {
      "x": 32,
      "y": 13,
      "z": 10,
      "r": 120,
      "g": 80,
      "b": 40
    },
    {
      "x": 33,
      "y": 14,
      "z": 16,
      "r": 120,
      "g": 80,
      "b": 40
    },
    {
      "x": 33,
      "y": 14,
      "z": 17,
      "r": 120,
      "g": 80,
      "b": 40
    },
    {
      "x": 34,
      "y": 14,
      "z": 16,
      "r": 120,
      "g": 80,
      "b": 40
    },
    {
      "x": 10,
      "y": 13,
      "z": 18,
      "r": 120,
      "g": 80,
      "b": 40
    },
    {
      "x": 11,
      "y": 13,
      "z": 14,
      "r": 120,
      "g": 80,
      "b": 40
    },
    {
      "x": 11,
      "y": 13,
      "z": 15,
      "r": 120,
      "g": 80,
      "b": 40
    },
    {
      "x": 11,
      "y": 13,
      "z": 16,
      "r": 120,
      "g": 80,
      "b": 40
    },
    {
      "x": 11,
      "y": 13,
      "z": 17,
      "r": 120,
      "g": 80,
      "b": 40
    },
    {
      "x": 11,
      "y": 13,
      "z": 18,
      "r": 120,
      "g": 80,
      "b": 40
    },
    {
      "x": 12,
      "y": 12,
      "z": 11,
      "r": 120,
      "g": 80,
      "b": 40
    },
    {
      "x": 12,
      "y": 12,
      "z": 12,
      "r": 120,
      "g": 80,
      "b": 40
    },
    {
      "x": 12,
      "y": 12,
      "z": 13,
      "r": 120,
      "g": 80,
      "b": 40
    },
    {
      "x": 12,
      "y": 12,
      "z": 14,
      "r": 120,
      "g": 80,
      "b": 40
    },
    {
      "x": 12,
      "y": 13,
      "z": 13,
      "r": 120,
      "g": 80,
      "b": 40
    },
    {
      "x": 12,
      "y": 13,
      "z": 14,
      "r": 120,
      "g": 80,
      "b": 40
    },
    {
      "x": 13,
      "y": 12,
      "z": 10,
      "r": 120,
      "g": 80,
      "b": 40
    },
    {
      "x": 13,
      "y": 12,
      "z": 11,
      "r": 120,
      "g": 80,
      "b": 40
    },
    {
      "x": 12,
      "y": 12,
      "z": 10,
      "r": 120,
      "g": 80,
      "b": 40
    },
    {
      "x": 9,
      "y": 13,
      "z": 23,
      "r": 120,
      "g": 80,
      "b": 40
    },
    {
      "x": 9,
      "y": 13,
      "z": 24,
      "r": 120,
      "g": 80,
      "b": 40
    },
    {
      "x": 9,
      "y": 13,
      "z": 25,
      "r": 120,
      "g": 80,
      "b": 40
    },
    {
      "x": 9,
      "y": 13,
      "z": 26,
      "r": 120,
      "g": 80,
      "b": 40
    },
    {
      "x": 9,
      "y": 14,
      "z": 26,
      "r": 120,
      "g": 80,
      "b": 40
    },
    {
      "x": 9,
      "y": 14,
      "z": 27,
      "r": 120,
      "g": 80,
      "b": 40
    },
    {
      "x": 10,
      "y": 13,
      "z": 19,
      "r": 120,
      "g": 80,
      "b": 40
    },
    {
      "x": 10,
      "y": 13,
      "z": 20,
      "r": 120,
      "g": 80,
      "b": 40
    },
    {
      "x": 10,
      "y": 13,
      "z": 21,
      "r": 120,
      "g": 80,
      "b": 40
    },
    {
      "x": 10,
      "y": 13,
      "z": 22,
      "r": 120,
      "g": 80,
      "b": 40
    },
    {
      "x": 10,
      "y": 13,
      "z": 23,
      "r": 120,
      "g": 80,
      "b": 40
    },
    {
      "x": 8,
      "y": 14,
      "z": 27,
      "r": 120,
      "g": 80,
      "b": 40
    },
    {
      "x": 9,
      "y": 13,
      "z": 22,
      "r": 120,
      "g": 80,
      "b": 40
    },
    {
      "x": 9,
      "y": 14,
      "z": 22,
      "r": 120,
      "g": 80,
      "b": 40
    },
    {
      "x": 9,
      "y": 14,
      "z": 23,
      "r": 120,
      "g": 80,
      "b": 40
    },
    {
      "x": 9,
      "y": 14,
      "z": 24,
      "r": 120,
      "g": 80,
      "b": 40
    },
    {
      "x": 9,
      "y": 14,
      "z": 25,
      "r": 120,
      "g": 80,
      "b": 40
    },
    {
      "x": 10,
      "y": 14,
      "z": 22,
      "r": 120,
      "g": 80,
      "b": 40
    },
    {
      "x": 10,
      "y": 14,
      "z": 18,
      "r": 120,
      "g": 80,
      "b": 40
    },
    {
      "x": 10,
      "y": 14,
      "z": 19,
      "r": 120,
      "g": 80,
      "b": 40
    },
    {
      "x": 10,
      "y": 14,
      "z": 20,
      "r": 120,
      "g": 80,
      "b": 40
    },
    {
      "x": 10,
      "y": 14,
      "z": 21,
      "r": 120,
      "g": 80,
      "b": 40
    },
    {
      "x": 10,
      "y": 13,
      "z": 17,
      "r": 120,
      "g": 80,
      "b": 40
    },
    {
      "x": 10,
      "y": 14,
      "z": 17,
      "r": 120,
      "g": 80,
      "b": 40
    },
    {
      "x": 11,
      "y": 14,
      "z": 17,
      "r": 120,
      "g": 80,
      "b": 40
    },
    {
      "x": 12,
      "y": 13,
      "z": 11,
      "r": 120,
      "g": 80,
      "b": 40
    },
    {
      "x": 12,
      "y": 13,
      "z": 12,
      "r": 120,
      "g": 80,
      "b": 40
    },
    {
      "x": 12,
      "y": 13,
      "z": 10,
      "r": 120,
      "g": 80,
      "b": 40
    },
    {
      "x": 13,
      "y": 13,
      "z": 10,
      "r": 120,
      "g": 80,
      "b": 40
    },
    {
      "x": 14,
      "y": 12,
      "z": 9,
      "r": 120,
      "g": 80,
      "b": 40
    },
    {
      "x": 14,
      "y": 13,
      "z": 9,
      "r": 120,
      "g": 80,
      "b": 40
    },
    {
      "x": 15,
      "y": 12,
      "z": 7,
      "r": 120,
      "g": 80,
      "b": 40
    },
    {
      "x": 15,
      "y": 13,
      "z": 7,
      "r": 120,
      "g": 80,
      "b": 40
    },
    {
      "x": 17,
      "y": 12,
      "z": 5,
      "r": 120,
      "g": 80,
      "b": 40
    },
    {
      "x": 17,
      "y": 13,
      "z": 5,
      "r": 120,
      "g": 80,
      "b": 40
    },
    {
      "x": 19,
      "y": 13,
      "z": 4,
      "r": 120,
      "g": 80,
      "b": 40
    },
    {
      "x": 20,
      "y": 12,
      "z": 4,
      "r": 120,
      "g": 80,
      "b": 40
    },
    {
      "x": 20,
      "y": 13,
      "z": 4,
      "r": 120,
      "g": 80,
      "b": 40
    },
    {
      "x": 21,
      "y": 12,
      "z": 4,
      "r": 120,
      "g": 80,
      "b": 40
    },
    {
      "x": 24,
      "y": 12,
      "z": 4,
      "r": 120,
      "g": 80,
      "b": 40
    },
    {
      "x": 24,
      "y": 13,
      "z": 4,
      "r": 120,
      "g": 80,
      "b": 40
    },
    {
      "x": 25,
      "y": 12,
      "z": 4,
      "r": 120,
      "g": 80,
      "b": 40
    },
    {
      "x": 25,
      "y": 13,
      "z": 4,
      "r": 120,
      "g": 80,
      "b": 40
    },
    {
      "x": 23,
      "y": 12,
      "z": 4,
      "r": 120,
      "g": 80,
      "b": 40
    },
    {
      "x": 29,
      "y": 13,
      "z": 7,
      "r": 120,
      "g": 80,
      "b": 40
    },
    {
      "x": 30,
      "y": 13,
      "z": 8,
      "r": 120,
      "g": 80,
      "b": 40
    },
    {
      "x": 29,
      "y": 12,
      "z": 7,
      "r": 120,
      "g": 80,
      "b": 40
    },
    {
      "x": 27,
      "y": 12,
      "z": 5,
      "r": 120,
      "g": 80,
      "b": 40
    },
    {
      "x": 27,
      "y": 13,
      "z": 5,
      "r": 120,
      "g": 80,
      "b": 40
    },
    {
      "x": 28,
      "y": 13,
      "z": 5,
      "r": 120,
      "g": 80,
      "b": 40
    },
    {
      "x": 31,
      "y": 12,
      "z": 11,
      "r": 120,
      "g": 80,
      "b": 40
    },
    {
      "x": 31,
      "y": 13,
      "z": 11,
      "r": 120,
      "g": 80,
      "b": 40
    },
    {
      "x": 32,
      "y": 13,
      "z": 15,
      "r": 120,
      "g": 80,
      "b": 40
    },
    {
      "x": 33,
      "y": 13,
      "z": 18,
      "r": 120,
      "g": 80,
      "b": 40
    },
    {
      "x": 33,
      "y": 13,
      "z": 19,
      "r": 120,
      "g": 80,
      "b": 40
    },
    {
      "x": 34,
      "y": 13,
      "z": 23,
      "r": 120,
      "g": 80,
      "b": 40
    },
    {
      "x": 34,
      "y": 13,
      "z": 24,
      "r": 120,
      "g": 80,
      "b": 40
    },
    {
      "x": 34,
      "y": 14,
      "z": 24,
      "r": 120,
      "g": 80,
      "b": 40
    },
    {
      "x": 35,
      "y": 14,
      "z": 27,
      "r": 120,
      "g": 80,
      "b": 40
    },
    {
      "x": 34,
      "y": 14,
      "z": 23,
      "r": 120,
      "g": 80,
      "b": 40
    },
    {
      "x": 34,
      "y": 14,
      "z": 22,
      "r": 120,
      "g": 80,
      "b": 40
    },
    {
      "x": 33,
      "y": 14,
      "z": 18,
      "r": 120,
      "g": 80,
      "b": 40
    },
    {
      "x": 33,
      "y": 14,
      "z": 19,
      "r": 120,
      "g": 80,
      "b": 40
    },
    {
      "x": 32,
      "y": 14,
      "z": 13,
      "r": 120,
      "g": 80,
      "b": 40
    },
    {
      "x": 32,
      "y": 14,
      "z": 14,
      "r": 120,
      "g": 80,
      "b": 40
    },
    {
      "x": 32,
      "y": 14,
      "z": 15,
      "r": 120,
      "g": 80,
      "b": 40
    },
    {
      "x": 33,
      "y": 14,
      "z": 14,
      "r": 120,
      "g": 80,
      "b": 40
    },
    {
      "x": 33,
      "y": 14,
      "z": 15,
      "r": 120,
      "g": 80,
      "b": 40
    },
    {
      "x": 12,
      "y": 13,
      "z": 15,
      "r": 120,
      "g": 80,
      "b": 40
    },
    {
      "x": 12,
      "y": 13,
      "z": 16,
      "r": 120,
      "g": 80,
      "b": 40
    },
    {
      "x": 13,
      "y": 13,
      "z": 11,
      "r": 120,
      "g": 80,
      "b": 40
    },
    {
      "x": 13,
      "y": 13,
      "z": 12,
      "r": 120,
      "g": 80,
      "b": 40
    },
    {
      "x": 11,
      "y": 14,
      "z": 15,
      "r": 120,
      "g": 80,
      "b": 40
    },
    {
      "x": 11,
      "y": 14,
      "z": 16,
      "r": 120,
      "g": 80,
      "b": 40
    },
    {
      "x": 11,
      "y": 14,
      "z": 18,
      "r": 120,
      "g": 80,
      "b": 40
    },
    {
      "x": 12,
      "y": 14,
      "z": 14,
      "r": 120,
      "g": 80,
      "b": 40
    },
    {
      "x": 12,
      "y": 14,
      "z": 15,
      "r": 120,
      "g": 80,
      "b": 40
    },
    {
      "x": 9,
      "y": 14,
      "z": 28,
      "r": 120,
      "g": 80,
      "b": 40
    },
    {
      "x": 9,
      "y": 15,
      "z": 27,
      "r": 120,
      "g": 80,
      "b": 40
    },
    {
      "x": 9,
      "y": 15,
      "z": 28,
      "r": 120,
      "g": 80,
      "b": 40
    },
    {
      "x": 10,
      "y": 14,
      "z": 23,
      "r": 120,
      "g": 80,
      "b": 40
    },
    {
      "x": 10,
      "y": 14,
      "z": 24,
      "r": 120,
      "g": 80,
      "b": 40
    },
    {
      "x": 11,
      "y": 13,
      "z": 19,
      "r": 120,
      "g": 80,
      "b": 40
    },
    {
      "x": 11,
      "y": 13,
      "z": 20,
      "r": 120,
      "g": 80,
      "b": 40
    },
    {
      "x": 11,
      "y": 14,
      "z": 19,
      "r": 120,
      "g": 80,
      "b": 40
    },
    {
      "x": 11,
      "y": 14,
      "z": 20,
      "r": 120,
      "g": 80,
      "b": 40
    },
    {
      "x": 10,
      "y": 13,
      "z": 24,
      "r": 120,
      "g": 80,
      "b": 40
    },
    {
      "x": 10,
      "y": 14,
      "z": 25,
      "r": 120,
      "g": 80,
      "b": 40
    },
    {
      "x": 10,
      "y": 13,
      "z": 25,
      "r": 120,
      "g": 80,
      "b": 40
    },
    {
      "x": 13,
      "y": 18,
      "z": 6,
      "r": 120,
      "g": 80,
      "b": 40
    },
    {
      "x": 13,
      "y": 18,
      "z": 7,
      "r": 120,
      "g": 80,
      "b": 40
    },
    {
      "x": 14,
      "y": 18,
      "z": 4,
      "r": 120,
      "g": 80,
      "b": 40
    },
    {
      "x": 14,
      "y": 18,
      "z": 5,
      "r": 120,
      "g": 80,
      "b": 40
    },
    {
      "x": 14,
      "y": 18,
      "z": 6,
      "r": 120,
      "g": 80,
      "b": 40
    },
    {
      "x": 15,
      "y": 18,
      "z": 3,
      "r": 120,
      "g": 80,
      "b": 40
    },
    {
      "x": 15,
      "y": 18,
      "z": 4,
      "r": 120,
      "g": 80,
      "b": 40
    },
    {
      "x": 16,
      "y": 18,
      "z": 3,
      "r": 120,
      "g": 80,
      "b": 40
    },
    {
      "x": 17,
      "y": 18,
      "z": 2,
      "r": 120,
      "g": 80,
      "b": 40
    },
    {
      "x": 17,
      "y": 18,
      "z": 3,
      "r": 120,
      "g": 80,
      "b": 40
    },
    {
      "x": 16,
      "y": 18,
      "z": 2,
      "r": 120,
      "g": 80,
      "b": 40
    },
    {
      "x": 18,
      "y": 18,
      "z": 2,
      "r": 120,
      "g": 80,
      "b": 40
    },
    {
      "x": 19,
      "y": 18,
      "z": 2,
      "r": 120,
      "g": 80,
      "b": 40
    },
    {
      "x": 20,
      "y": 18,
      "z": 2,
      "r": 120,
      "g": 80,
      "b": 40
    },
    {
      "x": 20,
      "y": 18,
      "z": 1,
      "r": 120,
      "g": 80,
      "b": 40
    },
    {
      "x": 21,
      "y": 18,
      "z": 1,
      "r": 120,
      "g": 80,
      "b": 40
    },
    {
      "x": 21,
      "y": 18,
      "z": 2,
      "r": 120,
      "g": 80,
      "b": 40
    },
    {
      "x": 22,
      "y": 18,
      "z": 1,
      "r": 120,
      "g": 80,
      "b": 40
    },
    {
      "x": 19,
      "y": 18,
      "z": 1,
      "r": 120,
      "g": 80,
      "b": 40
    },
    {
      "x": 23,
      "y": 18,
      "z": 1,
      "r": 120,
      "g": 80,
      "b": 40
    },
    {
      "x": 23,
      "y": 18,
      "z": 2,
      "r": 120,
      "g": 80,
      "b": 40
    },
    {
      "x": 24,
      "y": 18,
      "z": 1,
      "r": 120,
      "g": 80,
      "b": 40
    },
    {
      "x": 24,
      "y": 18,
      "z": 2,
      "r": 120,
      "g": 80,
      "b": 40
    },
    {
      "x": 25,
      "y": 18,
      "z": 2,
      "r": 120,
      "g": 80,
      "b": 40
    },
    {
      "x": 26,
      "y": 18,
      "z": 2,
      "r": 120,
      "g": 80,
      "b": 40
    },
    {
      "x": 27,
      "y": 18,
      "z": 2,
      "r": 120,
      "g": 80,
      "b": 40
    },
    {
      "x": 25,
      "y": 18,
      "z": 1,
      "r": 120,
      "g": 80,
      "b": 40
    },
    {
      "x": 27,
      "y": 18,
      "z": 3,
      "r": 120,
      "g": 80,
      "b": 40
    },
    {
      "x": 28,
      "y": 18,
      "z": 3,
      "r": 120,
      "g": 80,
      "b": 40
    },
    {
      "x": 29,
      "y": 18,
      "z": 3,
      "r": 120,
      "g": 80,
      "b": 40
    },
    {
      "x": 28,
      "y": 18,
      "z": 2,
      "r": 120,
      "g": 80,
      "b": 40
    },
    {
      "x": 29,
      "y": 18,
      "z": 4,
      "r": 120,
      "g": 80,
      "b": 40
    },
    {
      "x": 30,
      "y": 18,
      "z": 4,
      "r": 120,
      "g": 80,
      "b": 40
    },
    {
      "x": 30,
      "y": 18,
      "z": 5,
      "r": 120,
      "g": 80,
      "b": 40
    },
    {
      "x": 31,
      "y": 18,
      "z": 5,
      "r": 120,
      "g": 80,
      "b": 40
    },
    {
      "x": 31,
      "y": 18,
      "z": 6,
      "r": 120,
      "g": 80,
      "b": 40
    },
    {
      "x": 31,
      "y": 18,
      "z": 7,
      "r": 120,
      "g": 80,
      "b": 40
    },
    {
      "x": 32,
      "y": 18,
      "z": 7,
      "r": 120,
      "g": 80,
      "b": 40
    },
    {
      "x": 32,
      "y": 18,
      "z": 8,
      "r": 120,
      "g": 80,
      "b": 40
    },
    {
      "x": 32,
      "y": 18,
      "z": 9,
      "r": 120,
      "g": 80,
      "b": 40
    },
    {
      "x": 32,
      "y": 18,
      "z": 10,
      "r": 120,
      "g": 80,
      "b": 40
    },
    {
      "x": 33,
      "y": 18,
      "z": 10,
      "r": 120,
      "g": 80,
      "b": 40
    },
    {
      "x": 33,
      "y": 18,
      "z": 11,
      "r": 120,
      "g": 80,
      "b": 40
    },
    {
      "x": 33,
      "y": 18,
      "z": 12,
      "r": 120,
      "g": 80,
      "b": 40
    },
    {
      "x": 33,
      "y": 18,
      "z": 13,
      "r": 120,
      "g": 80,
      "b": 40
    },
    {
      "x": 33,
      "y": 18,
      "z": 14,
      "r": 120,
      "g": 80,
      "b": 40
    },
    {
      "x": 34,
      "y": 18,
      "z": 14,
      "r": 120,
      "g": 80,
      "b": 40
    },
    {
      "x": 34,
      "y": 18,
      "z": 15,
      "r": 120,
      "g": 80,
      "b": 40
    },
    {
      "x": 34,
      "y": 18,
      "z": 16,
      "r": 120,
      "g": 80,
      "b": 40
    },
    {
      "x": 34,
      "y": 18,
      "z": 17,
      "r": 120,
      "g": 80,
      "b": 40
    },
    {
      "x": 34,
      "y": 19,
      "z": 16,
      "r": 120,
      "g": 80,
      "b": 40
    },
    {
      "x": 34,
      "y": 19,
      "z": 17,
      "r": 120,
      "g": 80,
      "b": 40
    },
    {
      "x": 34,
      "y": 19,
      "z": 18,
      "r": 120,
      "g": 80,
      "b": 40
    },
    {
      "x": 35,
      "y": 19,
      "z": 18,
      "r": 120,
      "g": 80,
      "b": 40
    },
    {
      "x": 35,
      "y": 19,
      "z": 19,
      "r": 120,
      "g": 80,
      "b": 40
    },
    {
      "x": 35,
      "y": 19,
      "z": 20,
      "r": 120,
      "g": 80,
      "b": 40
    },
    {
      "x": 35,
      "y": 19,
      "z": 21,
      "r": 120,
      "g": 80,
      "b": 40
    },
    {
      "x": 35,
      "y": 19,
      "z": 22,
      "r": 120,
      "g": 80,
      "b": 40
    },
    {
      "x": 36,
      "y": 19,
      "z": 22,
      "r": 120,
      "g": 80,
      "b": 40
    },
    {
      "x": 36,
      "y": 19,
      "z": 23,
      "r": 120,
      "g": 80,
      "b": 40
    },
    {
      "x": 36,
      "y": 19,
      "z": 24,
      "r": 120,
      "g": 80,
      "b": 40
    },
    {
      "x": 35,
      "y": 19,
      "z": 17,
      "r": 120,
      "g": 80,
      "b": 40
    },
    {
      "x": 36,
      "y": 14,
      "z": 29,
      "r": 120,
      "g": 80,
      "b": 40
    },
    {
      "x": 36,
      "y": 15,
      "z": 29,
      "r": 120,
      "g": 80,
      "b": 40
    },
    {
      "x": 35,
      "y": 14,
      "z": 28,
      "r": 120,
      "g": 80,
      "b": 40
    },
    {
      "x": 36,
      "y": 14,
      "z": 27,
      "r": 120,
      "g": 80,
      "b": 40
    },
    {
      "x": 36,
      "y": 14,
      "z": 28,
      "r": 120,
      "g": 80,
      "b": 40
    },
    {
      "x": 36,
      "y": 15,
      "z": 28,
      "r": 120,
      "g": 80,
      "b": 40
    },
    {
      "x": 13,
      "y": 12,
      "z": 12,
      "r": 120,
      "g": 80,
      "b": 40
    },
    {
      "x": 8,
      "y": 14,
      "z": 30,
      "r": 120,
      "g": 80,
      "b": 40
    },
    {
      "x": 9,
      "y": 14,
      "z": 29,
      "r": 120,
      "g": 80,
      "b": 40
    },
    {
      "x": 9,
      "y": 14,
      "z": 30,
      "r": 120,
      "g": 80,
      "b": 40
    },
    {
      "x": 8,
      "y": 14,
      "z": 29,
      "r": 120,
      "g": 80,
      "b": 40
    },
    {
      "x": 8,
      "y": 15,
      "z": 29,
      "r": 120,
      "g": 80,
      "b": 40
    },
    {
      "x": 8,
      "y": 15,
      "z": 30,
      "r": 120,
      "g": 80,
      "b": 40
    },
    {
      "x": 9,
      "y": 15,
      "z": 29,
      "r": 120,
      "g": 80,
      "b": 40
    },
    {
      "x": 8,
      "y": 19,
      "z": 24,
      "r": 120,
      "g": 80,
      "b": 40
    },
    {
      "x": 8,
      "y": 19,
      "z": 25,
      "r": 120,
      "g": 80,
      "b": 40
    },
    {
      "x": 9,
      "y": 19,
      "z": 19,
      "r": 120,
      "g": 80,
      "b": 40
    },
    {
      "x": 9,
      "y": 19,
      "z": 20,
      "r": 120,
      "g": 80,
      "b": 40
    },
    {
      "x": 9,
      "y": 19,
      "z": 21,
      "r": 120,
      "g": 80,
      "b": 40
    },
    {
      "x": 9,
      "y": 19,
      "z": 22,
      "r": 120,
      "g": 80,
      "b": 40
    },
    {
      "x": 9,
      "y": 19,
      "z": 23,
      "r": 120,
      "g": 80,
      "b": 40
    },
    {
      "x": 9,
      "y": 19,
      "z": 24,
      "r": 120,
      "g": 80,
      "b": 40
    },
    {
      "x": 10,
      "y": 18,
      "z": 16,
      "r": 120,
      "g": 80,
      "b": 40
    },
    {
      "x": 10,
      "y": 19,
      "z": 16,
      "r": 120,
      "g": 80,
      "b": 40
    },
    {
      "x": 10,
      "y": 19,
      "z": 17,
      "r": 120,
      "g": 80,
      "b": 40
    },
    {
      "x": 10,
      "y": 19,
      "z": 18,
      "r": 120,
      "g": 80,
      "b": 40
    },
    {
      "x": 10,
      "y": 19,
      "z": 19,
      "r": 120,
      "g": 80,
      "b": 40
    },
    {
      "x": 10,
      "y": 18,
      "z": 17,
      "r": 120,
      "g": 80,
      "b": 40
    },
    {
      "x": 10,
      "y": 18,
      "z": 18,
      "r": 120,
      "g": 80,
      "b": 40
    },
    {
      "x": 10,
      "y": 18,
      "z": 15,
      "r": 120,
      "g": 80,
      "b": 40
    },
    {
      "x": 11,
      "y": 18,
      "z": 11,
      "r": 120,
      "g": 80,
      "b": 40
    },
    {
      "x": 11,
      "y": 18,
      "z": 12,
      "r": 120,
      "g": 80,
      "b": 40
    },
    {
      "x": 11,
      "y": 18,
      "z": 13,
      "r": 120,
      "g": 80,
      "b": 40
    },
    {
      "x": 11,
      "y": 18,
      "z": 14,
      "r": 120,
      "g": 80,
      "b": 40
    },
    {
      "x": 11,
      "y": 18,
      "z": 15,
      "r": 120,
      "g": 80,
      "b": 40
    },
    {
      "x": 12,
      "y": 18,
      "z": 8,
      "r": 120,
      "g": 80,
      "b": 40
    },
    {
      "x": 12,
      "y": 18,
      "z": 9,
      "r": 120,
      "g": 80,
      "b": 40
    },
    {
      "x": 12,
      "y": 18,
      "z": 10,
      "r": 120,
      "g": 80,
      "b": 40
    },
    {
      "x": 12,
      "y": 18,
      "z": 11,
      "r": 120,
      "g": 80,
      "b": 40
    },
    {
      "x": 13,
      "y": 18,
      "z": 8,
      "r": 120,
      "g": 80,
      "b": 40
    },
    {
      "x": 12,
      "y": 18,
      "z": 7,
      "r": 120,
      "g": 80,
      "b": 40
    },
    {
      "x": 36,
      "y": 19,
      "z": 25,
      "r": 120,
      "g": 80,
      "b": 40
    },
    {
      "x": 36,
      "y": 19,
      "z": 26,
      "r": 120,
      "g": 80,
      "b": 40
    },
    {
      "x": 36,
      "y": 19,
      "z": 27,
      "r": 120,
      "g": 80,
      "b": 40
    },
    {
      "x": 37,
      "y": 19,
      "z": 26,
      "r": 120,
      "g": 80,
      "b": 40
    },
    {
      "x": 37,
      "y": 19,
      "z": 27,
      "r": 120,
      "g": 80,
      "b": 40
    },
    {
      "x": 36,
      "y": 18,
      "z": 25,
      "r": 120,
      "g": 80,
      "b": 40
    },
    {
      "x": 36,
      "y": 18,
      "z": 26,
      "r": 120,
      "g": 80,
      "b": 40
    },
    {
      "x": 36,
      "y": 18,
      "z": 27,
      "r": 120,
      "g": 80,
      "b": 40
    },
    {
      "x": 37,
      "y": 18,
      "z": 27,
      "r": 120,
      "g": 80,
      "b": 40
    },
    {
      "x": 37,
      "y": 18,
      "z": 28,
      "r": 120,
      "g": 80,
      "b": 40
    },
    {
      "x": 31,
      "y": 17,
      "z": 7,
      "r": 120,
      "g": 80,
      "b": 40
    },
    {
      "x": 31,
      "y": 17,
      "z": 8,
      "r": 120,
      "g": 80,
      "b": 40
    },
    {
      "x": 32,
      "y": 17,
      "z": 8,
      "r": 120,
      "g": 80,
      "b": 40
    },
    {
      "x": 32,
      "y": 17,
      "z": 9,
      "r": 120,
      "g": 80,
      "b": 40
    },
    {
      "x": 32,
      "y": 17,
      "z": 10,
      "r": 120,
      "g": 80,
      "b": 40
    },
    {
      "x": 32,
      "y": 18,
      "z": 11,
      "r": 120,
      "g": 80,
      "b": 40
    },
    {
      "x": 33,
      "y": 18,
      "z": 15,
      "r": 120,
      "g": 80,
      "b": 40
    },
    {
      "x": 31,
      "y": 18,
      "z": 8,
      "r": 120,
      "g": 80,
      "b": 40
    },
    {
      "x": 34,
      "y": 18,
      "z": 18,
      "r": 120,
      "g": 80,
      "b": 40
    },
    {
      "x": 34,
      "y": 18,
      "z": 19,
      "r": 120,
      "g": 80,
      "b": 40
    },
    {
      "x": 35,
      "y": 18,
      "z": 18,
      "r": 120,
      "g": 80,
      "b": 40
    },
    {
      "x": 35,
      "y": 18,
      "z": 19,
      "r": 120,
      "g": 80,
      "b": 40
    },
    {
      "x": 35,
      "y": 18,
      "z": 20,
      "r": 120,
      "g": 80,
      "b": 40
    },
    {
      "x": 35,
      "y": 18,
      "z": 21,
      "r": 120,
      "g": 80,
      "b": 40
    },
    {
      "x": 35,
      "y": 18,
      "z": 22,
      "r": 120,
      "g": 80,
      "b": 40
    },
    {
      "x": 35,
      "y": 18,
      "z": 23,
      "r": 120,
      "g": 80,
      "b": 40
    },
    {
      "x": 36,
      "y": 18,
      "z": 22,
      "r": 120,
      "g": 80,
      "b": 40
    },
    {
      "x": 36,
      "y": 18,
      "z": 23,
      "r": 120,
      "g": 80,
      "b": 40
    },
    {
      "x": 36,
      "y": 18,
      "z": 24,
      "r": 120,
      "g": 80,
      "b": 40
    },
    {
      "x": 27,
      "y": 17,
      "z": 2,
      "r": 120,
      "g": 80,
      "b": 40
    },
    {
      "x": 27,
      "y": 17,
      "z": 3,
      "r": 120,
      "g": 80,
      "b": 40
    },
    {
      "x": 28,
      "y": 17,
      "z": 3,
      "r": 120,
      "g": 80,
      "b": 40
    },
    {
      "x": 29,
      "y": 17,
      "z": 3,
      "r": 120,
      "g": 80,
      "b": 40
    },
    {
      "x": 29,
      "y": 17,
      "z": 4,
      "r": 120,
      "g": 80,
      "b": 40
    },
    {
      "x": 30,
      "y": 18,
      "z": 6,
      "r": 120,
      "g": 80,
      "b": 40
    },
    {
      "x": 30,
      "y": 17,
      "z": 4,
      "r": 120,
      "g": 80,
      "b": 40
    },
    {
      "x": 30,
      "y": 17,
      "z": 5,
      "r": 120,
      "g": 80,
      "b": 40
    },
    {
      "x": 30,
      "y": 17,
      "z": 6,
      "r": 120,
      "g": 80,
      "b": 40
    },
    {
      "x": 31,
      "y": 17,
      "z": 6,
      "r": 120,
      "g": 80,
      "b": 40
    },
    {
      "x": 22,
      "y": 17,
      "z": 2,
      "r": 120,
      "g": 80,
      "b": 40
    },
    {
      "x": 22,
      "y": 18,
      "z": 2,
      "r": 120,
      "g": 80,
      "b": 40
    },
    {
      "x": 23,
      "y": 17,
      "z": 2,
      "r": 120,
      "g": 80,
      "b": 40
    },
    {
      "x": 24,
      "y": 17,
      "z": 2,
      "r": 120,
      "g": 80,
      "b": 40
    },
    {
      "x": 25,
      "y": 17,
      "z": 2,
      "r": 120,
      "g": 80,
      "b": 40
    },
    {
      "x": 26,
      "y": 17,
      "z": 2,
      "r": 120,
      "g": 80,
      "b": 40
    },
    {
      "x": 17,
      "y": 17,
      "z": 2,
      "r": 120,
      "g": 80,
      "b": 40
    },
    {
      "x": 17,
      "y": 17,
      "z": 3,
      "r": 120,
      "g": 80,
      "b": 40
    },
    {
      "x": 18,
      "y": 17,
      "z": 2,
      "r": 120,
      "g": 80,
      "b": 40
    },
    {
      "x": 19,
      "y": 17,
      "z": 2,
      "r": 120,
      "g": 80,
      "b": 40
    },
    {
      "x": 20,
      "y": 17,
      "z": 2,
      "r": 120,
      "g": 80,
      "b": 40
    },
    {
      "x": 21,
      "y": 17,
      "z": 2,
      "r": 120,
      "g": 80,
      "b": 40
    },
    {
      "x": 13,
      "y": 17,
      "z": 6,
      "r": 120,
      "g": 80,
      "b": 40
    },
    {
      "x": 13,
      "y": 17,
      "z": 7,
      "r": 120,
      "g": 80,
      "b": 40
    },
    {
      "x": 14,
      "y": 17,
      "z": 4,
      "r": 120,
      "g": 80,
      "b": 40
    },
    {
      "x": 14,
      "y": 17,
      "z": 5,
      "r": 120,
      "g": 80,
      "b": 40
    },
    {
      "x": 14,
      "y": 17,
      "z": 6,
      "r": 120,
      "g": 80,
      "b": 40
    },
    {
      "x": 15,
      "y": 17,
      "z": 4,
      "r": 120,
      "g": 80,
      "b": 40
    },
    {
      "x": 15,
      "y": 17,
      "z": 5,
      "r": 120,
      "g": 80,
      "b": 40
    },
    {
      "x": 15,
      "y": 17,
      "z": 3,
      "r": 120,
      "g": 80,
      "b": 40
    },
    {
      "x": 16,
      "y": 17,
      "z": 3,
      "r": 120,
      "g": 80,
      "b": 40
    },
    {
      "x": 9,
      "y": 18,
      "z": 19,
      "r": 120,
      "g": 80,
      "b": 40
    },
    {
      "x": 9,
      "y": 18,
      "z": 20,
      "r": 120,
      "g": 80,
      "b": 40
    },
    {
      "x": 10,
      "y": 18,
      "z": 19,
      "r": 120,
      "g": 80,
      "b": 40
    },
    {
      "x": 8,
      "y": 18,
      "z": 24,
      "r": 120,
      "g": 80,
      "b": 40
    },
    {
      "x": 8,
      "y": 18,
      "z": 25,
      "r": 120,
      "g": 80,
      "b": 40
    },
    {
      "x": 8,
      "y": 18,
      "z": 26,
      "r": 120,
      "g": 80,
      "b": 40
    },
    {
      "x": 9,
      "y": 18,
      "z": 21,
      "r": 120,
      "g": 80,
      "b": 40
    },
    {
      "x": 9,
      "y": 18,
      "z": 22,
      "r": 120,
      "g": 80,
      "b": 40
    },
    {
      "x": 9,
      "y": 18,
      "z": 23,
      "r": 120,
      "g": 80,
      "b": 40
    },
    {
      "x": 9,
      "y": 18,
      "z": 24,
      "r": 120,
      "g": 80,
      "b": 40
    },
    {
      "x": 9,
      "y": 18,
      "z": 25,
      "r": 120,
      "g": 80,
      "b": 40
    },
    {
      "x": 10,
      "y": 18,
      "z": 20,
      "r": 120,
      "g": 80,
      "b": 40
    },
    {
      "x": 11,
      "y": 18,
      "z": 16,
      "r": 120,
      "g": 80,
      "b": 40
    },
    {
      "x": 12,
      "y": 17,
      "z": 8,
      "r": 120,
      "g": 80,
      "b": 40
    },
    {
      "x": 12,
      "y": 17,
      "z": 9,
      "r": 120,
      "g": 80,
      "b": 40
    },
    {
      "x": 12,
      "y": 17,
      "z": 10,
      "r": 120,
      "g": 80,
      "b": 40
    },
    {
      "x": 12,
      "y": 18,
      "z": 12,
      "r": 120,
      "g": 80,
      "b": 40
    },
    {
      "x": 13,
      "y": 17,
      "z": 8,
      "r": 120,
      "g": 80,
      "b": 40
    },
    {
      "x": 8,
      "y": 19,
      "z": 26,
      "r": 120,
      "g": 80,
      "b": 40
    },
    {
      "x": 8,
      "y": 19,
      "z": 27,
      "r": 120,
      "g": 80,
      "b": 40
    },
    {
      "x": 8,
      "y": 19,
      "z": 28,
      "r": 120,
      "g": 80,
      "b": 40
    },
    {
      "x": 8,
      "y": 18,
      "z": 28,
      "r": 120,
      "g": 80,
      "b": 40
    },
    {
      "x": 8,
      "y": 18,
      "z": 27,
      "r": 120,
      "g": 80,
      "b": 40
    },
    {
      "x": 10,
      "y": 17,
      "z": 14,
      "r": 120,
      "g": 80,
      "b": 40
    },
    {
      "x": 10,
      "y": 17,
      "z": 15,
      "r": 120,
      "g": 80,
      "b": 40
    },
    {
      "x": 10,
      "y": 17,
      "z": 16,
      "r": 120,
      "g": 80,
      "b": 40
    },
    {
      "x": 10,
      "y": 18,
      "z": 14,
      "r": 120,
      "g": 80,
      "b": 40
    },
    {
      "x": 11,
      "y": 17,
      "z": 10,
      "r": 120,
      "g": 80,
      "b": 40
    },
    {
      "x": 11,
      "y": 17,
      "z": 11,
      "r": 120,
      "g": 80,
      "b": 40
    },
    {
      "x": 11,
      "y": 17,
      "z": 12,
      "r": 120,
      "g": 80,
      "b": 40
    },
    {
      "x": 11,
      "y": 17,
      "z": 13,
      "r": 120,
      "g": 80,
      "b": 40
    },
    {
      "x": 11,
      "y": 17,
      "z": 14,
      "r": 120,
      "g": 80,
      "b": 40
    },
    {
      "x": 11,
      "y": 18,
      "z": 10,
      "r": 120,
      "g": 80,
      "b": 40
    },
    {
      "x": 12,
      "y": 17,
      "z": 7,
      "r": 120,
      "g": 80,
      "b": 40
    },
    {
      "x": 10,
      "y": 18,
      "z": 13,
      "r": 120,
      "g": 80,
      "b": 40
    },
    {
      "x": 8,
      "y": 18,
      "z": 22,
      "r": 120,
      "g": 80,
      "b": 40
    },
    {
      "x": 8,
      "y": 18,
      "z": 23,
      "r": 120,
      "g": 80,
      "b": 40
    },
    {
      "x": 9,
      "y": 18,
      "z": 18,
      "r": 120,
      "g": 80,
      "b": 40
    },
    {
      "x": 10,
      "y": 17,
      "z": 17,
      "r": 120,
      "g": 80,
      "b": 40
    },
    {
      "x": 9,
      "y": 18,
      "z": 17,
      "r": 120,
      "g": 80,
      "b": 40
    },
    {
      "x": 13,
      "y": 18,
      "z": 5,
      "r": 120,
      "g": 80,
      "b": 40
    },
    {
      "x": 14,
      "y": 18,
      "z": 3,
      "r": 120,
      "g": 80,
      "b": 40
    },
    {
      "x": 16,
      "y": 17,
      "z": 2,
      "r": 120,
      "g": 80,
      "b": 40
    },
    {
      "x": 13,
      "y": 17,
      "z": 5,
      "r": 120,
      "g": 80,
      "b": 40
    },
    {
      "x": 18,
      "y": 18,
      "z": 1,
      "r": 120,
      "g": 80,
      "b": 40
    },
    {
      "x": 21,
      "y": 17,
      "z": 1,
      "r": 120,
      "g": 80,
      "b": 40
    },
    {
      "x": 22,
      "y": 17,
      "z": 1,
      "r": 120,
      "g": 80,
      "b": 40
    },
    {
      "x": 20,
      "y": 17,
      "z": 1,
      "r": 120,
      "g": 80,
      "b": 40
    },
    {
      "x": 19,
      "y": 17,
      "z": 1,
      "r": 120,
      "g": 80,
      "b": 40
    },
    {
      "x": 23,
      "y": 17,
      "z": 1,
      "r": 120,
      "g": 80,
      "b": 40
    },
    {
      "x": 24,
      "y": 17,
      "z": 1,
      "r": 120,
      "g": 80,
      "b": 40
    },
    {
      "x": 26,
      "y": 18,
      "z": 1,
      "r": 120,
      "g": 80,
      "b": 40
    },
    {
      "x": 25,
      "y": 17,
      "z": 1,
      "r": 120,
      "g": 80,
      "b": 40
    },
    {
      "x": 28,
      "y": 17,
      "z": 2,
      "r": 120,
      "g": 80,
      "b": 40
    },
    {
      "x": 29,
      "y": 18,
      "z": 2,
      "r": 120,
      "g": 80,
      "b": 40
    },
    {
      "x": 30,
      "y": 18,
      "z": 3,
      "r": 120,
      "g": 80,
      "b": 40
    },
    {
      "x": 32,
      "y": 18,
      "z": 6,
      "r": 120,
      "g": 80,
      "b": 40
    },
    {
      "x": 30,
      "y": 17,
      "z": 3,
      "r": 120,
      "g": 80,
      "b": 40
    },
    {
      "x": 31,
      "y": 17,
      "z": 5,
      "r": 120,
      "g": 80,
      "b": 40
    },
    {
      "x": 32,
      "y": 17,
      "z": 6,
      "r": 120,
      "g": 80,
      "b": 40
    },
    {
      "x": 32,
      "y": 17,
      "z": 7,
      "r": 120,
      "g": 80,
      "b": 40
    },
    {
      "x": 35,
      "y": 18,
      "z": 16,
      "r": 120,
      "g": 80,
      "b": 40
    },
    {
      "x": 35,
      "y": 18,
      "z": 17,
      "r": 120,
      "g": 80,
      "b": 40
    },
    {
      "x": 36,
      "y": 18,
      "z": 20,
      "r": 120,
      "g": 80,
      "b": 40
    },
    {
      "x": 36,
      "y": 18,
      "z": 21,
      "r": 120,
      "g": 80,
      "b": 40
    },
    {
      "x": 34,
      "y": 17,
      "z": 16,
      "r": 120,
      "g": 80,
      "b": 40
    },
    {
      "x": 33,
      "y": 17,
      "z": 9,
      "r": 120,
      "g": 80,
      "b": 40
    },
    {
      "x": 33,
      "y": 17,
      "z": 10,
      "r": 120,
      "g": 80,
      "b": 40
    },
    {
      "x": 33,
      "y": 17,
      "z": 11,
      "r": 120,
      "g": 80,
      "b": 40
    },
    {
      "x": 33,
      "y": 17,
      "z": 12,
      "r": 120,
      "g": 80,
      "b": 40
    },
    {
      "x": 33,
      "y": 17,
      "z": 13,
      "r": 120,
      "g": 80,
      "b": 40
    },
    {
      "x": 34,
      "y": 17,
      "z": 13,
      "r": 120,
      "g": 80,
      "b": 40
    },
    {
      "x": 34,
      "y": 17,
      "z": 14,
      "r": 120,
      "g": 80,
      "b": 40
    },
    {
      "x": 34,
      "y": 17,
      "z": 15,
      "r": 120,
      "g": 80,
      "b": 40
    },
    {
      "x": 34,
      "y": 18,
      "z": 13,
      "r": 120,
      "g": 80,
      "b": 40
    },
    {
      "x": 33,
      "y": 18,
      "z": 9,
      "r": 120,
      "g": 80,
      "b": 40
    },
    {
      "x": 34,
      "y": 18,
      "z": 12,
      "r": 120,
      "g": 80,
      "b": 40
    },
    {
      "x": 36,
      "y": 16,
      "z": 28,
      "r": 120,
      "g": 80,
      "b": 40
    },
    {
      "x": 36,
      "y": 17,
      "z": 28,
      "r": 120,
      "g": 80,
      "b": 40
    },
    {
      "x": 36,
      "y": 18,
      "z": 28,
      "r": 120,
      "g": 80,
      "b": 40
    },
    {
      "x": 36,
      "y": 16,
      "z": 25,
      "r": 120,
      "g": 80,
      "b": 40
    },
    {
      "x": 36,
      "y": 16,
      "z": 26,
      "r": 120,
      "g": 80,
      "b": 40
    },
    {
      "x": 36,
      "y": 17,
      "z": 25,
      "r": 120,
      "g": 80,
      "b": 40
    },
    {
      "x": 36,
      "y": 17,
      "z": 26,
      "r": 120,
      "g": 80,
      "b": 40
    },
    {
      "x": 36,
      "y": 17,
      "z": 27,
      "r": 120,
      "g": 80,
      "b": 40
    },
    {
      "x": 36,
      "y": 16,
      "z": 27,
      "r": 120,
      "g": 80,
      "b": 40
    },
    {
      "x": 35,
      "y": 15,
      "z": 26,
      "r": 120,
      "g": 80,
      "b": 40
    },
    {
      "x": 35,
      "y": 15,
      "z": 27,
      "r": 120,
      "g": 80,
      "b": 40
    },
    {
      "x": 35,
      "y": 16,
      "z": 26,
      "r": 120,
      "g": 80,
      "b": 40
    },
    {
      "x": 36,
      "y": 15,
      "z": 26,
      "r": 120,
      "g": 80,
      "b": 40
    },
    {
      "x": 36,
      "y": 15,
      "z": 27,
      "r": 120,
      "g": 80,
      "b": 40
    },
    {
      "x": 36,
      "y": 16,
      "z": 29,
      "r": 120,
      "g": 80,
      "b": 40
    },
    {
      "x": 31,
      "y": 14,
      "z": 10,
      "r": 120,
      "g": 80,
      "b": 40
    },
    {
      "x": 31,
      "y": 14,
      "z": 11,
      "r": 120,
      "g": 80,
      "b": 40
    },
    {
      "x": 32,
      "y": 14,
      "z": 10,
      "r": 120,
      "g": 80,
      "b": 40
    },
    {
      "x": 32,
      "y": 14,
      "z": 11,
      "r": 120,
      "g": 80,
      "b": 40
    },
    {
      "x": 32,
      "y": 14,
      "z": 12,
      "r": 120,
      "g": 80,
      "b": 40
    },
    {
      "x": 32,
      "y": 15,
      "z": 13,
      "r": 120,
      "g": 80,
      "b": 40
    },
    {
      "x": 32,
      "y": 15,
      "z": 14,
      "r": 120,
      "g": 80,
      "b": 40
    },
    {
      "x": 33,
      "y": 15,
      "z": 13,
      "r": 120,
      "g": 80,
      "b": 40
    },
    {
      "x": 33,
      "y": 15,
      "z": 14,
      "r": 120,
      "g": 80,
      "b": 40
    },
    {
      "x": 33,
      "y": 15,
      "z": 15,
      "r": 120,
      "g": 80,
      "b": 40
    },
    {
      "x": 33,
      "y": 15,
      "z": 16,
      "r": 120,
      "g": 80,
      "b": 40
    },
    {
      "x": 33,
      "y": 15,
      "z": 17,
      "r": 120,
      "g": 80,
      "b": 40
    },
    {
      "x": 33,
      "y": 16,
      "z": 16,
      "r": 120,
      "g": 80,
      "b": 40
    },
    {
      "x": 33,
      "y": 16,
      "z": 17,
      "r": 120,
      "g": 80,
      "b": 40
    },
    {
      "x": 34,
      "y": 15,
      "z": 17,
      "r": 120,
      "g": 80,
      "b": 40
    },
    {
      "x": 34,
      "y": 16,
      "z": 16,
      "r": 120,
      "g": 80,
      "b": 40
    },
    {
      "x": 34,
      "y": 16,
      "z": 17,
      "r": 120,
      "g": 80,
      "b": 40
    },
    {
      "x": 31,
      "y": 14,
      "z": 8,
      "r": 120,
      "g": 80,
      "b": 40
    },
    {
      "x": 31,
      "y": 14,
      "z": 9,
      "r": 120,
      "g": 80,
      "b": 40
    },
    {
      "x": 31,
      "y": 15,
      "z": 8,
      "r": 120,
      "g": 80,
      "b": 40
    },
    {
      "x": 31,
      "y": 15,
      "z": 9,
      "r": 120,
      "g": 80,
      "b": 40
    },
    {
      "x": 31,
      "y": 15,
      "z": 10,
      "r": 120,
      "g": 80,
      "b": 40
    },
    {
      "x": 32,
      "y": 15,
      "z": 9,
      "r": 120,
      "g": 80,
      "b": 40
    },
    {
      "x": 32,
      "y": 15,
      "z": 10,
      "r": 120,
      "g": 80,
      "b": 40
    },
    {
      "x": 32,
      "y": 15,
      "z": 11,
      "r": 120,
      "g": 80,
      "b": 40
    },
    {
      "x": 32,
      "y": 15,
      "z": 12,
      "r": 120,
      "g": 80,
      "b": 40
    },
    {
      "x": 32,
      "y": 16,
      "z": 12,
      "r": 120,
      "g": 80,
      "b": 40
    },
    {
      "x": 32,
      "y": 16,
      "z": 13,
      "r": 120,
      "g": 80,
      "b": 40
    },
    {
      "x": 33,
      "y": 16,
      "z": 13,
      "r": 120,
      "g": 80,
      "b": 40
    },
    {
      "x": 33,
      "y": 16,
      "z": 14,
      "r": 120,
      "g": 80,
      "b": 40
    },
    {
      "x": 33,
      "y": 16,
      "z": 15,
      "r": 120,
      "g": 80,
      "b": 40
    },
    {
      "x": 34,
      "y": 15,
      "z": 20,
      "r": 120,
      "g": 80,
      "b": 40
    },
    {
      "x": 34,
      "y": 15,
      "z": 21,
      "r": 120,
      "g": 80,
      "b": 40
    },
    {
      "x": 34,
      "y": 15,
      "z": 22,
      "r": 120,
      "g": 80,
      "b": 40
    },
    {
      "x": 35,
      "y": 15,
      "z": 22,
      "r": 120,
      "g": 80,
      "b": 40
    },
    {
      "x": 35,
      "y": 15,
      "z": 23,
      "r": 120,
      "g": 80,
      "b": 40
    },
    {
      "x": 35,
      "y": 15,
      "z": 24,
      "r": 120,
      "g": 80,
      "b": 40
    },
    {
      "x": 35,
      "y": 15,
      "z": 25,
      "r": 120,
      "g": 80,
      "b": 40
    },
    {
      "x": 35,
      "y": 16,
      "z": 23,
      "r": 120,
      "g": 80,
      "b": 40
    },
    {
      "x": 35,
      "y": 16,
      "z": 24,
      "r": 120,
      "g": 80,
      "b": 40
    },
    {
      "x": 35,
      "y": 16,
      "z": 25,
      "r": 120,
      "g": 80,
      "b": 40
    },
    {
      "x": 33,
      "y": 15,
      "z": 18,
      "r": 120,
      "g": 80,
      "b": 40
    },
    {
      "x": 34,
      "y": 15,
      "z": 18,
      "r": 120,
      "g": 80,
      "b": 40
    },
    {
      "x": 34,
      "y": 15,
      "z": 19,
      "r": 120,
      "g": 80,
      "b": 40
    },
    {
      "x": 34,
      "y": 16,
      "z": 18,
      "r": 120,
      "g": 80,
      "b": 40
    },
    {
      "x": 34,
      "y": 16,
      "z": 19,
      "r": 120,
      "g": 80,
      "b": 40
    },
    {
      "x": 34,
      "y": 16,
      "z": 20,
      "r": 120,
      "g": 80,
      "b": 40
    },
    {
      "x": 34,
      "y": 16,
      "z": 21,
      "r": 120,
      "g": 80,
      "b": 40
    },
    {
      "x": 35,
      "y": 15,
      "z": 21,
      "r": 120,
      "g": 80,
      "b": 40
    },
    {
      "x": 35,
      "y": 16,
      "z": 21,
      "r": 120,
      "g": 80,
      "b": 40
    },
    {
      "x": 35,
      "y": 16,
      "z": 22,
      "r": 120,
      "g": 80,
      "b": 40
    },
    {
      "x": 34,
      "y": 17,
      "z": 20,
      "r": 120,
      "g": 80,
      "b": 40
    },
    {
      "x": 35,
      "y": 16,
      "z": 20,
      "r": 120,
      "g": 80,
      "b": 40
    },
    {
      "x": 35,
      "y": 17,
      "z": 20,
      "r": 120,
      "g": 80,
      "b": 40
    },
    {
      "x": 35,
      "y": 17,
      "z": 21,
      "r": 120,
      "g": 80,
      "b": 40
    },
    {
      "x": 35,
      "y": 17,
      "z": 22,
      "r": 120,
      "g": 80,
      "b": 40
    },
    {
      "x": 35,
      "y": 17,
      "z": 23,
      "r": 120,
      "g": 80,
      "b": 40
    },
    {
      "x": 35,
      "y": 17,
      "z": 24,
      "r": 120,
      "g": 80,
      "b": 40
    },
    {
      "x": 35,
      "y": 17,
      "z": 25,
      "r": 120,
      "g": 80,
      "b": 40
    },
    {
      "x": 35,
      "y": 18,
      "z": 24,
      "r": 120,
      "g": 80,
      "b": 40
    },
    {
      "x": 36,
      "y": 17,
      "z": 24,
      "r": 120,
      "g": 80,
      "b": 40
    },
    {
      "x": 34,
      "y": 17,
      "z": 17,
      "r": 120,
      "g": 80,
      "b": 40
    },
    {
      "x": 34,
      "y": 17,
      "z": 18,
      "r": 120,
      "g": 80,
      "b": 40
    },
    {
      "x": 34,
      "y": 17,
      "z": 19,
      "r": 120,
      "g": 80,
      "b": 40
    },
    {
      "x": 35,
      "y": 17,
      "z": 19,
      "r": 120,
      "g": 80,
      "b": 40
    },
    {
      "x": 31,
      "y": 16,
      "z": 9,
      "r": 120,
      "g": 80,
      "b": 40
    },
    {
      "x": 32,
      "y": 16,
      "z": 9,
      "r": 120,
      "g": 80,
      "b": 40
    },
    {
      "x": 32,
      "y": 16,
      "z": 10,
      "r": 120,
      "g": 80,
      "b": 40
    },
    {
      "x": 32,
      "y": 16,
      "z": 11,
      "r": 120,
      "g": 80,
      "b": 40
    },
    {
      "x": 33,
      "y": 16,
      "z": 12,
      "r": 120,
      "g": 80,
      "b": 40
    },
    {
      "x": 33,
      "y": 17,
      "z": 14,
      "r": 120,
      "g": 80,
      "b": 40
    },
    {
      "x": 33,
      "y": 17,
      "z": 15,
      "r": 120,
      "g": 80,
      "b": 40
    },
    {
      "x": 33,
      "y": 17,
      "z": 16,
      "r": 120,
      "g": 80,
      "b": 40
    },
    {
      "x": 31,
      "y": 16,
      "z": 8,
      "r": 120,
      "g": 80,
      "b": 40
    },
    {
      "x": 32,
      "y": 16,
      "z": 8,
      "r": 120,
      "g": 80,
      "b": 40
    },
    {
      "x": 32,
      "y": 17,
      "z": 11,
      "r": 120,
      "g": 80,
      "b": 40
    },
    {
      "x": 32,
      "y": 17,
      "z": 12,
      "r": 120,
      "g": 80,
      "b": 40
    },
    {
      "x": 29,
      "y": 15,
      "z": 4,
      "r": 120,
      "g": 80,
      "b": 40
    },
    {
      "x": 29,
      "y": 15,
      "z": 5,
      "r": 120,
      "g": 80,
      "b": 40
    },
    {
      "x": 29,
      "y": 16,
      "z": 4,
      "r": 120,
      "g": 80,
      "b": 40
    },
    {
      "x": 29,
      "y": 16,
      "z": 5,
      "r": 120,
      "g": 80,
      "b": 40
    },
    {
      "x": 29,
      "y": 17,
      "z": 5,
      "r": 120,
      "g": 80,
      "b": 40
    },
    {
      "x": 30,
      "y": 16,
      "z": 5,
      "r": 120,
      "g": 80,
      "b": 40
    },
    {
      "x": 30,
      "y": 16,
      "z": 6,
      "r": 120,
      "g": 80,
      "b": 40
    },
    {
      "x": 30,
      "y": 15,
      "z": 5,
      "r": 120,
      "g": 80,
      "b": 40
    },
    {
      "x": 30,
      "y": 15,
      "z": 6,
      "r": 120,
      "g": 80,
      "b": 40
    },
    {
      "x": 30,
      "y": 15,
      "z": 7,
      "r": 120,
      "g": 80,
      "b": 40
    },
    {
      "x": 30,
      "y": 16,
      "z": 7,
      "r": 120,
      "g": 80,
      "b": 40
    },
    {
      "x": 31,
      "y": 15,
      "z": 7,
      "r": 120,
      "g": 80,
      "b": 40
    },
    {
      "x": 31,
      "y": 16,
      "z": 6,
      "r": 120,
      "g": 80,
      "b": 40
    },
    {
      "x": 31,
      "y": 16,
      "z": 7,
      "r": 120,
      "g": 80,
      "b": 40
    },
    {
      "x": 27,
      "y": 15,
      "z": 3,
      "r": 120,
      "g": 80,
      "b": 40
    },
    {
      "x": 27,
      "y": 16,
      "z": 3,
      "r": 120,
      "g": 80,
      "b": 40
    },
    {
      "x": 28,
      "y": 16,
      "z": 3,
      "r": 120,
      "g": 80,
      "b": 40
    },
    {
      "x": 27,
      "y": 15,
      "z": 4,
      "r": 120,
      "g": 80,
      "b": 40
    },
    {
      "x": 27,
      "y": 16,
      "z": 4,
      "r": 120,
      "g": 80,
      "b": 40
    },
    {
      "x": 28,
      "y": 15,
      "z": 4,
      "r": 120,
      "g": 80,
      "b": 40
    },
    {
      "x": 28,
      "y": 16,
      "z": 4,
      "r": 120,
      "g": 80,
      "b": 40
    },
    {
      "x": 28,
      "y": 17,
      "z": 4,
      "r": 120,
      "g": 80,
      "b": 40
    },
    {
      "x": 27,
      "y": 14,
      "z": 3,
      "r": 120,
      "g": 80,
      "b": 40
    },
    {
      "x": 27,
      "y": 14,
      "z": 4,
      "r": 120,
      "g": 80,
      "b": 40
    },
    {
      "x": 28,
      "y": 14,
      "z": 4,
      "r": 120,
      "g": 80,
      "b": 40
    },
    {
      "x": 28,
      "y": 14,
      "z": 5,
      "r": 120,
      "g": 80,
      "b": 40
    },
    {
      "x": 29,
      "y": 14,
      "z": 4,
      "r": 120,
      "g": 80,
      "b": 40
    },
    {
      "x": 29,
      "y": 14,
      "z": 5,
      "r": 120,
      "g": 80,
      "b": 40
    },
    {
      "x": 29,
      "y": 14,
      "z": 6,
      "r": 120,
      "g": 80,
      "b": 40
    },
    {
      "x": 29,
      "y": 15,
      "z": 6,
      "r": 120,
      "g": 80,
      "b": 40
    },
    {
      "x": 30,
      "y": 14,
      "z": 6,
      "r": 120,
      "g": 80,
      "b": 40
    },
    {
      "x": 30,
      "y": 14,
      "z": 7,
      "r": 120,
      "g": 80,
      "b": 40
    },
    {
      "x": 30,
      "y": 14,
      "z": 8,
      "r": 120,
      "g": 80,
      "b": 40
    },
    {
      "x": 31,
      "y": 14,
      "z": 7,
      "r": 120,
      "g": 80,
      "b": 40
    },
    {
      "x": 24,
      "y": 15,
      "z": 3,
      "r": 120,
      "g": 80,
      "b": 40
    },
    {
      "x": 24,
      "y": 16,
      "z": 2,
      "r": 120,
      "g": 80,
      "b": 40
    },
    {
      "x": 24,
      "y": 16,
      "z": 3,
      "r": 120,
      "g": 80,
      "b": 40
    },
    {
      "x": 25,
      "y": 15,
      "z": 3,
      "r": 120,
      "g": 80,
      "b": 40
    },
    {
      "x": 25,
      "y": 16,
      "z": 2,
      "r": 120,
      "g": 80,
      "b": 40
    },
    {
      "x": 25,
      "y": 16,
      "z": 3,
      "r": 120,
      "g": 80,
      "b": 40
    },
    {
      "x": 26,
      "y": 16,
      "z": 2,
      "r": 120,
      "g": 80,
      "b": 40
    },
    {
      "x": 26,
      "y": 16,
      "z": 3,
      "r": 120,
      "g": 80,
      "b": 40
    },
    {
      "x": 26,
      "y": 17,
      "z": 3,
      "r": 120,
      "g": 80,
      "b": 40
    },
    {
      "x": 26,
      "y": 15,
      "z": 3,
      "r": 120,
      "g": 80,
      "b": 40
    },
    {
      "x": 22,
      "y": 15,
      "z": 2,
      "r": 120,
      "g": 80,
      "b": 40
    },
    {
      "x": 22,
      "y": 16,
      "z": 2,
      "r": 120,
      "g": 80,
      "b": 40
    },
    {
      "x": 23,
      "y": 16,
      "z": 2,
      "r": 120,
      "g": 80,
      "b": 40
    },
    {
      "x": 23,
      "y": 15,
      "z": 2,
      "r": 120,
      "g": 80,
      "b": 40
    },
    {
      "x": 23,
      "y": 15,
      "z": 3,
      "r": 120,
      "g": 80,
      "b": 40
    },
    {
      "x": 24,
      "y": 15,
      "z": 2,
      "r": 120,
      "g": 80,
      "b": 40
    },
    {
      "x": 22,
      "y": 14,
      "z": 3,
      "r": 120,
      "g": 80,
      "b": 40
    },
    {
      "x": 22,
      "y": 15,
      "z": 3,
      "r": 120,
      "g": 80,
      "b": 40
    },
    {
      "x": 23,
      "y": 14,
      "z": 3,
      "r": 120,
      "g": 80,
      "b": 40
    },
    {
      "x": 24,
      "y": 14,
      "z": 3,
      "r": 120,
      "g": 80,
      "b": 40
    },
    {
      "x": 25,
      "y": 14,
      "z": 3,
      "r": 120,
      "g": 80,
      "b": 40
    },
    {
      "x": 26,
      "y": 14,
      "z": 3,
      "r": 120,
      "g": 80,
      "b": 40
    },
    {
      "x": 25,
      "y": 14,
      "z": 4,
      "r": 120,
      "g": 80,
      "b": 40
    },
    {
      "x": 26,
      "y": 14,
      "z": 4,
      "r": 120,
      "g": 80,
      "b": 40
    },
    {
      "x": 17,
      "y": 16,
      "z": 3,
      "r": 120,
      "g": 80,
      "b": 40
    },
    {
      "x": 18,
      "y": 15,
      "z": 3,
      "r": 120,
      "g": 80,
      "b": 40
    },
    {
      "x": 18,
      "y": 16,
      "z": 3,
      "r": 120,
      "g": 80,
      "b": 40
    },
    {
      "x": 18,
      "y": 17,
      "z": 3,
      "r": 120,
      "g": 80,
      "b": 40
    },
    {
      "x": 19,
      "y": 15,
      "z": 3,
      "r": 120,
      "g": 80,
      "b": 40
    },
    {
      "x": 19,
      "y": 16,
      "z": 3,
      "r": 120,
      "g": 80,
      "b": 40
    },
    {
      "x": 20,
      "y": 15,
      "z": 3,
      "r": 120,
      "g": 80,
      "b": 40
    },
    {
      "x": 19,
      "y": 16,
      "z": 2,
      "r": 120,
      "g": 80,
      "b": 40
    },
    {
      "x": 19,
      "y": 17,
      "z": 3,
      "r": 120,
      "g": 80,
      "b": 40
    },
    {
      "x": 20,
      "y": 16,
      "z": 2,
      "r": 120,
      "g": 80,
      "b": 40
    },
    {
      "x": 20,
      "y": 16,
      "z": 3,
      "r": 120,
      "g": 80,
      "b": 40
    },
    {
      "x": 18,
      "y": 14,
      "z": 3,
      "r": 120,
      "g": 80,
      "b": 40
    },
    {
      "x": 18,
      "y": 14,
      "z": 4,
      "r": 120,
      "g": 80,
      "b": 40
    },
    {
      "x": 19,
      "y": 14,
      "z": 3,
      "r": 120,
      "g": 80,
      "b": 40
    },
    {
      "x": 19,
      "y": 14,
      "z": 4,
      "r": 120,
      "g": 80,
      "b": 40
    },
    {
      "x": 20,
      "y": 14,
      "z": 3,
      "r": 120,
      "g": 80,
      "b": 40
    },
    {
      "x": 21,
      "y": 14,
      "z": 3,
      "r": 120,
      "g": 80,
      "b": 40
    },
    {
      "x": 21,
      "y": 15,
      "z": 3,
      "r": 120,
      "g": 80,
      "b": 40
    },
    {
      "x": 21,
      "y": 15,
      "z": 2,
      "r": 120,
      "g": 80,
      "b": 40
    },
    {
      "x": 20,
      "y": 15,
      "z": 2,
      "r": 120,
      "g": 80,
      "b": 40
    },
    {
      "x": 21,
      "y": 16,
      "z": 2,
      "r": 120,
      "g": 80,
      "b": 40
    },
    {
      "x": 13,
      "y": 15,
      "z": 7,
      "r": 120,
      "g": 80,
      "b": 40
    },
    {
      "x": 13,
      "y": 15,
      "z": 8,
      "r": 120,
      "g": 80,
      "b": 40
    },
    {
      "x": 13,
      "y": 16,
      "z": 7,
      "r": 120,
      "g": 80,
      "b": 40
    },
    {
      "x": 13,
      "y": 16,
      "z": 8,
      "r": 120,
      "g": 80,
      "b": 40
    },
    {
      "x": 14,
      "y": 15,
      "z": 5,
      "r": 120,
      "g": 80,
      "b": 40
    },
    {
      "x": 14,
      "y": 15,
      "z": 6,
      "r": 120,
      "g": 80,
      "b": 40
    },
    {
      "x": 14,
      "y": 15,
      "z": 7,
      "r": 120,
      "g": 80,
      "b": 40
    },
    {
      "x": 14,
      "y": 16,
      "z": 5,
      "r": 120,
      "g": 80,
      "b": 40
    },
    {
      "x": 14,
      "y": 16,
      "z": 6,
      "r": 120,
      "g": 80,
      "b": 40
    },
    {
      "x": 14,
      "y": 16,
      "z": 7,
      "r": 120,
      "g": 80,
      "b": 40
    },
    {
      "x": 14,
      "y": 17,
      "z": 7,
      "r": 120,
      "g": 80,
      "b": 40
    },
    {
      "x": 15,
      "y": 15,
      "z": 4,
      "r": 120,
      "g": 80,
      "b": 40
    },
    {
      "x": 15,
      "y": 15,
      "z": 5,
      "r": 120,
      "g": 80,
      "b": 40
    },
    {
      "x": 15,
      "y": 15,
      "z": 6,
      "r": 120,
      "g": 80,
      "b": 40
    },
    {
      "x": 15,
      "y": 16,
      "z": 5,
      "r": 120,
      "g": 80,
      "b": 40
    },
    {
      "x": 15,
      "y": 16,
      "z": 4,
      "r": 120,
      "g": 80,
      "b": 40
    },
    {
      "x": 13,
      "y": 14,
      "z": 8,
      "r": 120,
      "g": 80,
      "b": 40
    },
    {
      "x": 13,
      "y": 14,
      "z": 9,
      "r": 120,
      "g": 80,
      "b": 40
    },
    {
      "x": 14,
      "y": 14,
      "z": 6,
      "r": 120,
      "g": 80,
      "b": 40
    },
    {
      "x": 14,
      "y": 14,
      "z": 7,
      "r": 120,
      "g": 80,
      "b": 40
    },
    {
      "x": 14,
      "y": 14,
      "z": 8,
      "r": 120,
      "g": 80,
      "b": 40
    },
    {
      "x": 14,
      "y": 15,
      "z": 8,
      "r": 120,
      "g": 80,
      "b": 40
    },
    {
      "x": 15,
      "y": 14,
      "z": 6,
      "r": 120,
      "g": 80,
      "b": 40
    },
    {
      "x": 15,
      "y": 14,
      "z": 5,
      "r": 120,
      "g": 80,
      "b": 40
    },
    {
      "x": 15,
      "y": 14,
      "z": 4,
      "r": 120,
      "g": 80,
      "b": 40
    },
    {
      "x": 16,
      "y": 14,
      "z": 4,
      "r": 120,
      "g": 80,
      "b": 40
    },
    {
      "x": 16,
      "y": 14,
      "z": 5,
      "r": 120,
      "g": 80,
      "b": 40
    },
    {
      "x": 16,
      "y": 15,
      "z": 4,
      "r": 120,
      "g": 80,
      "b": 40
    },
    {
      "x": 17,
      "y": 14,
      "z": 4,
      "r": 120,
      "g": 80,
      "b": 40
    },
    {
      "x": 17,
      "y": 15,
      "z": 3,
      "r": 120,
      "g": 80,
      "b": 40
    },
    {
      "x": 17,
      "y": 15,
      "z": 4,
      "r": 120,
      "g": 80,
      "b": 40
    },
    {
      "x": 18,
      "y": 15,
      "z": 4,
      "r": 120,
      "g": 80,
      "b": 40
    },
    {
      "x": 16,
      "y": 16,
      "z": 3,
      "r": 120,
      "g": 80,
      "b": 40
    },
    {
      "x": 16,
      "y": 16,
      "z": 4,
      "r": 120,
      "g": 80,
      "b": 40
    },
    {
      "x": 16,
      "y": 17,
      "z": 4,
      "r": 120,
      "g": 80,
      "b": 40
    },
    {
      "x": 17,
      "y": 16,
      "z": 4,
      "r": 120,
      "g": 80,
      "b": 40
    },
    {
      "x": 8,
      "y": 17,
      "z": 25,
      "r": 120,
      "g": 80,
      "b": 40
    },
    {
      "x": 8,
      "y": 17,
      "z": 26,
      "r": 120,
      "g": 80,
      "b": 40
    },
    {
      "x": 9,
      "y": 16,
      "z": 21,
      "r": 120,
      "g": 80,
      "b": 40
    },
    {
      "x": 9,
      "y": 16,
      "z": 22,
      "r": 120,
      "g": 80,
      "b": 40
    },
    {
      "x": 9,
      "y": 16,
      "z": 23,
      "r": 120,
      "g": 80,
      "b": 40
    },
    {
      "x": 9,
      "y": 16,
      "z": 24,
      "r": 120,
      "g": 80,
      "b": 40
    },
    {
      "x": 9,
      "y": 16,
      "z": 25,
      "r": 120,
      "g": 80,
      "b": 40
    },
    {
      "x": 9,
      "y": 16,
      "z": 26,
      "r": 120,
      "g": 80,
      "b": 40
    },
    {
      "x": 9,
      "y": 17,
      "z": 21,
      "r": 120,
      "g": 80,
      "b": 40
    },
    {
      "x": 9,
      "y": 17,
      "z": 22,
      "r": 120,
      "g": 80,
      "b": 40
    },
    {
      "x": 9,
      "y": 17,
      "z": 23,
      "r": 120,
      "g": 80,
      "b": 40
    },
    {
      "x": 9,
      "y": 17,
      "z": 24,
      "r": 120,
      "g": 80,
      "b": 40
    },
    {
      "x": 9,
      "y": 17,
      "z": 25,
      "r": 120,
      "g": 80,
      "b": 40
    },
    {
      "x": 9,
      "y": 17,
      "z": 26,
      "r": 120,
      "g": 80,
      "b": 40
    },
    {
      "x": 10,
      "y": 16,
      "z": 17,
      "r": 120,
      "g": 80,
      "b": 40
    },
    {
      "x": 10,
      "y": 16,
      "z": 18,
      "r": 120,
      "g": 80,
      "b": 40
    },
    {
      "x": 10,
      "y": 16,
      "z": 19,
      "r": 120,
      "g": 80,
      "b": 40
    },
    {
      "x": 10,
      "y": 16,
      "z": 20,
      "r": 120,
      "g": 80,
      "b": 40
    },
    {
      "x": 10,
      "y": 16,
      "z": 21,
      "r": 120,
      "g": 80,
      "b": 40
    },
    {
      "x": 10,
      "y": 16,
      "z": 22,
      "r": 120,
      "g": 80,
      "b": 40
    },
    {
      "x": 10,
      "y": 17,
      "z": 20,
      "r": 120,
      "g": 80,
      "b": 40
    },
    {
      "x": 10,
      "y": 17,
      "z": 21,
      "r": 120,
      "g": 80,
      "b": 40
    },
    {
      "x": 11,
      "y": 16,
      "z": 17,
      "r": 120,
      "g": 80,
      "b": 40
    },
    {
      "x": 9,
      "y": 17,
      "z": 20,
      "r": 120,
      "g": 80,
      "b": 40
    },
    {
      "x": 10,
      "y": 17,
      "z": 18,
      "r": 120,
      "g": 80,
      "b": 40
    },
    {
      "x": 10,
      "y": 17,
      "z": 19,
      "r": 120,
      "g": 80,
      "b": 40
    },
    {
      "x": 9,
      "y": 15,
      "z": 23,
      "r": 120,
      "g": 80,
      "b": 40
    },
    {
      "x": 9,
      "y": 15,
      "z": 24,
      "r": 120,
      "g": 80,
      "b": 40
    },
    {
      "x": 9,
      "y": 15,
      "z": 25,
      "r": 120,
      "g": 80,
      "b": 40
    },
    {
      "x": 9,
      "y": 15,
      "z": 26,
      "r": 120,
      "g": 80,
      "b": 40
    },
    {
      "x": 9,
      "y": 16,
      "z": 27,
      "r": 120,
      "g": 80,
      "b": 40
    },
    {
      "x": 10,
      "y": 15,
      "z": 20,
      "r": 120,
      "g": 80,
      "b": 40
    },
    {
      "x": 10,
      "y": 15,
      "z": 21,
      "r": 120,
      "g": 80,
      "b": 40
    },
    {
      "x": 10,
      "y": 15,
      "z": 22,
      "r": 120,
      "g": 80,
      "b": 40
    },
    {
      "x": 10,
      "y": 15,
      "z": 23,
      "r": 120,
      "g": 80,
      "b": 40
    },
    {
      "x": 10,
      "y": 15,
      "z": 24,
      "r": 120,
      "g": 80,
      "b": 40
    },
    {
      "x": 10,
      "y": 15,
      "z": 18,
      "r": 120,
      "g": 80,
      "b": 40
    },
    {
      "x": 10,
      "y": 15,
      "z": 19,
      "r": 120,
      "g": 80,
      "b": 40
    },
    {
      "x": 10,
      "y": 16,
      "z": 23,
      "r": 120,
      "g": 80,
      "b": 40
    },
    {
      "x": 11,
      "y": 15,
      "z": 18,
      "r": 120,
      "g": 80,
      "b": 40
    },
    {
      "x": 11,
      "y": 15,
      "z": 19,
      "r": 120,
      "g": 80,
      "b": 40
    },
    {
      "x": 11,
      "y": 16,
      "z": 18,
      "r": 120,
      "g": 80,
      "b": 40
    },
    {
      "x": 11,
      "y": 15,
      "z": 14,
      "r": 120,
      "g": 80,
      "b": 40
    },
    {
      "x": 11,
      "y": 15,
      "z": 15,
      "r": 120,
      "g": 80,
      "b": 40
    },
    {
      "x": 11,
      "y": 15,
      "z": 16,
      "r": 120,
      "g": 80,
      "b": 40
    },
    {
      "x": 11,
      "y": 15,
      "z": 17,
      "r": 120,
      "g": 80,
      "b": 40
    },
    {
      "x": 12,
      "y": 14,
      "z": 11,
      "r": 120,
      "g": 80,
      "b": 40
    },
    {
      "x": 12,
      "y": 14,
      "z": 12,
      "r": 120,
      "g": 80,
      "b": 40
    },
    {
      "x": 12,
      "y": 14,
      "z": 13,
      "r": 120,
      "g": 80,
      "b": 40
    },
    {
      "x": 12,
      "y": 15,
      "z": 13,
      "r": 120,
      "g": 80,
      "b": 40
    },
    {
      "x": 12,
      "y": 15,
      "z": 14,
      "r": 120,
      "g": 80,
      "b": 40
    },
    {
      "x": 12,
      "y": 15,
      "z": 15,
      "r": 120,
      "g": 80,
      "b": 40
    },
    {
      "x": 13,
      "y": 14,
      "z": 10,
      "r": 120,
      "g": 80,
      "b": 40
    },
    {
      "x": 13,
      "y": 14,
      "z": 11,
      "r": 120,
      "g": 80,
      "b": 40
    },
    {
      "x": 11,
      "y": 16,
      "z": 14,
      "r": 120,
      "g": 80,
      "b": 40
    },
    {
      "x": 11,
      "y": 16,
      "z": 15,
      "r": 120,
      "g": 80,
      "b": 40
    },
    {
      "x": 11,
      "y": 16,
      "z": 16,
      "r": 120,
      "g": 80,
      "b": 40
    },
    {
      "x": 12,
      "y": 15,
      "z": 10,
      "r": 120,
      "g": 80,
      "b": 40
    },
    {
      "x": 12,
      "y": 15,
      "z": 11,
      "r": 120,
      "g": 80,
      "b": 40
    },
    {
      "x": 12,
      "y": 15,
      "z": 12,
      "r": 120,
      "g": 80,
      "b": 40
    },
    {
      "x": 12,
      "y": 16,
      "z": 12,
      "r": 120,
      "g": 80,
      "b": 40
    },
    {
      "x": 12,
      "y": 16,
      "z": 13,
      "r": 120,
      "g": 80,
      "b": 40
    },
    {
      "x": 12,
      "y": 16,
      "z": 14,
      "r": 120,
      "g": 80,
      "b": 40
    },
    {
      "x": 13,
      "y": 15,
      "z": 9,
      "r": 120,
      "g": 80,
      "b": 40
    },
    {
      "x": 13,
      "y": 15,
      "z": 10,
      "r": 120,
      "g": 80,
      "b": 40
    },
    {
      "x": 13,
      "y": 15,
      "z": 11,
      "r": 120,
      "g": 80,
      "b": 40
    },
    {
      "x": 11,
      "y": 16,
      "z": 13,
      "r": 120,
      "g": 80,
      "b": 40
    },
    {
      "x": 11,
      "y": 17,
      "z": 15,
      "r": 120,
      "g": 80,
      "b": 40
    },
    {
      "x": 11,
      "y": 17,
      "z": 16,
      "r": 120,
      "g": 80,
      "b": 40
    },
    {
      "x": 11,
      "y": 17,
      "z": 17,
      "r": 120,
      "g": 80,
      "b": 40
    },
    {
      "x": 12,
      "y": 16,
      "z": 10,
      "r": 120,
      "g": 80,
      "b": 40
    },
    {
      "x": 12,
      "y": 16,
      "z": 11,
      "r": 120,
      "g": 80,
      "b": 40
    },
    {
      "x": 12,
      "y": 17,
      "z": 12,
      "r": 120,
      "g": 80,
      "b": 40
    },
    {
      "x": 12,
      "y": 17,
      "z": 13,
      "r": 120,
      "g": 80,
      "b": 40
    },
    {
      "x": 13,
      "y": 16,
      "z": 9,
      "r": 120,
      "g": 80,
      "b": 40
    },
    {
      "x": 13,
      "y": 16,
      "z": 10,
      "r": 120,
      "g": 80,
      "b": 40
    },
    {
      "x": 12,
      "y": 16,
      "z": 9,
      "r": 120,
      "g": 80,
      "b": 40
    },
    {
      "x": 12,
      "y": 17,
      "z": 11,
      "r": 120,
      "g": 80,
      "b": 40
    },
    {
      "x": 13,
      "y": 17,
      "z": 9,
      "r": 120,
      "g": 80,
      "b": 40
    },
    {
      "x": 8,
      "y": 16,
      "z": 29,
      "r": 120,
      "g": 80,
      "b": 40
    },
    {
      "x": 8,
      "y": 16,
      "z": 30,
      "r": 120,
      "g": 80,
      "b": 40
    },
    {
      "x": 8,
      "y": 15,
      "z": 28,
      "r": 120,
      "g": 80,
      "b": 40
    },
    {
      "x": 8,
      "y": 17,
      "z": 29,
      "r": 120,
      "g": 80,
      "b": 40
    },
    {
      "x": 8,
      "y": 18,
      "z": 29,
      "r": 120,
      "g": 80,
      "b": 40
    },
    {
      "x": 7,
      "y": 18,
      "z": 28,
      "r": 120,
      "g": 80,
      "b": 40
    },
    {
      "x": 7,
      "y": 18,
      "z": 29,
      "r": 120,
      "g": 80,
      "b": 40
    },
    {
      "x": 8,
      "y": 16,
      "z": 27,
      "r": 120,
      "g": 80,
      "b": 40
    },
    {
      "x": 8,
      "y": 16,
      "z": 28,
      "r": 120,
      "g": 80,
      "b": 40
    },
    {
      "x": 8,
      "y": 17,
      "z": 27,
      "r": 120,
      "g": 80,
      "b": 40
    },
    {
      "x": 8,
      "y": 17,
      "z": 28,
      "r": 120,
      "g": 80,
      "b": 40
    },
    {
      "x": 9,
      "y": 16,
      "z": 28,
      "r": 120,
      "g": 80,
      "b": 40
    },
    {
      "x": 8,
      "y": 16,
      "z": 26,
      "r": 120,
      "g": 80,
      "b": 40
    },
    {
      "x": 10,
      "y": 15,
      "z": 16,
      "r": 120,
      "g": 80,
      "b": 40
    },
    {
      "x": 10,
      "y": 15,
      "z": 17,
      "r": 120,
      "g": 80,
      "b": 40
    },
    {
      "x": 11,
      "y": 13,
      "z": 13,
      "r": 120,
      "g": 80,
      "b": 40
    },
    {
      "x": 11,
      "y": 14,
      "z": 13,
      "r": 120,
      "g": 80,
      "b": 40
    },
    {
      "x": 11,
      "y": 14,
      "z": 14,
      "r": 120,
      "g": 80,
      "b": 40
    },
    {
      "x": 12,
      "y": 14,
      "z": 10,
      "r": 120,
      "g": 80,
      "b": 40
    },
    {
      "x": 10,
      "y": 16,
      "z": 16,
      "r": 120,
      "g": 80,
      "b": 40
    },
    {
      "x": 11,
      "y": 15,
      "z": 12,
      "r": 120,
      "g": 80,
      "b": 40
    },
    {
      "x": 11,
      "y": 15,
      "z": 13,
      "r": 120,
      "g": 80,
      "b": 40
    },
    {
      "x": 12,
      "y": 14,
      "z": 9,
      "r": 120,
      "g": 80,
      "b": 40
    },
    {
      "x": 12,
      "y": 15,
      "z": 8,
      "r": 120,
      "g": 80,
      "b": 40
    },
    {
      "x": 12,
      "y": 15,
      "z": 9,
      "r": 120,
      "g": 80,
      "b": 40
    },
    {
      "x": 8,
      "y": 14,
      "z": 26,
      "r": 120,
      "g": 80,
      "b": 40
    },
    {
      "x": 8,
      "y": 15,
      "z": 25,
      "r": 120,
      "g": 80,
      "b": 40
    },
    {
      "x": 8,
      "y": 15,
      "z": 26,
      "r": 120,
      "g": 80,
      "b": 40
    },
    {
      "x": 8,
      "y": 15,
      "z": 27,
      "r": 120,
      "g": 80,
      "b": 40
    },
    {
      "x": 8,
      "y": 16,
      "z": 25,
      "r": 120,
      "g": 80,
      "b": 40
    },
    {
      "x": 9,
      "y": 14,
      "z": 21,
      "r": 120,
      "g": 80,
      "b": 40
    },
    {
      "x": 9,
      "y": 15,
      "z": 21,
      "r": 120,
      "g": 80,
      "b": 40
    },
    {
      "x": 9,
      "y": 15,
      "z": 22,
      "r": 120,
      "g": 80,
      "b": 40
    },
    {
      "x": 9,
      "y": 15,
      "z": 20,
      "r": 120,
      "g": 80,
      "b": 40
    },
    {
      "x": 9,
      "y": 16,
      "z": 20,
      "r": 120,
      "g": 80,
      "b": 40
    },
    {
      "x": 8,
      "y": 16,
      "z": 24,
      "r": 120,
      "g": 80,
      "b": 40
    },
    {
      "x": 8,
      "y": 17,
      "z": 23,
      "r": 120,
      "g": 80,
      "b": 40
    },
    {
      "x": 8,
      "y": 17,
      "z": 24,
      "r": 120,
      "g": 80,
      "b": 40
    },
    {
      "x": 9,
      "y": 16,
      "z": 19,
      "r": 120,
      "g": 80,
      "b": 40
    },
    {
      "x": 9,
      "y": 17,
      "z": 18,
      "r": 120,
      "g": 80,
      "b": 40
    },
    {
      "x": 9,
      "y": 17,
      "z": 19,
      "r": 120,
      "g": 80,
      "b": 40
    },
    {
      "x": 10,
      "y": 16,
      "z": 15,
      "r": 120,
      "g": 80,
      "b": 40
    },
    {
      "x": 11,
      "y": 16,
      "z": 11,
      "r": 120,
      "g": 80,
      "b": 40
    },
    {
      "x": 11,
      "y": 16,
      "z": 12,
      "r": 120,
      "g": 80,
      "b": 40
    },
    {
      "x": 12,
      "y": 16,
      "z": 7,
      "r": 120,
      "g": 80,
      "b": 40
    },
    {
      "x": 12,
      "y": 16,
      "z": 8,
      "r": 120,
      "g": 80,
      "b": 40
    },
    {
      "x": 13,
      "y": 16,
      "z": 6,
      "r": 120,
      "g": 80,
      "b": 40
    },
    {
      "x": 14,
      "y": 15,
      "z": 4,
      "r": 120,
      "g": 80,
      "b": 40
    },
    {
      "x": 14,
      "y": 16,
      "z": 4,
      "r": 120,
      "g": 80,
      "b": 40
    },
    {
      "x": 15,
      "y": 16,
      "z": 3,
      "r": 120,
      "g": 80,
      "b": 40
    },
    {
      "x": 13,
      "y": 15,
      "z": 6,
      "r": 120,
      "g": 80,
      "b": 40
    },
    {
      "x": 17,
      "y": 16,
      "z": 2,
      "r": 120,
      "g": 80,
      "b": 40
    },
    {
      "x": 15,
      "y": 15,
      "z": 3,
      "r": 120,
      "g": 80,
      "b": 40
    },
    {
      "x": 16,
      "y": 15,
      "z": 3,
      "r": 120,
      "g": 80,
      "b": 40
    },
    {
      "x": 16,
      "y": 14,
      "z": 3,
      "r": 120,
      "g": 80,
      "b": 40
    },
    {
      "x": 17,
      "y": 14,
      "z": 3,
      "r": 120,
      "g": 80,
      "b": 40
    },
    {
      "x": 13,
      "y": 14,
      "z": 7,
      "r": 120,
      "g": 80,
      "b": 40
    },
    {
      "x": 14,
      "y": 13,
      "z": 5,
      "r": 120,
      "g": 80,
      "b": 40
    },
    {
      "x": 14,
      "y": 14,
      "z": 5,
      "r": 120,
      "g": 80,
      "b": 40
    },
    {
      "x": 18,
      "y": 16,
      "z": 2,
      "r": 120,
      "g": 80,
      "b": 40
    },
    {
      "x": 19,
      "y": 15,
      "z": 2,
      "r": 120,
      "g": 80,
      "b": 40
    },
    {
      "x": 18,
      "y": 15,
      "z": 2,
      "r": 120,
      "g": 80,
      "b": 40
    },
    {
      "x": 20,
      "y": 16,
      "z": 1,
      "r": 120,
      "g": 80,
      "b": 40
    },
    {
      "x": 21,
      "y": 16,
      "z": 1,
      "r": 120,
      "g": 80,
      "b": 40
    },
    {
      "x": 22,
      "y": 16,
      "z": 1,
      "r": 120,
      "g": 80,
      "b": 40
    },
    {
      "x": 20,
      "y": 14,
      "z": 2,
      "r": 120,
      "g": 80,
      "b": 40
    },
    {
      "x": 21,
      "y": 13,
      "z": 2,
      "r": 120,
      "g": 80,
      "b": 40
    },
    {
      "x": 21,
      "y": 14,
      "z": 2,
      "r": 120,
      "g": 80,
      "b": 40
    },
    {
      "x": 22,
      "y": 13,
      "z": 2,
      "r": 120,
      "g": 80,
      "b": 40
    },
    {
      "x": 22,
      "y": 14,
      "z": 2,
      "r": 120,
      "g": 80,
      "b": 40
    },
    {
      "x": 19,
      "y": 14,
      "z": 2,
      "r": 120,
      "g": 80,
      "b": 40
    },
    {
      "x": 23,
      "y": 13,
      "z": 2,
      "r": 120,
      "g": 80,
      "b": 40
    },
    {
      "x": 23,
      "y": 14,
      "z": 2,
      "r": 120,
      "g": 80,
      "b": 40
    },
    {
      "x": 24,
      "y": 14,
      "z": 2,
      "r": 120,
      "g": 80,
      "b": 40
    },
    {
      "x": 23,
      "y": 16,
      "z": 1,
      "r": 120,
      "g": 80,
      "b": 40
    },
    {
      "x": 24,
      "y": 16,
      "z": 1,
      "r": 120,
      "g": 80,
      "b": 40
    },
    {
      "x": 25,
      "y": 15,
      "z": 2,
      "r": 120,
      "g": 80,
      "b": 40
    },
    {
      "x": 26,
      "y": 15,
      "z": 2,
      "r": 120,
      "g": 80,
      "b": 40
    },
    {
      "x": 27,
      "y": 15,
      "z": 2,
      "r": 120,
      "g": 80,
      "b": 40
    },
    {
      "x": 27,
      "y": 16,
      "z": 2,
      "r": 120,
      "g": 80,
      "b": 40
    },
    {
      "x": 25,
      "y": 14,
      "z": 2,
      "r": 120,
      "g": 80,
      "b": 40
    },
    {
      "x": 28,
      "y": 14,
      "z": 3,
      "r": 120,
      "g": 80,
      "b": 40
    },
    {
      "x": 28,
      "y": 15,
      "z": 3,
      "r": 120,
      "g": 80,
      "b": 40
    },
    {
      "x": 29,
      "y": 16,
      "z": 3,
      "r": 120,
      "g": 80,
      "b": 40
    },
    {
      "x": 29,
      "y": 15,
      "z": 3,
      "r": 120,
      "g": 80,
      "b": 40
    },
    {
      "x": 30,
      "y": 15,
      "z": 4,
      "r": 120,
      "g": 80,
      "b": 40
    },
    {
      "x": 30,
      "y": 16,
      "z": 4,
      "r": 120,
      "g": 80,
      "b": 40
    },
    {
      "x": 31,
      "y": 16,
      "z": 5,
      "r": 120,
      "g": 80,
      "b": 40
    },
    {
      "x": 31,
      "y": 15,
      "z": 6,
      "r": 120,
      "g": 80,
      "b": 40
    },
    {
      "x": 32,
      "y": 15,
      "z": 7,
      "r": 120,
      "g": 80,
      "b": 40
    },
    {
      "x": 32,
      "y": 15,
      "z": 8,
      "r": 120,
      "g": 80,
      "b": 40
    },
    {
      "x": 32,
      "y": 16,
      "z": 7,
      "r": 120,
      "g": 80,
      "b": 40
    },
    {
      "x": 30,
      "y": 14,
      "z": 5,
      "r": 120,
      "g": 80,
      "b": 40
    },
    {
      "x": 31,
      "y": 14,
      "z": 6,
      "r": 120,
      "g": 80,
      "b": 40
    },
    {
      "x": 35,
      "y": 16,
      "z": 18,
      "r": 120,
      "g": 80,
      "b": 40
    },
    {
      "x": 35,
      "y": 16,
      "z": 19,
      "r": 120,
      "g": 80,
      "b": 40
    },
    {
      "x": 36,
      "y": 16,
      "z": 23,
      "r": 120,
      "g": 80,
      "b": 40
    },
    {
      "x": 36,
      "y": 16,
      "z": 24,
      "r": 120,
      "g": 80,
      "b": 40
    },
    {
      "x": 36,
      "y": 17,
      "z": 22,
      "r": 120,
      "g": 80,
      "b": 40
    },
    {
      "x": 36,
      "y": 17,
      "z": 23,
      "r": 120,
      "g": 80,
      "b": 40
    },
    {
      "x": 35,
      "y": 17,
      "z": 17,
      "r": 120,
      "g": 80,
      "b": 40
    },
    {
      "x": 35,
      "y": 17,
      "z": 18,
      "r": 120,
      "g": 80,
      "b": 40
    },
    {
      "x": 36,
      "y": 17,
      "z": 21,
      "r": 120,
      "g": 80,
      "b": 40
    },
    {
      "x": 35,
      "y": 14,
      "z": 20,
      "r": 120,
      "g": 80,
      "b": 40
    },
    {
      "x": 35,
      "y": 15,
      "z": 20,
      "r": 120,
      "g": 80,
      "b": 40
    },
    {
      "x": 36,
      "y": 14,
      "z": 25,
      "r": 120,
      "g": 80,
      "b": 40
    },
    {
      "x": 36,
      "y": 15,
      "z": 24,
      "r": 120,
      "g": 80,
      "b": 40
    },
    {
      "x": 36,
      "y": 15,
      "z": 25,
      "r": 120,
      "g": 80,
      "b": 40
    },
    {
      "x": 35,
      "y": 15,
      "z": 19,
      "r": 120,
      "g": 80,
      "b": 40
    },
    {
      "x": 33,
      "y": 14,
      "z": 12,
      "r": 120,
      "g": 80,
      "b": 40
    },
    {
      "x": 33,
      "y": 14,
      "z": 13,
      "r": 120,
      "g": 80,
      "b": 40
    },
    {
      "x": 34,
      "y": 15,
      "z": 15,
      "r": 120,
      "g": 80,
      "b": 40
    },
    {
      "x": 34,
      "y": 15,
      "z": 16,
      "r": 120,
      "g": 80,
      "b": 40
    },
    {
      "x": 32,
      "y": 14,
      "z": 8,
      "r": 120,
      "g": 80,
      "b": 40
    },
    {
      "x": 32,
      "y": 14,
      "z": 9,
      "r": 120,
      "g": 80,
      "b": 40
    },
    {
      "x": 33,
      "y": 15,
      "z": 11,
      "r": 120,
      "g": 80,
      "b": 40
    },
    {
      "x": 33,
      "y": 15,
      "z": 12,
      "r": 120,
      "g": 80,
      "b": 40
    },
    {
      "x": 33,
      "y": 16,
      "z": 11,
      "r": 120,
      "g": 80,
      "b": 40
    },
    {
      "x": 34,
      "y": 16,
      "z": 14,
      "r": 120,
      "g": 80,
      "b": 40
    },
    {
      "x": 34,
      "y": 16,
      "z": 15,
      "r": 120,
      "g": 80,
      "b": 40
    },
    {
      "x": 33,
      "y": 16,
      "z": 10,
      "r": 120,
      "g": 80,
      "b": 40
    },
    {
      "x": 36,
      "y": 19,
      "z": 21,
      "r": 120,
      "g": 80,
      "b": 40
    },
    {
      "x": 8,
      "y": 19,
      "z": 23,
      "r": 120,
      "g": 80,
      "b": 40
    },
    {
      "x": 8,
      "y": 19,
      "z": 22,
      "r": 120,
      "g": 80,
      "b": 40
    },
    {
      "x": 7,
      "y": 19,
      "z": 27,
      "r": 120,
      "g": 80,
      "b": 40
    },
    {
      "x": 7,
      "y": 19,
      "z": 28,
      "r": 120,
      "g": 80,
      "b": 40
    },
    {
