{
  "resolution": 64,
  "gridSize": {
    "x": 31,
    "y": 56,
    "z": 64
  },
  "voxelCount": 6058,
  "voxels": [
    {
      "x": 13,
      "y": 14,
      "z": 11,
      "r": 80,
      "g": 50,
      "b": 30
    },
    {
      "x": 14,
      "y": 14,
      "z": 11,
      "r": 80,
      "g": 50,
      "b": 30
    },
    {
      "x": 14,
      "y": 15,
      "z": 11,
      "r": 80,
      "g": 50,
      "b": 30
    },
    {
      "x": 15,
      "y": 15,
      "z": 11,
      "r": 80,
      "g": 50,
      "b": 30
    },
    {
      "x": 16,
      "y": 14,
      "z": 11,
      "r": 80,
      "g": 50,
      "b": 30
    },
    {
      "x": 16,
      "y": 15,
      "z": 11,
      "r": 80,
      "g": 50,
      "b": 30
    },
    {
      "x": 16,
      "y": 13,
      "z": 11,
      "r": 80,
      "g": 50,
      "b": 30
    },
    {
      "x": 15,
      "y": 13,
      "z": 11,
      "r": 80,
      "g": 50,
      "b": 30
    },
    {
      "x": 14,
      "y": 13,
      "z": 11,
      "r": 80,
      "g": 50,
      "b": 30
    },
    {
      "x": 13,
      "y": 13,
      "z": 11,
      "r": 80,
      "g": 50,
      "b": 30
    },
    {
      "x": 13,
      "y": 15,
      "z": 11,
      "r": 80,
      "g": 50,
      "b": 30
    },
    {
      "x": 15,
      "y": 12,
      "z": 11,
      "r": 80,
      "g": 50,
      "b": 30
    },
    {
      "x": 14,
      "y": 12,
      "z": 11,
      "r": 80,
      "g": 50,
      "b": 30
    },
    {
      "x": 15,
      "y": 14,
      "z": 11,
      "r": 80,
      "g": 50,
      "b": 30
    },
    {
      "x": 12,
      "y": 14,
      "z": 11,
      "r": 80,
      "g": 50,
      "b": 30
    },
    {
      "x": 13,
      "y": 12,
      "z": 11,
      "r": 80,
      "g": 50,
      "b": 30
    },
    {
      "x": 16,
      "y": 12,
      "z": 11,
      "r": 80,
      "g": 50,
      "b": 30
    },
    {
      "x": 17,
      "y": 14,
      "z": 11,
      "r": 80,
      "g": 50,
      "b": 30
    },
    {
      "x": 17,
      "y": 13,
      "z": 11,
      "r": 80,
      "g": 50,
      "b": 30
    },
    {
      "x": 14,
      "y": 16,
      "z": 11,
      "r": 80,
      "g": 50,
      "b": 30
    },
    {
      "x": 15,
      "y": 16,
      "z": 11,
      "r": 80,
      "g": 50,
      "b": 30
    },
    {
      "x": 14,
      "y": 10,
      "z": 12,
      "r": 80,
      "g": 50,
      "b": 30
    },
    {
      "x": 14,
      "y": 11,
      "z": 12,
      "r": 80,
      "g": 50,
      "b": 30
    },
    {
      "x": 14,
      "y": 12,
      "z": 12,
      "r": 80,
      "g": 50,
      "b": 30
    },
    {
      "x": 14,
      "y": 13,
      "z": 12,
      "r": 80,
      "g": 50,
      "b": 30
    },
    {
      "x": 15,
      "y": 11,
      "z": 12,
      "r": 80,
      "g": 50,
      "b": 30
    },
    {
      "x": 15,
      "y": 12,
      "z": 12,
      "r": 80,
      "g": 50,
      "b": 30
    },
    {
      "x": 15,
      "y": 10,
      "z": 12,
      "r": 80,
      "g": 50,
      "b": 30
    },
    {
      "x": 15,
      "y": 13,
      "z": 12,
      "r": 80,
      "g": 50,
      "b": 30
    },
    {
      "x": 14,
      "y": 14,
      "z": 12,
      "r": 80,
      "g": 50,
      "b": 30
    },
    {
      "x": 15,
      "y": 14,
      "z": 12,
      "r": 80,
      "g": 50,
      "b": 30
    },
    {
      "x": 14,
      "y": 9,
      "z": 12,
      "r": 80,
      "g": 50,
      "b": 30
    },
    {
      "x": 15,
      "y": 9,
      "z": 12,
      "r": 80,
      "g": 50,
      "b": 30
    },
    {
      "x": 21,
      "y": 12,
      "z": 46,
      "r": 148,
      "g": 98,
      "b": 52
    },
    {
      "x": 21,
      "y": 11,
      "z": 46,
      "r": 148,
      "g": 98,
      "b": 52
    },
    {
      "x": 21,
      "y": 11,
      "z": 47,
      "r": 148,
      "g": 98,
      "b": 52
    },
    {
      "x": 20,
      "y": 11,
      "z": 47,
      "r": 148,
      "g": 98,
      "b": 52
    },
    {
      "x": 21,
      "y": 12,
      "z": 47,
      "r": 148,
      "g": 98,
      "b": 52
    },
    {
      "x": 20,
      "y": 11,
      "z": 46,
      "r": 148,
      "g": 98,
      "b": 52
    },
    {
      "x": 20,
      "y": 12,
      "z": 46,
      "r": 148,
      "g": 98,
      "b": 52
    },
    {
      "x": 20,
      "y": 12,
      "z": 47,
      "r": 148,
      "g": 98,
      "b": 52
    },
    {
      "x": 8,
      "y": 12,
      "z": 46,
      "r": 148,
      "g": 98,
      "b": 52
    },
    {
      "x": 8,
      "y": 11,
      "z": 46,
      "r": 148,
      "g": 98,
      "b": 52
    },
    {
      "x": 8,
      "y": 11,
      "z": 47,
      "r": 148,
      "g": 98,
      "b": 52
    },
    {
      "x": 9,
      "y": 11,
      "z": 46,
      "r": 148,
      "g": 98,
      "b": 52
    },
    {
      "x": 9,
      "y": 11,
      "z": 47,
      "r": 148,
      "g": 98,
      "b": 52
    },
    {
      "x": 8,
      "y": 12,
      "z": 47,
      "r": 148,
      "g": 98,
      "b": 52
    },
    {
      "x": 9,
      "y": 12,
      "z": 47,
      "r": 148,
      "g": 98,
      "b": 52
    },
    {
      "x": 9,
      "y": 12,
      "z": 46,
      "r": 148,
      "g": 98,
      "b": 52
    },
    {
      "x": 8,
      "y": 8,
      "z": 5,
      "r": 120,
      "g": 80,
      "b": 40
    },
    {
      "x": 8,
      "y": 8,
      "z": 6,
      "r": 120,
      "g": 80,
      "b": 40
    },
    {
      "x": 9,
      "y": 8,
      "z": 4,
      "r": 120,
      "g": 80,
      "b": 40
    },
    {
      "x": 9,
      "y": 8,
      "z": 5,
      "r": 120,
      "g": 80,
      "b": 40
    },
    {
      "x": 10,
      "y": 8,
      "z": 3,
      "r": 120,
      "g": 80,
      "b": 40
    },
    {
      "x": 10,
      "y": 8,
      "z": 4,
      "r": 120,
      "g": 80,
      "b": 40
    },
    {
      "x": 9,
      "y": 8,
      "z": 6,
      "r": 120,
      "g": 80,
      "b": 40
    },
    {
      "x": 11,
      "y": 8,
      "z": 2,
      "r": 120,
      "g": 80,
      "b": 40
    },
    {
      "x": 11,
      "y": 8,
      "z": 3,
      "r": 120,
      "g": 80,
      "b": 40
    },
    {
      "x": 12,
      "y": 8,
      "z": 2,
      "r": 120,
      "g": 80,
      "b": 40
    },
    {
      "x": 13,
      "y": 8,
      "z": 2,
      "r": 120,
      "g": 80,
      "b": 40
    },
    {
      "x": 14,
      "y": 8,
      "z": 2,
      "r": 120,
      "g": 80,
      "b": 40
    },
    {
      "x": 15,
      "y": 8,
      "z": 2,
      "r": 120,
      "g": 80,
      "b": 40
    },
    {
      "x": 16,
      "y": 8,
      "z": 2,
      "r": 120,
      "g": 80,
      "b": 40
    },
    {
      "x": 17,
      "y": 8,
      "z": 2,
      "r": 120,
      "g": 80,
      "b": 40
    },
    {
      "x": 18,
      "y": 8,
      "z": 2,
      "r": 120,
      "g": 80,
      "b": 40
    },
    {
      "x": 18,
      "y": 8,
      "z": 3,
      "r": 120,
      "g": 80,
      "b": 40
    },
    {
      "x": 19,
      "y": 8,
      "z": 3,
      "r": 120,
      "g": 80,
      "b": 40
    },
    {
      "x": 19,
      "y": 8,
      "z": 4,
      "r": 120,
      "g": 80,
      "b": 40
    },
    {
      "x": 20,
      "y": 8,
      "z": 3,
      "r": 120,
      "g": 80,
      "b": 40
    },
    {
      "x": 20,
      "y": 8,
      "z": 4,
      "r": 120,
      "g": 80,
      "b": 40
    },
    {
      "x": 20,
      "y": 8,
      "z": 5,
      "r": 120,
      "g": 80,
      "b": 40
    },
    {
      "x": 21,
      "y": 8,
      "z": 5,
      "r": 120,
      "g": 80,
      "b": 40
    },
    {
      "x": 21,
      "y": 8,
      "z": 6,
      "r": 120,
      "g": 80,
      "b": 40
    },
    {
      "x": 22,
      "y": 8,
      "z": 12,
      "r": 120,
      "g": 80,
      "b": 40
    },
    {
      "x": 22,
      "y": 8,
      "z": 13,
      "r": 120,
      "g": 80,
      "b": 40
    },
    {
      "x": 22,
      "y": 9,
      "z": 12,
      "r": 120,
      "g": 80,
      "b": 40
    },
    {
      "x": 22,
      "y": 9,
      "z": 13,
      "r": 120,
      "g": 80,
      "b": 40
    },
    {
      "x": 23,
      "y": 9,
      "z": 13,
      "r": 120,
      "g": 80,
      "b": 40
    },
    {
      "x": 23,
      "y": 9,
      "z": 14,
      "r": 120,
      "g": 80,
      "b": 40
    },
    {
      "x": 23,
      "y": 9,
      "z": 15,
      "r": 120,
      "g": 80,
      "b": 40
    },
    {
      "x": 23,
      "y": 9,
      "z": 16,
      "r": 120,
      "g": 80,
      "b": 40
    },
    {
      "x": 23,
      "y": 9,
      "z": 17,
      "r": 120,
      "g": 80,
      "b": 40
    },
    {
      "x": 24,
      "y": 9,
      "z": 17,
      "r": 120,
      "g": 80,
      "b": 40
    },
    {
      "x": 22,
      "y": 9,
      "z": 11,
      "r": 120,
      "g": 80,
      "b": 40
    },
    {
      "x": 23,
      "y": 9,
      "z": 12,
      "r": 120,
      "g": 80,
      "b": 40
    },
    {
      "x": 23,
      "y": 8,
      "z": 13,
      "r": 120,
      "g": 80,
      "b": 40
    },
    {
      "x": 21,
      "y": 8,
      "z": 7,
      "r": 120,
      "g": 80,
      "b": 40
    },
    {
      "x": 21,
      "y": 8,
      "z": 8,
      "r": 120,
      "g": 80,
      "b": 40
    },
    {
      "x": 21,
      "y": 8,
      "z": 9,
      "r": 120,
      "g": 80,
      "b": 40
    },
    {
      "x": 22,
      "y": 8,
      "z": 9,
      "r": 120,
      "g": 80,
      "b": 40
    },
    {
      "x": 22,
      "y": 8,
      "z": 10,
      "r": 120,
      "g": 80,
      "b": 40
    },
    {
      "x": 22,
      "y": 8,
      "z": 11,
      "r": 120,
      "g": 80,
      "b": 40
    },
    {
      "x": 22,
      "y": 9,
      "z": 9,
      "r": 120,
      "g": 80,
      "b": 40
    },
    {
      "x": 22,
      "y": 9,
      "z": 10,
      "r": 120,
      "g": 80,
      "b": 40
    },
    {
      "x": 21,
      "y": 9,
      "z": 6,
      "r": 120,
      "g": 80,
      "b": 40
    },
    {
      "x": 21,
      "y": 9,
      "z": 7,
      "r": 120,
      "g": 80,
      "b": 40
    },
    {
      "x": 21,
      "y": 9,
      "z": 8,
      "r": 120,
      "g": 80,
      "b": 40
    },
    {
      "x": 21,
      "y": 9,
      "z": 9,
      "r": 120,
      "g": 80,
      "b": 40
    },
    {
      "x": 22,
      "y": 9,
      "z": 8,
      "r": 120,
      "g": 80,
      "b": 40
    },
    {
      "x": 7,
      "y": 8,
      "z": 9,
      "r": 120,
      "g": 80,
      "b": 40
    },
    {
      "x": 7,
      "y": 8,
      "z": 10,
      "r": 120,
      "g": 80,
      "b": 40
    },
    {
      "x": 7,
      "y": 8,
      "z": 11,
      "r": 120,
      "g": 80,
      "b": 40
    },
    {
      "x": 7,
      "y": 8,
      "z": 12,
      "r": 120,
      "g": 80,
      "b": 40
    },
    {
      "x": 8,
      "y": 8,
      "z": 7,
      "r": 120,
      "g": 80,
      "b": 40
    },
    {
      "x": 8,
      "y": 8,
      "z": 8,
      "r": 120,
      "g": 80,
      "b": 40
    },
    {
      "x": 8,
      "y": 8,
      "z": 9,
      "r": 120,
      "g": 80,
      "b": 40
    },
    {
      "x": 6,
      "y": 9,
      "z": 14,
      "r": 120,
      "g": 80,
      "b": 40
    },
    {
      "x": 6,
      "y": 9,
      "z": 15,
      "r": 120,
      "g": 80,
      "b": 40
    },
    {
      "x": 6,
      "y": 9,
      "z": 16,
      "r": 120,
      "g": 80,
      "b": 40
    },
    {
      "x": 6,
      "y": 9,
      "z": 17,
      "r": 120,
      "g": 80,
      "b": 40
    },
    {
      "x": 6,
      "y": 9,
      "z": 18,
      "r": 120,
      "g": 80,
      "b": 40
    },
    {
      "x": 7,
      "y": 8,
      "z": 13,
      "r": 120,
      "g": 80,
      "b": 40
    },
    {
      "x": 7,
      "y": 9,
      "z": 13,
      "r": 120,
      "g": 80,
      "b": 40
    },
    {
      "x": 7,
      "y": 9,
      "z": 14,
      "r": 120,
      "g": 80,
      "b": 40
    },
    {
      "x": 6,
      "y": 9,
      "z": 13,
      "r": 120,
      "g": 80,
      "b": 40
    },
    {
      "x": 5,
      "y": 9,
      "z": 18,
      "r": 120,
      "g": 80,
      "b": 40
    },
    {
      "x": 7,
      "y": 9,
      "z": 12,
      "r": 120,
      "g": 80,
      "b": 40
    },
    {
      "x": 7,
      "y": 9,
      "z": 9,
      "r": 120,
      "g": 80,
      "b": 40
    },
    {
      "x": 7,
      "y": 9,
      "z": 10,
      "r": 120,
      "g": 80,
      "b": 40
    },
    {
      "x": 7,
      "y": 9,
      "z": 11,
      "r": 120,
      "g": 80,
      "b": 40
    },
    {
      "x": 8,
      "y": 9,
      "z": 6,
      "r": 120,
      "g": 80,
      "b": 40
    },
    {
      "x": 8,
      "y": 9,
      "z": 7,
      "r": 120,
      "g": 80,
      "b": 40
    },
    {
      "x": 8,
      "y": 9,
      "z": 8,
      "r": 120,
      "g": 80,
      "b": 40
    },
    {
      "x": 8,
      "y": 9,
      "z": 9,
      "r": 120,
      "g": 80,
      "b": 40
    },
    {
      "x": 9,
      "y": 9,
      "z": 5,
      "r": 120,
      "g": 80,
      "b": 40
    },
    {
      "x": 9,
      "y": 9,
      "z": 6,
      "r": 120,
      "g": 80,
      "b": 40
    },
    {
      "x": 10,
      "y": 8,
      "z": 5,
      "r": 120,
      "g": 80,
      "b": 40
    },
    {
      "x": 9,
      "y": 9,
      "z": 4,
      "r": 120,
      "g": 80,
      "b": 40
    },
    {
      "x": 10,
      "y": 9,
      "z": 3,
      "r": 120,
      "g": 80,
      "b": 40
    },
    {
      "x": 10,
      "y": 9,
      "z": 4,
      "r": 120,
      "g": 80,
      "b": 40
    },
    {
      "x": 12,
      "y": 8,
      "z": 3,
      "r": 120,
      "g": 80,
      "b": 40
    },
    {
      "x": 17,
      "y": 8,
      "z": 3,
      "r": 120,
      "g": 80,
      "b": 40
    },
    {
      "x": 19,
      "y": 9,
      "z": 3,
      "r": 120,
      "g": 80,
      "b": 40
    },
    {
      "x": 19,
      "y": 9,
      "z": 4,
      "r": 120,
      "g": 80,
      "b": 40
    },
    {
      "x": 20,
      "y": 9,
      "z": 4,
      "r": 120,
      "g": 80,
      "b": 40
    },
    {
      "x": 20,
      "y": 9,
      "z": 5,
      "r": 120,
      "g": 80,
      "b": 40
    },
    {
      "x": 20,
      "y": 9,
      "z": 6,
      "r": 120,
      "g": 80,
      "b": 40
    },
    {
      "x": 20,
      "y": 8,
      "z": 6,
      "r": 120,
      "g": 80,
      "b": 40
    },
    {
      "x": 21,
      "y": 8,
      "z": 10,
      "r": 120,
      "g": 80,
      "b": 40
    },
    {
      "x": 22,
      "y": 9,
      "z": 14,
      "r": 120,
      "g": 80,
      "b": 40
    },
    {
      "x": 23,
      "y": 9,
      "z": 18,
      "r": 120,
      "g": 80,
      "b": 40
    },
    {
      "x": 21,
      "y": 9,
      "z": 10,
      "r": 120,
      "g": 80,
      "b": 40
    },
    {
      "x": 8,
      "y": 8,
      "z": 10,
      "r": 120,
      "g": 80,
      "b": 40
    },
    {
      "x": 9,
      "y": 8,
      "z": 7,
      "r": 120,
      "g": 80,
      "b": 40
    },
    {
      "x": 8,
      "y": 9,
      "z": 10,
      "r": 120,
      "g": 80,
      "b": 40
    },
    {
      "x": 6,
      "y": 10,
      "z": 18,
      "r": 120,
      "g": 80,
      "b": 40
    },
    {
      "x": 6,
      "y": 10,
      "z": 19,
      "r": 120,
      "g": 80,
      "b": 40
    },
    {
      "x": 7,
      "y": 9,
      "z": 15,
      "r": 120,
      "g": 80,
      "b": 40
    },
    {
      "x": 6,
      "y": 9,
      "z": 19,
      "r": 120,
      "g": 80,
      "b": 40
    },
    {
      "x": 8,
      "y": 12,
      "z": 4,
      "r": 120,
      "g": 80,
      "b": 40
    },
    {
      "x": 8,
      "y": 12,
      "z": 5,
      "r": 120,
      "g": 80,
      "b": 40
    },
    {
      "x": 9,
      "y": 12,
      "z": 3,
      "r": 120,
      "g": 80,
      "b": 40
    },
    {
      "x": 9,
      "y": 12,
      "z": 4,
      "r": 120,
      "g": 80,
      "b": 40
    },
    {
      "x": 10,
      "y": 12,
      "z": 2,
      "r": 120,
      "g": 80,
      "b": 40
    },
    {
      "x": 10,
      "y": 12,
      "z": 3,
      "r": 120,
      "g": 80,
      "b": 40
    },
    {
      "x": 9,
      "y": 12,
      "z": 2,
      "r": 120,
      "g": 80,
      "b": 40
    },
    {
      "x": 11,
      "y": 12,
      "z": 1,
      "r": 120,
      "g": 80,
      "b": 40
    },
    {
      "x": 11,
      "y": 12,
      "z": 2,
      "r": 120,
      "g": 80,
      "b": 40
    },
    {
      "x": 12,
      "y": 12,
      "z": 1,
      "r": 120,
      "g": 80,
      "b": 40
    },
    {
      "x": 13,
      "y": 12,
      "z": 1,
      "r": 120,
      "g": 80,
      "b": 40
    },
    {
      "x": 14,
      "y": 12,
      "z": 1,
      "r": 120,
      "g": 80,
      "b": 40
    },
    {
      "x": 15,
      "y": 12,
      "z": 1,
      "r": 120,
      "g": 80,
      "b": 40
    },
    {
      "x": 16,
      "y": 12,
      "z": 1,
      "r": 120,
      "g": 80,
      "b": 40
    },
    {
      "x": 17,
      "y": 12,
      "z": 1,
      "r": 120,
      "g": 80,
      "b": 40
    },
    {
      "x": 18,
      "y": 12,
      "z": 1,
      "r": 120,
      "g": 80,
      "b": 40
    },
    {
      "x": 18,
      "y": 12,
      "z": 2,
      "r": 120,
      "g": 80,
      "b": 40
    },
    {
      "x": 19,
      "y": 12,
      "z": 2,
      "r": 120,
      "g": 80,
      "b": 40
    },
    {
      "x": 20,
      "y": 12,
      "z": 2,
      "r": 120,
      "g": 80,
      "b": 40
    },
    {
      "x": 20,
      "y": 12,
      "z": 3,
      "r": 120,
      "g": 80,
      "b": 40
    },
    {
      "x": 20,
      "y": 12,
      "z": 4,
      "r": 120,
      "g": 80,
      "b": 40
    },
    {
      "x": 21,
      "y": 12,
      "z": 4,
      "r": 120,
      "g": 80,
      "b": 40
    },
    {
      "x": 21,
      "y": 12,
      "z": 5,
      "r": 120,
      "g": 80,
      "b": 40
    },
    {
      "x": 21,
      "y": 12,
      "z": 6,
      "r": 120,
      "g": 80,
      "b": 40
    },
    {
      "x": 21,
      "y": 12,
      "z": 7,
      "r": 120,
      "g": 80,
      "b": 40
    },
    {
      "x": 22,
      "y": 12,
      "z": 7,
      "r": 120,
      "g": 80,
      "b": 40
    },
    {
      "x": 22,
      "y": 12,
      "z": 8,
      "r": 120,
      "g": 80,
      "b": 40
    },
    {
      "x": 22,
      "y": 12,
      "z": 9,
      "r": 120,
      "g": 80,
      "b": 40
    },
    {
      "x": 22,
      "y": 12,
      "z": 10,
      "r": 120,
      "g": 80,
      "b": 40
    },
    {
      "x": 23,
      "y": 12,
      "z": 10,
      "r": 120,
      "g": 80,
      "b": 40
    },
    {
      "x": 23,
      "y": 12,
      "z": 11,
      "r": 120,
      "g": 80,
      "b": 40
    },
    {
      "x": 23,
      "y": 12,
      "z": 12,
      "r": 120,
      "g": 80,
      "b": 40
    },
    {
      "x": 23,
      "y": 12,
      "z": 13,
      "r": 120,
      "g": 80,
      "b": 40
    },
    {
      "x": 23,
      "y": 12,
      "z": 14,
      "r": 120,
      "g": 80,
      "b": 40
    },
    {
      "x": 23,
      "y": 12,
      "z": 15,
      "r": 120,
      "g": 80,
      "b": 40
    },
    {
      "x": 24,
      "y": 12,
      "z": 15,
      "r": 120,
      "g": 80,
      "b": 40
    },
    {
      "x": 24,
      "y": 12,
      "z": 16,
      "r": 120,
      "g": 80,
      "b": 40
    },
    {
      "x": 24,
      "y": 12,
      "z": 14,
      "r": 120,
      "g": 80,
      "b": 40
    },
    {
      "x": 24,
      "y": 9,
      "z": 19,
      "r": 120,
      "g": 80,
      "b": 40
    },
    {
      "x": 24,
      "y": 10,
      "z": 19,
      "r": 120,
      "g": 80,
      "b": 40
    },
    {
      "x": 24,
      "y": 9,
      "z": 18,
      "r": 120,
      "g": 80,
      "b": 40
    },
    {
      "x": 24,
      "y": 10,
      "z": 18,
      "r": 120,
      "g": 80,
      "b": 40
    },
    {
      "x": 23,
      "y": 9,
      "z": 19,
      "r": 120,
      "g": 80,
      "b": 40
    },
    {
      "x": 5,
      "y": 9,
      "z": 20,
      "r": 120,
      "g": 80,
      "b": 40
    },
    {
      "x": 6,
      "y": 9,
      "z": 20,
      "r": 120,
      "g": 80,
      "b": 40
    },
    {
      "x": 5,
      "y": 9,
      "z": 19,
      "r": 120,
      "g": 80,
      "b": 40
    },
    {
      "x": 5,
      "y": 10,
      "z": 19,
      "r": 120,
      "g": 80,
      "b": 40
    },
    {
      "x": 5,
      "y": 10,
      "z": 20,
      "r": 120,
      "g": 80,
      "b": 40
    },
    {
      "x": 5,
      "y": 12,
      "z": 16,
      "r": 120,
      "g": 80,
      "b": 40
    },
    {
      "x": 5,
      "y": 12,
      "z": 17,
      "r": 120,
      "g": 80,
      "b": 40
    },
    {
      "x": 6,
      "y": 12,
      "z": 11,
      "r": 120,
      "g": 80,
      "b": 40
    },
    {
      "x": 6,
      "y": 12,
      "z": 12,
      "r": 120,
      "g": 80,
      "b": 40
    },
    {
      "x": 6,
      "y": 12,
      "z": 13,
      "r": 120,
      "g": 80,
      "b": 40
    },
    {
      "x": 6,
      "y": 12,
      "z": 14,
      "r": 120,
      "g": 80,
      "b": 40
    },
    {
      "x": 6,
      "y": 12,
      "z": 15,
      "r": 120,
      "g": 80,
      "b": 40
    },
    {
      "x": 6,
      "y": 12,
      "z": 16,
      "r": 120,
      "g": 80,
      "b": 40
    },
    {
      "x": 7,
      "y": 12,
      "z": 11,
      "r": 120,
      "g": 80,
      "b": 40
    },
    {
      "x": 7,
      "y": 12,
      "z": 7,
      "r": 120,
      "g": 80,
      "b": 40
    },
    {
      "x": 7,
      "y": 12,
      "z": 8,
      "r": 120,
      "g": 80,
      "b": 40
    },
    {
      "x": 7,
      "y": 12,
      "z": 9,
      "r": 120,
      "g": 80,
      "b": 40
    },
    {
      "x": 7,
      "y": 12,
      "z": 10,
      "r": 120,
      "g": 80,
      "b": 40
    },
    {
      "x": 8,
      "y": 12,
      "z": 6,
      "r": 120,
      "g": 80,
      "b": 40
    },
    {
      "x": 8,
      "y": 12,
      "z": 7,
      "r": 120,
      "g": 80,
      "b": 40
    },
    {
      "x": 24,
      "y": 12,
      "z": 17,
      "r": 120,
      "g": 80,
      "b": 40
    },
    {
      "x": 24,
      "y": 12,
      "z": 18,
      "r": 120,
      "g": 80,
      "b": 40
    },
    {
      "x": 21,
      "y": 11,
      "z": 5,
      "r": 120,
      "g": 80,
      "b": 40
    },
    {
      "x": 21,
      "y": 11,
      "z": 6,
      "r": 120,
      "g": 80,
      "b": 40
    },
    {
      "x": 22,
      "y": 12,
      "z": 11,
      "r": 120,
      "g": 80,
      "b": 40
    },
    {
      "x": 18,
      "y": 11,
      "z": 1,
      "r": 120,
      "g": 80,
      "b": 40
    },
    {
      "x": 18,
      "y": 11,
      "z": 2,
      "r": 120,
      "g": 80,
      "b": 40
    },
    {
      "x": 19,
      "y": 11,
      "z": 2,
      "r": 120,
      "g": 80,
      "b": 40
    },
    {
      "x": 19,
      "y": 11,
      "z": 3,
      "r": 120,
      "g": 80,
      "b": 40
    },
    {
      "x": 19,
      "y": 12,
      "z": 3,
      "r": 120,
      "g": 80,
      "b": 40
    },
    {
      "x": 20,
      "y": 11,
      "z": 3,
      "r": 120,
      "g": 80,
      "b": 40
    },
    {
      "x": 20,
      "y": 11,
      "z": 4,
      "r": 120,
      "g": 80,
      "b": 40
    },
    {
      "x": 21,
      "y": 11,
      "z": 4,
      "r": 120,
      "g": 80,
      "b": 40
    },
    {
      "x": 15,
      "y": 11,
      "z": 1,
      "r": 120,
      "g": 80,
      "b": 40
    },
    {
      "x": 16,
      "y": 11,
      "z": 1,
      "r": 120,
      "g": 80,
      "b": 40
    },
    {
      "x": 17,
      "y": 11,
      "z": 1,
      "r": 120,
      "g": 80,
      "b": 40
    },
    {
      "x": 11,
      "y": 11,
      "z": 1,
      "r": 120,
      "g": 80,
      "b": 40
    },
    {
      "x": 11,
      "y": 11,
      "z": 2,
      "r": 120,
      "g": 80,
      "b": 40
    },
    {
      "x": 12,
      "y": 11,
      "z": 1,
      "r": 120,
      "g": 80,
      "b": 40
    },
    {
      "x": 13,
      "y": 11,
      "z": 1,
      "r": 120,
      "g": 80,
      "b": 40
    },
    {
      "x": 14,
      "y": 11,
      "z": 1,
      "r": 120,
      "g": 80,
      "b": 40
    },
    {
      "x": 8,
      "y": 11,
      "z": 4,
      "r": 120,
      "g": 80,
      "b": 40
    },
    {
      "x": 8,
      "y": 11,
      "z": 5,
      "r": 120,
      "g": 80,
      "b": 40
    },
    {
      "x": 9,
      "y": 11,
      "z": 3,
      "r": 120,
      "g": 80,
      "b": 40
    },
    {
      "x": 9,
      "y": 11,
      "z": 4,
      "r": 120,
      "g": 80,
      "b": 40
    },
    {
      "x": 9,
      "y": 11,
      "z": 5,
      "r": 120,
      "g": 80,
      "b": 40
    },
    {
      "x": 10,
      "y": 11,
      "z": 2,
      "r": 120,
      "g": 80,
      "b": 40
    },
    {
      "x": 10,
      "y": 11,
      "z": 3,
      "r": 120,
      "g": 80,
      "b": 40
    },
    {
      "x": 7,
      "y": 12,
      "z": 12,
      "r": 120,
      "g": 80,
      "b": 40
    },
    {
      "x": 8,
      "y": 11,
      "z": 6,
      "r": 120,
      "g": 80,
      "b": 40
    },
    {
      "x": 8,
      "y": 12,
      "z": 8,
      "r": 120,
      "g": 80,
      "b": 40
    },
    {
      "x": 5,
      "y": 12,
      "z": 18,
      "r": 120,
      "g": 80,
      "b": 40
    },
    {
      "x": 5,
      "y": 12,
      "z": 19,
      "r": 120,
      "g": 80,
      "b": 40
    },
    {
      "x": 6,
      "y": 11,
      "z": 10,
      "r": 120,
      "g": 80,
      "b": 40
    },
    {
      "x": 6,
      "y": 11,
      "z": 11,
      "r": 120,
      "g": 80,
      "b": 40
    },
    {
      "x": 6,
      "y": 12,
      "z": 10,
      "r": 120,
      "g": 80,
      "b": 40
    },
    {
      "x": 7,
      "y": 11,
      "z": 7,
      "r": 120,
      "g": 80,
      "b": 40
    },
    {
      "x": 7,
      "y": 11,
      "z": 8,
      "r": 120,
      "g": 80,
      "b": 40
    },
    {
      "x": 7,
      "y": 11,
      "z": 9,
      "r": 120,
      "g": 80,
      "b": 40
    },
    {
      "x": 7,
      "y": 11,
      "z": 10,
      "r": 120,
      "g": 80,
      "b": 40
    },
    {
      "x": 8,
      "y": 11,
      "z": 7,
      "r": 120,
      "g": 80,
      "b": 40
    },
    {
      "x": 7,
      "y": 12,
      "z": 6,
      "r": 120,
      "g": 80,
      "b": 40
    },
    {
      "x": 5,
      "y": 12,
      "z": 15,
      "r": 120,
      "g": 80,
      "b": 40
    },
    {
      "x": 10,
      "y": 12,
      "z": 1,
      "r": 120,
      "g": 80,
      "b": 40
    },
    {
      "x": 10,
      "y": 11,
      "z": 1,
      "r": 120,
      "g": 80,
      "b": 40
    },
    {
      "x": 9,
      "y": 11,
      "z": 2,
      "r": 120,
      "g": 80,
      "b": 40
    },
    {
      "x": 13,
      "y": 12,
      "z": 0,
      "r": 120,
      "g": 80,
      "b": 40
    },
    {
      "x": 14,
      "y": 12,
      "z": 0,
      "r": 120,
      "g": 80,
      "b": 40
    },
    {
      "x": 15,
      "y": 12,
      "z": 0,
      "r": 120,
      "g": 80,
      "b": 40
    },
    {
      "x": 16,
      "y": 12,
      "z": 0,
      "r": 120,
      "g": 80,
      "b": 40
    },
    {
      "x": 19,
      "y": 11,
      "z": 1,
      "r": 120,
      "g": 80,
      "b": 40
    },
    {
      "x": 19,
      "y": 12,
      "z": 1,
      "r": 120,
      "g": 80,
      "b": 40
    },
    {
      "x": 21,
      "y": 12,
      "z": 3,
      "r": 120,
      "g": 80,
      "b": 40
    },
    {
      "x": 20,
      "y": 11,
      "z": 2,
      "r": 120,
      "g": 80,
      "b": 40
    },
    {
      "x": 24,
      "y": 12,
      "z": 13,
      "r": 120,
      "g": 80,
      "b": 40
    },
    {
      "x": 23,
      "y": 11,
      "z": 10,
      "r": 120,
      "g": 80,
      "b": 40
    },
    {
      "x": 23,
      "y": 11,
      "z": 11,
      "r": 120,
      "g": 80,
      "b": 40
    },
    {
      "x": 22,
      "y": 11,
      "z": 6,
      "r": 120,
      "g": 80,
      "b": 40
    },
    {
      "x": 22,
      "y": 11,
      "z": 7,
      "r": 120,
      "g": 80,
      "b": 40
    },
    {
      "x": 22,
      "y": 11,
      "z": 8,
      "r": 120,
      "g": 80,
      "b": 40
    },
    {
      "x": 22,
      "y": 11,
      "z": 9,
      "r": 120,
      "g": 80,
      "b": 40
    },
    {
      "x": 22,
      "y": 11,
      "z": 10,
      "r": 120,
      "g": 80,
      "b": 40
    },
    {
      "x": 22,
      "y": 12,
      "z": 6,
      "r": 120,
      "g": 80,
      "b": 40
    },
    {
      "x": 23,
      "y": 12,
      "z": 9,
      "r": 120,
      "g": 80,
      "b": 40
    },
    {
      "x": 24,
      "y": 11,
      "z": 18,
      "r": 120,
      "g": 80,
      "b": 40
    },
    {
      "x": 24,
      "y": 11,
      "z": 19,
      "r": 120,
      "g": 80,
      "b": 40
    },
    {
      "x": 24,
      "y": 11,
      "z": 16,
      "r": 120,
      "g": 80,
      "b": 40
    },
    {
      "x": 24,
      "y": 11,
      "z": 17,
      "r": 120,
      "g": 80,
      "b": 40
    },
    {
      "x": 23,
      "y": 10,
      "z": 17,
      "r": 120,
      "g": 80,
      "b": 40
    },
    {
      "x": 23,
      "y": 10,
      "z": 18,
      "r": 120,
      "g": 80,
      "b": 40
    },
    {
      "x": 24,
      "y": 10,
      "z": 17,
      "r": 120,
      "g": 80,
      "b": 40
    },
    {
      "x": 21,
      "y": 10,
      "z": 8,
      "r": 120,
      "g": 80,
      "b": 40
    },
    {
      "x": 21,
      "y": 10,
      "z": 9,
      "r": 120,
      "g": 80,
      "b": 40
    },
    {
      "x": 22,
      "y": 10,
      "z": 9,
      "r": 120,
      "g": 80,
      "b": 40
    },
    {
      "x": 22,
      "y": 10,
      "z": 10,
      "r": 120,
      "g": 80,
      "b": 40
    },
    {
      "x": 22,
      "y": 10,
      "z": 11,
      "r": 120,
      "g": 80,
      "b": 40
    },
    {
      "x": 21,
      "y": 9,
      "z": 5,
      "r": 120,
      "g": 80,
      "b": 40
    },
    {
      "x": 21,
      "y": 10,
      "z": 5,
      "r": 120,
      "g": 80,
      "b": 40
    },
    {
      "x": 21,
      "y": 10,
      "z": 6,
      "r": 120,
      "g": 80,
      "b": 40
    },
    {
      "x": 21,
      "y": 10,
      "z": 7,
      "r": 120,
      "g": 80,
      "b": 40
    },
    {
      "x": 22,
      "y": 10,
      "z": 8,
      "r": 120,
      "g": 80,
      "b": 40
    },
    {
      "x": 23,
      "y": 10,
      "z": 13,
      "r": 120,
      "g": 80,
      "b": 40
    },
    {
      "x": 23,
      "y": 10,
      "z": 14,
      "r": 120,
      "g": 80,
      "b": 40
    },
    {
      "x": 23,
      "y": 10,
      "z": 15,
      "r": 120,
      "g": 80,
      "b": 40
    },
    {
      "x": 23,
      "y": 10,
      "z": 16,
      "r": 120,
      "g": 80,
      "b": 40
    },
    {
      "x": 23,
      "y": 11,
      "z": 16,
      "r": 120,
      "g": 80,
      "b": 40
    },
    {
      "x": 23,
      "y": 11,
      "z": 17,
      "r": 120,
      "g": 80,
      "b": 40
    },
    {
      "x": 22,
      "y": 10,
      "z": 12,
      "r": 120,
      "g": 80,
      "b": 40
    },
    {
      "x": 22,
      "y": 10,
      "z": 13,
      "r": 120,
      "g": 80,
      "b": 40
    },
    {
      "x": 23,
      "y": 10,
      "z": 12,
      "r": 120,
      "g": 80,
      "b": 40
    },
    {
      "x": 23,
      "y": 11,
      "z": 15,
      "r": 120,
      "g": 80,
      "b": 40
    },
    {
      "x": 22,
      "y": 11,
      "z": 12,
      "r": 120,
      "g": 80,
      "b": 40
    },
    {
      "x": 23,
      "y": 11,
      "z": 12,
      "r": 120,
      "g": 80,
      "b": 40
    },
    {
      "x": 23,
      "y": 11,
      "z": 13,
      "r": 120,
      "g": 80,
      "b": 40
    },
    {
      "x": 23,
      "y": 11,
      "z": 14,
      "r": 120,
      "g": 80,
      "b": 40
    },
    {
      "x": 23,
      "y": 12,
      "z": 16,
      "r": 120,
      "g": 80,
      "b": 40
    },
    {
      "x": 22,
      "y": 11,
      "z": 11,
      "r": 120,
      "g": 80,
      "b": 40
    },
    {
      "x": 21,
      "y": 11,
      "z": 7,
      "r": 120,
      "g": 80,
      "b": 40
    },
    {
      "x": 21,
      "y": 11,
      "z": 8,
      "r": 120,
      "g": 80,
      "b": 40
    },
    {
      "x": 19,
      "y": 10,
      "z": 3,
      "r": 120,
      "g": 80,
      "b": 40
    },
    {
      "x": 20,
      "y": 10,
      "z": 3,
      "r": 120,
      "g": 80,
      "b": 40
    },
    {
      "x": 20,
      "y": 10,
      "z": 4,
      "r": 120,
      "g": 80,
      "b": 40
    },
    {
      "x": 20,
      "y": 10,
      "z": 5,
      "r": 120,
      "g": 80,
      "b": 40
    },
    {
      "x": 20,
      "y": 11,
      "z": 5,
      "r": 120,
      "g": 80,
      "b": 40
    },
    {
      "x": 18,
      "y": 10,
      "z": 2,
      "r": 120,
      "g": 80,
      "b": 40
    },
    {
      "x": 19,
      "y": 10,
      "z": 2,
      "r": 120,
      "g": 80,
      "b": 40
    },
    {
      "x": 17,
      "y": 9,
      "z": 2,
      "r": 120,
      "g": 80,
      "b": 40
    },
    {
      "x": 18,
      "y": 9,
      "z": 2,
      "r": 120,
      "g": 80,
      "b": 40
    },
    {
      "x": 18,
      "y": 9,
      "z": 3,
      "r": 120,
      "g": 80,
      "b": 40
    },
    {
      "x": 18,
      "y": 10,
      "z": 3,
      "r": 120,
      "g": 80,
      "b": 40
    },
    {
      "x": 19,
      "y": 10,
      "z": 4,
      "r": 120,
      "g": 80,
      "b": 40
    },
    {
      "x": 16,
      "y": 10,
      "z": 1,
      "r": 120,
      "g": 80,
      "b": 40
    },
    {
      "x": 16,
      "y": 10,
      "z": 2,
      "r": 120,
      "g": 80,
      "b": 40
    },
    {
      "x": 16,
      "y": 11,
      "z": 2,
      "r": 120,
      "g": 80,
      "b": 40
    },
    {
      "x": 17,
      "y": 10,
      "z": 2,
      "r": 120,
      "g": 80,
      "b": 40
    },
    {
      "x": 17,
      "y": 11,
      "z": 2,
      "r": 120,
      "g": 80,
      "b": 40
    },
    {
      "x": 15,
      "y": 10,
      "z": 1,
      "r": 120,
      "g": 80,
      "b": 40
    },
    {
      "x": 15,
      "y": 10,
      "z": 2,
      "r": 120,
      "g": 80,
      "b": 40
    },
    {
      "x": 15,
      "y": 9,
      "z": 2,
      "r": 120,
      "g": 80,
      "b": 40
    },
    {
      "x": 16,
      "y": 9,
      "z": 2,
      "r": 120,
      "g": 80,
      "b": 40
    },
    {
      "x": 12,
      "y": 10,
      "z": 2,
      "r": 120,
      "g": 80,
      "b": 40
    },
    {
      "x": 12,
      "y": 11,
      "z": 2,
      "r": 120,
      "g": 80,
      "b": 40
    },
    {
      "x": 13,
      "y": 10,
      "z": 2,
      "r": 120,
      "g": 80,
      "b": 40
    },
    {
      "x": 13,
      "y": 10,
      "z": 1,
      "r": 120,
      "g": 80,
      "b": 40
    },
    {
      "x": 13,
      "y": 11,
      "z": 2,
      "r": 120,
      "g": 80,
      "b": 40
    },
    {
      "x": 12,
      "y": 9,
      "z": 2,
      "r": 120,
      "g": 80,
      "b": 40
    },
    {
      "x": 13,
      "y": 9,
      "z": 2,
      "r": 120,
      "g": 80,
      "b": 40
    },
    {
      "x": 14,
      "y": 9,
      "z": 2,
      "r": 120,
      "g": 80,
      "b": 40
    },
    {
      "x": 14,
      "y": 10,
      "z": 2,
      "r": 120,
      "g": 80,
      "b": 40
    },
    {
      "x": 14,
      "y": 10,
      "z": 1,
      "r": 120,
      "g": 80,
      "b": 40
    },
    {
      "x": 8,
      "y": 10,
      "z": 5,
      "r": 120,
      "g": 80,
      "b": 40
    },
    {
      "x": 9,
      "y": 10,
      "z": 3,
      "r": 120,
      "g": 80,
      "b": 40
    },
    {
      "x": 9,
      "y": 10,
      "z": 4,
      "r": 120,
      "g": 80,
      "b": 40
    },
    {
      "x": 9,
      "y": 10,
      "z": 5,
      "r": 120,
      "g": 80,
      "b": 40
    },
    {
      "x": 10,
      "y": 10,
      "z": 3,
      "r": 120,
      "g": 80,
      "b": 40
    },
    {
      "x": 10,
      "y": 10,
      "z": 4,
      "r": 120,
      "g": 80,
      "b": 40
    },
    {
      "x": 11,
      "y": 9,
      "z": 3,
      "r": 120,
      "g": 80,
      "b": 40
    },
    {
      "x": 11,
      "y": 10,
      "z": 3,
      "r": 120,
      "g": 80,
      "b": 40
    },
    {
      "x": 12,
      "y": 9,
      "z": 3,
      "r": 120,
      "g": 80,
      "b": 40
    },
    {
      "x": 10,
      "y": 10,
      "z": 2,
      "r": 120,
      "g": 80,
      "b": 40
    },
    {
      "x": 11,
      "y": 9,
      "z": 2,
      "r": 120,
      "g": 80,
      "b": 40
    },
    {
      "x": 11,
      "y": 10,
      "z": 2,
      "r": 120,
      "g": 80,
      "b": 40
    },
    {
      "x": 5,
      "y": 11,
      "z": 17,
      "r": 120,
      "g": 80,
      "b": 40
    },
    {
      "x": 6,
      "y": 10,
      "z": 13,
      "r": 120,
      "g": 80,
      "b": 40
    },
    {
      "x": 6,
      "y": 10,
      "z": 14,
      "r": 120,
      "g": 80,
      "b": 40
    },
    {
      "x": 6,
      "y": 11,
      "z": 13,
      "r": 120,
      "g": 80,
      "b": 40
    },
    {
      "x": 6,
      "y": 11,
      "z": 14,
      "r": 120,
      "g": 80,
      "b": 40
    },
    {
      "x": 6,
      "y": 11,
      "z": 15,
      "r": 120,
      "g": 80,
      "b": 40
    },
    {
      "x": 6,
      "y": 11,
      "z": 16,
      "r": 120,
      "g": 80,
      "b": 40
    },
    {
      "x": 6,
      "y": 11,
      "z": 17,
      "r": 120,
      "g": 80,
      "b": 40
    },
    {
      "x": 6,
      "y": 12,
      "z": 17,
      "r": 120,
      "g": 80,
      "b": 40
    },
    {
      "x": 7,
      "y": 10,
      "z": 11,
      "r": 120,
      "g": 80,
      "b": 40
    },
    {
      "x": 7,
      "y": 10,
      "z": 12,
      "r": 120,
      "g": 80,
      "b": 40
    },
    {
      "x": 7,
      "y": 10,
      "z": 13,
      "r": 120,
      "g": 80,
      "b": 40
    },
    {
      "x": 7,
      "y": 11,
      "z": 12,
      "r": 120,
      "g": 80,
      "b": 40
    },
    {
      "x": 7,
      "y": 11,
      "z": 13,
      "r": 120,
      "g": 80,
      "b": 40
    },
    {
      "x": 6,
      "y": 11,
      "z": 12,
      "r": 120,
      "g": 80,
      "b": 40
    },
    {
      "x": 7,
      "y": 11,
      "z": 11,
      "r": 120,
      "g": 80,
      "b": 40
    },
    {
      "x": 6,
      "y": 10,
      "z": 15,
      "r": 120,
      "g": 80,
      "b": 40
    },
    {
      "x": 6,
      "y": 10,
      "z": 16,
      "r": 120,
      "g": 80,
      "b": 40
    },
    {
      "x": 6,
      "y": 10,
      "z": 17,
      "r": 120,
      "g": 80,
      "b": 40
    },
    {
      "x": 6,
      "y": 11,
      "z": 18,
      "r": 120,
      "g": 80,
      "b": 40
    },
    {
      "x": 7,
      "y": 10,
      "z": 14,
      "r": 120,
      "g": 80,
      "b": 40
    },
    {
      "x": 7,
      "y": 10,
      "z": 9,
      "r": 120,
      "g": 80,
      "b": 40
    },
    {
      "x": 7,
      "y": 10,
      "z": 10,
      "r": 120,
      "g": 80,
      "b": 40
    },
    {
      "x": 8,
      "y": 10,
      "z": 9,
      "r": 120,
      "g": 80,
      "b": 40
    },
    {
      "x": 8,
      "y": 10,
      "z": 10,
      "r": 120,
      "g": 80,
      "b": 40
    },
    {
      "x": 8,
      "y": 10,
      "z": 6,
      "r": 120,
      "g": 80,
      "b": 40
    },
    {
      "x": 8,
      "y": 10,
      "z": 7,
      "r": 120,
      "g": 80,
      "b": 40
    },
    {
      "x": 8,
      "y": 10,
      "z": 8,
      "r": 120,
      "g": 80,
      "b": 40
    },
    {
      "x": 9,
      "y": 10,
      "z": 6,
      "r": 120,
      "g": 80,
      "b": 40
    },
    {
      "x": 8,
      "y": 11,
      "z": 8,
      "r": 120,
      "g": 80,
      "b": 40
    },
    {
      "x": 8,
      "y": 11,
      "z": 9,
      "r": 120,
      "g": 80,
      "b": 40
    },
    {
      "x": 5,
      "y": 11,
      "z": 19,
      "r": 120,
      "g": 80,
      "b": 40
    },
    {
      "x": 5,
      "y": 10,
      "z": 18,
      "r": 120,
      "g": 80,
      "b": 40
    },
    {
      "x": 5,
      "y": 11,
      "z": 18,
      "r": 120,
      "g": 80,
      "b": 40
    },
    {
      "x": 7,
      "y": 9,
      "z": 8,
      "r": 120,
      "g": 80,
      "b": 40
    },
    {
      "x": 7,
      "y": 10,
      "z": 8,
      "r": 120,
      "g": 80,
      "b": 40
    },
    {
      "x": 8,
      "y": 9,
      "z": 5,
      "r": 120,
      "g": 80,
      "b": 40
    },
    {
      "x": 5,
      "y": 9,
      "z": 17,
      "r": 120,
      "g": 80,
      "b": 40
    },
    {
      "x": 5,
      "y": 10,
      "z": 17,
      "r": 120,
      "g": 80,
      "b": 40
    },
    {
      "x": 5,
      "y": 10,
      "z": 16,
      "r": 120,
      "g": 80,
      "b": 40
    },
    {
      "x": 6,
      "y": 9,
      "z": 12,
      "r": 120,
      "g": 80,
      "b": 40
    },
    {
      "x": 6,
      "y": 10,
      "z": 12,
      "r": 120,
      "g": 80,
      "b": 40
    },
    {
      "x": 5,
      "y": 11,
      "z": 15,
      "r": 120,
      "g": 80,
      "b": 40
    },
    {
      "x": 5,
      "y": 11,
      "z": 16,
      "r": 120,
      "g": 80,
      "b": 40
    },
    {
      "x": 6,
      "y": 10,
      "z": 11,
      "r": 120,
      "g": 80,
      "b": 40
    },
    {
      "x": 7,
      "y": 10,
      "z": 7,
      "r": 120,
      "g": 80,
      "b": 40
    },
    {
      "x": 8,
      "y": 10,
      "z": 4,
      "r": 120,
      "g": 80,
      "b": 40
    },
    {
      "x": 11,
      "y": 10,
      "z": 1,
      "r": 120,
      "g": 80,
      "b": 40
    },
    {
      "x": 10,
      "y": 9,
      "z": 2,
      "r": 120,
      "g": 80,
      "b": 40
    },
    {
      "x": 9,
      "y": 9,
      "z": 3,
      "r": 120,
      "g": 80,
      "b": 40
    },
    {
      "x": 12,
      "y": 10,
      "z": 1,
      "r": 120,
      "g": 80,
      "b": 40
    },
    {
      "x": 13,
      "y": 9,
      "z": 1,
      "r": 120,
      "g": 80,
      "b": 40
    },
    {
      "x": 14,
      "y": 9,
      "z": 1,
      "r": 120,
      "g": 80,
      "b": 40
    },
    {
      "x": 15,
      "y": 9,
      "z": 1,
      "r": 120,
      "g": 80,
      "b": 40
    },
    {
      "x": 12,
      "y": 9,
      "z": 1,
      "r": 120,
      "g": 80,
      "b": 40
    },
    {
      "x": 16,
      "y": 9,
      "z": 1,
      "r": 120,
      "g": 80,
      "b": 40
    },
    {
      "x": 17,
      "y": 10,
      "z": 1,
      "r": 120,
      "g": 80,
      "b": 40
    },
    {
      "x": 18,
      "y": 10,
      "z": 1,
      "r": 120,
      "g": 80,
      "b": 40
    },
    {
      "x": 17,
      "y": 9,
      "z": 1,
      "r": 120,
      "g": 80,
      "b": 40
    },
    {
      "x": 19,
      "y": 9,
      "z": 2,
      "r": 120,
      "g": 80,
      "b": 40
    },
    {
      "x": 20,
      "y": 10,
      "z": 2,
      "r": 120,
      "g": 80,
      "b": 40
    },
    {
      "x": 21,
      "y": 10,
      "z": 4,
      "r": 120,
      "g": 80,
      "b": 40
    },
    {
      "x": 20,
      "y": 9,
      "z": 3,
      "r": 120,
      "g": 80,
      "b": 40
    },
    {
      "x": 23,
      "y": 10,
      "z": 11,
      "r": 120,
      "g": 80,
      "b": 40
    },
    {
      "x": 24,
      "y": 10,
      "z": 15,
      "r": 120,
      "g": 80,
      "b": 40
    },
    {
      "x": 24,
      "y": 10,
      "z": 16,
      "r": 120,
      "g": 80,
      "b": 40
    },
    {
      "x": 24,
      "y": 11,
      "z": 14,
      "r": 120,
      "g": 80,
      "b": 40
    },
    {
      "x": 24,
      "y": 11,
      "z": 15,
      "r": 120,
      "g": 80,
      "b": 40
    },
    {
      "x": 22,
      "y": 10,
      "z": 7,
      "r": 120,
      "g": 80,
      "b": 40
    },
    {
      "x": 7,
      "y": 8,
      "z": 14,
      "r": 120,
      "g": 80,
      "b": 40
    },
    {
      "x": 25,
      "y": 12,
      "z": 18,
      "r": 120,
      "g": 80,
      "b": 40
    },
    {
      "x": 10,
      "y": 12,
      "z": 52,
      "r": 139,
      "g": 90,
      "b": 43
    },
    {
      "x": 11,
      "y": 12,
      "z": 52,
      "r": 139,
      "g": 90,
      "b": 43
    },
    {
      "x": 11,
      "y": 12,
      "z": 53,
      "r": 139,
      "g": 90,
      "b": 43
    },
    {
      "x": 10,
      "y": 12,
      "z": 51,
      "r": 139,
      "g": 90,
      "b": 43
    },
    {
      "x": 12,
      "y": 12,
      "z": 53,
      "r": 139,
      "g": 90,
      "b": 43
    },
    {
      "x": 12,
      "y": 12,
      "z": 54,
      "r": 139,
      "g": 90,
      "b": 43
    },
    {
      "x": 13,
      "y": 12,
      "z": 54,
      "r": 139,
      "g": 90,
      "b": 43
    },
    {
      "x": 14,
      "y": 12,
      "z": 54,
      "r": 139,
      "g": 90,
      "b": 43
    },
    {
      "x": 15,
      "y": 12,
      "z": 54,
      "r": 139,
      "g": 90,
      "b": 43
    },
    {
      "x": 16,
      "y": 12,
      "z": 54,
      "r": 139,
      "g": 90,
      "b": 43
    },
    {
      "x": 17,
      "y": 12,
      "z": 54,
      "r": 139,
      "g": 90,
      "b": 43
    },
    {
      "x": 19,
      "y": 11,
      "z": 50,
      "r": 139,
      "g": 90,
      "b": 43
    },
    {
      "x": 19,
      "y": 11,
      "z": 51,
      "r": 139,
      "g": 90,
      "b": 43
    },
    {
      "x": 19,
      "y": 12,
      "z": 50,
      "r": 139,
      "g": 90,
      "b": 43
    },
    {
      "x": 19,
      "y": 12,
      "z": 51,
      "r": 139,
      "g": 90,
      "b": 43
    },
    {
      "x": 19,
      "y": 12,
      "z": 52,
      "r": 139,
      "g": 90,
      "b": 43
    },
    {
      "x": 19,
      "y": 12,
      "z": 53,
      "r": 139,
      "g": 90,
      "b": 43
    },
    {
      "x": 20,
      "y": 11,
      "z": 50,
      "r": 139,
      "g": 90,
      "b": 43
    },
    {
      "x": 18,
      "y": 12,
      "z": 52,
      "r": 139,
      "g": 90,
      "b": 43
    },
    {
      "x": 18,
      "y": 12,
      "z": 53,
      "r": 139,
      "g": 90,
      "b": 43
    },
    {
      "x": 19,
      "y": 11,
      "z": 52,
      "r": 139,
      "g": 90,
      "b": 43
    },
    {
      "x": 20,
      "y": 12,
      "z": 50,
      "r": 139,
      "g": 90,
      "b": 43
    },
    {
      "x": 17,
      "y": 12,
      "z": 53,
      "r": 139,
      "g": 90,
      "b": 43
    },
    {
      "x": 20,
      "y": 12,
      "z": 51,
      "r": 139,
      "g": 90,
      "b": 43
    },
    {
      "x": 20,
      "y": 11,
      "z": 48,
      "r": 139,
      "g": 90,
      "b": 43
    },
    {
      "x": 20,
      "y": 11,
      "z": 49,
      "r": 139,
      "g": 90,
      "b": 43
    },
    {
      "x": 21,
      "y": 11,
      "z": 44,
      "r": 139,
      "g": 90,
      "b": 43
    },
    {
      "x": 21,
      "y": 11,
      "z": 45,
      "r": 139,
      "g": 90,
      "b": 43
    },
    {
      "x": 21,
      "y": 11,
      "z": 43,
      "r": 139,
      "g": 90,
      "b": 43
    },
    {
      "x": 22,
      "y": 11,
      "z": 39,
      "r": 139,
      "g": 90,
      "b": 43
    },
    {
      "x": 22,
      "y": 11,
      "z": 40,
      "r": 139,
      "g": 90,
      "b": 43
    },
    {
      "x": 22,
      "y": 11,
      "z": 41,
      "r": 139,
      "g": 90,
      "b": 43
    },
    {
      "x": 22,
      "y": 11,
      "z": 42,
      "r": 139,
      "g": 90,
      "b": 43
    },
    {
      "x": 22,
      "y": 11,
      "z": 43,
      "r": 139,
      "g": 90,
      "b": 43
    },
    {
      "x": 23,
      "y": 11,
      "z": 38,
      "r": 139,
      "g": 90,
      "b": 43
    },
    {
      "x": 23,
      "y": 11,
      "z": 39,
      "r": 139,
      "g": 90,
      "b": 43
    },
    {
      "x": 20,
      "y": 12,
      "z": 49,
      "r": 139,
      "g": 90,
      "b": 43
    },
    {
      "x": 8,
      "y": 11,
      "z": 44,
      "r": 139,
      "g": 90,
      "b": 43
    },
    {
      "x": 8,
      "y": 11,
      "z": 45,
      "r": 139,
      "g": 90,
      "b": 43
    },
    {
      "x": 9,
      "y": 11,
      "z": 48,
      "r": 139,
      "g": 90,
      "b": 43
    },
    {
      "x": 9,
      "y": 11,
      "z": 49,
      "r": 139,
      "g": 90,
      "b": 43
    },
    {
      "x": 9,
      "y": 11,
      "z": 50,
      "r": 139,
      "g": 90,
      "b": 43
    },
    {
      "x": 10,
      "y": 11,
      "z": 50,
      "r": 139,
      "g": 90,
      "b": 43
    },
    {
      "x": 10,
      "y": 11,
      "z": 51,
      "r": 139,
      "g": 90,
      "b": 43
    },
    {
      "x": 10,
      "y": 11,
      "z": 52,
      "r": 139,
      "g": 90,
      "b": 43
    },
    {
      "x": 10,
      "y": 12,
      "z": 50,
      "r": 139,
      "g": 90,
      "b": 43
    },
    {
      "x": 9,
      "y": 12,
      "z": 49,
      "r": 139,
      "g": 90,
      "b": 43
    },
    {
      "x": 9,
      "y": 12,
      "z": 50,
      "r": 139,
      "g": 90,
      "b": 43
    },
    {
      "x": 9,
      "y": 12,
      "z": 48,
      "r": 139,
      "g": 90,
      "b": 43
    },
    {
      "x": 11,
      "y": 12,
      "z": 51,
      "r": 139,
      "g": 90,
      "b": 43
    },
    {
      "x": 13,
      "y": 12,
      "z": 53,
      "r": 139,
      "g": 90,
      "b": 43
    },
    {
      "x": 16,
      "y": 12,
      "z": 53,
      "r": 139,
      "g": 90,
      "b": 43
    },
    {
      "x": 19,
      "y": 12,
      "z": 49,
      "r": 139,
      "g": 90,
      "b": 43
    },
    {
      "x": 20,
      "y": 12,
      "z": 48,
      "r": 139,
      "g": 90,
      "b": 43
    },
    {
      "x": 21,
      "y": 12,
      "z": 44,
      "r": 139,
      "g": 90,
      "b": 43
    },
    {
      "x": 21,
      "y": 12,
      "z": 45,
      "r": 139,
      "g": 90,
      "b": 43
    },
    {
      "x": 21,
      "y": 11,
      "z": 42,
      "r": 139,
      "g": 90,
      "b": 43
    },
    {
      "x": 22,
      "y": 11,
      "z": 38,
      "r": 139,
      "g": 90,
      "b": 43
    },
    {
      "x": 10,
      "y": 12,
      "z": 49,
      "r": 139,
      "g": 90,
      "b": 43
    },
    {
      "x": 9,
      "y": 11,
      "z": 45,
      "r": 139,
      "g": 90,
      "b": 43
    },
    {
      "x": 9,
      "y": 12,
      "z": 45,
      "r": 139,
      "g": 90,
      "b": 43
    },
    {
      "x": 8,
      "y": 12,
      "z": 44,
      "r": 139,
      "g": 90,
      "b": 43
    },
    {
      "x": 8,
      "y": 12,
      "z": 45,
      "r": 139,
      "g": 90,
      "b": 43
    },
    {
      "x": 11,
      "y": 15,
      "z": 54,
      "r": 139,
      "g": 90,
      "b": 43
    },
    {
      "x": 12,
      "y": 15,
      "z": 54,
      "r": 139,
      "g": 90,
      "b": 43
    },
    {
      "x": 10,
      "y": 15,
      "z": 52,
      "r": 139,
      "g": 90,
      "b": 43
    },
    {
      "x": 10,
      "y": 15,
      "z": 53,
      "r": 139,
      "g": 90,
      "b": 43
    },
    {
      "x": 11,
      "y": 15,
      "z": 53,
      "r": 139,
      "g": 90,
      "b": 43
    },
    {
      "x": 13,
      "y": 15,
      "z": 55,
      "r": 139,
      "g": 90,
      "b": 43
    },
    {
      "x": 14,
      "y": 15,
      "z": 55,
      "r": 139,
      "g": 90,
      "b": 43
    },
    {
      "x": 15,
      "y": 15,
      "z": 55,
      "r": 139,
      "g": 90,
      "b": 43
    },
    {
      "x": 13,
      "y": 15,
      "z": 54,
      "r": 139,
      "g": 90,
      "b": 43
    },
    {
      "x": 16,
      "y": 15,
      "z": 54,
      "r": 139,
      "g": 90,
      "b": 43
    },
    {
      "x": 16,
      "y": 15,
      "z": 55,
      "r": 139,
      "g": 90,
      "b": 43
    },
    {
      "x": 17,
      "y": 15,
      "z": 54,
      "r": 139,
      "g": 90,
      "b": 43
    },
    {
      "x": 17,
      "y": 15,
      "z": 55,
      "r": 139,
      "g": 90,
      "b": 43
    },
    {
      "x": 18,
      "y": 15,
      "z": 53,
      "r": 139,
      "g": 90,
      "b": 43
    },
    {
      "x": 18,
      "y": 15,
      "z": 54,
      "r": 139,
      "g": 90,
      "b": 43
    },
    {
      "x": 19,
      "y": 15,
      "z": 51,
      "r": 139,
      "g": 90,
      "b": 43
    },
    {
      "x": 19,
      "y": 15,
      "z": 52,
      "r": 139,
      "g": 90,
      "b": 43
    },
    {
      "x": 19,
      "y": 15,
      "z": 53,
      "r": 139,
      "g": 90,
      "b": 43
    },
    {
      "x": 20,
      "y": 15,
      "z": 51,
      "r": 139,
      "g": 90,
      "b": 43
    },
    {
      "x": 23,
      "y": 11,
      "z": 36,
      "r": 139,
      "g": 90,
      "b": 43
    },
    {
      "x": 21,
      "y": 14,
      "z": 44,
      "r": 139,
      "g": 90,
      "b": 43
    },
    {
      "x": 21,
      "y": 14,
      "z": 45,
      "r": 139,
      "g": 90,
      "b": 43
    },
    {
      "x": 21,
      "y": 14,
      "z": 46,
      "r": 139,
      "g": 90,
      "b": 43
    },
    {
      "x": 22,
      "y": 14,
      "z": 40,
      "r": 139,
      "g": 90,
      "b": 43
    },
    {
      "x": 22,
      "y": 14,
      "z": 41,
      "r": 139,
      "g": 90,
      "b": 43
    },
    {
      "x": 22,
      "y": 14,
      "z": 42,
      "r": 139,
      "g": 90,
      "b": 43
    },
    {
      "x": 22,
      "y": 14,
      "z": 43,
      "r": 139,
      "g": 90,
      "b": 43
    },
    {
      "x": 22,
      "y": 14,
      "z": 44,
      "r": 139,
      "g": 90,
      "b": 43
    },
    {
      "x": 20,
      "y": 15,
      "z": 48,
      "r": 139,
      "g": 90,
      "b": 43
    },
    {
      "x": 20,
      "y": 15,
      "z": 49,
      "r": 139,
      "g": 90,
      "b": 43
    },
    {
      "x": 20,
      "y": 15,
      "z": 50,
      "r": 139,
      "g": 90,
      "b": 43
    },
    {
      "x": 21,
      "y": 14,
      "z": 47,
      "r": 139,
      "g": 90,
      "b": 43
    },
    {
      "x": 21,
      "y": 15,
      "z": 47,
      "r": 139,
      "g": 90,
      "b": 43
    },
    {
      "x": 21,
      "y": 15,
      "z": 48,
      "r": 139,
      "g": 90,
      "b": 43
    },
    {
      "x": 9,
      "y": 15,
      "z": 48,
      "r": 139,
      "g": 90,
      "b": 43
    },
    {
      "x": 9,
      "y": 15,
      "z": 49,
      "r": 139,
      "g": 90,
      "b": 43
    },
    {
      "x": 9,
      "y": 15,
      "z": 50,
      "r": 139,
      "g": 90,
      "b": 43
    },
    {
      "x": 10,
      "y": 15,
      "z": 50,
      "r": 139,
      "g": 90,
      "b": 43
    },
    {
      "x": 10,
      "y": 15,
      "z": 51,
      "r": 139,
      "g": 90,
      "b": 43
    },
    {
      "x": 8,
      "y": 14,
      "z": 44,
      "r": 139,
      "g": 90,
      "b": 43
    },
    {
      "x": 8,
      "y": 14,
      "z": 45,
      "r": 139,
      "g": 90,
      "b": 43
    },
    {
      "x": 8,
      "y": 15,
      "z": 45,
      "r": 139,
      "g": 90,
      "b": 43
    },
    {
      "x": 8,
      "y": 15,
      "z": 46,
      "r": 139,
      "g": 90,
      "b": 43
    },
    {
      "x": 8,
      "y": 15,
      "z": 47,
      "r": 139,
      "g": 90,
      "b": 43
    },
    {
      "x": 9,
      "y": 15,
      "z": 47,
      "r": 139,
      "g": 90,
      "b": 43
    },
    {
      "x": 9,
      "y": 15,
      "z": 51,
      "r": 139,
      "g": 90,
      "b": 43
    },
    {
      "x": 6,
      "y": 11,
      "z": 36,
      "r": 139,
      "g": 90,
      "b": 43
    },
    {
      "x": 6,
      "y": 13,
      "z": 38,
      "r": 139,
      "g": 90,
      "b": 43
    },
    {
      "x": 6,
      "y": 13,
      "z": 39,
      "r": 139,
      "g": 90,
      "b": 43
    },
    {
      "x": 6,
      "y": 11,
      "z": 37,
      "r": 139,
      "g": 90,
      "b": 43
    },
    {
      "x": 7,
      "y": 11,
      "z": 37,
      "r": 139,
      "g": 90,
      "b": 43
    },
    {
      "x": 20,
      "y": 14,
      "z": 49,
      "r": 139,
      "g": 90,
      "b": 43
    },
    {
      "x": 20,
      "y": 14,
      "z": 50,
      "r": 139,
      "g": 90,
      "b": 43
    },
    {
      "x": 20,
      "y": 14,
      "z": 51,
      "r": 139,
      "g": 90,
      "b": 43
    },
    {
      "x": 20,
      "y": 14,
      "z": 52,
      "r": 139,
      "g": 90,
      "b": 43
    },
    {
      "x": 21,
      "y": 14,
      "z": 48,
      "r": 139,
      "g": 90,
      "b": 43
    },
    {
      "x": 21,
      "y": 14,
      "z": 49,
      "r": 139,
      "g": 90,
      "b": 43
    },
    {
      "x": 20,
      "y": 15,
      "z": 52,
      "r": 139,
      "g": 90,
      "b": 43
    },
    {
      "x": 21,
      "y": 15,
      "z": 49,
      "r": 139,
      "g": 90,
      "b": 43
    },
    {
      "x": 22,
      "y": 13,
      "z": 41,
      "r": 139,
      "g": 90,
      "b": 43
    },
    {
      "x": 22,
      "y": 13,
      "z": 42,
      "r": 139,
      "g": 90,
      "b": 43
    },
    {
      "x": 22,
      "y": 13,
      "z": 43,
      "r": 139,
      "g": 90,
      "b": 43
    },
    {
      "x": 22,
      "y": 14,
      "z": 45,
      "r": 139,
      "g": 90,
      "b": 43
    },
    {
      "x": 23,
      "y": 13,
      "z": 40,
      "r": 139,
      "g": 90,
      "b": 43
    },
    {
      "x": 23,
      "y": 13,
      "z": 41,
      "r": 139,
      "g": 90,
      "b": 43
    },
    {
      "x": 23,
      "y": 14,
      "z": 41,
      "r": 139,
      "g": 90,
      "b": 43
    },
    {
      "x": 19,
      "y": 14,
      "z": 52,
      "r": 139,
      "g": 90,
      "b": 43
    },
    {
      "x": 19,
      "y": 14,
      "z": 53,
      "r": 139,
      "g": 90,
      "b": 43
    },
    {
      "x": 19,
      "y": 15,
      "z": 54,
      "r": 139,
      "g": 90,
      "b": 43
    },
    {
      "x": 12,
      "y": 15,
      "z": 55,
      "r": 139,
      "g": 90,
      "b": 43
    },
    {
      "x": 10,
      "y": 14,
      "z": 52,
      "r": 139,
      "g": 90,
      "b": 43
    },
    {
      "x": 10,
      "y": 14,
      "z": 53,
      "r": 139,
      "g": 90,
      "b": 43
    },
    {
      "x": 8,
      "y": 14,
      "z": 46,
      "r": 139,
      "g": 90,
      "b": 43
    },
    {
      "x": 8,
      "y": 14,
      "z": 47,
      "r": 139,
      "g": 90,
      "b": 43
    },
    {
      "x": 8,
      "y": 15,
      "z": 48,
      "r": 139,
      "g": 90,
      "b": 43
    },
    {
      "x": 8,
      "y": 14,
      "z": 48,
      "r": 139,
      "g": 90,
      "b": 43
    },
    {
      "x": 9,
      "y": 14,
      "z": 48,
      "r": 139,
      "g": 90,
      "b": 43
    },
    {
      "x": 9,
      "y": 14,
      "z": 49,
      "r": 139,
      "g": 90,
      "b": 43
    },
    {
      "x": 9,
      "y": 14,
      "z": 50,
      "r": 139,
      "g": 90,
      "b": 43
    },
    {
      "x": 9,
      "y": 14,
      "z": 51,
      "r": 139,
      "g": 90,
      "b": 43
    },
    {
      "x": 10,
      "y": 14,
      "z": 51,
      "r": 139,
      "g": 90,
      "b": 43
    },
    {
      "x": 10,
      "y": 14,
      "z": 50,
      "r": 139,
      "g": 90,
      "b": 43
    },
    {
      "x": 9,
      "y": 14,
      "z": 47,
      "r": 139,
      "g": 90,
      "b": 43
    },
    {
      "x": 22,
      "y": 13,
      "z": 40,
      "r": 139,
      "g": 90,
      "b": 43
    },
    {
      "x": 19,
      "y": 14,
      "z": 51,
      "r": 139,
      "g": 90,
      "b": 43
    },
    {
      "x": 20,
      "y": 14,
      "z": 48,
      "r": 139,
      "g": 90,
      "b": 43
    },
    {
      "x": 23,
      "y": 13,
      "z": 39,
      "r": 139,
      "g": 90,
      "b": 43
    },
    {
      "x": 23,
      "y": 13,
      "z": 38,
      "r": 139,
      "g": 90,
      "b": 43
    },
    {
      "x": 22,
      "y": 12,
      "z": 39,
      "r": 139,
      "g": 90,
      "b": 43
    },
    {
      "x": 22,
      "y": 12,
      "z": 40,
      "r": 139,
      "g": 90,
      "b": 43
    },
    {
      "x": 22,
      "y": 12,
      "z": 41,
      "r": 139,
      "g": 90,
      "b": 43
    },
    {
      "x": 23,
      "y": 12,
      "z": 38,
      "r": 139,
      "g": 90,
      "b": 43
    },
    {
      "x": 23,
      "y": 12,
      "z": 39,
      "r": 139,
      "g": 90,
      "b": 43
    },
    {
      "x": 21,
      "y": 12,
      "z": 43,
      "r": 139,
      "g": 90,
      "b": 43
    },
    {
      "x": 22,
      "y": 12,
      "z": 42,
      "r": 139,
      "g": 90,
      "b": 43
    },
    {
      "x": 22,
      "y": 12,
      "z": 43,
      "r": 139,
      "g": 90,
      "b": 43
    },
    {
      "x": 18,
      "y": 12,
      "z": 54,
      "r": 139,
      "g": 90,
      "b": 43
    },
    {
      "x": 18,
      "y": 13,
      "z": 53,
      "r": 139,
      "g": 90,
      "b": 43
    },
    {
      "x": 17,
      "y": 13,
      "z": 54,
      "r": 139,
      "g": 90,
      "b": 43
    },
    {
      "x": 18,
      "y": 13,
      "z": 54,
      "r": 139,
      "g": 90,
      "b": 43
    },
    {
      "x": 19,
      "y": 13,
      "z": 51,
      "r": 139,
      "g": 90,
      "b": 43
    },
    {
      "x": 19,
      "y": 13,
      "z": 52,
      "r": 139,
      "g": 90,
      "b": 43
    },
    {
      "x": 19,
      "y": 13,
      "z": 53,
      "r": 139,
      "g": 90,
      "b": 43
    },
    {
      "x": 20,
      "y": 13,
      "z": 51,
      "r": 139,
      "g": 90,
      "b": 43
    },
    {
      "x": 18,
      "y": 14,
      "z": 53,
      "r": 139,
      "g": 90,
      "b": 43
    },
    {
      "x": 15,
      "y": 12,
      "z": 55,
      "r": 139,
      "g": 90,
      "b": 43
    },
    {
      "x": 15,
      "y": 13,
      "z": 54,
      "r": 139,
      "g": 90,
      "b": 43
    },
    {
      "x": 15,
      "y": 13,
      "z": 55,
      "r": 139,
      "g": 90,
      "b": 43
    },
    {
      "x": 16,
      "y": 13,
      "z": 54,
      "r": 139,
      "g": 90,
      "b": 43
    },
    {
      "x": 16,
      "y": 13,
      "z": 55,
      "r": 139,
      "g": 90,
      "b": 43
    },
    {
      "x": 16,
      "y": 14,
      "z": 54,
      "r": 139,
      "g": 90,
      "b": 43
    },
    {
      "x": 16,
      "y": 14,
      "z": 55,
      "r": 139,
      "g": 90,
      "b": 43
    },
    {
      "x": 17,
      "y": 14,
      "z": 54,
      "r": 139,
      "g": 90,
      "b": 43
    },
    {
      "x": 17,
      "y": 14,
      "z": 55,
      "r": 139,
      "g": 90,
      "b": 43
    },
    {
      "x": 13,
      "y": 13,
      "z": 54,
      "r": 139,
      "g": 90,
      "b": 43
    },
    {
      "x": 12,
      "y": 13,
      "z": 54,
      "r": 139,
      "g": 90,
      "b": 43
    },
    {
      "x": 14,
      "y": 12,
      "z": 55,
      "r": 139,
      "g": 90,
      "b": 43
    },
    {
      "x": 14,
      "y": 13,
      "z": 54,
      "r": 139,
      "g": 90,
      "b": 43
    },
    {
      "x": 14,
      "y": 13,
      "z": 55,
      "r": 139,
      "g": 90,
      "b": 43
    },
    {
      "x": 13,
      "y": 13,
      "z": 55,
      "r": 139,
      "g": 90,
      "b": 43
    },
    {
      "x": 12,
      "y": 14,
      "z": 54,
      "r": 139,
      "g": 90,
      "b": 43
    },
    {
      "x": 12,
      "y": 14,
      "z": 55,
      "r": 139,
      "g": 90,
      "b": 43
    },
    {
      "x": 13,
      "y": 14,
      "z": 54,
      "r": 139,
      "g": 90,
      "b": 43
    },
    {
      "x": 13,
      "y": 14,
      "z": 55,
      "r": 139,
      "g": 90,
      "b": 43
    },
    {
      "x": 11,
      "y": 13,
      "z": 53,
      "r": 139,
      "g": 90,
      "b": 43
    },
    {
      "x": 10,
      "y": 13,
      "z": 52,
      "r": 139,
      "g": 90,
      "b": 43
    },
    {
      "x": 11,
      "y": 13,
      "z": 52,
      "r": 139,
      "g": 90,
      "b": 43
    },
    {
      "x": 11,
      "y": 13,
      "z": 54,
      "r": 139,
      "g": 90,
      "b": 43
    },
    {
      "x": 12,
      "y": 13,
      "z": 53,
      "r": 139,
      "g": 90,
      "b": 43
    },
    {
      "x": 10,
      "y": 13,
      "z": 53,
      "r": 139,
      "g": 90,
      "b": 43
    },
    {
      "x": 11,
      "y": 14,
      "z": 53,
      "r": 139,
      "g": 90,
      "b": 43
    },
    {
      "x": 6,
      "y": 12,
      "z": 36,
      "r": 139,
      "g": 90,
      "b": 43
    },
    {
      "x": 6,
      "y": 12,
      "z": 37,
      "r": 139,
      "g": 90,
      "b": 43
    },
    {
      "x": 7,
      "y": 12,
      "z": 37,
      "r": 139,
      "g": 90,
      "b": 43
    },
    {
      "x": 10,
      "y": 13,
      "z": 51,
      "r": 139,
      "g": 90,
      "b": 43
    },
    {
      "x": 11,
      "y": 14,
      "z": 52,
      "r": 139,
      "g": 90,
      "b": 43
    },
    {
      "x": 14,
      "y": 14,
      "z": 54,
      "r": 139,
      "g": 90,
      "b": 43
    },
    {
      "x": 17,
      "y": 13,
      "z": 53,
      "r": 139,
      "g": 90,
      "b": 43
    },
    {
      "x": 18,
      "y": 13,
      "z": 52,
      "r": 139,
      "g": 90,
      "b": 43
    },
    {
      "x": 19,
      "y": 13,
      "z": 50,
      "r": 139,
      "g": 90,
      "b": 43
    },
    {
      "x": 18,
      "y": 14,
      "z": 52,
      "r": 139,
      "g": 90,
      "b": 43
    },
    {
      "x": 21,
      "y": 12,
      "z": 42,
      "r": 139,
      "g": 90,
      "b": 43
    },
    {
      "x": 22,
      "y": 12,
      "z": 38,
      "r": 139,
      "g": 90,
      "b": 43
    },
    {
      "x": 23,
      "y": 12,
      "z": 36,
      "r": 139,
      "g": 90,
      "b": 43
    },
    {
      "x": 23,
      "y": 14,
      "z": 39,
      "r": 139,
      "g": 90,
      "b": 43
    },
    {
      "x": 23,
      "y": 14,
      "z": 40,
      "r": 139,
      "g": 90,
      "b": 43
    },
    {
      "x": 22,
      "y": 11,
      "z": 37,
      "r": 139,
      "g": 90,
      "b": 43
    },
    {
      "x": 23,
      "y": 11,
      "z": 37,
      "r": 139,
      "g": 90,
      "b": 43
    },
    {
      "x": 23,
      "y": 12,
      "z": 37,
      "r": 139,
      "g": 90,
      "b": 43
    },
    {
      "x": 10,
      "y": 11,
      "z": 49,
      "r": 139,
      "g": 90,
      "b": 43
    },
    {
      "x": 7,
      "y": 11,
      "z": 40,
      "r": 139,
      "g": 90,
      "b": 43
    },
    {
      "x": 7,
      "y": 11,
      "z": 41,
      "r": 139,
      "g": 90,
      "b": 43
    },
    {
      "x": 8,
      "y": 11,
      "z": 41,
      "r": 139,
      "g": 90,
      "b": 43
    },
    {
      "x": 8,
      "y": 11,
      "z": 42,
      "r": 139,
      "g": 90,
      "b": 43
    },
    {
      "x": 8,
      "y": 11,
      "z": 43,
      "r": 139,
      "g": 90,
      "b": 43
    },
    {
      "x": 8,
      "y": 12,
      "z": 42,
      "r": 139,
      "g": 90,
      "b": 43
    },
    {
      "x": 8,
      "y": 12,
      "z": 43,
      "r": 139,
      "g": 90,
      "b": 43
    },
    {
      "x": 7,
      "y": 11,
      "z": 38,
      "r": 139,
      "g": 90,
      "b": 43
    },
    {
      "x": 7,
      "y": 11,
      "z": 39,
      "r": 139,
      "g": 90,
      "b": 43
    },
    {
      "x": 7,
      "y": 12,
      "z": 38,
      "r": 139,
      "g": 90,
      "b": 43
    },
    {
      "x": 7,
      "y": 12,
      "z": 39,
      "r": 139,
      "g": 90,
      "b": 43
    },
    {
      "x": 7,
      "y": 12,
      "z": 40,
      "r": 139,
      "g": 90,
      "b": 43
    },
    {
      "x": 7,
      "y": 12,
      "z": 41,
      "r": 139,
      "g": 90,
      "b": 43
    },
    {
      "x": 8,
      "y": 12,
      "z": 41,
      "r": 139,
      "g": 90,
      "b": 43
    },
    {
      "x": 6,
      "y": 11,
      "z": 38,
      "r": 139,
      "g": 90,
      "b": 43
    },
    {
      "x": 7,
      "y": 11,
      "z": 42,
      "r": 139,
      "g": 90,
      "b": 43
    },
    {
      "x": 6,
      "y": 12,
      "z": 38,
      "r": 139,
      "g": 90,
      "b": 43
    },
    {
      "x": 7,
      "y": 12,
      "z": 42,
      "r": 139,
      "g": 90,
      "b": 43
    },
    {
      "x": 6,
      "y": 13,
      "z": 40,
      "r": 139,
      "g": 90,
      "b": 43
    },
    {
      "x": 6,
      "y": 14,
      "z": 40,
      "r": 139,
      "g": 90,
      "b": 43
    },
    {
      "x": 7,
      "y": 14,
      "z": 40,
      "r": 139,
      "g": 90,
      "b": 43
    },
    {
      "x": 7,
      "y": 14,
      "z": 41,
      "r": 139,
      "g": 90,
      "b": 43
    },
    {
      "x": 7,
      "y": 13,
      "z": 40,
      "r": 139,
      "g": 90,
      "b": 43
    },
    {
      "x": 7,
      "y": 13,
      "z": 41,
      "r": 139,
      "g": 90,
      "b": 43
    },
    {
      "x": 7,
      "y": 13,
      "z": 42,
      "r": 139,
      "g": 90,
      "b": 43
    },
    {
      "x": 7,
      "y": 14,
      "z": 42,
      "r": 139,
      "g": 90,
      "b": 43
    },
    {
      "x": 7,
      "y": 14,
      "z": 43,
      "r": 139,
      "g": 90,
      "b": 43
    },
    {
      "x": 7,
      "y": 14,
      "z": 44,
      "r": 139,
      "g": 90,
      "b": 43
    },
    {
      "x": 6,
      "y": 14,
      "z": 39,
      "r": 139,
      "g": 90,
      "b": 43
    },
    {
      "x": 8,
      "y": 14,
      "z": 43,
      "r": 139,
      "g": 90,
      "b": 43
    },
    {
      "x": 7,
      "y": 14,
      "z": 39,
      "r": 139,
      "g": 90,
      "b": 43
    },
    {
      "x": 7,
      "y": 13,
      "z": 39,
      "r": 139,
      "g": 90,
      "b": 43
    },
    {
      "x": 21,
      "y": 13,
      "z": 45,
      "r": 139,
      "g": 90,
      "b": 43
    },
    {
      "x": 21,
      "y": 13,
      "z": 46,
      "r": 139,
      "g": 90,
      "b": 43
    },
    {
      "x": 21,
      "y": 13,
      "z": 47,
      "r": 139,
      "g": 90,
      "b": 43
    },
    {
      "x": 20,
      "y": 13,
      "z": 48,
      "r": 139,
      "g": 90,
      "b": 43
    },
    {
      "x": 20,
      "y": 13,
      "z": 49,
      "r": 139,
      "g": 90,
      "b": 43
    },
    {
      "x": 20,
      "y": 13,
      "z": 50,
      "r": 139,
      "g": 90,
      "b": 43
    },
    {
      "x": 21,
      "y": 12,
      "z": 48,
      "r": 139,
      "g": 90,
      "b": 43
    },
    {
      "x": 21,
      "y": 13,
      "z": 48,
      "r": 139,
      "g": 90,
      "b": 43
    },
    {
      "x": 23,
      "y": 12,
      "z": 40,
      "r": 139,
      "g": 90,
      "b": 43
    },
    {
      "x": 21,
      "y": 13,
      "z": 44,
      "r": 139,
      "g": 90,
      "b": 43
    },
    {
      "x": 22,
      "y": 12,
      "z": 44,
      "r": 139,
      "g": 90,
      "b": 43
    },
    {
      "x": 22,
      "y": 13,
      "z": 44,
      "r": 139,
      "g": 90,
      "b": 43
    },
    {
      "x": 22,
      "y": 13,
      "z": 45,
      "r": 139,
      "g": 90,
      "b": 43
    },
    {
      "x": 18,
      "y": 14,
      "z": 54,
      "r": 139,
      "g": 90,
      "b": 43
    },
    {
      "x": 15,
      "y": 14,
      "z": 55,
      "r": 139,
      "g": 90,
      "b": 43
    },
    {
      "x": 14,
      "y": 14,
      "z": 55,
      "r": 139,
      "g": 90,
      "b": 43
    },
    {
      "x": 11,
      "y": 14,
      "z": 54,
      "r": 139,
      "g": 90,
      "b": 43
    },
    {
      "x": 8,
      "y": 13,
      "z": 44,
      "r": 139,
      "g": 90,
      "b": 43
    },
    {
      "x": 8,
      "y": 13,
      "z": 45,
      "r": 139,
      "g": 90,
      "b": 43
    },
    {
      "x": 8,
      "y": 13,
      "z": 46,
      "r": 139,
      "g": 90,
      "b": 43
    },
    {
      "x": 8,
      "y": 13,
      "z": 47,
      "r": 139,
      "g": 90,
      "b": 43
    },
    {
      "x": 9,
      "y": 13,
      "z": 47,
      "r": 139,
      "g": 90,
      "b": 43
    },
    {
      "x": 9,
      "y": 13,
      "z": 48,
      "r": 139,
      "g": 90,
      "b": 43
    },
    {
      "x": 9,
      "y": 13,
      "z": 49,
      "r": 139,
      "g": 90,
      "b": 43
    },
    {
      "x": 9,
      "y": 13,
      "z": 50,
      "r": 139,
      "g": 90,
      "b": 43
    },
    {
      "x": 10,
      "y": 13,
      "z": 50,
      "r": 139,
      "g": 90,
      "b": 43
    },
    {
      "x": 9,
      "y": 13,
      "z": 51,
      "r": 139,
      "g": 90,
      "b": 43
    },
    {
      "x": 6,
      "y": 12,
      "z": 39,
      "r": 139,
      "g": 90,
      "b": 43
    },
    {
      "x": 7,
      "y": 12,
      "z": 43,
      "r": 139,
      "g": 90,
      "b": 43
    },
    {
      "x": 7,
      "y": 13,
      "z": 43,
      "r": 139,
      "g": 90,
      "b": 43
    },
    {
      "x": 8,
      "y": 13,
      "z": 43,
      "r": 139,
      "g": 90,
      "b": 43
    },
    {
      "x": 7,
      "y": 13,
      "z": 44,
      "r": 139,
      "g": 90,
      "b": 43
    },
    {
      "x": 6,
      "y": 13,
      "z": 37,
      "r": 139,
      "g": 90,
      "b": 43
    },
    {
      "x": 8,
      "y": 13,
      "z": 42,
      "r": 139,
      "g": 90,
      "b": 43
    },
    {
      "x": 7,
      "y": 13,
      "z": 38,
      "r": 139,
      "g": 90,
      "b": 43
    },
    {
      "x": 10,
      "y": 13,
      "z": 49,
      "r": 139,
      "g": 90,
      "b": 43
    },
    {
      "x": 9,
      "y": 13,
      "z": 46,
      "r": 139,
      "g": 90,
      "b": 43
    },
    {
      "x": 9,
      "y": 14,
      "z": 46,
      "r": 139,
      "g": 90,
      "b": 43
    },
    {
      "x": 12,
      "y": 14,
      "z": 53,
      "r": 139,
      "g": 90,
      "b": 43
    },
    {
      "x": 11,
      "y": 15,
      "z": 52,
      "r": 139,
      "g": 90,
      "b": 43
    },
    {
      "x": 15,
      "y": 14,
      "z": 54,
      "r": 139,
      "g": 90,
      "b": 43
    },
    {
      "x": 17,
      "y": 14,
      "z": 53,
      "r": 139,
      "g": 90,
      "b": 43
    },
    {
      "x": 21,
      "y": 13,
      "z": 43,
      "r": 139,
      "g": 90,
      "b": 43
    },
    {
      "x": 22,
      "y": 13,
      "z": 39,
      "r": 139,
      "g": 90,
      "b": 43
    },
    {
      "x": 20,
      "y": 13,
      "z": 46,
      "r": 139,
      "g": 90,
      "b": 43
    },
    {
      "x": 20,
      "y": 13,
      "z": 47,
      "r": 139,
      "g": 90,
      "b": 43
    },
    {
      "x": 20,
      "y": 14,
      "z": 47,
      "r": 139,
      "g": 90,
      "b": 43
    },
    {
      "x": 19,
      "y": 14,
      "z": 50,
      "r": 139,
      "g": 90,
      "b": 43
    },
    {
      "x": 23,
      "y": 13,
      "z": 37,
      "r": 139,
      "g": 90,
      "b": 43
    },
    {
      "x": 10,
      "y": 8,
      "z": 49,
      "r": 139,
      "g": 90,
      "b": 43
    },
    {
      "x": 10,
      "y": 9,
      "z": 49,
      "r": 139,
      "g": 90,
      "b": 43
    },
    {
      "x": 11,
      "y": 8,
      "z": 49,
      "r": 139,
      "g": 90,
      "b": 43
    },
    {
      "x": 11,
      "y": 8,
      "z": 50,
      "r": 139,
      "g": 90,
      "b": 43
    },
    {
      "x": 11,
      "y": 8,
      "z": 51,
      "r": 139,
      "g": 90,
      "b": 43
    },
    {
      "x": 11,
      "y": 9,
      "z": 49,
      "r": 139,
      "g": 90,
      "b": 43
    },
    {
      "x": 11,
      "y": 9,
      "z": 50,
      "r": 139,
      "g": 90,
      "b": 43
    },
    {
      "x": 10,
      "y": 9,
      "z": 50,
      "r": 139,
      "g": 90,
      "b": 43
    },
    {
      "x": 11,
      "y": 9,
      "z": 51,
      "r": 139,
      "g": 90,
      "b": 43
    },
    {
      "x": 12,
      "y": 8,
      "z": 51,
      "r": 139,
      "g": 90,
      "b": 43
    },
    {
      "x": 12,
      "y": 9,
      "z": 51,
      "r": 139,
      "g": 90,
      "b": 43
    },
    {
      "x": 12,
      "y": 8,
      "z": 52,
      "r": 139,
      "g": 90,
      "b": 43
    },
    {
      "x": 12,
      "y": 9,
      "z": 52,
      "r": 139,
      "g": 90,
      "b": 43
    },
    {
      "x": 13,
      "y": 8,
      "z": 51,
      "r": 139,
      "g": 90,
      "b": 43
    },
    {
      "x": 13,
      "y": 8,
      "z": 52,
      "r": 139,
      "g": 90,
      "b": 43
    },
    {
      "x": 13,
      "y": 9,
      "z": 52,
      "r": 139,
      "g": 90,
      "b": 43
    },
    {
      "x": 14,
      "y": 8,
      "z": 52,
      "r": 139,
      "g": 90,
      "b": 43
    },
    {
      "x": 14,
      "y": 9,
      "z": 52,
      "r": 139,
      "g": 90,
      "b": 43
    },
    {
      "x": 15,
      "y": 8,
      "z": 52,
      "r": 139,
      "g": 90,
      "b": 43
    },
    {
      "x": 14,
      "y": 9,
      "z": 53,
      "r": 139,
      "g": 90,
      "b": 43
    },
    {
      "x": 15,
      "y": 9,
      "z": 52,
      "r": 139,
      "g": 90,
      "b": 43
    },
    {
      "x": 15,
      "y": 9,
      "z": 53,
      "r": 139,
      "g": 90,
      "b": 43
    },
    {
      "x": 16,
      "y": 8,
      "z": 52,
      "r": 139,
      "g": 90,
      "b": 43
    },
    {
      "x": 17,
      "y": 8,
      "z": 51,
      "r": 139,
      "g": 90,
      "b": 43
    },
    {
      "x": 17,
      "y": 8,
      "z": 52,
      "r": 139,
      "g": 90,
      "b": 43
    },
    {
      "x": 16,
      "y": 9,
      "z": 52,
      "r": 139,
      "g": 90,
      "b": 43
    },
    {
      "x": 17,
      "y": 9,
      "z": 52,
      "r": 139,
      "g": 90,
      "b": 43
    },
    {
      "x": 18,
      "y": 8,
      "z": 51,
      "r": 139,
      "g": 90,
      "b": 43
    },
    {
      "x": 18,
      "y": 8,
      "z": 49,
      "r": 139,
      "g": 90,
      "b": 43
    },
    {
      "x": 18,
      "y": 8,
      "z": 50,
      "r": 139,
      "g": 90,
      "b": 43
    },
    {
      "x": 19,
      "y": 8,
      "z": 49,
      "r": 139,
      "g": 90,
      "b": 43
    },
    {
      "x": 18,
      "y": 9,
      "z": 49,
      "r": 139,
      "g": 90,
      "b": 43
    },
    {
      "x": 18,
      "y": 9,
      "z": 50,
      "r": 139,
      "g": 90,
      "b": 43
    },
    {
      "x": 19,
      "y": 9,
      "z": 49,
      "r": 139,
      "g": 90,
      "b": 43
    },
    {
      "x": 19,
      "y": 9,
      "z": 50,
      "r": 139,
      "g": 90,
      "b": 43
    },
    {
      "x": 18,
      "y": 9,
      "z": 51,
      "r": 139,
      "g": 90,
      "b": 43
    },
    {
      "x": 17,
      "y": 9,
      "z": 51,
      "r": 139,
      "g": 90,
      "b": 43
    },
    {
      "x": 9,
      "y": 6,
      "z": 6,
      "r": 139,
      "g": 90,
      "b": 43
    },
    {
      "x": 10,
      "y": 5,
      "z": 5,
      "r": 139,
      "g": 90,
      "b": 43
    },
    {
      "x": 10,
      "y": 6,
      "z": 4,
      "r": 139,
      "g": 90,
      "b": 43
    },
    {
      "x": 10,
      "y": 6,
      "z": 5,
      "r": 139,
      "g": 90,
      "b": 43
    },
    {
      "x": 10,
      "y": 6,
      "z": 6,
      "r": 139,
      "g": 90,
      "b": 43
    },
    {
      "x": 9,
      "y": 5,
      "z": 6,
      "r": 139,
      "g": 90,
      "b": 43
    },
    {
      "x": 9,
      "y": 5,
      "z": 7,
      "r": 139,
      "g": 90,
      "b": 43
    },
    {
      "x": 9,
      "y": 6,
      "z": 7,
      "r": 139,
      "g": 90,
      "b": 43
    },
    {
      "x": 10,
      "y": 5,
      "z": 6,
      "r": 139,
      "g": 90,
      "b": 43
    },
    {
      "x": 11,
      "y": 5,
      "z": 4,
      "r": 139,
      "g": 90,
      "b": 43
    },
    {
      "x": 11,
      "y": 6,
      "z": 4,
      "r": 139,
      "g": 90,
      "b": 43
    },
    {
      "x": 12,
      "y": 5,
      "z": 4,
      "r": 139,
      "g": 90,
      "b": 43
    },
    {
      "x": 12,
      "y": 6,
      "z": 4,
      "r": 139,
      "g": 90,
      "b": 43
    },
    {
      "x": 10,
      "y": 5,
      "z": 4,
      "r": 139,
      "g": 90,
      "b": 43
    },
    {
      "x": 11,
      "y": 5,
      "z": 5,
      "r": 139,
      "g": 90,
      "b": 43
    },
    {
      "x": 13,
      "y": 5,
      "z": 3,
      "r": 139,
      "g": 90,
      "b": 43
    },
    {
      "x": 13,
      "y": 5,
      "z": 4,
      "r": 139,
      "g": 90,
      "b": 43
    },
    {
      "x": 13,
      "y": 6,
      "z": 3,
      "r": 139,
      "g": 90,
      "b": 43
    },
    {
      "x": 13,
      "y": 6,
      "z": 4,
      "r": 139,
      "g": 90,
      "b": 43
    },
    {
      "x": 14,
      "y": 5,
      "z": 3,
      "r": 139,
      "g": 90,
      "b": 43
    },
    {
      "x": 14,
      "y": 6,
      "z": 3,
      "r": 139,
      "g": 90,
      "b": 43
    },
    {
      "x": 15,
      "y": 5,
      "z": 3,
      "r": 139,
      "g": 90,
      "b": 43
    },
    {
      "x": 15,
      "y": 6,
      "z": 3,
      "r": 139,
      "g": 90,
      "b": 43
    },
    {
      "x": 14,
      "y": 5,
      "z": 4,
      "r": 139,
      "g": 90,
      "b": 43
    },
    {
      "x": 16,
      "y": 5,
      "z": 3,
      "r": 139,
      "g": 90,
      "b": 43
    },
    {
      "x": 16,
      "y": 5,
      "z": 4,
      "r": 139,
      "g": 90,
      "b": 43
    },
    {
      "x": 15,
      "y": 5,
      "z": 4,
      "r": 139,
      "g": 90,
      "b": 43
    },
    {
      "x": 16,
      "y": 6,
      "z": 3,
      "r": 139,
      "g": 90,
      "b": 43
    },
    {
      "x": 16,
      "y": 6,
      "z": 4,
      "r": 139,
      "g": 90,
      "b": 43
    },
    {
      "x": 17,
      "y": 5,
      "z": 4,
      "r": 139,
      "g": 90,
      "b": 43
    },
    {
      "x": 17,
      "y": 6,
      "z": 3,
      "r": 139,
      "g": 90,
      "b": 43
    },
    {
      "x": 17,
      "y": 6,
      "z": 4,
      "r": 139,
      "g": 90,
      "b": 43
    },
    {
      "x": 18,
      "y": 5,
      "z": 4,
      "r": 139,
      "g": 90,
      "b": 43
    },
    {
      "x": 18,
      "y": 5,
      "z": 5,
      "r": 139,
      "g": 90,
      "b": 43
    },
    {
      "x": 19,
      "y": 5,
      "z": 5,
      "r": 139,
      "g": 90,
      "b": 43
    },
    {
      "x": 18,
      "y": 6,
      "z": 4,
      "r": 139,
      "g": 90,
      "b": 43
    },
    {
      "x": 19,
      "y": 6,
      "z": 4,
      "r": 139,
      "g": 90,
      "b": 43
    },
    {
      "x": 19,
      "y": 5,
      "z": 4,
      "r": 139,
      "g": 90,
      "b": 43
    },
    {
      "x": 19,
      "y": 6,
      "z": 5,
      "r": 139,
      "g": 90,
      "b": 43
    },
    {
      "x": 19,
      "y": 6,
      "z": 6,
      "r": 139,
      "g": 90,
      "b": 43
    },
    {
      "x": 20,
      "y": 6,
      "z": 6,
      "r": 139,
      "g": 90,
      "b": 43
    },
    {
      "x": 19,
      "y": 5,
      "z": 6,
      "r": 139,
      "g": 90,
      "b": 43
    },
    {
      "x": 20,
      "y": 5,
      "z": 6,
      "r": 139,
      "g": 90,
      "b": 43
    },
    {
      "x": 20,
      "y": 5,
      "z": 7,
      "r": 139,
      "g": 90,
      "b": 43
    },
    {
      "x": 20,
      "y": 6,
      "z": 7,
      "r": 139,
      "g": 90,
      "b": 43
    },
    {
      "x": 21,
      "y": 6,
      "z": 11,
      "r": 139,
      "g": 90,
      "b": 43
    },
    {
      "x": 22,
      "y": 6,
      "z": 11,
      "r": 139,
      "g": 90,
      "b": 43
    },
    {
      "x": 22,
      "y": 6,
      "z": 12,
      "r": 139,
      "g": 90,
      "b": 43
    },
    {
      "x": 22,
      "y": 6,
      "z": 13,
      "r": 139,
      "g": 90,
      "b": 43
    },
    {
      "x": 22,
      "y": 6,
      "z": 14,
      "r": 139,
      "g": 90,
      "b": 43
    },
    {
      "x": 22,
      "y": 6,
      "z": 15,
      "r": 139,
      "g": 90,
      "b": 43
    },
    {
      "x": 22,
      "y": 6,
      "z": 16,
      "r": 139,
      "g": 90,
      "b": 43
    },
    {
      "x": 22,
      "y": 7,
      "z": 15,
      "r": 139,
      "g": 90,
      "b": 43
    },
    {
      "x": 23,
      "y": 6,
      "z": 15,
      "r": 139,
      "g": 90,
      "b": 43
    },
    {
      "x": 23,
      "y": 6,
      "z": 16,
      "r": 139,
      "g": 90,
      "b": 43
    },
    {
      "x": 23,
      "y": 7,
      "z": 15,
      "r": 139,
      "g": 90,
      "b": 43
    },
    {
      "x": 23,
      "y": 7,
      "z": 16,
      "r": 139,
      "g": 90,
      "b": 43
    },
    {
      "x": 21,
      "y": 6,
      "z": 10,
      "r": 139,
      "g": 90,
      "b": 43
    },
    {
      "x": 22,
      "y": 7,
      "z": 14,
      "r": 139,
      "g": 90,
      "b": 43
    },
    {
      "x": 20,
      "y": 5,
      "z": 8,
      "r": 139,
      "g": 90,
      "b": 43
    },
    {
      "x": 20,
      "y": 6,
      "z": 8,
      "r": 139,
      "g": 90,
      "b": 43
    },
    {
      "x": 21,
      "y": 6,
      "z": 8,
      "r": 139,
      "g": 90,
      "b": 43
    },
    {
      "x": 21,
      "y": 6,
      "z": 9,
      "r": 139,
      "g": 90,
      "b": 43
    },
    {
      "x": 23,
      "y": 7,
      "z": 21,
      "r": 139,
      "g": 90,
      "b": 43
    },
    {
      "x": 23,
      "y": 7,
      "z": 22,
      "r": 139,
      "g": 90,
      "b": 43
    },
    {
      "x": 23,
      "y": 7,
      "z": 23,
      "r": 139,
      "g": 90,
      "b": 43
    },
    {
      "x": 23,
      "y": 7,
      "z": 24,
      "r": 139,
      "g": 90,
      "b": 43
    },
    {
      "x": 24,
      "y": 7,
      "z": 23,
      "r": 139,
      "g": 90,
      "b": 43
    },
    {
      "x": 24,
      "y": 7,
      "z": 24,
      "r": 139,
      "g": 90,
      "b": 43
    },
    {
      "x": 24,
      "y": 7,
      "z": 25,
      "r": 139,
      "g": 90,
      "b": 43
    },
    {
      "x": 24,
      "y": 7,
      "z": 26,
      "r": 139,
      "g": 90,
      "b": 43
    },
    {
      "x": 24,
      "y": 7,
      "z": 27,
      "r": 139,
      "g": 90,
      "b": 43
    },
    {
      "x": 24,
      "y": 8,
      "z": 26,
      "r": 139,
      "g": 90,
      "b": 43
    },
    {
      "x": 24,
      "y": 8,
      "z": 27,
      "r": 139,
      "g": 90,
      "b": 43
    },
    {
      "x": 24,
      "y": 7,
      "z": 21,
      "r": 139,
      "g": 90,
      "b": 43
    },
    {
      "x": 24,
      "y": 7,
      "z": 22,
      "r": 139,
      "g": 90,
      "b": 43
    },
    {
      "x": 24,
      "y": 8,
      "z": 25,
      "r": 139,
      "g": 90,
      "b": 43
    },
    {
      "x": 23,
      "y": 6,
      "z": 17,
      "r": 139,
      "g": 90,
      "b": 43
    },
    {
      "x": 23,
      "y": 6,
      "z": 18,
      "r": 139,
      "g": 90,
      "b": 43
    },
    {
      "x": 23,
      "y": 6,
      "z": 19,
      "r": 139,
      "g": 90,
      "b": 43
    },
    {
      "x": 23,
      "y": 7,
      "z": 18,
      "r": 139,
      "g": 90,
      "b": 43
    },
    {
      "x": 23,
      "y": 7,
      "z": 19,
      "r": 139,
      "g": 90,
      "b": 43
    },
    {
      "x": 23,
      "y": 7,
      "z": 20,
      "r": 139,
      "g": 90,
      "b": 43
    },
    {
      "x": 23,
      "y": 7,
      "z": 17,
      "r": 139,
      "g": 90,
      "b": 43
    },
    {
      "x": 22,
      "y": 8,
      "z": 35,
      "r": 139,
      "g": 90,
      "b": 43
    },
    {
      "x": 22,
      "y": 8,
      "z": 36,
      "r": 139,
      "g": 90,
      "b": 43
    },
    {
      "x": 22,
      "y": 8,
      "z": 37,
      "r": 139,
      "g": 90,
      "b": 43
    },
    {
      "x": 22,
      "y": 8,
      "z": 38,
      "r": 139,
      "g": 90,
      "b": 43
    },
    {
      "x": 23,
      "y": 8,
      "z": 33,
      "r": 139,
      "g": 90,
      "b": 43
    },
    {
      "x": 23,
      "y": 8,
      "z": 34,
      "r": 139,
      "g": 90,
      "b": 43
    },
    {
      "x": 23,
      "y": 8,
      "z": 35,
      "r": 139,
      "g": 90,
      "b": 43
    },
    {
      "x": 23,
      "y": 7,
      "z": 28,
      "r": 139,
      "g": 90,
      "b": 43
    },
    {
      "x": 23,
      "y": 7,
      "z": 29,
      "r": 139,
      "g": 90,
      "b": 43
    },
    {
      "x": 23,
      "y": 7,
      "z": 30,
      "r": 139,
      "g": 90,
      "b": 43
    },
    {
      "x": 23,
      "y": 7,
      "z": 31,
      "r": 139,
      "g": 90,
      "b": 43
    },
    {
      "x": 23,
      "y": 7,
      "z": 32,
      "r": 139,
      "g": 90,
      "b": 43
    },
    {
      "x": 23,
      "y": 8,
      "z": 32,
      "r": 139,
      "g": 90,
      "b": 43
    },
    {
      "x": 24,
      "y": 7,
      "z": 28,
      "r": 139,
      "g": 90,
      "b": 43
    },
    {
      "x": 23,
      "y": 8,
      "z": 31,
      "r": 139,
      "g": 90,
      "b": 43
    },
    {
      "x": 23,
      "y": 8,
      "z": 29,
      "r": 139,
      "g": 90,
      "b": 43
    },
    {
      "x": 23,
      "y": 8,
      "z": 30,
      "r": 139,
      "g": 90,
      "b": 43
    },
    {
      "x": 24,
      "y": 7,
      "z": 29,
      "r": 139,
      "g": 90,
      "b": 43
    },
    {
      "x": 24,
      "y": 8,
      "z": 28,
      "r": 139,
      "g": 90,
      "b": 43
    },
    {
      "x": 24,
      "y": 8,
      "z": 29,
      "r": 139,
      "g": 90,
      "b": 43
    },
    {
      "x": 19,
      "y": 8,
      "z": 47,
      "r": 139,
      "g": 90,
      "b": 43
    },
    {
      "x": 19,
      "y": 8,
      "z": 48,
      "r": 139,
      "g": 90,
      "b": 43
    },
    {
      "x": 20,
      "y": 8,
      "z": 44,
      "r": 139,
      "g": 90,
      "b": 43
    },
    {
      "x": 20,
      "y": 8,
      "z": 45,
      "r": 139,
      "g": 90,
      "b": 43
    },
    {
      "x": 20,
      "y": 8,
      "z": 46,
      "r": 139,
      "g": 90,
      "b": 43
    },
    {
      "x": 20,
      "y": 8,
      "z": 47,
      "r": 139,
      "g": 90,
      "b": 43
    },
    {
      "x": 20,
      "y": 8,
      "z": 43,
      "r": 139,
      "g": 90,
      "b": 43
    },
    {
      "x": 21,
      "y": 8,
      "z": 39,
      "r": 139,
      "g": 90,
      "b": 43
    },
    {
      "x": 21,
      "y": 8,
      "z": 40,
      "r": 139,
      "g": 90,
      "b": 43
    },
    {
      "x": 21,
      "y": 8,
      "z": 41,
      "r": 139,
      "g": 90,
      "b": 43
    },
    {
      "x": 21,
      "y": 8,
      "z": 42,
      "r": 139,
      "g": 90,
      "b": 43
    },
    {
      "x": 21,
      "y": 8,
      "z": 43,
      "r": 139,
      "g": 90,
      "b": 43
    },
    {
      "x": 22,
      "y": 8,
      "z": 39,
      "r": 139,
      "g": 90,
      "b": 43
    },
    {
      "x": 20,
      "y": 9,
      "z": 44,
      "r": 139,
      "g": 90,
      "b": 43
    },
    {
      "x": 21,
      "y": 8,
      "z": 44,
      "r": 139,
      "g": 90,
      "b": 43
    },
    {
      "x": 21,
      "y": 9,
      "z": 41,
      "r": 139,
      "g": 90,
      "b": 43
    },
    {
      "x": 21,
      "y": 9,
      "z": 42,
      "r": 139,
      "g": 90,
      "b": 43
    },
    {
      "x": 21,
      "y": 9,
      "z": 43,
      "r": 139,
      "g": 90,
      "b": 43
    },
    {
      "x": 21,
      "y": 9,
      "z": 44,
      "r": 139,
      "g": 90,
      "b": 43
    },
    {
      "x": 22,
      "y": 8,
      "z": 40,
      "r": 139,
      "g": 90,
      "b": 43
    },
    {
      "x": 20,
      "y": 9,
      "z": 45,
      "r": 139,
      "g": 90,
      "b": 43
    },
    {
      "x": 20,
      "y": 9,
      "z": 46,
      "r": 139,
      "g": 90,
      "b": 43
    },
    {
      "x": 19,
      "y": 9,
      "z": 47,
      "r": 139,
      "g": 90,
      "b": 43
    },
    {
      "x": 19,
      "y": 9,
      "z": 48,
      "r": 139,
      "g": 90,
      "b": 43
    },
    {
      "x": 20,
      "y": 9,
      "z": 47,
      "r": 139,
      "g": 90,
      "b": 43
    },
    {
      "x": 8,
      "y": 6,
      "z": 8,
      "r": 139,
      "g": 90,
      "b": 43
    },
    {
      "x": 8,
      "y": 6,
      "z": 9,
      "r": 139,
      "g": 90,
      "b": 43
    },
    {
      "x": 8,
      "y": 6,
      "z": 10,
      "r": 139,
      "g": 90,
      "b": 43
    },
    {
      "x": 8,
      "y": 6,
      "z": 11,
      "r": 139,
      "g": 90,
      "b": 43
    },
    {
      "x": 9,
      "y": 5,
      "z": 8,
      "r": 139,
      "g": 90,
      "b": 43
    },
    {
      "x": 9,
      "y": 6,
      "z": 8,
      "r": 139,
      "g": 90,
      "b": 43
    },
    {
      "x": 7,
      "y": 6,
      "z": 12,
      "r": 139,
      "g": 90,
      "b": 43
    },
    {
      "x": 7,
      "y": 6,
      "z": 13,
      "r": 139,
      "g": 90,
      "b": 43
    },
    {
      "x": 7,
      "y": 6,
      "z": 14,
      "r": 139,
      "g": 90,
      "b": 43
    },
    {
      "x": 7,
      "y": 6,
      "z": 15,
      "r": 139,
      "g": 90,
      "b": 43
    },
    {
      "x": 7,
      "y": 6,
      "z": 16,
      "r": 139,
      "g": 90,
      "b": 43
    },
    {
      "x": 8,
      "y": 6,
      "z": 12,
      "r": 139,
      "g": 90,
      "b": 43
    },
    {
      "x": 6,
      "y": 7,
      "z": 16,
      "r": 139,
      "g": 90,
      "b": 43
    },
    {
      "x": 7,
      "y": 7,
      "z": 15,
      "r": 139,
      "g": 90,
      "b": 43
    },
    {
      "x": 7,
      "y": 7,
      "z": 16,
      "r": 139,
      "g": 90,
      "b": 43
    },
    {
      "x": 7,
      "y": 6,
      "z": 11,
      "r": 139,
      "g": 90,
      "b": 43
    },
    {
      "x": 7,
      "y": 7,
      "z": 14,
      "r": 139,
      "g": 90,
      "b": 43
    },
    {
      "x": 6,
      "y": 6,
      "z": 17,
      "r": 139,
      "g": 90,
      "b": 43
    },
    {
      "x": 6,
      "y": 6,
      "z": 18,
      "r": 139,
      "g": 90,
      "b": 43
    },
    {
      "x": 6,
      "y": 6,
      "z": 19,
      "r": 139,
      "g": 90,
      "b": 43
    },
    {
      "x": 6,
      "y": 7,
      "z": 18,
      "r": 139,
      "g": 90,
      "b": 43
    },
    {
      "x": 6,
      "y": 7,
      "z": 19,
      "r": 139,
      "g": 90,
      "b": 43
    },
    {
      "x": 6,
      "y": 7,
      "z": 20,
      "r": 139,
      "g": 90,
      "b": 43
    },
    {
      "x": 6,
      "y": 7,
      "z": 21,
      "r": 139,
      "g": 90,
      "b": 43
    },
    {
      "x": 7,
      "y": 6,
      "z": 17,
      "r": 139,
      "g": 90,
      "b": 43
    },
    {
      "x": 5,
      "y": 7,
      "z": 27,
      "r": 139,
      "g": 90,
      "b": 43
    },
    {
      "x": 6,
      "y": 7,
      "z": 22,
      "r": 139,
      "g": 90,
      "b": 43
    },
    {
      "x": 6,
      "y": 7,
      "z": 23,
      "r": 139,
      "g": 90,
      "b": 43
    },
    {
      "x": 6,
      "y": 7,
      "z": 24,
      "r": 139,
      "g": 90,
      "b": 43
    },
    {
      "x": 6,
      "y": 7,
      "z": 25,
      "r": 139,
      "g": 90,
      "b": 43
    },
    {
      "x": 6,
      "y": 7,
      "z": 26,
      "r": 139,
      "g": 90,
      "b": 43
    },
    {
      "x": 6,
      "y": 7,
      "z": 27,
      "r": 139,
      "g": 90,
      "b": 43
    },
    {
      "x": 5,
      "y": 7,
      "z": 26,
      "r": 139,
      "g": 90,
      "b": 43
    },
    {
      "x": 5,
      "y": 7,
      "z": 25,
      "r": 139,
      "g": 90,
      "b": 43
    },
    {
      "x": 5,
      "y": 8,
      "z": 26,
      "r": 139,
      "g": 90,
      "b": 43
    },
    {
      "x": 5,
      "y": 8,
      "z": 27,
      "r": 139,
      "g": 90,
      "b": 43
    },
    {
      "x": 5,
      "y": 7,
      "z": 24,
      "r": 139,
      "g": 90,
      "b": 43
    },
    {
      "x": 5,
      "y": 8,
      "z": 25,
      "r": 139,
      "g": 90,
      "b": 43
    },
    {
      "x": 6,
      "y": 6,
      "z": 16,
      "r": 139,
      "g": 90,
      "b": 43
    },
    {
      "x": 6,
      "y": 7,
      "z": 17,
      "r": 139,
      "g": 90,
      "b": 43
    },
    {
      "x": 5,
      "y": 7,
      "z": 28,
      "r": 139,
      "g": 90,
      "b": 43
    },
    {
      "x": 5,
      "y": 8,
      "z": 28,
      "r": 139,
      "g": 90,
      "b": 43
    },
    {
      "x": 6,
      "y": 7,
      "z": 28,
      "r": 139,
      "g": 90,
      "b": 43
    },
    {
      "x": 6,
      "y": 7,
      "z": 29,
      "r": 139,
      "g": 90,
      "b": 43
    },
    {
      "x": 6,
      "y": 7,
      "z": 30,
      "r": 139,
      "g": 90,
      "b": 43
    },
    {
      "x": 6,
      "y": 7,
      "z": 31,
      "r": 139,
      "g": 90,
      "b": 43
    },
    {
      "x": 6,
      "y": 8,
      "z": 28,
      "r": 139,
      "g": 90,
      "b": 43
    },
    {
      "x": 6,
      "y": 8,
      "z": 29,
      "r": 139,
      "g": 90,
      "b": 43
    },
    {
      "x": 6,
      "y": 8,
      "z": 30,
      "r": 139,
      "g": 90,
      "b": 43
    },
    {
      "x": 6,
      "y": 8,
      "z": 31,
      "r": 139,
      "g": 90,
      "b": 43
    },
    {
      "x": 6,
      "y": 8,
      "z": 32,
      "r": 139,
      "g": 90,
      "b": 43
    },
    {
      "x": 6,
      "y": 8,
      "z": 33,
      "r": 139,
      "g": 90,
      "b": 43
    },
    {
      "x": 6,
      "y": 7,
      "z": 32,
      "r": 139,
      "g": 90,
      "b": 43
    },
    {
      "x": 6,
      "y": 8,
      "z": 34,
      "r": 139,
      "g": 90,
      "b": 43
    },
    {
      "x": 7,
      "y": 8,
      "z": 34,
      "r": 139,
      "g": 90,
      "b": 43
    },
    {
      "x": 7,
      "y": 8,
      "z": 35,
      "r": 139,
      "g": 90,
      "b": 43
    },
    {
      "x": 7,
      "y": 8,
      "z": 36,
      "r": 139,
      "g": 90,
      "b": 43
    },
    {
      "x": 7,
      "y": 8,
      "z": 37,
      "r": 139,
      "g": 90,
      "b": 43
    },
    {
      "x": 7,
      "y": 8,
      "z": 38,
      "r": 139,
      "g": 90,
      "b": 43
    },
    {
      "x": 6,
      "y": 8,
      "z": 35,
      "r": 139,
      "g": 90,
      "b": 43
    },
    {
      "x": 7,
      "y": 8,
      "z": 39,
      "r": 139,
      "g": 90,
      "b": 43
    },
    {
      "x": 8,
      "y": 8,
      "z": 39,
      "r": 139,
      "g": 90,
      "b": 43
    },
    {
      "x": 8,
      "y": 8,
      "z": 40,
      "r": 139,
      "g": 90,
      "b": 43
    },
    {
      "x": 8,
      "y": 8,
      "z": 41,
      "r": 139,
      "g": 90,
      "b": 43
    },
    {
      "x": 8,
      "y": 8,
      "z": 42,
      "r": 139,
      "g": 90,
      "b": 43
    },
    {
      "x": 8,
      "y": 8,
      "z": 43,
      "r": 139,
      "g": 90,
      "b": 43
    },
    {
      "x": 9,
      "y": 8,
      "z": 43,
      "r": 139,
      "g": 90,
      "b": 43
    },
    {
      "x": 9,
      "y": 8,
      "z": 44,
      "r": 139,
      "g": 90,
      "b": 43
    },
    {
      "x": 8,
      "y": 9,
      "z": 41,
      "r": 139,
      "g": 90,
      "b": 43
    },
    {
      "x": 8,
      "y": 9,
      "z": 42,
      "r": 139,
      "g": 90,
      "b": 43
    },
    {
      "x": 8,
      "y": 9,
      "z": 43,
      "r": 139,
      "g": 90,
      "b": 43
    },
    {
      "x": 9,
      "y": 9,
      "z": 43,
      "r": 139,
      "g": 90,
      "b": 43
    },
    {
      "x": 9,
      "y": 9,
      "z": 44,
      "r": 139,
      "g": 90,
      "b": 43
    },
    {
      "x": 9,
      "y": 8,
      "z": 45,
      "r": 139,
      "g": 90,
      "b": 43
    },
    {
      "x": 9,
      "y": 8,
      "z": 46,
      "r": 139,
      "g": 90,
      "b": 43
    },
    {
      "x": 10,
      "y": 8,
      "z": 46,
      "r": 139,
      "g": 90,
      "b": 43
    },
    {
      "x": 10,
      "y": 8,
      "z": 47,
      "r": 139,
      "g": 90,
      "b": 43
    },
    {
      "x": 10,
      "y": 8,
      "z": 48,
      "r": 139,
      "g": 90,
      "b": 43
    },
    {
      "x": 9,
      "y": 9,
      "z": 45,
      "r": 139,
      "g": 90,
      "b": 43
    },
    {
      "x": 9,
      "y": 9,
      "z": 46,
      "r": 139,
      "g": 90,
      "b": 43
    },
    {
      "x": 9,
      "y": 9,
      "z": 47,
      "r": 139,
      "g": 90,
      "b": 43
    },
    {
      "x": 10,
      "y": 9,
      "z": 46,
      "r": 139,
      "g": 90,
      "b": 43
    },
    {
      "x": 10,
      "y": 9,
      "z": 47,
      "r": 139,
      "g": 90,
      "b": 43
    },
    {
      "x": 10,
      "y": 9,
      "z": 48,
      "r": 139,
      "g": 90,
      "b": 43
    },
    {
      "x": 12,
      "y": 9,
      "z": 50,
      "r": 139,
      "g": 90,
      "b": 43
    },
    {
      "x": 13,
      "y": 9,
      "z": 51,
      "r": 139,
      "g": 90,
      "b": 43
    },
    {
      "x": 16,
      "y": 9,
      "z": 51,
      "r": 139,
      "g": 90,
      "b": 43
    },
    {
      "x": 17,
      "y": 9,
      "z": 50,
      "r": 139,
      "g": 90,
      "b": 43
    },
    {
      "x": 11,
      "y": 6,
      "z": 5,
      "r": 139,
      "g": 90,
      "b": 43
    },
    {
      "x": 14,
      "y": 6,
      "z": 4,
      "r": 139,
      "g": 90,
      "b": 43
    },
    {
      "x": 15,
      "y": 6,
      "z": 4,
      "r": 139,
      "g": 90,
      "b": 43
    },
    {
      "x": 18,
      "y": 6,
      "z": 5,
      "r": 139,
      "g": 90,
      "b": 43
    },
    {
      "x": 20,
      "y": 6,
      "z": 9,
      "r": 139,
      "g": 90,
      "b": 43
    },
    {
      "x": 21,
      "y": 6,
      "z": 12,
      "r": 139,
      "g": 90,
      "b": 43
    },
    {
      "x": 21,
      "y": 6,
      "z": 13,
      "r": 139,
