{
  "resolution": 40,
  "gridSize": {
    "x": 40,
    "y": 39,
    "z": 16
  },
  "voxelCount": 3476,
  "voxels": [
    {
      "x": 20,
      "y": 28,
      "z": 7,
      "r": 90,
      "g": 90,
      "b": 95
    },
    {
      "x": 20,
      "y": 28,
      "z": 8,
      "r": 90,
      "g": 90,
      "b": 95
    },
    {
      "x": 21,
      "y": 28,
      "z": 7,
      "r": 90,
      "g": 90,
      "b": 95
    },
    {
      "x": 21,
      "y": 28,
      "z": 8,
      "r": 90,
      "g": 90,
      "b": 95
    },
    {
      "x": 22,
      "y": 28,
      "z": 7,
      "r": 90,
      "g": 90,
      "b": 95
    },
    {
      "x": 22,
      "y": 28,
      "z": 8,
      "r": 90,
      "g": 90,
      "b": 95
    },
    {
      "x": 23,
      "y": 28,
      "z": 7,
      "r": 90,
      "g": 90,
      "b": 95
    },
    {
      "x": 23,
      "y": 28,
      "z": 8,
      "r": 90,
      "g": 90,
      "b": 95
    },
    {
      "x": 24,
      "y": 28,
      "z": 7,
      "r": 90,
      "g": 90,
      "b": 95
    },
    {
      "x": 24,
      "y": 28,
      "z": 8,
      "r": 90,
      "g": 90,
      "b": 95
    },
    {
      "x": 25,
      "y": 28,
      "z": 7,
      "r": 90,
      "g": 90,
      "b": 95
    },
    {
      "x": 25,
      "y": 28,
      "z": 8,
      "r": 90,
      "g": 90,
      "b": 95
    },
    {
      "x": 25,
      "y": 28,
      "z": 9,
      "r": 90,
      "g": 90,
      "b": 95
    },
    {
      "x": 26,
      "y": 28,
      "z": 7,
      "r": 90,
      "g": 90,
      "b": 95
    },
    {
      "x": 26,
      "y": 28,
      "z": 8,
      "r": 90,
      "g": 90,
      "b": 95
    },
    {
      "x": 26,
      "y": 28,
      "z": 9,
      "r": 90,
      "g": 90,
      "b": 95
    },
    {
      "x": 27,
      "y": 28,
      "z": 7,
      "r": 90,
      "g": 90,
      "b": 95
    },
    {
      "x": 27,
      "y": 28,
      "z": 8,
      "r": 90,
      "g": 90,
      "b": 95
    },
    {
      "x": 27,
      "y": 28,
      "z": 9,
      "r": 90,
      "g": 90,
      "b": 95
    },
    {
      "x": 28,
      "y": 28,
      "z": 7,
      "r": 90,
      "g": 90,
      "b": 95
    },
    {
      "x": 28,
      "y": 28,
      "z": 8,
      "r": 90,
      "g": 90,
      "b": 95
    },
    {
      "x": 28,
      "y": 28,
      "z": 9,
      "r": 90,
      "g": 90,
      "b": 95
    },
    {
      "x": 29,
      "y": 28,
      "z": 7,
      "r": 90,
      "g": 90,
      "b": 95
    },
    {
      "x": 29,
      "y": 28,
      "z": 8,
      "r": 90,
      "g": 90,
      "b": 95
    },
    {
      "x": 29,
      "y": 28,
      "z": 9,
      "r": 90,
      "g": 90,
      "b": 95
    },
    {
      "x": 29,
      "y": 28,
      "z": 10,
      "r": 90,
      "g": 90,
      "b": 95
    },
    {
      "x": 30,
      "y": 28,
      "z": 7,
      "r": 90,
      "g": 90,
      "b": 95
    },
    {
      "x": 30,
      "y": 28,
      "z": 8,
      "r": 90,
      "g": 90,
      "b": 95
    },
    {
      "x": 30,
      "y": 28,
      "z": 9,
      "r": 90,
      "g": 90,
      "b": 95
    },
    {
      "x": 30,
      "y": 28,
      "z": 10,
      "r": 90,
      "g": 90,
      "b": 95
    },
    {
      "x": 31,
      "y": 28,
      "z": 7,
      "r": 90,
      "g": 90,
      "b": 95
    },
    {
      "x": 31,
      "y": 28,
      "z": 8,
      "r": 90,
      "g": 90,
      "b": 95
    },
    {
      "x": 31,
      "y": 28,
      "z": 9,
      "r": 90,
      "g": 90,
      "b": 95
    },
    {
      "x": 31,
      "y": 28,
      "z": 10,
      "r": 90,
      "g": 90,
      "b": 95
    },
    {
      "x": 32,
      "y": 28,
      "z": 7,
      "r": 90,
      "g": 90,
      "b": 95
    },
    {
      "x": 32,
      "y": 28,
      "z": 8,
      "r": 90,
      "g": 90,
      "b": 95
    },
    {
      "x": 32,
      "y": 28,
      "z": 9,
      "r": 90,
      "g": 90,
      "b": 95
    },
    {
      "x": 32,
      "y": 28,
      "z": 10,
      "r": 90,
      "g": 90,
      "b": 95
    },
    {
      "x": 33,
      "y": 28,
      "z": 7,
      "r": 90,
      "g": 90,
      "b": 95
    },
    {
      "x": 33,
      "y": 28,
      "z": 8,
      "r": 90,
      "g": 90,
      "b": 95
    },
    {
      "x": 33,
      "y": 28,
      "z": 9,
      "r": 90,
      "g": 90,
      "b": 95
    },
    {
      "x": 33,
      "y": 28,
      "z": 10,
      "r": 90,
      "g": 90,
      "b": 95
    },
    {
      "x": 34,
      "y": 28,
      "z": 7,
      "r": 90,
      "g": 90,
      "b": 95
    },
    {
      "x": 34,
      "y": 28,
      "z": 8,
      "r": 90,
      "g": 90,
      "b": 95
    },
    {
      "x": 34,
      "y": 28,
      "z": 9,
      "r": 90,
      "g": 90,
      "b": 95
    },
    {
      "x": 34,
      "y": 28,
      "z": 10,
      "r": 90,
      "g": 90,
      "b": 95
    },
    {
      "x": 34,
      "y": 28,
      "z": 11,
      "r": 90,
      "g": 90,
      "b": 95
    },
    {
      "x": 35,
      "y": 28,
      "z": 7,
      "r": 90,
      "g": 90,
      "b": 95
    },
    {
      "x": 35,
      "y": 28,
      "z": 8,
      "r": 90,
      "g": 90,
      "b": 95
    },
    {
      "x": 35,
      "y": 28,
      "z": 9,
      "r": 90,
      "g": 90,
      "b": 95
    },
    {
      "x": 35,
      "y": 28,
      "z": 10,
      "r": 90,
      "g": 90,
      "b": 95
    },
    {
      "x": 35,
      "y": 28,
      "z": 11,
      "r": 90,
      "g": 90,
      "b": 95
    },
    {
      "x": 36,
      "y": 28,
      "z": 7,
      "r": 90,
      "g": 90,
      "b": 95
    },
    {
      "x": 36,
      "y": 28,
      "z": 8,
      "r": 90,
      "g": 90,
      "b": 95
    },
    {
      "x": 36,
      "y": 28,
      "z": 9,
      "r": 90,
      "g": 90,
      "b": 95
    },
    {
      "x": 36,
      "y": 28,
      "z": 10,
      "r": 90,
      "g": 90,
      "b": 95
    },
    {
      "x": 36,
      "y": 28,
      "z": 11,
      "r": 90,
      "g": 90,
      "b": 95
    },
    {
      "x": 37,
      "y": 28,
      "z": 7,
      "r": 90,
      "g": 90,
      "b": 95
    },
    {
      "x": 37,
      "y": 28,
      "z": 8,
      "r": 90,
      "g": 90,
      "b": 95
    },
    {
      "x": 37,
      "y": 28,
      "z": 9,
      "r": 90,
      "g": 90,
      "b": 95
    },
    {
      "x": 37,
      "y": 28,
      "z": 10,
      "r": 90,
      "g": 90,
      "b": 95
    },
    {
      "x": 37,
      "y": 28,
      "z": 11,
      "r": 90,
      "g": 90,
      "b": 95
    },
    {
      "x": 38,
      "y": 28,
      "z": 7,
      "r": 90,
      "g": 90,
      "b": 95
    },
    {
      "x": 38,
      "y": 28,
      "z": 8,
      "r": 90,
      "g": 90,
      "b": 95
    },
    {
      "x": 38,
      "y": 28,
      "z": 9,
      "r": 90,
      "g": 90,
      "b": 95
    },
    {
      "x": 38,
      "y": 28,
      "z": 10,
      "r": 90,
      "g": 90,
      "b": 95
    },
    {
      "x": 38,
      "y": 28,
      "z": 11,
      "r": 90,
      "g": 90,
      "b": 95
    },
    {
      "x": 20,
      "y": 28,
      "z": 9,
      "r": 90,
      "g": 90,
      "b": 95
    },
    {
      "x": 20,
      "y": 28,
      "z": 10,
      "r": 90,
      "g": 90,
      "b": 95
    },
    {
      "x": 20,
      "y": 28,
      "z": 11,
      "r": 90,
      "g": 90,
      "b": 95
    },
    {
      "x": 21,
      "y": 28,
      "z": 9,
      "r": 90,
      "g": 90,
      "b": 95
    },
    {
      "x": 21,
      "y": 28,
      "z": 10,
      "r": 90,
      "g": 90,
      "b": 95
    },
    {
      "x": 21,
      "y": 28,
      "z": 11,
      "r": 90,
      "g": 90,
      "b": 95
    },
    {
      "x": 22,
      "y": 28,
      "z": 9,
      "r": 90,
      "g": 90,
      "b": 95
    },
    {
      "x": 22,
      "y": 28,
      "z": 10,
      "r": 90,
      "g": 90,
      "b": 95
    },
    {
      "x": 22,
      "y": 28,
      "z": 11,
      "r": 90,
      "g": 90,
      "b": 95
    },
    {
      "x": 23,
      "y": 28,
      "z": 9,
      "r": 90,
      "g": 90,
      "b": 95
    },
    {
      "x": 23,
      "y": 28,
      "z": 10,
      "r": 90,
      "g": 90,
      "b": 95
    },
    {
      "x": 23,
      "y": 28,
      "z": 11,
      "r": 90,
      "g": 90,
      "b": 95
    },
    {
      "x": 24,
      "y": 28,
      "z": 9,
      "r": 90,
      "g": 90,
      "b": 95
    },
    {
      "x": 24,
      "y": 28,
      "z": 10,
      "r": 90,
      "g": 90,
      "b": 95
    },
    {
      "x": 24,
      "y": 28,
      "z": 11,
      "r": 90,
      "g": 90,
      "b": 95
    },
    {
      "x": 25,
      "y": 28,
      "z": 10,
      "r": 90,
      "g": 90,
      "b": 95
    },
    {
      "x": 25,
      "y": 28,
      "z": 11,
      "r": 90,
      "g": 90,
      "b": 95
    },
    {
      "x": 26,
      "y": 28,
      "z": 10,
      "r": 90,
      "g": 90,
      "b": 95
    },
    {
      "x": 26,
      "y": 28,
      "z": 11,
      "r": 90,
      "g": 90,
      "b": 95
    },
    {
      "x": 27,
      "y": 28,
      "z": 10,
      "r": 90,
      "g": 90,
      "b": 95
    },
    {
      "x": 27,
      "y": 28,
      "z": 11,
      "r": 90,
      "g": 90,
      "b": 95
    },
    {
      "x": 28,
      "y": 28,
      "z": 10,
      "r": 90,
      "g": 90,
      "b": 95
    },
    {
      "x": 28,
      "y": 28,
      "z": 11,
      "r": 90,
      "g": 90,
      "b": 95
    },
    {
      "x": 29,
      "y": 28,
      "z": 11,
      "r": 90,
      "g": 90,
      "b": 95
    },
    {
      "x": 30,
      "y": 28,
      "z": 11,
      "r": 90,
      "g": 90,
      "b": 95
    },
    {
      "x": 31,
      "y": 28,
      "z": 11,
      "r": 90,
      "g": 90,
      "b": 95
    },
    {
      "x": 32,
      "y": 28,
      "z": 11,
      "r": 90,
      "g": 90,
      "b": 95
    },
    {
      "x": 33,
      "y": 28,
      "z": 11,
      "r": 90,
      "g": 90,
      "b": 95
    },
    {
      "x": 1,
      "y": 28,
      "z": 11,
      "r": 90,
      "g": 90,
      "b": 95
    },
    {
      "x": 2,
      "y": 28,
      "z": 11,
      "r": 90,
      "g": 90,
      "b": 95
    },
    {
      "x": 3,
      "y": 28,
      "z": 11,
      "r": 90,
      "g": 90,
      "b": 95
    },
    {
      "x": 4,
      "y": 28,
      "z": 11,
      "r": 90,
      "g": 90,
      "b": 95
    },
    {
      "x": 5,
      "y": 28,
      "z": 10,
      "r": 90,
      "g": 90,
      "b": 95
    },
    {
      "x": 5,
      "y": 28,
      "z": 11,
      "r": 90,
      "g": 90,
      "b": 95
    },
    {
      "x": 6,
      "y": 28,
      "z": 10,
      "r": 90,
      "g": 90,
      "b": 95
    },
    {
      "x": 6,
      "y": 28,
      "z": 11,
      "r": 90,
      "g": 90,
      "b": 95
    },
    {
      "x": 7,
      "y": 28,
      "z": 10,
      "r": 90,
      "g": 90,
      "b": 95
    },
    {
      "x": 7,
      "y": 28,
      "z": 11,
      "r": 90,
      "g": 90,
      "b": 95
    },
    {
      "x": 8,
      "y": 28,
      "z": 10,
      "r": 90,
      "g": 90,
      "b": 95
    },
    {
      "x": 8,
      "y": 28,
      "z": 11,
      "r": 90,
      "g": 90,
      "b": 95
    },
    {
      "x": 9,
      "y": 28,
      "z": 10,
      "r": 90,
      "g": 90,
      "b": 95
    },
    {
      "x": 9,
      "y": 28,
      "z": 11,
      "r": 90,
      "g": 90,
      "b": 95
    },
    {
      "x": 10,
      "y": 28,
      "z": 9,
      "r": 90,
      "g": 90,
      "b": 95
    },
    {
      "x": 10,
      "y": 28,
      "z": 10,
      "r": 90,
      "g": 90,
      "b": 95
    },
    {
      "x": 10,
      "y": 28,
      "z": 11,
      "r": 90,
      "g": 90,
      "b": 95
    },
    {
      "x": 11,
      "y": 28,
      "z": 9,
      "r": 90,
      "g": 90,
      "b": 95
    },
    {
      "x": 11,
      "y": 28,
      "z": 10,
      "r": 90,
      "g": 90,
      "b": 95
    },
    {
      "x": 11,
      "y": 28,
      "z": 11,
      "r": 90,
      "g": 90,
      "b": 95
    },
    {
      "x": 12,
      "y": 28,
      "z": 9,
      "r": 90,
      "g": 90,
      "b": 95
    },
    {
      "x": 12,
      "y": 28,
      "z": 10,
      "r": 90,
      "g": 90,
      "b": 95
    },
    {
      "x": 12,
      "y": 28,
      "z": 11,
      "r": 90,
      "g": 90,
      "b": 95
    },
    {
      "x": 13,
      "y": 28,
      "z": 9,
      "r": 90,
      "g": 90,
      "b": 95
    },
    {
      "x": 13,
      "y": 28,
      "z": 10,
      "r": 90,
      "g": 90,
      "b": 95
    },
    {
      "x": 13,
      "y": 28,
      "z": 11,
      "r": 90,
      "g": 90,
      "b": 95
    },
    {
      "x": 14,
      "y": 28,
      "z": 8,
      "r": 90,
      "g": 90,
      "b": 95
    },
    {
      "x": 14,
      "y": 28,
      "z": 9,
      "r": 90,
      "g": 90,
      "b": 95
    },
    {
      "x": 14,
      "y": 28,
      "z": 10,
      "r": 90,
      "g": 90,
      "b": 95
    },
    {
      "x": 14,
      "y": 28,
      "z": 11,
      "r": 90,
      "g": 90,
      "b": 95
    },
    {
      "x": 15,
      "y": 28,
      "z": 8,
      "r": 90,
      "g": 90,
      "b": 95
    },
    {
      "x": 15,
      "y": 28,
      "z": 9,
      "r": 90,
      "g": 90,
      "b": 95
    },
    {
      "x": 15,
      "y": 28,
      "z": 10,
      "r": 90,
      "g": 90,
      "b": 95
    },
    {
      "x": 15,
      "y": 28,
      "z": 11,
      "r": 90,
      "g": 90,
      "b": 95
    },
    {
      "x": 16,
      "y": 28,
      "z": 8,
      "r": 90,
      "g": 90,
      "b": 95
    },
    {
      "x": 16,
      "y": 28,
      "z": 9,
      "r": 90,
      "g": 90,
      "b": 95
    },
    {
      "x": 16,
      "y": 28,
      "z": 10,
      "r": 90,
      "g": 90,
      "b": 95
    },
    {
      "x": 16,
      "y": 28,
      "z": 11,
      "r": 90,
      "g": 90,
      "b": 95
    },
    {
      "x": 17,
      "y": 28,
      "z": 8,
      "r": 90,
      "g": 90,
      "b": 95
    },
    {
      "x": 17,
      "y": 28,
      "z": 9,
      "r": 90,
      "g": 90,
      "b": 95
    },
    {
      "x": 17,
      "y": 28,
      "z": 10,
      "r": 90,
      "g": 90,
      "b": 95
    },
    {
      "x": 17,
      "y": 28,
      "z": 11,
      "r": 90,
      "g": 90,
      "b": 95
    },
    {
      "x": 18,
      "y": 28,
      "z": 8,
      "r": 90,
      "g": 90,
      "b": 95
    },
    {
      "x": 18,
      "y": 28,
      "z": 9,
      "r": 90,
      "g": 90,
      "b": 95
    },
    {
      "x": 18,
      "y": 28,
      "z": 10,
      "r": 90,
      "g": 90,
      "b": 95
    },
    {
      "x": 18,
      "y": 28,
      "z": 11,
      "r": 90,
      "g": 90,
      "b": 95
    },
    {
      "x": 19,
      "y": 28,
      "z": 7,
      "r": 90,
      "g": 90,
      "b": 95
    },
    {
      "x": 19,
      "y": 28,
      "z": 8,
      "r": 90,
      "g": 90,
      "b": 95
    },
    {
      "x": 19,
      "y": 28,
      "z": 9,
      "r": 90,
      "g": 90,
      "b": 95
    },
    {
      "x": 19,
      "y": 28,
      "z": 10,
      "r": 90,
      "g": 90,
      "b": 95
    },
    {
      "x": 19,
      "y": 28,
      "z": 11,
      "r": 90,
      "g": 90,
      "b": 95
    },
    {
      "x": 1,
      "y": 28,
      "z": 7,
      "r": 90,
      "g": 90,
      "b": 95
    },
    {
      "x": 1,
      "y": 28,
      "z": 8,
      "r": 90,
      "g": 90,
      "b": 95
    },
    {
      "x": 1,
      "y": 28,
      "z": 9,
      "r": 90,
      "g": 90,
      "b": 95
    },
    {
      "x": 1,
      "y": 28,
      "z": 10,
      "r": 90,
      "g": 90,
      "b": 95
    },
    {
      "x": 2,
      "y": 28,
      "z": 7,
      "r": 90,
      "g": 90,
      "b": 95
    },
    {
      "x": 2,
      "y": 28,
      "z": 8,
      "r": 90,
      "g": 90,
      "b": 95
    },
    {
      "x": 2,
      "y": 28,
      "z": 9,
      "r": 90,
      "g": 90,
      "b": 95
    },
    {
      "x": 2,
      "y": 28,
      "z": 10,
      "r": 90,
      "g": 90,
      "b": 95
    },
    {
      "x": 3,
      "y": 28,
      "z": 7,
      "r": 90,
      "g": 90,
      "b": 95
    },
    {
      "x": 3,
      "y": 28,
      "z": 8,
      "r": 90,
      "g": 90,
      "b": 95
    },
    {
      "x": 3,
      "y": 28,
      "z": 9,
      "r": 90,
      "g": 90,
      "b": 95
    },
    {
      "x": 3,
      "y": 28,
      "z": 10,
      "r": 90,
      "g": 90,
      "b": 95
    },
    {
      "x": 4,
      "y": 28,
      "z": 7,
      "r": 90,
      "g": 90,
      "b": 95
    },
    {
      "x": 4,
      "y": 28,
      "z": 8,
      "r": 90,
      "g": 90,
      "b": 95
    },
    {
      "x": 4,
      "y": 28,
      "z": 9,
      "r": 90,
      "g": 90,
      "b": 95
    },
    {
      "x": 4,
      "y": 28,
      "z": 10,
      "r": 90,
      "g": 90,
      "b": 95
    },
    {
      "x": 5,
      "y": 28,
      "z": 7,
      "r": 90,
      "g": 90,
      "b": 95
    },
    {
      "x": 5,
      "y": 28,
      "z": 8,
      "r": 90,
      "g": 90,
      "b": 95
    },
    {
      "x": 5,
      "y": 28,
      "z": 9,
      "r": 90,
      "g": 90,
      "b": 95
    },
    {
      "x": 6,
      "y": 28,
      "z": 7,
      "r": 90,
      "g": 90,
      "b": 95
    },
    {
      "x": 6,
      "y": 28,
      "z": 8,
      "r": 90,
      "g": 90,
      "b": 95
    },
    {
      "x": 6,
      "y": 28,
      "z": 9,
      "r": 90,
      "g": 90,
      "b": 95
    },
    {
      "x": 7,
      "y": 28,
      "z": 7,
      "r": 90,
      "g": 90,
      "b": 95
    },
    {
      "x": 7,
      "y": 28,
      "z": 8,
      "r": 90,
      "g": 90,
      "b": 95
    },
    {
      "x": 7,
      "y": 28,
      "z": 9,
      "r": 90,
      "g": 90,
      "b": 95
    },
    {
      "x": 8,
      "y": 28,
      "z": 7,
      "r": 90,
      "g": 90,
      "b": 95
    },
    {
      "x": 8,
      "y": 28,
      "z": 8,
      "r": 90,
      "g": 90,
      "b": 95
    },
    {
      "x": 8,
      "y": 28,
      "z": 9,
      "r": 90,
      "g": 90,
      "b": 95
    },
    {
      "x": 9,
      "y": 28,
      "z": 7,
      "r": 90,
      "g": 90,
      "b": 95
    },
    {
      "x": 9,
      "y": 28,
      "z": 8,
      "r": 90,
      "g": 90,
      "b": 95
    },
    {
      "x": 9,
      "y": 28,
      "z": 9,
      "r": 90,
      "g": 90,
      "b": 95
    },
    {
      "x": 10,
      "y": 28,
      "z": 7,
      "r": 90,
      "g": 90,
      "b": 95
    },
    {
      "x": 10,
      "y": 28,
      "z": 8,
      "r": 90,
      "g": 90,
      "b": 95
    },
    {
      "x": 11,
      "y": 28,
      "z": 7,
      "r": 90,
      "g": 90,
      "b": 95
    },
    {
      "x": 11,
      "y": 28,
      "z": 8,
      "r": 90,
      "g": 90,
      "b": 95
    },
    {
      "x": 12,
      "y": 28,
      "z": 7,
      "r": 90,
      "g": 90,
      "b": 95
    },
    {
      "x": 12,
      "y": 28,
      "z": 8,
      "r": 90,
      "g": 90,
      "b": 95
    },
    {
      "x": 13,
      "y": 28,
      "z": 7,
      "r": 90,
      "g": 90,
      "b": 95
    },
    {
      "x": 13,
      "y": 28,
      "z": 8,
      "r": 90,
      "g": 90,
      "b": 95
    },
    {
      "x": 14,
      "y": 28,
      "z": 7,
      "r": 90,
      "g": 90,
      "b": 95
    },
    {
      "x": 15,
      "y": 28,
      "z": 7,
      "r": 90,
      "g": 90,
      "b": 95
    },
    {
      "x": 16,
      "y": 28,
      "z": 7,
      "r": 90,
      "g": 90,
      "b": 95
    },
    {
      "x": 17,
      "y": 28,
      "z": 7,
      "r": 90,
      "g": 90,
      "b": 95
    },
    {
      "x": 18,
      "y": 28,
      "z": 7,
      "r": 90,
      "g": 90,
      "b": 95
    },
    {
      "x": 38,
      "y": 29,
      "z": 7,
      "r": 90,
      "g": 90,
      "b": 95
    },
    {
      "x": 38,
      "y": 29,
      "z": 8,
      "r": 90,
      "g": 90,
      "b": 95
    },
    {
      "x": 38,
      "y": 29,
      "z": 9,
      "r": 90,
      "g": 90,
      "b": 95
    },
    {
      "x": 38,
      "y": 29,
      "z": 10,
      "r": 90,
      "g": 90,
      "b": 95
    },
    {
      "x": 38,
      "y": 29,
      "z": 11,
      "r": 90,
      "g": 90,
      "b": 95
    },
    {
      "x": 20,
      "y": 29,
      "z": 11,
      "r": 90,
      "g": 90,
      "b": 95
    },
    {
      "x": 21,
      "y": 29,
      "z": 11,
      "r": 90,
      "g": 90,
      "b": 95
    },
    {
      "x": 22,
      "y": 29,
      "z": 11,
      "r": 90,
      "g": 90,
      "b": 95
    },
    {
      "x": 23,
      "y": 29,
      "z": 11,
      "r": 90,
      "g": 90,
      "b": 95
    },
    {
      "x": 24,
      "y": 29,
      "z": 11,
      "r": 90,
      "g": 90,
      "b": 95
    },
    {
      "x": 25,
      "y": 29,
      "z": 11,
      "r": 90,
      "g": 90,
      "b": 95
    },
    {
      "x": 26,
      "y": 29,
      "z": 11,
      "r": 90,
      "g": 90,
      "b": 95
    },
    {
      "x": 27,
      "y": 29,
      "z": 11,
      "r": 90,
      "g": 90,
      "b": 95
    },
    {
      "x": 28,
      "y": 29,
      "z": 11,
      "r": 90,
      "g": 90,
      "b": 95
    },
    {
      "x": 29,
      "y": 29,
      "z": 11,
      "r": 90,
      "g": 90,
      "b": 95
    },
    {
      "x": 30,
      "y": 29,
      "z": 11,
      "r": 90,
      "g": 90,
      "b": 95
    },
    {
      "x": 31,
      "y": 29,
      "z": 11,
      "r": 90,
      "g": 90,
      "b": 95
    },
    {
      "x": 32,
      "y": 29,
      "z": 11,
      "r": 90,
      "g": 90,
      "b": 95
    },
    {
      "x": 33,
      "y": 29,
      "z": 11,
      "r": 90,
      "g": 90,
      "b": 95
    },
    {
      "x": 34,
      "y": 29,
      "z": 11,
      "r": 90,
      "g": 90,
      "b": 95
    },
    {
      "x": 35,
      "y": 29,
      "z": 11,
      "r": 90,
      "g": 90,
      "b": 95
    },
    {
      "x": 36,
      "y": 29,
      "z": 11,
      "r": 90,
      "g": 90,
      "b": 95
    },
    {
      "x": 37,
      "y": 29,
      "z": 11,
      "r": 90,
      "g": 90,
      "b": 95
    },
    {
      "x": 20,
      "y": 37,
      "z": 11,
      "r": 90,
      "g": 90,
      "b": 95
    },
    {
      "x": 21,
      "y": 36,
      "z": 11,
      "r": 90,
      "g": 90,
      "b": 95
    },
    {
      "x": 21,
      "y": 37,
      "z": 11,
      "r": 90,
      "g": 90,
      "b": 95
    },
    {
      "x": 22,
      "y": 36,
      "z": 11,
      "r": 90,
      "g": 90,
      "b": 95
    },
    {
      "x": 23,
      "y": 35,
      "z": 11,
      "r": 90,
      "g": 90,
      "b": 95
    },
    {
      "x": 23,
      "y": 36,
      "z": 11,
      "r": 90,
      "g": 90,
      "b": 95
    },
    {
      "x": 24,
      "y": 35,
      "z": 11,
      "r": 90,
      "g": 90,
      "b": 95
    },
    {
      "x": 25,
      "y": 34,
      "z": 11,
      "r": 90,
      "g": 90,
      "b": 95
    },
    {
      "x": 25,
      "y": 35,
      "z": 11,
      "r": 90,
      "g": 90,
      "b": 95
    },
    {
      "x": 26,
      "y": 34,
      "z": 11,
      "r": 90,
      "g": 90,
      "b": 95
    },
    {
      "x": 27,
      "y": 33,
      "z": 11,
      "r": 90,
      "g": 90,
      "b": 95
    },
    {
      "x": 27,
      "y": 34,
      "z": 11,
      "r": 90,
      "g": 90,
      "b": 95
    },
    {
      "x": 28,
      "y": 33,
      "z": 11,
      "r": 90,
      "g": 90,
      "b": 95
    },
    {
      "x": 29,
      "y": 33,
      "z": 11,
      "r": 90,
      "g": 90,
      "b": 95
    },
    {
      "x": 30,
      "y": 32,
      "z": 11,
      "r": 90,
      "g": 90,
      "b": 95
    },
    {
      "x": 30,
      "y": 33,
      "z": 11,
      "r": 90,
      "g": 90,
      "b": 95
    },
    {
      "x": 31,
      "y": 32,
      "z": 11,
      "r": 90,
      "g": 90,
      "b": 95
    },
    {
      "x": 32,
      "y": 31,
      "z": 11,
      "r": 90,
      "g": 90,
      "b": 95
    },
    {
      "x": 32,
      "y": 32,
      "z": 11,
      "r": 90,
      "g": 90,
      "b": 95
    },
    {
      "x": 33,
      "y": 31,
      "z": 11,
      "r": 90,
      "g": 90,
      "b": 95
    },
    {
      "x": 34,
      "y": 30,
      "z": 11,
      "r": 90,
      "g": 90,
      "b": 95
    },
    {
      "x": 34,
      "y": 31,
      "z": 11,
      "r": 90,
      "g": 90,
      "b": 95
    },
    {
      "x": 35,
      "y": 30,
      "z": 11,
      "r": 90,
      "g": 90,
      "b": 95
    },
    {
      "x": 36,
      "y": 30,
      "z": 11,
      "r": 90,
      "g": 90,
      "b": 95
    },
    {
      "x": 2,
      "y": 29,
      "z": 11,
      "r": 90,
      "g": 90,
      "b": 95
    },
    {
      "x": 3,
      "y": 29,
      "z": 11,
      "r": 90,
      "g": 90,
      "b": 95
    },
    {
      "x": 4,
      "y": 29,
      "z": 11,
      "r": 90,
      "g": 90,
      "b": 95
    },
    {
      "x": 5,
      "y": 29,
      "z": 11,
      "r": 90,
      "g": 90,
      "b": 95
    },
    {
      "x": 6,
      "y": 29,
      "z": 11,
      "r": 90,
      "g": 90,
      "b": 95
    },
    {
      "x": 7,
      "y": 29,
      "z": 11,
      "r": 90,
      "g": 90,
      "b": 95
    },
    {
      "x": 8,
      "y": 29,
      "z": 11,
      "r": 90,
      "g": 90,
      "b": 95
    },
    {
      "x": 9,
      "y": 29,
      "z": 11,
      "r": 90,
      "g": 90,
      "b": 95
    },
    {
      "x": 10,
      "y": 29,
      "z": 11,
      "r": 90,
      "g": 90,
      "b": 95
    },
    {
      "x": 11,
      "y": 29,
      "z": 11,
      "r": 90,
      "g": 90,
      "b": 95
    },
    {
      "x": 12,
      "y": 29,
      "z": 11,
      "r": 90,
      "g": 90,
      "b": 95
    },
    {
      "x": 13,
      "y": 29,
      "z": 11,
      "r": 90,
      "g": 90,
      "b": 95
    },
    {
      "x": 14,
      "y": 29,
      "z": 11,
      "r": 90,
      "g": 90,
      "b": 95
    },
    {
      "x": 15,
      "y": 29,
      "z": 11,
      "r": 90,
      "g": 90,
      "b": 95
    },
    {
      "x": 16,
      "y": 29,
      "z": 11,
      "r": 90,
      "g": 90,
      "b": 95
    },
    {
      "x": 17,
      "y": 29,
      "z": 11,
      "r": 90,
      "g": 90,
      "b": 95
    },
    {
      "x": 18,
      "y": 29,
      "z": 11,
      "r": 90,
      "g": 90,
      "b": 95
    },
    {
      "x": 19,
      "y": 29,
      "z": 11,
      "r": 90,
      "g": 90,
      "b": 95
    },
    {
      "x": 2,
      "y": 29,
      "z": 10,
      "r": 90,
      "g": 90,
      "b": 95
    },
    {
      "x": 3,
      "y": 29,
      "z": 10,
      "r": 90,
      "g": 90,
      "b": 95
    },
    {
      "x": 4,
      "y": 29,
      "z": 10,
      "r": 90,
      "g": 90,
      "b": 95
    },
    {
      "x": 5,
      "y": 29,
      "z": 10,
      "r": 90,
      "g": 90,
      "b": 95
    },
    {
      "x": 6,
      "y": 29,
      "z": 10,
      "r": 90,
      "g": 90,
      "b": 95
    },
    {
      "x": 7,
      "y": 29,
      "z": 10,
      "r": 90,
      "g": 90,
      "b": 95
    },
    {
      "x": 8,
      "y": 29,
      "z": 10,
      "r": 90,
      "g": 90,
      "b": 95
    },
    {
      "x": 9,
      "y": 29,
      "z": 10,
      "r": 90,
      "g": 90,
      "b": 95
    },
    {
      "x": 10,
      "y": 29,
      "z": 10,
      "r": 90,
      "g": 90,
      "b": 95
    },
    {
      "x": 11,
      "y": 29,
      "z": 10,
      "r": 90,
      "g": 90,
      "b": 95
    },
    {
      "x": 12,
      "y": 29,
      "z": 10,
      "r": 90,
      "g": 90,
      "b": 95
    },
    {
      "x": 13,
      "y": 29,
      "z": 10,
      "r": 90,
      "g": 90,
      "b": 95
    },
    {
      "x": 14,
      "y": 29,
      "z": 10,
      "r": 90,
      "g": 90,
      "b": 95
    },
    {
      "x": 15,
      "y": 29,
      "z": 10,
      "r": 90,
      "g": 90,
      "b": 95
    },
    {
      "x": 16,
      "y": 29,
      "z": 10,
      "r": 90,
      "g": 90,
      "b": 95
    },
    {
      "x": 17,
      "y": 29,
      "z": 10,
      "r": 90,
      "g": 90,
      "b": 95
    },
    {
      "x": 18,
      "y": 29,
      "z": 10,
      "r": 90,
      "g": 90,
      "b": 95
    },
    {
      "x": 19,
      "y": 29,
      "z": 10,
      "r": 90,
      "g": 90,
      "b": 95
    },
    {
      "x": 26,
      "y": 35,
      "z": 11,
      "r": 90,
      "g": 90,
      "b": 95
    },
    {
      "x": 28,
      "y": 34,
      "z": 11,
      "r": 90,
      "g": 90,
      "b": 95
    },
    {
      "x": 33,
      "y": 32,
      "z": 11,
      "r": 90,
      "g": 90,
      "b": 95
    },
    {
      "x": 35,
      "y": 31,
      "z": 11,
      "r": 90,
      "g": 90,
      "b": 95
    },
    {
      "x": 37,
      "y": 30,
      "z": 11,
      "r": 90,
      "g": 90,
      "b": 95
    },
    {
      "x": 22,
      "y": 37,
      "z": 11,
      "r": 90,
      "g": 90,
      "b": 95
    },
    {
      "x": 24,
      "y": 36,
      "z": 11,
      "r": 90,
      "g": 90,
      "b": 95
    },
    {
      "x": 31,
      "y": 33,
      "z": 11,
      "r": 90,
      "g": 90,
      "b": 95
    },
    {
      "x": 20,
      "y": 36,
      "z": 10,
      "r": 90,
      "g": 90,
      "b": 95
    },
    {
      "x": 20,
      "y": 36,
      "z": 11,
      "r": 90,
      "g": 90,
      "b": 95
    },
    {
      "x": 20,
      "y": 37,
      "z": 10,
      "r": 90,
      "g": 90,
      "b": 95
    },
    {
      "x": 21,
      "y": 36,
      "z": 10,
      "r": 90,
      "g": 90,
      "b": 95
    },
    {
      "x": 22,
      "y": 35,
      "z": 10,
      "r": 90,
      "g": 90,
      "b": 95
    },
    {
      "x": 22,
      "y": 35,
      "z": 11,
      "r": 90,
      "g": 90,
      "b": 95
    },
    {
      "x": 22,
      "y": 36,
      "z": 10,
      "r": 90,
      "g": 90,
      "b": 95
    },
    {
      "x": 23,
      "y": 35,
      "z": 10,
      "r": 90,
      "g": 90,
      "b": 95
    },
    {
      "x": 24,
      "y": 34,
      "z": 10,
      "r": 90,
      "g": 90,
      "b": 95
    },
    {
      "x": 24,
      "y": 34,
      "z": 11,
      "r": 90,
      "g": 90,
      "b": 95
    },
    {
      "x": 24,
      "y": 35,
      "z": 10,
      "r": 90,
      "g": 90,
      "b": 95
    },
    {
      "x": 25,
      "y": 34,
      "z": 10,
      "r": 90,
      "g": 90,
      "b": 95
    },
    {
      "x": 26,
      "y": 34,
      "z": 10,
      "r": 90,
      "g": 90,
      "b": 95
    },
    {
      "x": 27,
      "y": 33,
      "z": 10,
      "r": 90,
      "g": 90,
      "b": 95
    },
    {
      "x": 27,
      "y": 34,
      "z": 10,
      "r": 90,
      "g": 90,
      "b": 95
    },
    {
      "x": 28,
      "y": 33,
      "z": 10,
      "r": 90,
      "g": 90,
      "b": 95
    },
    {
      "x": 29,
      "y": 32,
      "z": 10,
      "r": 90,
      "g": 90,
      "b": 95
    },
    {
      "x": 29,
      "y": 32,
      "z": 11,
      "r": 90,
      "g": 90,
      "b": 95
    },
    {
      "x": 29,
      "y": 33,
      "z": 10,
      "r": 90,
      "g": 90,
      "b": 95
    },
    {
      "x": 30,
      "y": 32,
      "z": 10,
      "r": 90,
      "g": 90,
      "b": 95
    },
    {
      "x": 31,
      "y": 31,
      "z": 10,
      "r": 90,
      "g": 90,
      "b": 95
    },
    {
      "x": 31,
      "y": 31,
      "z": 11,
      "r": 90,
      "g": 90,
      "b": 95
    },
    {
      "x": 31,
      "y": 32,
      "z": 10,
      "r": 90,
      "g": 90,
      "b": 95
    },
    {
      "x": 32,
      "y": 31,
      "z": 10,
      "r": 90,
      "g": 90,
      "b": 95
    },
    {
      "x": 33,
      "y": 30,
      "z": 11,
      "r": 90,
      "g": 90,
      "b": 95
    },
    {
      "x": 33,
      "y": 31,
      "z": 10,
      "r": 90,
      "g": 90,
      "b": 95
    },
    {
      "x": 25,
      "y": 35,
      "z": 10,
      "r": 90,
      "g": 90,
      "b": 95
    },
    {
      "x": 33,
      "y": 30,
      "z": 10,
      "r": 90,
      "g": 90,
      "b": 95
    },
    {
      "x": 34,
      "y": 30,
      "z": 10,
      "r": 90,
      "g": 90,
      "b": 95
    },
    {
      "x": 35,
      "y": 30,
      "z": 10,
      "r": 90,
      "g": 90,
      "b": 95
    },
    {
      "x": 36,
      "y": 29,
      "z": 10,
      "r": 90,
      "g": 90,
      "b": 95
    },
    {
      "x": 36,
      "y": 30,
      "z": 10,
      "r": 90,
      "g": 90,
      "b": 95
    },
    {
      "x": 37,
      "y": 29,
      "z": 10,
      "r": 90,
      "g": 90,
      "b": 95
    },
    {
      "x": 3,
      "y": 30,
      "z": 11,
      "r": 90,
      "g": 90,
      "b": 95
    },
    {
      "x": 4,
      "y": 30,
      "z": 11,
      "r": 90,
      "g": 90,
      "b": 95
    },
    {
      "x": 5,
      "y": 30,
      "z": 11,
      "r": 90,
      "g": 90,
      "b": 95
    },
    {
      "x": 5,
      "y": 31,
      "z": 11,
      "r": 90,
      "g": 90,
      "b": 95
    },
    {
      "x": 6,
      "y": 31,
      "z": 11,
      "r": 90,
      "g": 90,
      "b": 95
    },
    {
      "x": 7,
      "y": 31,
      "z": 11,
      "r": 90,
      "g": 90,
      "b": 95
    },
    {
      "x": 7,
      "y": 32,
      "z": 11,
      "r": 90,
      "g": 90,
      "b": 95
    },
    {
      "x": 8,
      "y": 32,
      "z": 11,
      "r": 90,
      "g": 90,
      "b": 95
    },
    {
      "x": 9,
      "y": 32,
      "z": 11,
      "r": 90,
      "g": 90,
      "b": 95
    },
    {
      "x": 10,
      "y": 32,
      "z": 11,
      "r": 90,
      "g": 90,
      "b": 95
    },
    {
      "x": 10,
      "y": 33,
      "z": 11,
      "r": 90,
      "g": 90,
      "b": 95
    },
    {
      "x": 11,
      "y": 33,
      "z": 11,
      "r": 90,
      "g": 90,
      "b": 95
    },
    {
      "x": 12,
      "y": 33,
      "z": 11,
      "r": 90,
      "g": 90,
      "b": 95
    },
    {
      "x": 12,
      "y": 34,
      "z": 11,
      "r": 90,
      "g": 90,
      "b": 95
    },
    {
      "x": 13,
      "y": 34,
      "z": 11,
      "r": 90,
      "g": 90,
      "b": 95
    },
    {
      "x": 14,
      "y": 34,
      "z": 11,
      "r": 90,
      "g": 90,
      "b": 95
    },
    {
      "x": 14,
      "y": 35,
      "z": 11,
      "r": 90,
      "g": 90,
      "b": 95
    },
    {
      "x": 15,
      "y": 35,
      "z": 11,
      "r": 90,
      "g": 90,
      "b": 95
    },
    {
      "x": 16,
      "y": 35,
      "z": 11,
      "r": 90,
      "g": 90,
      "b": 95
    },
    {
      "x": 16,
      "y": 36,
      "z": 11,
      "r": 90,
      "g": 90,
      "b": 95
    },
    {
      "x": 17,
      "y": 35,
      "z": 11,
      "r": 90,
      "g": 90,
      "b": 95
    },
    {
      "x": 17,
      "y": 36,
      "z": 11,
      "r": 90,
      "g": 90,
      "b": 95
    },
    {
      "x": 18,
      "y": 36,
      "z": 11,
      "r": 90,
      "g": 90,
      "b": 95
    },
    {
      "x": 19,
      "y": 36,
      "z": 11,
      "r": 90,
      "g": 90,
      "b": 95
    },
    {
      "x": 19,
      "y": 37,
      "z": 11,
      "r": 90,
      "g": 90,
      "b": 95
    },
    {
      "x": 8,
      "y": 31,
      "z": 11,
      "r": 90,
      "g": 90,
      "b": 95
    },
    {
      "x": 20,
      "y": 29,
      "z": 10,
      "r": 90,
      "g": 90,
      "b": 95
    },
    {
      "x": 20,
      "y": 30,
      "z": 10,
      "r": 90,
      "g": 90,
      "b": 95
    },
    {
      "x": 21,
      "y": 29,
      "z": 10,
      "r": 90,
      "g": 90,
      "b": 95
    },
    {
      "x": 21,
      "y": 30,
      "z": 10,
      "r": 90,
      "g": 90,
      "b": 95
    },
    {
      "x": 22,
      "y": 29,
      "z": 10,
      "r": 90,
      "g": 90,
      "b": 95
    },
    {
      "x": 22,
      "y": 30,
      "z": 10,
      "r": 90,
      "g": 90,
      "b": 95
    },
    {
      "x": 23,
      "y": 29,
      "z": 10,
      "r": 90,
      "g": 90,
      "b": 95
    },
    {
      "x": 23,
      "y": 30,
      "z": 10,
      "r": 90,
      "g": 90,
      "b": 95
    },
    {
      "x": 24,
      "y": 29,
      "z": 10,
      "r": 90,
      "g": 90,
      "b": 95
    },
    {
      "x": 24,
      "y": 30,
      "z": 10,
      "r": 90,
      "g": 90,
      "b": 95
    },
    {
      "x": 25,
      "y": 29,
      "z": 10,
      "r": 90,
      "g": 90,
      "b": 95
    },
    {
      "x": 25,
      "y": 30,
      "z": 10,
      "r": 90,
      "g": 90,
      "b": 95
    },
    {
      "x": 26,
      "y": 29,
      "z": 10,
      "r": 90,
      "g": 90,
      "b": 95
    },
    {
      "x": 26,
      "y": 30,
      "z": 10,
      "r": 90,
      "g": 90,
      "b": 95
    },
    {
      "x": 27,
      "y": 29,
      "z": 10,
      "r": 90,
      "g": 90,
      "b": 95
    },
    {
      "x": 27,
      "y": 30,
      "z": 10,
      "r": 90,
      "g": 90,
      "b": 95
    },
    {
      "x": 28,
      "y": 29,
      "z": 10,
      "r": 90,
      "g": 90,
      "b": 95
    },
    {
      "x": 28,
      "y": 30,
      "z": 10,
      "r": 90,
      "g": 90,
      "b": 95
    },
    {
      "x": 29,
      "y": 29,
      "z": 10,
      "r": 90,
      "g": 90,
      "b": 95
    },
    {
      "x": 29,
      "y": 30,
      "z": 10,
      "r": 90,
      "g": 90,
      "b": 95
    },
    {
      "x": 30,
      "y": 29,
      "z": 10,
      "r": 90,
      "g": 90,
      "b": 95
    },
    {
      "x": 30,
      "y": 30,
      "z": 10,
      "r": 90,
      "g": 90,
      "b": 95
    },
    {
      "x": 31,
      "y": 29,
      "z": 10,
      "r": 90,
      "g": 90,
      "b": 95
    },
    {
      "x": 31,
      "y": 30,
      "z": 10,
      "r": 90,
      "g": 90,
      "b": 95
    },
    {
      "x": 32,
      "y": 30,
      "z": 10,
      "r": 90,
      "g": 90,
      "b": 95
    },
    {
      "x": 32,
      "y": 29,
      "z": 10,
      "r": 90,
      "g": 90,
      "b": 95
    },
    {
      "x": 33,
      "y": 29,
      "z": 10,
      "r": 90,
      "g": 90,
      "b": 95
    },
    {
      "x": 34,
      "y": 29,
      "z": 10,
      "r": 90,
      "g": 90,
      "b": 95
    },
    {
      "x": 35,
      "y": 29,
      "z": 10,
      "r": 90,
      "g": 90,
      "b": 95
    },
    {
      "x": 4,
      "y": 30,
      "z": 10,
      "r": 90,
      "g": 90,
      "b": 95
    },
    {
      "x": 5,
      "y": 30,
      "z": 10,
      "r": 90,
      "g": 90,
      "b": 95
    },
    {
      "x": 6,
      "y": 30,
      "z": 10,
      "r": 90,
      "g": 90,
      "b": 95
    },
    {
      "x": 6,
      "y": 31,
      "z": 10,
      "r": 90,
      "g": 90,
      "b": 95
    },
    {
      "x": 7,
      "y": 31,
      "z": 10,
      "r": 90,
      "g": 90,
      "b": 95
    },
    {
      "x": 8,
      "y": 31,
      "z": 10,
      "r": 90,
      "g": 90,
      "b": 95
    },
    {
      "x": 8,
      "y": 32,
      "z": 10,
      "r": 90,
      "g": 90,
      "b": 95
    },
    {
      "x": 9,
      "y": 31,
      "z": 10,
      "r": 90,
      "g": 90,
      "b": 95
    },
    {
      "x": 9,
      "y": 32,
      "z": 10,
      "r": 90,
      "g": 90,
      "b": 95
    },
    {
      "x": 10,
      "y": 32,
      "z": 10,
      "r": 90,
      "g": 90,
      "b": 95
    },
    {
      "x": 10,
      "y": 33,
      "z": 10,
      "r": 90,
      "g": 90,
      "b": 95
    },
    {
      "x": 11,
      "y": 32,
      "z": 10,
      "r": 90,
      "g": 90,
      "b": 95
    },
    {
      "x": 11,
      "y": 33,
      "z": 10,
      "r": 90,
      "g": 90,
      "b": 95
    },
    {
      "x": 12,
      "y": 33,
      "z": 10,
      "r": 90,
      "g": 90,
      "b": 95
    },
    {
      "x": 12,
      "y": 34,
      "z": 10,
      "r": 90,
      "g": 90,
      "b": 95
    },
    {
      "x": 13,
      "y": 33,
      "z": 10,
      "r": 90,
      "g": 90,
      "b": 95
    },
    {
      "x": 13,
      "y": 34,
      "z": 10,
      "r": 90,
      "g": 90,
      "b": 95
    },
    {
      "x": 14,
      "y": 34,
      "z": 10,
      "r": 90,
      "g": 90,
      "b": 95
    },
    {
      "x": 15,
      "y": 34,
      "z": 10,
      "r": 90,
      "g": 90,
      "b": 95
    },
    {
      "x": 15,
      "y": 35,
      "z": 10,
      "r": 90,
      "g": 90,
      "b": 95
    },
    {
      "x": 16,
      "y": 34,
      "z": 10,
      "r": 90,
      "g": 90,
      "b": 95
    },
    {
      "x": 16,
      "y": 35,
      "z": 10,
      "r": 90,
      "g": 90,
      "b": 95
    },
    {
      "x": 17,
      "y": 35,
      "z": 10,
      "r": 90,
      "g": 90,
      "b": 95
    },
    {
      "x": 17,
      "y": 36,
      "z": 10,
      "r": 90,
      "g": 90,
      "b": 95
    },
    {
      "x": 18,
      "y": 35,
      "z": 10,
      "r": 90,
      "g": 90,
      "b": 95
    },
    {
      "x": 18,
      "y": 36,
      "z": 10,
      "r": 90,
      "g": 90,
      "b": 95
    },
    {
      "x": 19,
      "y": 36,
      "z": 10,
      "r": 90,
      "g": 90,
      "b": 95
    },
    {
      "x": 19,
      "y": 37,
      "z": 10,
      "r": 90,
      "g": 90,
      "b": 95
    },
    {
      "x": 7,
      "y": 30,
      "z": 10,
      "r": 90,
      "g": 90,
      "b": 95
    },
    {
      "x": 12,
      "y": 32,
      "z": 10,
      "r": 90,
      "g": 90,
      "b": 95
    },
    {
      "x": 14,
      "y": 33,
      "z": 10,
      "r": 90,
      "g": 90,
      "b": 95
    },
    {
      "x": 8,
      "y": 30,
      "z": 10,
      "r": 90,
      "g": 90,
      "b": 95
    },
    {
      "x": 9,
      "y": 30,
      "z": 10,
      "r": 90,
      "g": 90,
      "b": 95
    },
    {
      "x": 10,
      "y": 30,
      "z": 10,
      "r": 90,
      "g": 90,
      "b": 95
    },
    {
      "x": 11,
      "y": 30,
      "z": 10,
      "r": 90,
      "g": 90,
      "b": 95
    },
    {
      "x": 12,
      "y": 30,
      "z": 10,
      "r": 90,
      "g": 90,
      "b": 95
    },
    {
      "x": 13,
      "y": 30,
      "z": 10,
      "r": 90,
      "g": 90,
      "b": 95
    },
    {
      "x": 14,
      "y": 30,
      "z": 10,
      "r": 90,
      "g": 90,
      "b": 95
    },
    {
      "x": 15,
      "y": 30,
      "z": 10,
      "r": 90,
      "g": 90,
      "b": 95
    },
    {
      "x": 16,
      "y": 30,
      "z": 10,
      "r": 90,
      "g": 90,
      "b": 95
    },
    {
      "x": 17,
      "y": 30,
      "z": 10,
      "r": 90,
      "g": 90,
      "b": 95
    },
    {
      "x": 18,
      "y": 30,
      "z": 10,
      "r": 90,
      "g": 90,
      "b": 95
    },
    {
      "x": 19,
      "y": 30,
      "z": 10,
      "r": 90,
      "g": 90,
      "b": 95
    },
    {
      "x": 20,
      "y": 31,
      "z": 10,
      "r": 90,
      "g": 90,
      "b": 95
    },
    {
      "x": 20,
      "y": 32,
      "z": 10,
      "r": 90,
      "g": 90,
      "b": 95
    },
    {
      "x": 20,
      "y": 33,
      "z": 10,
      "r": 90,
      "g": 90,
      "b": 95
    },
    {
      "x": 20,
      "y": 34,
      "z": 10,
      "r": 90,
      "g": 90,
      "b": 95
    },
    {
      "x": 20,
      "y": 35,
      "z": 10,
      "r": 90,
      "g": 90,
      "b": 95
    },
    {
      "x": 21,
      "y": 31,
      "z": 10,
      "r": 90,
      "g": 90,
      "b": 95
    },
    {
      "x": 21,
      "y": 32,
      "z": 10,
      "r": 90,
      "g": 90,
      "b": 95
    },
    {
      "x": 21,
      "y": 33,
      "z": 10,
      "r": 90,
      "g": 90,
      "b": 95
    },
    {
      "x": 21,
      "y": 34,
      "z": 10,
      "r": 90,
      "g": 90,
      "b": 95
    },
    {
      "x": 21,
      "y": 35,
      "z": 10,
      "r": 90,
      "g": 90,
      "b": 95
    },
    {
      "x": 22,
      "y": 31,
      "z": 10,
      "r": 90,
      "g": 90,
      "b": 95
    },
    {
      "x": 22,
      "y": 32,
      "z": 10,
      "r": 90,
      "g": 90,
      "b": 95
    },
    {
      "x": 22,
      "y": 33,
      "z": 10,
      "r": 90,
      "g": 90,
      "b": 95
    },
    {
      "x": 22,
      "y": 34,
      "z": 10,
      "r": 90,
      "g": 90,
      "b": 95
    },
    {
      "x": 23,
      "y": 31,
      "z": 10,
      "r": 90,
      "g": 90,
      "b": 95
    },
    {
      "x": 23,
      "y": 32,
      "z": 10,
      "r": 90,
      "g": 90,
      "b": 95
    },
    {
      "x": 23,
      "y": 33,
      "z": 10,
      "r": 90,
      "g": 90,
      "b": 95
    },
    {
      "x": 23,
      "y": 34,
      "z": 10,
      "r": 90,
      "g": 90,
      "b": 95
    },
    {
      "x": 24,
      "y": 31,
      "z": 10,
      "r": 90,
      "g": 90,
      "b": 95
    },
    {
      "x": 24,
      "y": 32,
      "z": 10,
      "r": 90,
      "g": 90,
      "b": 95
    },
    {
      "x": 24,
      "y": 33,
      "z": 10,
      "r": 90,
      "g": 90,
      "b": 95
    },
    {
      "x": 25,
      "y": 31,
      "z": 10,
      "r": 90,
      "g": 90,
      "b": 95
    },
    {
      "x": 25,
      "y": 32,
      "z": 10,
      "r": 90,
      "g": 90,
      "b": 95
    },
    {
      "x": 25,
      "y": 33,
      "z": 10,
      "r": 90,
      "g": 90,
      "b": 95
    },
    {
      "x": 26,
      "y": 31,
      "z": 10,
      "r": 90,
      "g": 90,
      "b": 95
    },
    {
      "x": 26,
      "y": 32,
      "z": 10,
      "r": 90,
      "g": 90,
      "b": 95
    },
    {
      "x": 26,
      "y": 33,
      "z": 10,
      "r": 90,
      "g": 90,
      "b": 95
    },
    {
      "x": 27,
      "y": 31,
      "z": 10,
      "r": 90,
      "g": 90,
      "b": 95
    },
    {
      "x": 27,
      "y": 32,
      "z": 10,
      "r": 90,
      "g": 90,
      "b": 95
    },
    {
      "x": 28,
      "y": 31,
      "z": 10,
      "r": 90,
      "g": 90,
      "b": 95
    },
    {
      "x": 28,
      "y": 32,
      "z": 10,
      "r": 90,
      "g": 90,
      "b": 95
    },
    {
      "x": 29,
      "y": 31,
      "z": 10,
      "r": 90,
      "g": 90,
      "b": 95
    },
    {
      "x": 30,
      "y": 31,
      "z": 10,
      "r": 90,
      "g": 90,
      "b": 95
    },
    {
      "x": 1,
      "y": 29,
      "z": 7,
      "r": 90,
      "g": 90,
      "b": 95
    },
    {
      "x": 1,
      "y": 29,
      "z": 8,
      "r": 90,
      "g": 90,
      "b": 95
    },
    {
      "x": 1,
      "y": 29,
      "z": 9,
      "r": 90,
      "g": 90,
      "b": 95
    },
    {
      "x": 1,
      "y": 29,
      "z": 10,
      "r": 90,
      "g": 90,
      "b": 95
    },
    {
      "x": 1,
      "y": 29,
      "z": 11,
      "r": 90,
      "g": 90,
      "b": 95
    },
    {
      "x": 2,
      "y": 29,
      "z": 7,
      "r": 90,
      "g": 90,
      "b": 95
    },
    {
      "x": 2,
      "y": 29,
      "z": 8,
      "r": 90,
      "g": 90,
      "b": 95
    },
    {
      "x": 2,
      "y": 29,
      "z": 9,
      "r": 90,
      "g": 90,
      "b": 95
    },
    {
      "x": 2,
      "y": 30,
      "z": 7,
      "r": 90,
      "g": 90,
      "b": 95
    },
    {
      "x": 2,
      "y": 30,
      "z": 8,
      "r": 90,
      "g": 90,
      "b": 95
    },
    {
      "x": 2,
      "y": 30,
      "z": 9,
      "r": 90,
      "g": 90,
      "b": 95
    },
    {
      "x": 2,
      "y": 30,
      "z": 10,
      "r": 90,
      "g": 90,
      "b": 95
    },
    {
      "x": 2,
      "y": 30,
      "z": 11,
      "r": 90,
      "g": 90,
      "b": 95
    },
    {
      "x": 3,
      "y": 30,
      "z": 8,
      "r": 90,
      "g": 90,
      "b": 95
    },
    {
      "x": 3,
      "y": 30,
      "z": 9,
      "r": 90,
      "g": 90,
      "b": 95
    },
    {
      "x": 3,
      "y": 30,
      "z": 10,
      "r": 90,
      "g": 90,
      "b": 95
    },
    {
      "x": 4,
      "y": 30,
      "z": 8,
      "r": 90,
      "g": 90,
      "b": 95
    },
    {
      "x": 4,
      "y": 30,
      "z": 9,
      "r": 90,
      "g": 90,
      "b": 95
    },
    {
      "x": 4,
      "y": 31,
      "z": 8,
      "r": 90,
      "g": 90,
      "b": 95
    },
    {
      "x": 4,
      "y": 31,
      "z": 9,
      "r": 90,
      "g": 90,
      "b": 95
    },
    {
      "x": 4,
      "y": 31,
      "z": 10,
      "r": 90,
      "g": 90,
      "b": 95
    },
    {
      "x": 4,
      "y": 31,
      "z": 11,
      "r": 90,
      "g": 90,
      "b": 95
    },
    {
      "x": 5,
      "y": 31,
      "z": 8,
      "r": 90,
      "g": 90,
      "b": 95
    },
    {
      "x": 5,
      "y": 31,
      "z": 9,
      "r": 90,
      "g": 90,
      "b": 95
    },
    {
      "x": 5,
      "y": 31,
      "z": 10,
      "r": 90,
      "g": 90,
      "b": 95
    },
    {
      "x": 6,
      "y": 31,
      "z": 8,
      "r": 90,
      "g": 90,
      "b": 95
    },
    {
      "x": 6,
      "y": 31,
      "z": 9,
      "r": 90,
      "g": 90,
      "b": 95
    },
    {
      "x": 6,
      "y": 32,
      "z": 8,
      "r": 90,
      "g": 90,
      "b": 95
    },
    {
      "x": 6,
      "y": 32,
      "z": 9,
      "r": 90,
      "g": 90,
      "b": 95
    },
    {
      "x": 6,
      "y": 32,
      "z": 10,
      "r": 90,
      "g": 90,
      "b": 95
    },
    {
      "x": 6,
      "y": 32,
      "z": 11,
      "r": 90,
      "g": 90,
      "b": 95
    },
    {
      "x": 7,
      "y": 32,
      "z": 8,
      "r": 90,
      "g": 90,
      "b": 95
    },
    {
      "x": 7,
      "y": 32,
      "z": 9,
      "r": 90,
      "g": 90,
      "b": 95
    },
    {
      "x": 7,
      "y": 32,
      "z": 10,
      "r": 90,
      "g": 90,
      "b": 95
    },
    {
      "x": 8,
      "y": 32,
      "z": 9,
      "r": 90,
      "g": 90,
      "b": 95
    },
    {
      "x": 8,
      "y": 33,
      "z": 9,
      "r": 90,
      "g": 90,
      "b": 95
    },
    {
      "x": 8,
      "y": 33,
      "z": 10,
      "r": 90,
      "g": 90,
      "b": 95
    },
    {
      "x": 8,
      "y": 33,
      "z": 11,
      "r": 90,
      "g": 90,
      "b": 95
    },
    {
      "x": 9,
      "y": 33,
      "z": 9,
      "r": 90,
      "g": 90,
      "b": 95
    },
    {
      "x": 9,
      "y": 33,
      "z": 10,
      "r": 90,
      "g": 90,
      "b": 95
    },
    {
      "x": 9,
      "y": 33,
      "z": 11,
      "r": 90,
      "g": 90,
      "b": 95
    },
    {
      "x": 10,
      "y": 33,
      "z": 9,
      "r": 90,
      "g": 90,
      "b": 95
    },
    {
      "x": 10,
      "y": 34,
      "z": 9,
      "r": 90,
      "g": 90,
      "b": 95
    },
    {
      "x": 10,
      "y": 34,
      "z": 10,
      "r": 90,
      "g": 90,
      "b": 95
    },
    {
      "x": 10,
      "y": 34,
      "z": 11,
      "r": 90,
      "g": 90,
      "b": 95
    },
    {
      "x": 11,
      "y": 34,
      "z": 9,
      "r": 90,
      "g": 90,
      "b": 95
    },
    {
      "x": 11,
      "y": 34,
      "z": 10,
      "r": 90,
      "g": 90,
      "b": 95
    },
    {
      "x": 11,
      "y": 34,
      "z": 11,
      "r": 90,
      "g": 90,
      "b": 95
    },
    {
      "x": 13,
      "y": 35,
      "z": 10,
      "r": 90,
      "g": 90,
      "b": 95
    },
    {
      "x": 13,
      "y": 35,
      "z": 11,
      "r": 90,
      "g": 90,
      "b": 95
    },
    {
      "x": 14,
      "y": 35,
      "z": 10,
      "r": 90,
      "g": 90,
      "b": 95
    },
    {
      "x": 15,
      "y": 36,
      "z": 10,
      "r": 90,
      "g": 90,
      "b": 95
    },
    {
      "x": 15,
      "y": 36,
      "z": 11,
      "r": 90,
      "g": 90,
      "b": 95
    },
    {
      "x": 16,
      "y": 36,
      "z": 10,
      "r": 90,
      "g": 90,
      "b": 95
    },
    {
      "x": 17,
      "y": 37,
      "z": 11,
      "r": 90,
      "g": 90,
      "b": 95
    },
    {
      "x": 18,
      "y": 37,
      "z": 11,
      "r": 90,
      "g": 90,
      "b": 95
    },
    {
      "x": 19,
      "y": 38,
      "z": 11,
      "r": 90,
      "g": 90,
      "b": 95
    },
    {
      "x": 3,
      "y": 30,
      "z": 7,
      "r": 90,
      "g": 90,
      "b": 95
    },
    {
      "x": 4,
      "y": 30,
      "z": 7,
      "r": 90,
      "g": 90,
      "b": 95
    },
    {
      "x": 4,
      "y": 31,
      "z": 7,
      "r": 90,
      "g": 90,
      "b": 95
    },
    {
      "x": 5,
      "y": 31,
      "z": 7,
      "r": 90,
      "g": 90,
      "b": 95
    },
    {
      "x": 6,
      "y": 31,
      "z": 7,
      "r": 90,
      "g": 90,
      "b": 95
    },
    {
      "x": 6,
      "y": 32,
      "z": 7,
      "r": 90,
      "g": 90,
      "b": 95
    },
    {
      "x": 7,
      "y": 32,
      "z": 7,
      "r": 90,
      "g": 90,
      "b": 95
    },
    {
      "x": 8,
      "y": 32,
      "z": 7,
      "r": 90,
      "g": 90,
      "b": 95
    },
    {
      "x": 8,
      "y": 32,
      "z": 8,
      "r": 90,
      "g": 90,
      "b": 95
    },
    {
      "x": 8,
      "y": 33,
      "z": 7,
      "r": 90,
      "g": 90,
      "b": 95
    },
    {
      "x": 8,
      "y": 33,
      "z": 8,
      "r": 90,
      "g": 90,
      "b": 95
    },
    {
      "x": 9,
      "y": 33,
      "z": 7,
      "r": 90,
      "g": 90,
      "b": 95
    },
    {
      "x": 9,
      "y": 33,
      "z": 8,
      "r": 90,
      "g": 90,
      "b": 95
    },
    {
      "x": 10,
      "y": 33,
      "z": 7,
      "r": 90,
      "g": 90,
      "b": 95
    },
    {
      "x": 10,
      "y": 33,
      "z": 8,
      "r": 90,
      "g": 90,
      "b": 95
    },
    {
      "x": 10,
      "y": 34,
      "z": 7,
      "r": 90,
      "g": 90,
      "b": 95
    },
    {
      "x": 10,
      "y": 34,
      "z": 8,
      "r": 90,
      "g": 90,
      "b": 95
    },
    {
      "x": 11,
      "y": 34,
      "z": 7,
      "r": 90,
      "g": 90,
      "b": 95
    },
    {
      "x": 11,
      "y": 34,
      "z": 8,
      "r": 90,
      "g": 90,
      "b": 95
    },
    {
      "x": 12,
      "y": 34,
      "z": 7,
      "r": 90,
      "g": 90,
      "b": 95
    },
    {
      "x": 12,
      "y": 34,
      "z": 8,
      "r": 90,
      "g": 90,
      "b": 95
    },
    {
      "x": 12,
      "y": 34,
      "z": 9,
      "r": 90,
      "g": 90,
      "b": 95
    },
    {
      "x": 13,
      "y": 34,
      "z": 7,
      "r": 90,
      "g": 90,
      "b": 95
    },
    {
      "x": 13,
      "y": 34,
      "z": 8,
      "r": 90,
      "g": 90,
      "b": 95
    },
    {
      "x": 13,
      "y": 34,
      "z": 9,
      "r": 90,
      "g": 90,
      "b": 95
    },
    {
      "x": 13,
      "y": 35,
      "z": 7,
      "r": 90,
      "g": 90,
      "b": 95
    },
    {
      "x": 13,
      "y": 35,
      "z": 8,
      "r": 90,
      "g": 90,
      "b": 95
    },
    {
      "x": 13,
      "y": 35,
      "z": 9,
      "r": 90,
      "g": 90,
      "b": 95
    },
    {
      "x": 14,
      "y": 35,
      "z": 7,
      "r": 90,
      "g": 90,
      "b": 95
    },
    {
      "x": 14,
      "y": 35,
      "z": 8,
      "r": 90,
      "g": 90,
      "b": 95
    },
    {
      "x": 14,
      "y": 35,
      "z": 9,
      "r": 90,
      "g": 90,
      "b": 95
    },
    {
      "x": 15,
      "y": 35,
      "z": 7,
      "r": 90,
      "g": 90,
      "b": 95
    },
    {
      "x": 15,
      "y": 35,
      "z": 8,
      "r": 90,
      "g": 90,
      "b": 95
    },
    {
      "x": 15,
      "y": 35,
      "z": 9,
      "r": 90,
      "g": 90,
      "b": 95
    },
    {
      "x": 15,
      "y": 36,
      "z": 7,
      "r": 90,
      "g": 90,
      "b": 95
    },
    {
      "x": 15,
      "y": 36,
      "z": 8,
      "r": 90,
      "g": 90,
      "b": 95
    },
    {
      "x": 15,
      "y": 36,
      "z": 9,
      "r": 90,
      "g": 90,
      "b": 95
    },
    {
      "x": 16,
      "y": 36,
      "z": 7,
      "r": 90,
      "g": 90,
      "b": 95
    },
    {
      "x": 16,
      "y": 36,
      "z": 8,
      "r": 90,
      "g": 90,
      "b": 95
    },
    {
      "x": 16,
      "y": 36,
      "z": 9,
      "r": 90,
      "g": 90,
      "b": 95
    },
    {
      "x": 17,
      "y": 36,
      "z": 7,
      "r": 90,
      "g": 90,
      "b": 95
    },
    {
      "x": 17,
      "y": 36,
      "z": 8,
      "r": 90,
      "g": 90,
      "b": 95
    },
    {
      "x": 17,
      "y": 36,
      "z": 9,
      "r": 90,
      "g": 90,
      "b": 95
    },
    {
      "x": 17,
      "y": 37,
      "z": 7,
      "r": 90,
      "g": 90,
      "b": 95
    },
    {
      "x": 17,
      "y": 37,
      "z": 8,
      "r": 90,
      "g": 90,
      "b": 95
    },
    {
      "x": 17,
      "y": 37,
      "z": 9,
      "r": 90,
      "g": 90,
      "b": 95
    },
    {
      "x": 17,
      "y": 37,
      "z": 10,
      "r": 90,
      "g": 90,
      "b": 95
    },
    {
      "x": 18,
      "y": 37,
      "z": 7,
      "r": 90,
      "g": 90,
      "b": 95
    },
    {
      "x": 18,
      "y": 37,
      "z": 8,
      "r": 90,
      "g": 90,
      "b": 95
    },
    {
      "x": 18,
      "y": 37,
      "z": 9,
      "r": 90,
      "g": 90,
      "b": 95
    },
    {
      "x": 18,
      "y": 37,
      "z": 10,
      "r": 90,
      "g": 90,
      "b": 95
    },
    {
      "x": 19,
      "y": 37,
      "z": 7,
      "r": 90,
      "g": 90,
      "b": 95
    },
    {
      "x": 19,
      "y": 37,
      "z": 8,
      "r": 90,
      "g": 90,
      "b": 95
    },
    {
      "x": 19,
      "y": 37,
      "z": 9,
      "r": 90,
      "g": 90,
      "b": 95
    },
    {
      "x": 19,
      "y": 38,
      "z": 7,
      "r": 90,
      "g": 90,
      "b": 95
    },
    {
      "x": 19,
      "y": 38,
      "z": 8,
      "r": 90,
      "g": 90,
      "b": 95
    },
    {
      "x": 19,
      "y": 38,
      "z": 9,
      "r": 90,
      "g": 90,
      "b": 95
    },
    {
      "x": 19,
      "y": 38,
      "z": 10,
      "r": 90,
      "g": 90,
      "b": 95
    },
    {
      "x": 20,
      "y": 37,
      "z": 7,
      "r": 90,
      "g": 90,
      "b": 95
    },
    {
      "x": 20,
      "y": 37,
      "z": 8,
      "r": 90,
      "g": 90,
      "b": 95
    },
    {
      "x": 20,
      "y": 37,
      "z": 9,
      "r": 90,
      "g": 90,
      "b": 95
    },
    {
      "x": 20,
      "y": 38,
      "z": 7,
      "r": 90,
      "g": 90,
      "b": 95
    },
    {
      "x": 20,
      "y": 38,
      "z": 8,
      "r": 90,
      "g": 90,
      "b": 95
    },
    {
      "x": 20,
      "y": 38,
      "z": 9,
      "r": 90,
      "g": 90,
      "b": 95
    },
    {
      "x": 20,
      "y": 38,
      "z": 10,
      "r": 90,
      "g": 90,
      "b": 95
    },
    {
      "x": 20,
      "y": 38,
      "z": 11,
      "r": 90,
      "g": 90,
      "b": 95
    },
    {
      "x": 21,
      "y": 37,
      "z": 7,
      "r": 90,
      "g": 90,
      "b": 95
    },
    {
      "x": 21,
      "y": 37,
      "z": 8,
      "r": 90,
      "g": 90,
      "b": 95
    },
    {
      "x": 21,
      "y": 37,
      "z": 9,
      "r": 90,
      "g": 90,
      "b": 95
    },
    {
      "x": 21,
      "y": 37,
      "z": 10,
      "r": 90,
      "g": 90,
      "b": 95
    },
    {
      "x": 22,
      "y": 36,
      "z": 7,
      "r": 90,
      "g": 90,
      "b": 95
    },
    {
      "x": 22,
      "y": 36,
      "z": 8,
      "r": 90,
      "g": 90,
      "b": 95
    },
    {
      "x": 22,
      "y": 36,
      "z": 9,
      "r": 90,
      "g": 90,
      "b": 95
    },
    {
      "x": 22,
      "y": 37,
      "z": 7,
      "r": 90,
      "g": 90,
      "b": 95
    },
    {
      "x": 22,
      "y": 37,
      "z": 8,
      "r": 90,
      "g": 90,
      "b": 95
    },
    {
      "x": 22,
      "y": 37,
      "z": 9,
      "r": 90,
      "g": 90,
      "b": 95
    },
    {
      "x": 22,
      "y": 37,
      "z": 10,
      "r": 90,
      "g": 90,
      "b": 95
    },
    {
      "x": 23,
      "y": 36,
      "z": 7,
      "r": 90,
      "g": 90,
      "b": 95
    },
    {
      "x": 23,
      "y": 36,
      "z": 8,
      "r": 90,
      "g": 90,
      "b": 95
    },
    {
      "x": 23,
      "y": 36,
      "z": 9,
      "r": 90,
      "g": 90,
      "b": 95
    },
    {
      "x": 23,
      "y": 36,
      "z": 10,
      "r": 90,
      "g": 90,
      "b": 95
    },
    {
      "x": 24,
      "y": 35,
      "z": 7,
      "r": 90,
      "g": 90,
      "b": 95
    },
    {
      "x": 24,
      "y": 35,
      "z": 8,
      "r": 90,
      "g": 90,
      "b": 95
    },
    {
      "x": 24,
      "y": 35,
      "z": 9,
      "r": 90,
      "g": 90,
      "b": 95
    },
    {
      "x": 24,
      "y": 36,
      "z": 7,
      "r": 90,
      "g": 90,
      "b": 95
    },
    {
      "x": 24,
      "y": 36,
      "z": 8,
      "r": 90,
      "g": 90,
      "b": 95
    },
    {
      "x": 24,
      "y": 36,
      "z": 9,
      "r": 90,
      "g": 90,
      "b": 95
    },
    {
      "x": 24,
      "y": 36,
      "z": 10,
      "r": 90,
      "g": 90,
      "b": 95
    },
    {
      "x": 25,
      "y": 35,
      "z": 7,
      "r": 90,
      "g": 90,
      "b": 95
    },
    {
      "x": 25,
      "y": 35,
      "z": 8,
      "r": 90,
      "g": 90,
      "b": 95
    },
    {
      "x": 25,
      "y": 35,
      "z": 9,
      "r": 90,
      "g": 90,
      "b": 95
    },
    {
      "x": 26,
      "y": 34,
      "z": 7,
      "r": 90,
      "g": 90,
      "b": 95
    },
    {
      "x": 26,
      "y": 34,
      "z": 8,
      "r": 90,
      "g": 90,
      "b": 95
    },
    {
      "x": 26,
      "y": 34,
      "z": 9,
      "r": 90,
      "g": 90,
      "b": 95
    },
    {
      "x": 26,
      "y": 35,
      "z": 7,
      "r": 90,
      "g": 90,
      "b": 95
    },
    {
      "x": 26,
      "y": 35,
      "z": 8,
      "r": 90,
      "g": 90,
      "b": 95
    },
    {
      "x": 26,
      "y": 35,
      "z": 9,
      "r": 90,
      "g": 90,
      "b": 95
    },
    {
      "x": 26,
      "y": 35,
      "z": 10,
      "r": 90,
      "g": 90,
      "b": 95
    },
    {
      "x": 27,
      "y": 34,
      "z": 7,
      "r": 90,
      "g": 90,
      "b": 95
    },
    {
      "x": 27,
      "y": 34,
      "z": 8,
      "r": 90,
      "g": 90,
      "b": 95
    },
    {
      "x": 27,
      "y": 34,
      "z": 9,
      "r": 90,
      "g": 90,
      "b": 95
    },
    {
      "x": 28,
      "y": 34,
      "z": 7,
      "r": 90,
      "g": 90,
      "b": 95
    },
    {
      "x": 28,
      "y": 34,
      "z": 8,
      "r": 90,
      "g": 90,
      "b": 95
    },
    {
      "x": 28,
      "y": 34,
      "z": 9,
      "r": 90,
      "g": 90,
      "b": 95
    },
    {
      "x": 28,
      "y": 34,
      "z": 10,
      "r": 90,
      "g": 90,
      "b": 95
    },
    {
      "x": 29,
      "y": 33,
      "z": 7,
      "r": 90,
      "g": 90,
      "b": 95
    },
    {
      "x": 29,
      "y": 33,
      "z": 8,
      "r": 90,
      "g": 90,
      "b": 95
    },
    {
      "x": 29,
      "y": 33,
      "z": 9,
      "r": 90,
      "g": 90,
      "b": 95
    },
    {
      "x": 29,
      "y": 34,
      "z": 7,
      "r": 90,
      "g": 90,
      "b": 95
    },
    {
      "x": 29,
      "y": 34,
      "z": 8,
      "r": 90,
      "g": 90,
      "b": 95
    },
    {
      "x": 29,
      "y": 34,
      "z": 9,
      "r": 90,
      "g": 90,
      "b": 95
    },
    {
      "x": 30,
      "y": 33,
      "z": 7,
      "r": 90,
      "g": 90,
      "b": 95
    },
    {
      "x": 30,
      "y": 33,
      "z": 8,
      "r": 90,
      "g": 90,
      "b": 95
    },
    {
      "x": 30,
      "y": 33,
      "z": 9,
      "r": 90,
      "g": 90,
      "b": 95
    },
    {
      "x": 31,
      "y": 32,
      "z": 7,
      "r": 90,
      "g": 90,
      "b": 95
    },
    {
      "x": 31,
      "y": 32,
      "z": 8,
      "r": 90,
      "g": 90,
      "b": 95
    },
    {
      "x": 31,
      "y": 32,
      "z": 9,
      "r": 90,
      "g": 90,
      "b": 95
    },
    {
      "x": 31,
      "y": 33,
      "z": 7,
      "r": 90,
      "g": 90,
      "b": 95
    },
    {
      "x": 31,
      "y": 33,
      "z": 8,
      "r": 90,
      "g": 90,
      "b": 95
    },
    {
      "x": 31,
      "y": 33,
      "z": 9,
      "r": 90,
      "g": 90,
      "b": 95
    },
    {
      "x": 32,
      "y": 32,
      "z": 7,
      "r": 90,
      "g": 90,
      "b": 95
    },
    {
      "x": 32,
      "y": 32,
      "z": 8,
      "r": 90,
      "g": 90,
      "b": 95
    },
    {
      "x": 32,
      "y": 32,
      "z": 9,
      "r": 90,
      "g": 90,
      "b": 95
    },
    {
      "x": 33,
      "y": 31,
      "z": 7,
      "r": 90,
      "g": 90,
      "b": 95
    },
    {
      "x": 33,
      "y": 31,
      "z": 8,
      "r": 90,
      "g": 90,
      "b": 95
    },
    {
      "x": 33,
      "y": 32,
      "z": 7,
      "r": 90,
      "g": 90,
      "b": 95
    },
    {
      "x": 33,
      "y": 32,
      "z": 8,
      "r": 90,
      "g": 90,
      "b": 95
    },
    {
      "x": 34,
      "y": 31,
      "z": 7,
      "r": 90,
      "g": 90,
      "b": 95
    },
    {
      "x": 34,
      "y": 31,
      "z": 8,
      "r": 90,
      "g": 90,
      "b": 95
    },
    {
      "x": 35,
      "y": 30,
      "z": 7,
      "r": 90,
      "g": 90,
      "b": 95
    },
    {
      "x": 35,
      "y": 30,
      "z": 8,
      "r": 90,
      "g": 90,
      "b": 95
    },
    {
      "x": 35,
      "y": 31,
      "z": 7,
      "r": 90,
      "g": 90,
      "b": 95
    },
    {
      "x": 35,
      "y": 31,
      "z": 8,
      "r": 90,
      "g": 90,
      "b": 95
    },
    {
      "x": 36,
      "y": 30,
      "z": 7,
      "r": 90,
      "g": 90,
      "b": 95
    },
    {
      "x": 36,
      "y": 30,
      "z": 8,
      "r": 90,
      "g": 90,
      "b": 95
    },
    {
      "x": 37,
      "y": 29,
      "z": 7,
      "r": 90,
      "g": 90,
      "b": 95
    },
    {
      "x": 37,
      "y": 30,
      "z": 7,
      "r": 90,
      "g": 90,
      "b": 95
    },
    {
      "x": 37,
      "y": 30,
      "z": 8,
      "r": 90,
      "g": 90,
      "b": 95
    },
    {
      "x": 29,
      "y": 34,
      "z": 10,
      "r": 90,
      "g": 90,
      "b": 95
    },
    {
      "x": 29,
      "y": 34,
      "z": 11,
      "r": 90,
      "g": 90,
      "b": 95
    },
    {
      "x": 30,
      "y": 33,
      "z": 10,
      "r": 90,
      "g": 90,
      "b": 95
    },
    {
      "x": 31,
      "y": 33,
      "z": 10,
      "r": 90,
      "g": 90,
      "b": 95
    },
    {
      "x": 32,
      "y": 32,
      "z": 10,
      "r": 90,
      "g": 90,
      "b": 95
    },
    {
      "x": 33,
      "y": 31,
      "z": 9,
      "r": 90,
      "g": 90,
      "b": 95
    },
    {
      "x": 33,
      "y": 32,
      "z": 9,
      "r": 90,
      "g": 90,
      "b": 95
    },
    {
      "x": 33,
      "y": 32,
      "z": 10,
      "r": 90,
      "g": 90,
      "b": 95
    },
    {
      "x": 34,
      "y": 31,
      "z": 9,
      "r": 90,
      "g": 90,
      "b": 95
    },
    {
      "x": 34,
      "y": 31,
      "z": 10,
      "r": 90,
      "g": 90,
      "b": 95
    },
    {
      "x": 35,
      "y": 30,
      "z": 9,
      "r": 90,
      "g": 90,
      "b": 95
    },
    {
      "x": 35,
      "y": 31,
      "z": 9,
      "r": 90,
      "g": 90,
      "b": 95
    },
    {
      "x": 35,
      "y": 31,
      "z": 10,
      "r": 90,
      "g": 90,
      "b": 95
    },
    {
      "x": 36,
      "y": 30,
      "z": 9,
      "r": 90,
      "g": 90,
      "b": 95
    },
    {
      "x": 37,
      "y": 29,
      "z": 8,
      "r": 90,
      "g": 90,
      "b": 95
    },
    {
      "x": 37,
      "y": 29,
      "z": 9,
      "r": 90,
      "g": 90,
      "b": 95
    },
    {
      "x": 37,
      "y": 30,
      "z": 9,
      "r": 90,
      "g": 90,
      "b": 95
    },
    {
      "x": 37,
      "y": 30,
      "z": 10,
      "r": 90,
      "g": 90,
      "b": 95
    },
    {
      "x": 1,
      "y": 28,
      "z": 3,
      "r": 90,
      "g": 90,
      "b": 95
    },
    {
      "x": 1,
      "y": 28,
      "z": 4,
      "r": 90,
      "g": 90,
      "b": 95
    },
    {
      "x": 1,
      "y": 28,
      "z": 5,
      "r": 90,
      "g": 90,
      "b": 95
    },
    {
      "x": 1,
      "y": 28,
      "z": 6,
      "r": 90,
      "g": 90,
      "b": 95
    },
    {
      "x": 2,
      "y": 28,
      "z": 3,
      "r": 90,
      "g": 90,
      "b": 95
    },
    {
      "x": 2,
      "y": 28,
      "z": 4,
      "r": 90,
      "g": 90,
      "b": 95
    },
    {
      "x": 2,
      "y": 28,
      "z": 5,
      "r": 90,
      "g": 90,
      "b": 95
    },
    {
      "x": 2,
      "y": 28,
      "z": 6,
      "r": 90,
      "g": 90,
      "b": 95
    },
    {
      "x": 3,
      "y": 28,
      "z": 4,
      "r": 90,
      "g": 90,
      "b": 95
    },
    {
      "x": 3,
      "y": 28,
      "z": 5,
      "r": 90,
      "g": 90,
      "b": 95
    },
    {
      "x": 3,
      "y": 28,
      "z": 6,
      "r": 90,
      "g": 90,
      "b": 95
    },
    {
      "x": 4,
      "y": 28,
      "z": 4,
      "r": 90,
      "g": 90,
      "b": 95
    },
    {
      "x": 4,
      "y": 28,
      "z": 5,
      "r": 90,
      "g": 90,
      "b": 95
    },
    {
      "x": 4,
      "y": 28,
      "z": 6,
      "r": 90,
      "g": 90,
      "b": 95
    },
    {
      "x": 5,
      "y": 28,
      "z": 4,
      "r": 90,
      "g": 90,
      "b": 95
    },
    {
      "x": 5,
      "y": 28,
      "z": 5,
      "r": 90,
      "g": 90,
      "b": 95
    },
    {
      "x": 5,
      "y": 28,
      "z": 6,
      "r": 90,
      "g": 90,
      "b": 95
    },
    {
      "x": 6,
      "y": 28,
      "z": 4,
      "r": 90,
      "g": 90,
      "b": 95
    },
    {
      "x": 6,
      "y": 28,
      "z": 5,
      "r": 90,
      "g": 90,
      "b": 95
    },
    {
      "x": 6,
      "y": 28,
      "z": 6,
      "r": 90,
      "g": 90,
      "b": 95
    },
    {
      "x": 7,
      "y": 28,
      "z": 4,
      "r": 90,
      "g": 90,
      "b": 95
    },
    {
      "x": 7,
      "y": 28,
      "z": 5,
      "r": 90,
      "g": 90,
      "b": 95
    },
    {
      "x": 7,
      "y": 28,
      "z": 6,
      "r": 90,
      "g": 90,
      "b": 95
    },
    {
      "x": 8,
      "y": 28,
      "z": 5,
      "r": 90,
      "g": 90,
      "b": 95
    },
    {
      "x": 8,
      "y": 28,
      "z": 6,
      "r": 90,
      "g": 90,
      "b": 95
    },
    {
      "x": 9,
      "y": 28,
      "z": 5,
      "r": 90,
      "g": 90,
      "b": 95
    },
    {
      "x": 9,
      "y": 28,
      "z": 6,
      "r": 90,
      "g": 90,
      "b": 95
    },
    {
      "x": 10,
      "y": 28,
      "z": 5,
      "r": 90,
      "g": 90,
      "b": 95
    },
    {
      "x": 10,
      "y": 28,
      "z": 6,
      "r": 90,
      "g": 90,
      "b": 95
    },
    {
      "x": 11,
      "y": 28,
      "z": 5,
      "r": 90,
      "g": 90,
      "b": 95
    },
    {
      "x": 11,
      "y": 28,
      "z": 6,
      "r": 90,
      "g": 90,
      "b": 95
    },
    {
      "x": 12,
      "y": 28,
      "z": 6,
      "r": 90,
      "g": 90,
      "b": 95
    },
    {
      "x": 13,
      "y": 28,
      "z": 6,
      "r": 90,
      "g": 90,
      "b": 95
    },
    {
      "x": 14,
      "y": 28,
      "z": 6,
      "r": 90,
      "g": 90,
      "b": 95
    },
    {
      "x": 15,
      "y": 28,
      "z": 6,
      "r": 90,
      "g": 90,
      "b": 95
    },
    {
      "x": 16,
      "y": 28,
      "z": 6,
      "r": 90,
      "g": 90,
      "b": 95
    },
    {
      "x": 3,
      "y": 28,
      "z": 3,
      "r": 90,
      "g": 90,
      "b": 95
    },
    {
      "x": 4,
      "y": 28,
      "z": 3,
      "r": 90,
      "g": 90,
      "b": 95
    },
    {
      "x": 5,
      "y": 28,
      "z": 3,
      "r": 90,
      "g": 90,
      "b": 95
    },
    {
      "x": 6,
      "y": 28,
      "z": 3,
      "r": 90,
      "g": 90,
      "b": 95
    },
    {
      "x": 7,
      "y": 28,
      "z": 3,
      "r": 90,
      "g": 90,
      "b": 95
    },
    {
      "x": 8,
      "y": 28,
      "z": 3,
      "r": 90,
      "g": 90,
      "b": 95
    },
    {
      "x": 8,
      "y": 28,
      "z": 4,
      "r": 90,
      "g": 90,
      "b": 95
    },
    {
      "x": 9,
      "y": 28,
      "z": 3,
      "r": 90,
      "g": 90,
      "b": 95
    },
    {
      "x": 9,
      "y": 28,
      "z": 4,
      "r": 90,
      "g": 90,
      "b": 95
    },
    {
      "x": 10,
      "y": 28,
      "z": 3,
      "r": 90,
      "g": 90,
      "b": 95
    },
    {
      "x": 10,
      "y": 28,
      "z": 4,
      "r": 90,
      "g": 90,
      "b": 95
    },
    {
      "x": 11,
      "y": 28,
      "z": 3,
      "r": 90,
      "g": 90,
      "b": 95
    },
    {
      "x": 11,
      "y": 28,
      "z": 4,
      "r": 90,
      "g": 90,
      "b": 95
    },
    {
      "x": 12,
      "y": 28,
      "z": 3,
      "r": 90,
      "g": 90,
      "b": 95
    },
    {
      "x": 12,
      "y": 28,
      "z": 4,
      "r": 90,
      "g": 90,
      "b": 95
    },
    {
      "x": 12,
      "y": 28,
      "z": 5,
      "r": 90,
      "g": 90,
      "b": 95
    },
    {
      "x": 13,
      "y": 28,
      "z": 3,
      "r": 90,
      "g": 90,
      "b": 95
    },
    {
      "x": 13,
      "y": 28,
      "z": 4,
      "r": 90,
      "g": 90,
      "b": 95
    },
    {
      "x": 13,
      "y": 28,
      "z": 5,
      "r": 90,
      "g": 90,
      "b": 95
    },
    {
      "x": 14,
      "y": 28,
      "z": 3,
      "r": 90,
      "g": 90,
      "b": 95
    },
    {
      "x": 14,
      "y": 28,
      "z": 4,
      "r": 90,
      "g": 90,
      "b": 95
    },
    {
      "x": 14,
      "y": 28,
      "z": 5,
      "r": 90,
      "g": 90,
      "b": 95
    },
    {
      "x": 15,
      "y": 28,
      "z": 3,
      "r": 90,
      "g": 90,
      "b": 95
    },
    {
      "x": 15,
      "y": 28,
      "z": 4,
      "r": 90,
      "g": 90,
      "b": 95
    },
    {
      "x": 15,
      "y": 28,
      "z": 5,
      "r": 90,
      "g": 90,
      "b": 95
    },
    {
      "x": 16,
      "y": 28,
      "z": 3,
      "r": 90,
      "g": 90,
      "b": 95
    },
    {
      "x": 16,
      "y": 28,
      "z": 4,
      "r": 90,
      "g": 90,
      "b": 95
    },
    {
      "x": 16,
      "y": 28,
      "z": 5,
      "r": 90,
      "g": 90,
      "b": 95
    },
    {
      "x": 17,
      "y": 28,
      "z": 3,
      "r": 90,
      "g": 90,
      "b": 95
    },
    {
      "x": 17,
      "y": 28,
      "z": 4,
      "r": 90,
      "g": 90,
      "b": 95
    },
    {
      "x": 17,
      "y": 28,
      "z": 5,
      "r": 90,
      "g": 90,
      "b": 95
    },
    {
      "x": 17,
      "y": 28,
      "z": 6,
      "r": 90,
      "g": 90,
      "b": 95
    },
    {
      "x": 18,
      "y": 28,
      "z": 3,
      "r": 90,
      "g": 90,
      "b": 95
    },
    {
      "x": 18,
      "y": 28,
      "z": 4,
      "r": 90,
      "g": 90,
      "b": 95
    },
    {
      "x": 18,
      "y": 28,
      "z": 5,
      "r": 90,
      "g": 90,
      "b": 95
    },
    {
      "x": 18,
      "y": 28,
      "z": 6,
      "r": 90,
      "g": 90,
      "b": 95
    },
    {
      "x": 19,
      "y": 28,
      "z": 3,
      "r": 90,
      "g": 90,
      "b": 95
    },
    {
      "x": 19,
      "y": 28,
      "z": 4,
      "r": 90,
      "g": 90,
      "b": 95
    },
    {
      "x": 19,
      "y": 28,
      "z": 5,
      "r": 90,
      "g": 90,
      "b": 95
    },
    {
      "x": 19,
      "y": 28,
      "z": 6,
      "r": 90,
      "g": 90,
      "b": 95
    },
    {
      "x": 6,
      "y": 30,
      "z": 11,
      "r": 90,
      "g": 90,
      "b": 95
    },
    {
      "x": 15,
      "y": 34,
      "z": 11,
      "r": 90,
      "g": 90,
      "b": 95
    },
    {
      "x": 19,
      "y": 31,
      "z": 10,
      "r": 90,
      "g": 90,
      "b": 95
    },
    {
      "x": 19,
      "y": 32,
      "z": 10,
      "r": 90,
      "g": 90,
      "b": 95
    },
    {
      "x": 19,
      "y": 33,
      "z": 10,
      "r": 90,
      "g": 90,
      "b": 95
    },
    {
      "x": 19,
      "y": 34,
      "z": 10,
      "r": 90,
      "g": 90,
      "b": 95
    },
    {
      "x": 19,
      "y": 35,
      "z": 10,
      "r": 90,
      "g": 90,
      "b": 95
    },
    {
      "x": 20,
      "y": 28,
      "z": 3,
      "r": 90,
      "g": 90,
      "b": 95
    },
    {
      "x": 20,
      "y": 28,
      "z": 4,
      "r": 90,
      "g": 90,
      "b": 95
    },
    {
      "x": 20,
      "y": 28,
      "z": 5,
      "r": 90,
      "g": 90,
      "b": 95
    },
    {
      "x": 20,
      "y": 28,
      "z": 6,
      "r": 90,
      "g": 90,
      "b": 95
    },
    {
      "x": 21,
      "y": 28,
      "z": 3,
      "r": 90,
      "g": 90,
      "b": 95
    },
    {
      "x": 21,
      "y": 28,
      "z": 4,
      "r": 90,
      "g": 90,
      "b": 95
    },
    {
      "x": 21,
      "y": 28,
      "z": 5,
      "r": 90,
      "g": 90,
      "b": 95
    },
    {
      "x": 21,
      "y": 28,
      "z": 6,
      "r": 90,
      "g": 90,
      "b": 95
    },
    {
      "x": 22,
      "y": 28,
      "z": 3,
      "r": 90,
      "g": 90,
      "b": 95
    },
    {
      "x": 22,
      "y": 28,
      "z": 4,
      "r": 90,
      "g": 90,
      "b": 95
    },
    {
      "x": 22,
      "y": 28,
      "z": 5,
      "r": 90,
      "g": 90,
      "b": 95
    },
    {
      "x": 22,
      "y": 28,
      "z": 6,
      "r": 90,
      "g": 90,
      "b": 95
    },
    {
      "x": 23,
      "y": 28,
      "z": 3,
      "r": 90,
      "g": 90,
      "b": 95
    },
    {
      "x": 23,
      "y": 28,
      "z": 4,
      "r": 90,
      "g": 90,
      "b": 95
    },
    {
      "x": 23,
      "y": 28,
      "z": 5,
      "r": 90,
      "g": 90,
      "b": 95
    },
    {
      "x": 23,
      "y": 28,
      "z": 6,
      "r": 90,
      "g": 90,
      "b": 95
    },
    {
      "x": 24,
      "y": 28,
      "z": 3,
      "r": 90,
      "g": 90,
      "b": 95
    },
    {
      "x": 24,
      "y": 28,
      "z": 4,
      "r": 90,
      "g": 90,
      "b": 95
    },
    {
      "x": 24,
      "y": 28,
      "z": 5,
      "r": 90,
      "g": 90,
      "b": 95
    },
    {
      "x": 24,
      "y": 28,
      "z": 6,
      "r": 90,
      "g": 90,
      "b": 95
    },
    {
      "x": 25,
      "y": 28,
      "z": 3,
      "r": 90,
      "g": 90,
      "b": 95
    },
    {
      "x": 25,
      "y": 28,
      "z": 4,
      "r": 90,
      "g": 90,
      "b": 95
    },
    {
      "x": 25,
      "y": 28,
      "z": 5,
      "r": 90,
      "g": 90,
      "b": 95
    },
    {
      "x": 25,
      "y": 28,
      "z": 6,
      "r": 90,
      "g": 90,
      "b": 95
    },
    {
      "x": 26,
      "y": 28,
      "z": 3,
      "r": 90,
      "g": 90,
      "b": 95
    },
    {
      "x": 26,
      "y": 28,
      "z": 4,
      "r": 90,
      "g": 90,
      "b": 95
    },
    {
      "x": 26,
      "y": 28,
      "z": 5,
      "r": 90,
      "g": 90,
      "b": 95
    },
    {
      "x": 26,
      "y": 28,
      "z": 6,
      "r": 90,
      "g": 90,
      "b": 95
    },
    {
      "x": 27,
      "y": 28,
      "z": 3,
      "r": 90,
      "g": 90,
      "b": 95
    },
    {
      "x": 27,
      "y": 28,
      "z": 4,
      "r": 90,
      "g": 90,
      "b": 95
    },
    {
      "x": 27,
      "y": 28,
      "z": 5,
      "r": 90,
      "g": 90,
      "b": 95
    },
    {
      "x": 27,
      "y": 28,
      "z": 6,
      "r": 90,
      "g": 90,
      "b": 95
    },
    {
      "x": 28,
      "y": 28,
      "z": 3,
      "r": 90,
      "g": 90,
      "b": 95
    },
    {
      "x": 28,
      "y": 28,
      "z": 4,
      "r": 90,
      "g": 90,
      "b": 95
    },
    {
      "x": 28,
      "y": 28,
      "z": 5,
      "r": 90,
      "g": 90,
      "b": 95
    },
    {
      "x": 28,
      "y": 28,
      "z": 6,
      "r": 90,
      "g": 90,
      "b": 95
    },
    {
      "x": 29,
      "y": 28,
      "z": 3,
      "r": 90,
      "g": 90,
      "b": 95
    },
    {
      "x": 29,
      "y": 28,
      "z": 4,
      "r": 90,
      "g": 90,
      "b": 95
    },
    {
      "x": 29,
      "y": 28,
      "z": 5,
      "r": 90,
      "g": 90,
      "b": 95
    },
    {
      "x": 30,
      "y": 28,
      "z": 3,
      "r": 90,
      "g": 90,
      "b": 95
    },
    {
      "x": 30,
      "y": 28,
      "z": 4,
      "r": 90,
      "g": 90,
      "b": 95
    },
    {
      "x": 30,
      "y": 28,
      "z": 5,
      "r": 90,
      "g": 90,
      "b": 95
    },
    {
      "x": 31,
      "y": 28,
      "z": 3,
      "r": 90,
      "g": 90,
      "b": 95
    },
    {
      "x": 31,
      "y": 28,
      "z": 4,
      "r": 90,
      "g": 90,
      "b": 95
    },
    {
      "x": 31,
      "y": 28,
      "z": 5,
      "r": 90,
      "g": 90,
      "b": 95
    },
    {
      "x": 32,
      "y": 28,
      "z": 3,
      "r": 90,
      "g": 90,
      "b": 95
    },
    {
      "x": 32,
      "y": 28,
      "z": 4,
      "r": 90,
      "g": 90,
      "b": 95
    },
    {
      "x": 32,
      "y": 28,
      "z": 5,
      "r": 90,
      "g": 90,
      "b": 95
    },
    {
      "x": 33,
      "y": 28,
      "z": 3,
      "r": 90,
      "g": 90,
      "b": 95
    },
    {
      "x": 33,
      "y": 28,
      "z": 4,
      "r": 90,
      "g": 90,
      "b": 95
    },
    {
      "x": 34,
      "y": 28,
      "z": 3,
      "r": 90,
      "g": 90,
      "b": 95
    },
    {
      "x": 34,
      "y": 28,
      "z": 4,
      "r": 90,
      "g": 90,
      "b": 95
    },
    {
      "x": 35,
      "y": 28,
      "z": 3,
      "r": 90,
      "g": 90,
      "b": 95
    },
    {
      "x": 35,
      "y": 28,
      "z": 4,
      "r": 90,
      "g": 90,
      "b": 95
    },
    {
      "x": 36,
      "y": 28,
      "z": 3,
      "r": 90,
      "g": 90,
      "b": 95
    },
    {
      "x": 36,
      "y": 28,
      "z": 4,
      "r": 90,
      "g": 90,
      "b": 95
    },
    {
      "x": 37,
      "y": 28,
      "z": 3,
      "r": 90,
      "g": 90,
      "b": 95
    },
    {
      "x": 37,
      "y": 28,
      "z": 4,
      "r": 90,
      "g": 90,
      "b": 95
    },
    {
      "x": 38,
      "y": 28,
      "z": 3,
      "r": 90,
      "g": 90,
      "b": 95
    },
    {
      "x": 29,
      "y": 28,
      "z": 6,
      "r": 90,
      "g": 90,
      "b": 95
    },
    {
      "x": 30,
      "y": 28,
      "z": 6,
      "r": 90,
      "g": 90,
      "b": 95
    },
    {
      "x": 31,
      "y": 28,
      "z": 6,
      "r": 90,
      "g": 90,
      "b": 95
    },
    {
      "x": 32,
      "y": 28,
      "z": 6,
      "r": 90,
      "g": 90,
      "b": 95
    },
    {
      "x": 33,
      "y": 28,
      "z": 5,
      "r": 90,
      "g": 90,
      "b": 95
    },
    {
      "x": 33,
      "y": 28,
      "z": 6,
      "r": 90,
      "g": 90,
      "b": 95
    },
    {
      "x": 34,
      "y": 28,
      "z": 5,
      "r": 90,
      "g": 90,
      "b": 95
    },
    {
      "x": 34,
      "y": 28,
      "z": 6,
      "r": 90,
      "g": 90,
      "b": 95
    },
    {
      "x": 35,
      "y": 28,
      "z": 5,
      "r": 90,
      "g": 90,
      "b": 95
    },
    {
      "x": 35,
      "y": 28,
      "z": 6,
      "r": 90,
      "g": 90,
      "b": 95
    },
    {
      "x": 36,
      "y": 28,
      "z": 5,
      "r": 90,
      "g": 90,
      "b": 95
    },
    {
      "x": 36,
      "y": 28,
      "z": 6,
      "r": 90,
      "g": 90,
      "b": 95
    },
    {
      "x": 37,
      "y": 28,
      "z": 5,
      "r": 90,
      "g": 90,
      "b": 95
    },
    {
      "x": 37,
      "y": 28,
      "z": 6,
      "r": 90,
      "g": 90,
      "b": 95
    },
    {
      "x": 38,
      "y": 28,
      "z": 4,
      "r": 90,
      "g": 90,
      "b": 95
    },
    {
      "x": 38,
      "y": 28,
      "z": 5,
      "r": 90,
      "g": 90,
      "b": 95
    },
    {
      "x": 38,
      "y": 28,
      "z": 6,
      "r": 90,
      "g": 90,
      "b": 95
    },
    {
      "x": 10,
      "y": 31,
      "z": 10,
      "r": 90,
      "g": 90,
      "b": 95
    },
    {
      "x": 11,
      "y": 31,
      "z": 10,
      "r": 90,
      "g": 90,
      "b": 95
    },
    {
      "x": 12,
      "y": 31,
      "z": 10,
      "r": 90,
      "g": 90,
      "b": 95
    },
    {
      "x": 13,
      "y": 31,
      "z": 10,
      "r": 90,
      "g": 90,
      "b": 95
    },
    {
      "x": 13,
      "y": 32,
      "z": 10,
      "r": 90,
      "g": 90,
      "b": 95
    },
    {
      "x": 14,
      "y": 31,
      "z": 10,
      "r": 90,
      "g": 90,
      "b": 95
    },
    {
      "x": 14,
      "y": 32,
      "z": 10,
      "r": 90,
      "g": 90,
      "b": 95
    },
    {
      "x": 15,
      "y": 31,
      "z": 10,
      "r": 90,
      "g": 90,
      "b": 95
    },
    {
      "x": 15,
      "y": 32,
      "z": 10,
      "r": 90,
      "g": 90,
      "b": 95
    },
    {
      "x": 15,
      "y": 33,
      "z": 10,
      "r": 90,
      "g": 90,
      "b": 95
    },
    {
      "x": 16,
      "y": 31,
      "z": 10,
      "r": 90,
      "g": 90,
      "b": 95
    },
    {
      "x": 16,
      "y": 32,
      "z": 10,
      "r": 90,
      "g": 90,
      "b": 95
    },
    {
      "x": 16,
      "y": 33,
      "z": 10,
      "r": 90,
      "g": 90,
      "b": 95
    },
    {
      "x": 17,
      "y": 31,
      "z": 10,
      "r": 90,
      "g": 90,
      "b": 95
    },
    {
      "x": 17,
      "y": 32,
      "z": 10,
      "r": 90,
      "g": 90,
      "b": 95
    },
    {
      "x": 17,
      "y": 33,
      "z": 10,
      "r": 90,
      "g": 90,
      "b": 95
    },
    {
      "x": 17,
      "y": 34,
      "z": 10,
      "r": 90,
      "g": 90,
      "b": 95
    },
    {
      "x": 18,
      "y": 31,
      "z": 10,
      "r": 90,
      "g": 90,
      "b": 95
    },
    {
      "x": 18,
      "y": 32,
      "z": 10,
      "r": 90,
      "g": 90,
      "b": 95
    },
    {
      "x": 18,
      "y": 33,
      "z": 10,
      "r": 90,
      "g": 90,
      "b": 95
    },
    {
      "x": 18,
      "y": 34,
      "z": 10,
      "r": 90,
      "g": 90,
      "b": 95
    },
    {
      "x": 20,
      "y": 37,
      "z": 3,
      "r": 90,
      "g": 90,
      "b": 95
    },
    {
      "x": 20,
      "y": 37,
      "z": 4,
      "r": 90,
      "g": 90,
      "b": 95
    },
    {
      "x": 20,
      "y": 38,
      "z": 3,
      "r": 90,
      "g": 90,
      "b": 95
    },
    {
      "x": 21,
      "y": 37,
      "z": 3,
      "r": 90,
      "g": 90,
      "b": 95
    },
    {
      "x": 21,
      "y": 37,
      "z": 4,
      "r": 90,
      "g": 90,
      "b": 95
    },
    {
      "x": 22,
      "y": 36,
      "z": 3,
      "r": 90,
      "g": 90,
      "b": 95
    },
    {
      "x": 22,
      "y": 36,
      "z": 4,
      "r": 90,
      "g": 90,
      "b": 95
    },
    {
      "x": 22,
      "y": 37,
      "z": 3,
      "r": 90,
      "g": 90,
      "b": 95
    },
    {
      "x": 22,
      "y": 37,
      "z": 4,
      "r": 90,
      "g": 90,
      "b": 95
    },
    {
      "x": 23,
      "y": 36,
      "z": 3,
      "r": 90,
      "g": 90,
      "b": 95
    },
    {
      "x": 23,
      "y": 36,
      "z": 4,
      "r": 90,
      "g": 90,
      "b": 95
    },
    {
      "x": 24,
      "y": 35,
      "z": 3,
      "r": 90,
      "g": 90,
      "b": 95
    },
    {
      "x": 24,
      "y": 35,
      "z": 4,
      "r": 90,
      "g": 90,
      "b": 95
    },
    {
      "x": 24,
      "y": 36,
      "z": 3,
      "r": 90,
      "g": 90,
      "b": 95
    },
    {
      "x": 24,
      "y": 36,
      "z": 4,
      "r": 90,
      "g": 90,
      "b": 95
    },
    {
      "x": 25,
      "y": 35,
      "z": 3,
      "r": 90,
      "g": 90,
      "b": 95
    },
    {
      "x": 25,
      "y": 35,
      "z": 4,
      "r": 90,
      "g": 90,
      "b": 95
    },
    {
      "x": 25,
      "y": 35,
      "z": 5,
      "r": 90,
      "g": 90,
      "b": 95
    },
    {
      "x": 26,
      "y": 34,
      "z": 3,
      "r": 90,
      "g": 90,
      "b": 95
    },
    {
      "x": 26,
      "y": 34,
      "z": 4,
      "r": 90,
      "g": 90,
      "b": 95
    },
    {
      "x": 26,
      "y": 34,
      "z": 5,
      "r": 90,
      "g": 90,
      "b": 95
    },
    {
      "x": 26,
      "y": 35,
      "z": 3,
      "r": 90,
      "g": 90,
      "b": 95
    },
    {
      "x": 26,
      "y": 35,
      "z": 4,
      "r": 90,
      "g": 90,
      "b": 95
    },
    {
      "x": 26,
      "y": 35,
      "z": 5,
      "r": 90,
      "g": 90,
      "b": 95
    },
    {
      "x": 27,
      "y": 34,
      "z": 3,
      "r": 90,
      "g": 90,
      "b": 95
    },
    {
      "x": 27,
      "y": 34,
      "z": 4,
      "r": 90,
      "g": 90,
      "b": 95
    },
    {
      "x": 27,
      "y": 34,
      "z": 5,
      "r": 90,
      "g": 90,
      "b": 95
    },
    {
      "x": 28,
      "y": 34,
      "z": 3,
      "r": 90,
      "g": 90,
      "b": 95
    },
    {
      "x": 28,
      "y": 34,
      "z": 4,
      "r": 90,
      "g": 90,
      "b": 95
    },
    {
      "x": 28,
      "y": 34,
      "z": 5,
      "r": 90,
      "g": 90,
      "b": 95
    },
    {
      "x": 29,
      "y": 33,
      "z": 3,
      "r": 90,
      "g": 90,
      "b": 95
    },
    {
      "x": 29,
      "y": 33,
      "z": 4,
      "r": 90,
      "g": 90,
      "b": 95
    },
    {
      "x": 29,
      "y": 33,
      "z": 5,
      "r": 90,
      "g": 90,
      "b": 95
    },
    {
      "x": 29,
      "y": 33,
      "z": 6,
      "r": 90,
      "g": 90,
      "b": 95
    },
    {
      "x": 29,
      "y": 34,
      "z": 3,
      "r": 90,
      "g": 90,
      "b": 95
    },
    {
      "x": 29,
      "y": 34,
      "z": 4,
      "r": 90,
      "g": 90,
      "b": 95
    },
    {
      "x": 29,
      "y": 34,
      "z": 5,
      "r": 90,
      "g": 90,
      "b": 95
    },
    {
      "x": 30,
      "y": 33,
      "z": 3,
      "r": 90,
      "g": 90,
      "b": 95
    },
    {
      "x": 30,
      "y": 33,
      "z": 4,
      "r": 90,
      "g": 90,
      "b": 95
    },
    {
      "x": 30,
      "y": 33,
      "z": 5,
      "r": 90,
      "g": 90,
      "b": 95
    },
    {
      "x": 30,
      "y": 33,
      "z": 6,
      "r": 90,
      "g": 90,
      "b": 95
    },
    {
      "x": 31,
      "y": 32,
      "z": 3,
      "r": 90,
      "g": 90,
      "b": 95
    },
    {
      "x": 31,
      "y": 32,
      "z": 4,
      "r": 90,
      "g": 90,
      "b": 95
    },
    {
      "x": 31,
      "y": 32,
      "z": 5,
      "r": 90,
      "g": 90,
      "b": 95
    },
    {
      "x": 31,
      "y": 32,
      "z": 6,
      "r": 90,
      "g": 90,
      "b": 95
    },
    {
      "x": 31,
      "y": 33,
      "z": 3,
      "r": 90,
      "g": 90,
      "b": 95
    },
    {
      "x": 31,
      "y": 33,
      "z": 4,
      "r": 90,
      "g": 90,
      "b": 95
    },
    {
      "x": 31,
      "y": 33,
      "z": 5,
      "r": 90,
      "g": 90,
      "b": 95
    },
    {
      "x": 31,
      "y": 33,
      "z": 6,
      "r": 90,
      "g": 90,
      "b": 95
    },
    {
      "x": 32,
      "y": 32,
      "z": 3,
      "r": 90,
      "g": 90,
      "b": 95
    },
    {
      "x": 32,
      "y": 32,
      "z": 4,
      "r": 90,
      "g": 90,
      "b": 95
    },
    {
      "x": 32,
      "y": 32,
      "z": 5,
      "r": 90,
      "g": 90,
      "b": 95
    },
    {
      "x": 32,
      "y": 32,
      "z": 6,
      "r": 90,
      "g": 90,
      "b": 95
    },
    {
      "x": 33,
      "y": 31,
      "z": 3,
      "r": 90,
      "g": 90,
      "b": 95
    },
    {
      "x": 33,
      "y": 31,
      "z": 4,
      "r": 90,
      "g": 90,
      "b": 95
    },
    {
      "x": 33,
      "y": 31,
      "z": 5,
      "r": 90,
      "g": 90,
      "b": 95
    },
    {
      "x": 33,
      "y": 31,
      "z": 6,
      "r": 90,
      "g": 90,
      "b": 95
    },
    {
      "x": 33,
      "y": 32,
      "z": 3,
      "r": 90,
      "g": 90,
      "b": 95
    },
    {
      "x": 33,
      "y": 32,
      "z": 4,
      "r": 90,
      "g": 90,
      "b": 95
    },
    {
      "x": 33,
      "y": 32,
      "z": 5,
      "r": 90,
      "g": 90,
      "b": 95
    },
    {
      "x": 33,
      "y": 32,
      "z": 6,
      "r": 90,
      "g": 90,
      "b": 95
    },
    {
      "x": 34,
      "y": 31,
      "z": 3,
      "r": 90,
      "g": 90,
      "b": 95
    },
    {
      "x": 34,
      "y": 31,
      "z": 4,
      "r": 90,
      "g": 90,
      "b": 95
    },
    {
      "x": 34,
      "y": 31,
      "z": 5,
      "r": 90,
      "g": 90,
      "b": 95
    },
    {
      "x": 34,
      "y": 31,
      "z": 6,
      "r": 90,
      "g": 90,
      "b": 95
    },
    {
      "x": 35,
      "y": 30,
      "z": 3,
      "r": 90,
      "g": 90,
      "b": 95
    },
    {
      "x": 35,
      "y": 30,
      "z": 4,
      "r": 90,
      "g": 90,
      "b": 95
    },
    {
      "x": 35,
      "y": 30,
      "z": 5,
      "r": 90,
      "g": 90,
      "b": 95
    },
    {
      "x": 35,
      "y": 30,
      "z": 6,
      "r": 90,
      "g": 90,
      "b": 95
    },
    {
      "x": 35,
      "y": 31,
      "z": 3,
      "r": 90,
      "g": 90,
      "b": 95
    },
    {
      "x": 35,
      "y": 31,
      "z": 4,
      "r": 90,
      "g": 90,
      "b": 95
    },
    {
      "x": 35,
      "y": 31,
      "z": 5,
      "r": 90,
      "g": 90,
      "b": 95
    },
    {
      "x": 35,
      "y": 31,
      "z": 6,
      "r": 90,
      "g": 90,
      "b": 95
    },
    {
      "x": 36,
      "y": 30,
      "z": 3,
      "r": 90,
      "g": 90,
      "b": 95
    },
    {
      "x": 36,
      "y": 30,
      "z": 4,
      "r": 90,
      "g": 90,
      "b": 95
    },
    {
      "x": 36,
      "y": 30,
      "z": 5,
      "r": 90,
      "g": 90,
      "b": 95
    },
    {
      "x": 36,
      "y": 30,
      "z": 6,
      "r": 90,
      "g": 90,
      "b": 95
    },
    {
      "x": 37,
      "y": 29,
      "z": 3,
      "r": 90,
      "g": 90,
      "b": 95
    },
    {
      "x": 37,
      "y": 29,
      "z": 4,
      "r": 90,
      "g": 90,
      "b": 95
    },
    {
      "x": 37,
      "y": 29,
      "z": 5,
      "r": 90,
      "g": 90,
      "b": 95
    },
    {
      "x": 37,
      "y": 29,
      "z": 6,
      "r": 90,
      "g": 90,
      "b": 95
    },
    {
      "x": 37,
      "y": 30,
      "z": 3,
      "r": 90,
      "g": 90,
      "b": 95
    },
    {
      "x": 37,
      "y": 30,
      "z": 4,
      "r": 90,
      "g": 90,
      "b": 95
    },
    {
      "x": 37,
      "y": 30,
      "z": 5,
      "r": 90,
      "g": 90,
      "b": 95
    },
    {
      "x": 37,
      "y": 30,
      "z": 6,
      "r": 90,
      "g": 90,
      "b": 95
    },
    {
      "x": 38,
      "y": 29,
      "z": 3,
      "r": 90,
      "g": 90,
      "b": 95
    },
    {
      "x": 38,
      "y": 29,
      "z": 4,
      "r": 90,
      "g": 90,
      "b": 95
    },
    {
      "x": 38,
      "y": 29,
      "z": 5,
      "r": 90,
      "g": 90,
      "b": 95
    },
    {
      "x": 38,
      "y": 29,
      "z": 6,
      "r": 90,
      "g": 90,
      "b": 95
    },
    {
      "x": 20,
      "y": 37,
      "z": 5,
      "r": 90,
      "g": 90,
      "b": 95
    },
    {
      "x": 20,
      "y": 37,
      "z": 6,
      "r": 90,
      "g": 90,
      "b": 95
    },
    {
      "x": 20,
      "y": 38,
      "z": 4,
      "r": 90,
      "g": 90,
      "b": 95
    },
    {
      "x": 20,
      "y": 38,
      "z": 5,
      "r": 90,
      "g": 90,
      "b": 95
    },
    {
      "x": 20,
      "y": 38,
      "z": 6,
      "r": 90,
      "g": 90,
      "b": 95
    },
    {
      "x": 21,
      "y": 37,
      "z": 5,
      "r": 90,
      "g": 90,
      "b": 95
    },
    {
      "x": 21,
      "y": 37,
      "z": 6,
      "r": 90,
      "g": 90,
      "b": 95
    },
    {
      "x": 22,
      "y": 36,
      "z": 5,
      "r": 90,
      "g": 90,
      "b": 95
    },
    {
      "x": 22,
      "y": 36,
      "z": 6,
      "r": 90,
      "g": 90,
      "b": 95
    },
    {
      "x": 22,
      "y": 37,
      "z": 5,
      "r": 90,
      "g": 90,
      "b": 95
    },
    {
      "x": 22,
      "y": 37,
      "z": 6,
      "r": 90,
      "g": 90,
      "b": 95
    },
    {
      "x": 23,
      "y": 36,
      "z": 5,
      "r": 90,
      "g": 90,
      "b": 95
    },
    {
      "x": 23,
      "y": 36,
      "z": 6,
      "r": 90,
      "g": 90,
      "b": 95
    },
    {
      "x": 24,
      "y": 35,
      "z": 5,
      "r": 90,
      "g": 90,
      "b": 95
    },
    {
      "x": 24,
      "y": 35,
      "z": 6,
      "r": 90,
      "g": 90,
      "b": 95
    },
    {
      "x": 24,
      "y": 36,
      "z": 5,
      "r": 90,
      "g": 90,
      "b": 95
    },
    {
      "x": 24,
      "y": 36,
      "z": 6,
      "r": 90,
      "g": 90,
      "b": 95
    },
    {
      "x": 25,
      "y": 35,
      "z": 6,
      "r": 90,
      "g": 90,
      "b": 95
    },
    {
      "x": 26,
      "y": 34,
      "z": 6,
      "r": 90,
      "g": 90,
      "b": 95
    },
    {
      "x": 26,
      "y": 35,
      "z": 6,
      "r": 90,
      "g": 90,
      "b": 95
    },
    {
      "x": 27,
      "y": 34,
      "z": 6,
      "r": 90,
      "g": 90,
      "b": 95
    },
    {
      "x": 28,
      "y": 34,
      "z": 6,
      "r": 90,
      "g": 90,
      "b": 95
    },
    {
      "x": 29,
      "y": 34,
      "z": 6,
      "r": 90,
      "g": 90,
      "b": 95
    },
    {
      "x": 5,
      "y": 31,
      "z": 6,
      "r": 90,
      "g": 90,
      "b": 95
    },
    {
      "x": 6,
      "y": 31,
      "z": 6,
      "r": 90,
      "g": 90,
      "b": 95
    },
    {
      "x": 6,
      "y": 32,
      "z": 6,
      "r": 90,
      "g": 90,
      "b": 95
    },
    {
      "x": 7,
      "y": 32,
      "z": 6,
      "r": 90,
      "g": 90,
      "b": 95
    },
    {
      "x": 8,
      "y": 32,
      "z": 6,
      "r": 90,
      "g": 90,
      "b": 95
    },
    {
      "x": 8,
      "y": 33,
      "z": 6,
      "r": 90,
      "g": 90,
      "b": 95
    },
    {
      "x": 9,
      "y": 33,
      "z": 6,
      "r": 90,
      "g": 90,
      "b": 95
    },
    {
      "x": 10,
      "y": 33,
      "z": 5,
      "r": 90,
      "g": 90,
      "b": 95
    },
    {
      "x": 10,
      "y": 33,
      "z": 6,
      "r": 90,
      "g": 90,
      "b": 95
    },
    {
      "x": 10,
      "y": 34,
      "z": 5,
      "r": 90,
      "g": 90,
      "b": 95
    },
    {
      "x": 10,
      "y": 34,
      "z": 6,
      "r": 90,
      "g": 90,
      "b": 95
    },
    {
      "x": 11,
      "y": 34,
      "z": 5,
      "r": 90,
      "g": 90,
      "b": 95
    },
    {
      "x": 11,
      "y": 34,
      "z": 6,
      "r": 90,
      "g": 90,
      "b": 95
    },
    {
      "x": 12,
      "y": 34,
      "z": 5,
      "r": 90,
      "g": 90,
      "b": 95
    },
    {
      "x": 12,
      "y": 34,
      "z": 6,
      "r": 90,
      "g": 90,
      "b": 95
    },
    {
      "x": 13,
      "y": 34,
      "z": 5,
      "r": 90,
      "g": 90,
      "b": 95
    },
    {
      "x": 13,
      "y": 34,
      "z": 6,
      "r": 90,
      "g": 90,
      "b": 95
    },
    {
      "x": 13,
      "y": 35,
      "z": 5,
      "r": 90,
      "g": 90,
      "b": 95
    },
    {
      "x": 13,
      "y": 35,
      "z": 6,
      "r": 90,
      "g": 90,
      "b": 95
    },
    {
      "x": 14,
      "y": 35,
      "z": 4,
      "r": 90,
      "g": 90,
      "b": 95
    },
    {
      "x": 14,
      "y": 35,
      "z": 5,
      "r": 90,
      "g": 90,
      "b": 95
    },
    {
      "x": 14,
      "y": 35,
      "z": 6,
      "r": 90,
      "g": 90,
      "b": 95
    },
    {
      "x": 15,
      "y": 35,
      "z": 4,
      "r": 90,
      "g": 90,
      "b": 95
    },
    {
      "x": 15,
      "y": 35,
      "z": 5,
      "r": 90,
      "g": 90,
      "b": 95
    },
    {
      "x": 15,
      "y": 35,
      "z": 6,
      "r": 90,
      "g": 90,
      "b": 95
    },
    {
      "x": 15,
      "y": 36,
      "z": 4,
      "r": 90,
      "g": 90,
      "b": 95
    },
    {
      "x": 15,
      "y": 36,
      "z": 5,
      "r": 90,
      "g": 90,
      "b": 95
    },
    {
      "x": 15,
      "y": 36,
      "z": 6,
      "r": 90,
      "g": 90,
      "b": 95
    },
    {
      "x": 16,
      "y": 36,
      "z": 4,
      "r": 90,
      "g": 90,
      "b": 95
    },
    {
      "x": 16,
      "y": 36,
      "z": 5,
      "r": 90,
      "g": 90,
      "b": 95
    },
    {
      "x": 16,
      "y": 36,
      "z": 6,
      "r": 90,
      "g": 90,
      "b": 95
    },
    {
      "x": 17,
      "y": 36,
      "z": 4,
      "r": 90,
      "g": 90,
      "b": 95
    },
    {
      "x": 17,
      "y": 36,
      "z": 5,
      "r": 90,
      "g": 90,
      "b": 95
    },
    {
      "x": 17,
      "y": 36,
      "z": 6,
      "r": 90,
      "g": 90,
      "b": 95
    },
    {
      "x": 17,
      "y": 37,
      "z": 4,
      "r": 90,
      "g": 90,
      "b": 95
    },
    {
      "x": 17,
      "y": 37,
      "z": 5,
      "r": 90,
      "g": 90,
      "b": 95
    },
    {
      "x": 17,
      "y": 37,
      "z": 6,
      "r": 90,
